Workbook

Sheet README
A1: sheet | B1: purpose
A2: Simulated_Splits | B2: Chunk 1-6 style split-mechanics visuals and formulas.
A3: BreastCancer_Data | B3: Training/validation data with all tree features.
A4: Front_Input | B4: Manual what-if input panel like the original workbook.
A5: DTTable | B5: Decision table with leaf rules and formulas.
A6: Validation_Scoring | B6: Row-level rule evaluation and predictions via formulas only.
A7: Confusion_Metrics | B7: Confusion matrix, accuracy, precision, recall, F1 with charts.
A8: CP_Prune_Mechanics | B8: Root/stump/full xerror mechanics and cp-style curve.
A9: German_Data | B9: Chunk 7/20 German credit dataset with recoded target.
A10: German_Tree_Mechanics | B10: Chunk 7/20 tree-style rules, confusion and accuracy formulas.
A11: German_Caret_Tuning | B11: Chunk 22/23 caret-style cp tuning curve and predicted probabilities.
A12: AutoClaim_Data | B12: Chunk 15 cleaned AutoClaim with train/validation split.
... A15: Tree_Visuals | B15: Plotted tree diagrams for unpruned/pruned model proxies across chunks.

Sheet Simulated_Splits
A1: idx | B1: x1 | C1: x2 | D1: class | E1: split_v3 | F1: split_h2 | G1: split_h4 | I1: red_x | J1: red_y | K1: black_x | L1: black_y
A2: 1 | B2: =RAND()*4+1 | C2: =RAND()*4+1 | D2: =IF(OR(AND(B2>3,C2<4),AND(B2<=3,C2<2)),"Red","Black") | E2: 3 | F2: 2 | G2: 4 | I2: =IF(D2="Red",B2,NA()) | J2: =IF(D2="Red",C2,NA()) | K2: =IF(D2="Black",B2,NA()) | L2: =IF(D2="Black",C2,NA()) | N2: 3 | O2: 1
A3: 2 | B3: =RAND()*4+1 | C3: =RAND()*4+1 | D3: =IF(OR(AND(B3>3,C3<4),AND(B3<=3,C3<2)),"Red","Black") | E3: 3 | F3: 2 | G3: 4 | I3: =IF(D3="Red",B3,NA()) | J3: =IF(D3="Red",C3,NA()) | K3: =IF(D3="Black",B3,NA()) | L3: =IF(D3="Black",C3,NA()) | N3: 3 | O3: 5
A4: 3 | B4: =RAND()*4+1 | C4: =RAND()*4+1 | D4: =IF(OR(AND(B4>3,C4<4),AND(B4<=3,C4<2)),"Red","Black") | E4: 3 | F4: 2 | G4: 4 | I4: =IF(D4="Red",B4,NA()) | J4: =IF(D4="Red",C4,NA()) | K4: =IF(D4="Black",B4,NA()) | L4: =IF(D4="Black",C4,NA())
A5: 4 | B5: =RAND()*4+1 | C5: =RAND()*4+1 | D5: =IF(OR(AND(B5>3,C5<4),AND(B5<=3,C5<2)),"Red","Black") | E5: 3 | F5: 2 | G5: 4 | I5: =IF(D5="Red",B5,NA()) | J5: =IF(D5="Red",C5,NA()) | K5: =IF(D5="Black",B5,NA()) | L5: =IF(D5="Black",C5,NA()) | N5: 1 | O5: 2
A6: 5 | B6: =RAND()*4+1 | C6: =RAND()*4+1 | D6: =IF(OR(AND(B6>3,C6<4),AND(B6<=3,C6<2)),"Red","Black") | E6: 3 | F6: 2 | G6: 4 | I6: =IF(D6="Red",B6,NA()) | J6: =IF(D6="Red",C6,NA()) | K6: =IF(D6="Black",B6,NA()) | L6: =IF(D6="Black",C6,NA()) | N6: 3 | O6: 2
A7: 6 | B7: =RAND()*4+1 | C7: =RAND()*4+1 | D7: =IF(OR(AND(B7>3,C7<4),AND(B7<=3,C7<2)),"Red","Black") | E7: 3 | F7: 2 | G7: 4 | I7: =IF(D7="Red",B7,NA()) | J7: =IF(D7="Red",C7,NA()) | K7: =IF(D7="Black",B7,NA()) | L7: =IF(D7="Black",C7,NA())
A8: 7 | B8: =RAND()*4+1 | C8: =RAND()*4+1 | D8: =IF(OR(AND(B8>3,C8<4),AND(B8<=3,C8<2)),"Red","Black") | E8: 3 | F8: 2 | G8: 4 | I8: =IF(D8="Red",B8,NA()) | J8: =IF(D8="Red",C8,NA()) | K8: =IF(D8="Black",B8,NA()) | L8: =IF(D8="Black",C8,NA()) | N8: 3 | O8: 4
A9: 8 | B9: =RAND()*4+1 | C9: =RAND()*4+1 | D9: =IF(OR(AND(B9>3,C9<4),AND(B9<=3,C9<2)),"Red","Black") | E9: 3 | F9: 2 | G9: 4 | I9: =IF(D9="Red",B9,NA()) | J9: =IF(D9="Red",C9,NA()) | K9: =IF(D9="Black",B9,NA()) | L9: =IF(D9="Black",C9,NA()) | N9: 5 | O9: 4
A10: 9 | B10: =RAND()*4+1 | C10: =RAND()*4+1 | D10: =IF(OR(AND(B10>3,C10<4),AND(B10<=3,C10<2)),"Red","Black") | E10: 3 | F10: 2 | G10: 4 | I10: =IF(D10="Red",B10,NA()) | J10: =IF(D10="Red",C10,NA()) | K10: =IF(D10="Black",B10,NA()) | L10: =IF(D10="Black",C10,NA())
A11: 10 | B11: =RAND()*4+1 | C11: =RAND()*4+1 | D11: =IF(OR(AND(B11>3,C11<4),AND(B11<=3,C11<2)),"Red","Black") | E11: 3 | F11: 2 | G11: 4 | I11: =IF(D11="Red",B11,NA()) | J11: =IF(D11="Red",C11,NA()) | K11: =IF(D11="Black",B11,NA()) | L11: =IF(D11="Black",C11,NA())
A12: 11 | B12: =RAND()*4+1 | C12: =RAND()*4+1 | D12: =IF(OR(AND(B12>3,C12<4),AND(B12<=3,C12<2)),"Red","Black") | E12: 3 | F12: 2 | G12: 4 | I12: =IF(D12="Red",B12,NA()) | J12: =IF(D12="Red",C12,NA()) | K12: =IF(D12="Black",B12,NA()) | L12: =IF(D12="Black",C12,NA())
A13: 12 | B13: =RAND()*4+1 | C13: =RAND()*4+1 | D13: =IF(OR(AND(B13>3,C13<4),AND(B13<=3,C13<2)),"Red","Black") | E13: 3 | F13: 2 | G13: 4 | I13: =IF(D13="Red",B13,NA()) | J13: =IF(D13="Red",C13,NA()) | K13: =IF(D13="Black",B13,NA()) | L13: =IF(D13="Black",C13,NA())
A14: 13 | B14: =RAND()*4+1 | C14: =RAND()*4+1 | D14: =IF(OR(AND(B14>3,C14<4),AND(B14<=3,C14<2)),"Red","Black") | E14: 3 | F14: 2 | G14: 4 | I14: =IF(D14="Red",B14,NA()) | J14: =IF(D14="Red",C14,NA()) | K14: =IF(D14="Black",B14,NA()) | L14: =IF(D14="Black",C14,NA())
A15: 14 | B15: =RAND()*4+1 | C15: =RAND()*4+1 | D15: =IF(OR(AND(B15>3,C15<4),AND(B15<=3,C15<2)),"Red","Black") | E15: 3 | F15: 2 | G15: 4 | I15: =IF(D15="Red",B15,NA()) | J15: =IF(D15="Red",C15,NA()) | K15: =IF(D15="Black",B15,NA()) | L15: =IF(D15="Black",C15,NA())
A16: 15 | B16: =RAND()*4+1 | C16: =RAND()*4+1 | D16: =IF(OR(AND(B16>3,C16<4),AND(B16<=3,C16<2)),"Red","Black") | E16: 3 | F16: 2 | G16: 4 | I16: =IF(D16="Red",B16,NA()) | J16: =IF(D16="Red",C16,NA()) | K16: =IF(D16="Black",B16,NA()) | L16: =IF(D16="Black",C16,NA())
A17: 16 | B17: =RAND()*4+1 | C17: =RAND()*4+1 | D17: =IF(OR(AND(B17>3,C17<4),AND(B17<=3,C17<2)),"Red","Black") | E17: 3 | F17: 2 | G17: 4 | I17: =IF(D17="Red",B17,NA()) | J17: =IF(D17="Red",C17,NA()) | K17: =IF(D17="Black",B17,NA()) | L17: =IF(D17="Black",C17,NA())
A18: 17 | B18: =RAND()*4+1 | C18: =RAND()*4+1 | D18: =IF(OR(AND(B18>3,C18<4),AND(B18<=3,C18<2)),"Red","Black") | E18: 3 | F18: 2 | G18: 4 | I18: =IF(D18="Red",B18,NA()) | J18: =IF(D18="Red",C18,NA()) | K18: =IF(D18="Black",B18,NA()) | L18: =IF(D18="Black",C18,NA())
A19: 18 | B19: =RAND()*4+1 | C19: =RAND()*4+1 | D19: =IF(OR(AND(B19>3,C19<4),AND(B19<=3,C19<2)),"Red","Black") | E19: 3 | F19: 2 | G19: 4 | I19: =IF(D19="Red",B19,NA()) | J19: =IF(D19="Red",C19,NA()) | K19: =IF(D19="Black",B19,NA()) | L19: =IF(D19="Black",C19,NA())
A20: 19 | B20: =RAND()*4+1 | C20: =RAND()*4+1 | D20: =IF(OR(AND(B20>3,C20<4),AND(B20<=3,C20<2)),"Red","Black") | E20: 3 | F20: 2 | G20: 4 | I20: =IF(D20="Red",B20,NA()) | J20: =IF(D20="Red",C20,NA()) | K20: =IF(D20="Black",B20,NA()) | L20: =IF(D20="Black",C20,NA())
A21: 20 | B21: =RAND()*4+1 | C21: =RAND()*4+1 | D21: =IF(OR(AND(B21>3,C21<4),AND(B21<=3,C21<2)),"Red","Black") | E21: 3 | F21: 2 | G21: 4 | I21: =IF(D21="Red",B21,NA()) | J21: =IF(D21="Red",C21,NA()) | K21: =IF(D21="Black",B21,NA()) | L21: =IF(D21="Black",C21,NA())
... A501: 500 | B501: =RAND()*4+1 | C501: =RAND()*4+1 | D501: =IF(OR(AND(B501>3,C501<4),AND(B501<=3,C501<2)),"Red","Black") | E501: 3 | F501: 2 | G501: 4 | I501: =IF(D501="Red",B501,NA()) | J501: =IF(D501="Red",C501,NA()) | K501: =IF(D501="Black",B501,NA()) | L501: =IF(D501="Black",C501,NA())

Sheet BreastCancer_Data
A1: row_id | B1: set | C1: actual_label | D1: actual_num | E1: perimeter_worst | F1: points_worst | G1: radius_worst | H1: smoothness_worst | I1: texture_worst | J1: texture_mean | K1: fractal_dimension_worst | L1: concavity_worst | M1: concavity_se | N1: radius_mean | O1: area_worst
A2: 1 | B2: Train | C2: Malignant | D2: 1 | E2: 184.6 | F2: 0.2654 | G2: 25.38 | H2: 0.1622 | I2: 17.33 | J2: 10.38 | K2: 0.1189 | L2: 0.7119 | M2: 0.05373 | N2: 17.99 | O2: 2019
A3: 2 | B3: Train | C3: Malignant | D3: 1 | E3: 158.8 | F3: 0.186 | G3: 24.99 | H3: 0.1238 | I3: 23.41 | J3: 17.77 | K3: 0.08902 | L3: 0.2416 | M3: 0.0186 | N3: 20.57 | O3: 1956
A4: 3 | B4: Train | C4: Malignant | D4: 1 | E4: 152.5 | F4: 0.243 | G4: 23.57 | H4: 0.1444 | I4: 25.53 | J4: 21.25 | K4: 0.08758 | L4: 0.4504 | M4: 0.03832 | N4: 19.69 | O4: 1709
A5: 4 | B5: Train | C5: Malignant | D5: 1 | E5: 98.87 | F5: 0.2575 | G5: 14.91 | H5: 0.2098 | I5: 26.5 | J5: 20.38 | K5: 0.173 | L5: 0.6869 | M5: 0.05661 | N5: 11.42 | O5: 567.7
A6: 5 | B6: Train | C6: Malignant | D6: 1 | E6: 152.2 | F6: 0.1625 | G6: 22.54 | H6: 0.1374 | I6: 16.67 | J6: 14.34 | K6: 0.07678 | L6: 0.4 | M6: 0.05688 | N6: 20.29 | O6: 1575
A7: 6 | B7: Train | C7: Malignant | D7: 1 | E7: 103.4 | F7: 0.1741 | G7: 15.47 | H7: 0.1791 | I7: 23.75 | J7: 15.7 | K7: 0.1244 | L7: 0.5355 | M7: 0.03672 | N7: 12.45 | O7: 741.6
A8: 7 | B8: Train | C8: Malignant | D8: 1 | E8: 153.2 | F8: 0.1932 | G8: 22.88 | H8: 0.1442 | I8: 27.66 | J8: 19.98 | K8: 0.08368 | L8: 0.3784 | M8: 0.02254 | N8: 18.25 | O8: 1606
A9: 9 | B9: Train | C9: Malignant | D9: 1 | E9: 106.2 | F9: 0.206 | G9: 15.49 | H9: 0.1703 | I9: 30.73 | J9: 21.82 | K9: 0.1072 | L9: 0.539 | M9: 0.03553 | N9: 13 | O9: 739.3
A10: 11 | B10: Train | C10: Malignant | D10: 1 | E10: 123.8 | F10: 0.09975 | G10: 19.19 | H10: 0.1181 | I10: 33.88 | J10: 23.24 | K10: 0.08452 | L10: 0.1459 | M10: 0.01101 | N10: 16.02 | O10: 1150
A11: 12 | B11: Train | C11: Malignant | D11: 1 | E11: 136.5 | F11: 0.181 | G11: 20.42 | H11: 0.1396 | I11: 27.28 | J11: 17.89 | K11: 0.1048 | L11: 0.3965 | M11: 0.02791 | N11: 15.78 | O11: 1299
A12: 13 | B12: Train | C12: Malignant | D12: 1 | E12: 151.7 | F12: 0.1767 | G12: 20.96 | H12: 0.1037 | I12: 29.94 | J12: 24.8 | K12: 0.1023 | L12: 0.3639 | M12: 0.0889 | N12: 19.17 | O12: 1332
A13: 15 | B13: Train | C13: Malignant | D13: 1 | E13: 108.8 | F13: 0.2208 | G13: 15.03 | H13: 0.1651 | I13: 32.01 | J13: 22.61 | K13: 0.1431 | L13: 0.6943 | M13: 0.05501 | N13: 13.73 | O13: 697.7
... A570: 565 | B570: Validation | C570: Malignant | D570: 1 | E570: 166.1 | F570: 0.2216 | G570: 25.45 | H570: 0.141 | I570: 26.4 | J570: 22.39 | K570: 0.07115 | L570: 0.4107 | M570: 0.05198 | N570: 21.56 | O570: 2027

Sheet Front_Input
A1: texture_worst | B1: 1 | D1: Average result | E1: =AVERAGE(DTTable!A:A)
A2: fractal_dimension_worst | B2: 1
A3: radius_worst | B3: 1
A4: radius_mean | B4: 1
A5: concavity_se | B5: 1
A6: perimeter_worst | B6: 1
A7: texture_mean | B7: 1
A8: concavity_worst | B8: 1
A9: points_worst | B9: 1
A10: smoothness_worst | B10: 1
A11: area_worst | B11: 1

Sheet DTTable
A1: =IF(B1,0,"") | B1: =AND(C1:G1) | C1: =Front_Input!$B$6<=113.15 | D1: =Front_Input!$B$9<=0.15 | E1: =Front_Input!$B$3<=15.77 | F1: =Front_Input!$B$10<=0.18 | G1: =Front_Input!$B$1<=33.27
A2: =IF(B2,0,"") | B2: =AND(C2:G2) | C2: =Front_Input!$B$6<=113.15 | D2: =Front_Input!$B$9<=0.15 | E2: =Front_Input!$B$3<=15.77 | F2: =Front_Input!$B$10<=0.18 | G2: =Front_Input!$B$1>33.27
A3: =IF(B3,0,"") | B3: =AND(C3:G3) | C3: =Front_Input!$B$6<=113.15 | D3: =Front_Input!$B$9<=0.15 | E3: =Front_Input!$B$3<=15.77 | F3: =Front_Input!$B$10>0.18 | G3: =Front_Input!1=1
A4: =IF(B4,0,"") | B4: =AND(C4:G4) | C4: =Front_Input!$B$6<=113.15 | D4: =Front_Input!$B$9<=0.15 | E4: =Front_Input!$B$3>15.77 | F4: =Front_Input!$B$1<=28.86 | G4: =Front_Input!$B$10<=0.14
A5: =IF(B5,1,"") | B5: =AND(C5:G5) | C5: =Front_Input!$B$6<=113.15 | D5: =Front_Input!$B$9<=0.15 | E5: =Front_Input!$B$3>15.77 | F5: =Front_Input!$B$1<=28.86 | G5: =Front_Input!$B$10>0.14
A6: =IF(B6,1,"") | B6: =AND(C6:G6) | C6: =Front_Input!$B$6<=113.15 | D6: =Front_Input!$B$9<=0.15 | E6: =Front_Input!$B$3>15.77 | F6: =Front_Input!$B$1>28.86 | G6: =Front_Input!$B$4<=14.54
A7: =IF(B7,1,"") | B7: =AND(C7:G7) | C7: =Front_Input!$B$6<=113.15 | D7: =Front_Input!$B$9<=0.15 | E7: =Front_Input!$B$3>15.77 | F7: =Front_Input!$B$1>28.86 | G7: =Front_Input!$B$4>14.54
A8: =IF(B8,0,"") | B8: =AND(C8:G8) | C8: =Front_Input!$B$6<=113.15 | D8: =Front_Input!$B$9>0.15 | E8: =Front_Input!$B$1<=23.74 | F8: =Front_Input!1=1 | G8: =Front_Input!1=1
A9: =IF(B9,1,"") | B9: =AND(C9:G9) | C9: =Front_Input!$B$6<=113.15 | D9: =Front_Input!$B$9>0.15 | E9: =Front_Input!$B$1>23.74 | F9: =Front_Input!$B$2<=0.1 | G9: =Front_Input!1=1
A10: =IF(B10,1,"") | B10: =AND(C10:G10) | C10: =Front_Input!$B$6<=113.15 | D10: =Front_Input!$B$9>0.15 | E10: =Front_Input!$B$1>23.74 | F10: =Front_Input!$B$2>0.1 | G10: =Front_Input!1=1
A11: =IF(B11,1,"") | B11: =AND(C11:G11) | C11: =Front_Input!$B$6>113.15 | D11: =Front_Input!$B$8<=0.22 | E11: =Front_Input!$B$5<=0.02 | F11: =Front_Input!1=1 | G11: =Front_Input!1=1
A12: =IF(B12,0,"") | B12: =AND(C12:G12) | C12: =Front_Input!$B$6>113.15 | D12: =Front_Input!$B$8<=0.22 | E12: =Front_Input!$B$5>0.02 | F12: =Front_Input!1=1 | G12: =Front_Input!1=1
A13: =IF(B13,0,"") | B13: =AND(C13:G13) | C13: =Front_Input!$B$6>113.15 | D13: =Front_Input!$B$8>0.22 | E13: =Front_Input!$B$11<=810.1 | F13: =Front_Input!1=1 | G13: =Front_Input!1=1
A14: =IF(B14,1,"") | B14: =AND(C14:G14) | C14: =Front_Input!$B$6>113.15 | D14: =Front_Input!$B$8>0.22 | E14: =Front_Input!$B$11>810.1 | F14: =Front_Input!$B$7<=14.95 | G14: =Front_Input!1=1
A15: =IF(B15,1,"") | B15: =AND(C15:G15) | C15: =Front_Input!$B$6>113.15 | D15: =Front_Input!$B$8>0.22 | E15: =Front_Input!$B$11>810.1 | F15: =Front_Input!$B$7>14.95 | G15: =Front_Input!1=1

Sheet Validation_Scoring
A1: row_id | B1: set | C1: actual_num | D1: perimeter_worst | E1: points_worst | F1: radius_worst | G1: smoothness_worst | H1: texture_worst | I1: texture_mean | J1: fractal_dimension_worst | K1: concavity_worst | L1: concavity_se | M1: radius_mean | N1: area_worst | O1: leaf_01 | P1: leaf_02 | Q1: leaf_03 | R1: leaf_04 | S1: leaf_05 | T1: leaf_06 | U1: leaf_07 | V1: leaf_08 | W1: leaf_09 | X1: leaf_10 | Y1: leaf_11 | Z1: leaf_12 | AA1: leaf_13 | AB1: leaf_14 | AC1: leaf_15 | AD1: pred_num | AE1: pred_label | AF1: correct
A2: =BreastCancer_Data!A2 | B2: =BreastCancer_Data!B2 | C2: =BreastCancer_Data!D2 | D2: =BreastCancer_Data!E2 | E2: =BreastCancer_Data!F2 | F2: =BreastCancer_Data!G2 | G2: =BreastCancer_Data!H2 | H2: =BreastCancer_Data!I2 | I2: =BreastCancer_Data!J2 | J2: =BreastCancer_Data!K2 | ... N2: =BreastCancer_Data!O2 | O2: =0 | P2: =--(AND(D2<=113.15,E2<=0.15,F2<=15.77,G2<=0.18,H2<=33.27))*0 | Q2: =--(AND(D2<=113.15,E2<=0.15,F2<=15.77,G2<=0.18,H2>33.27))*0 | R2: =--(AND(D2<=113.15,E2<=0.15,F2<=15.77,G2>0.18))*0 | S2: =--(AND(D2<=113.15,E2<=0.15,F2>15.77,H2<=28.86,G2<=0.14))*0 | T2: =--(AND(D2<=113.15,E2<=0.15,F2>15.77,H2<=28.86,G2>0.14))*1 | U2: =--(AND(D2<=113.15,E2<=0.15,F2>15.77,H2>28.86,M2<=14.54))*1 | V2: =--(AND(D2<=113.15,E2<=0.15,F2>15.77,H2>28.86,M2>14.54))*1 | W2: =--(AND(D2<=113.15,E2>0.15,H2<=23.74))*0 | X2: =--(AND(D2<=113.15,E2>0.15,H2>23.74,J2<=0.1))*1 | Y2: =--(AND(D2<=113.15,E2>0.15,H2>23.74,J2>0.1))*1 | Z2: =--(AND(D2>113.15,K2<=0.22,L2<=0.02))*1 | AA2: =--(AND(D2>113.15,K2<=0.22,L2>0.02))*0 | AB2: =--(AND(D2>113.15,K2>0.22,N2<=810.1))*0 | AC2: =--(AND(D2>113.15,K2>0.22,N2>810.1,I2<=14.95))*1 | AD2: =--(AND(D2>113.15,K2>0.22,N2>810.1,I2>14.95))*1 | AE2: =SUM(P2:AD2) | AF2: =IF(AE2=1,"Malignant","Benign") | AG2: =--(AE2=C2)
A3: =BreastCancer_Data!A3 | B3: =BreastCancer_Data!B3 | C3: =BreastCancer_Data!D3 | D3: =BreastCancer_Data!E3 | E3: =BreastCancer_Data!F3 | F3: =BreastCancer_Data!G3 | G3: =BreastCancer_Data!H3 | H3: =BreastCancer_Data!I3 | I3: =BreastCancer_Data!J3 | J3: =BreastCancer_Data!K3 | ... N3: =BreastCancer_Data!O3 | O3: =0 | P3: =--(AND(D3<=113.15,E3<=0.15,F3<=15.77,G3<=0.18,H3<=33.27))*0 | Q3: =--(AND(D3<=113.15,E3<=0.15,F3<=15.77,G3<=0.18,H3>33.27))*0 | R3: =--(AND(D3<=113.15,E3<=0.15,F3<=15.77,G3>0.18))*0 | S3: =--(AND(D3<=113.15,E3<=0.15,F3>15.77,H3<=28.86,G3<=0.14))*0 | T3: =--(AND(D3<=113.15,E3<=0.15,F3>15.77,H3<=28.86,G3>0.14))*1 | U3: =--(AND(D3<=113.15,E3<=0.15,F3>15.77,H3>28.86,M3<=14.54))*1 | V3: =--(AND(D3<=113.15,E3<=0.15,F3>15.77,H3>28.86,M3>14.54))*1 | W3: =--(AND(D3<=113.15,E3>0.15,H3<=23.74))*0 | X3: =--(AND(D3<=113.15,E3>0.15,H3>23.74,J3<=0.1))*1 | Y3: =--(AND(D3<=113.15,E3>0.15,H3>23.74,J3>0.1))*1 | Z3: =--(AND(D3>113.15,K3<=0.22,L3<=0.02))*1 | AA3: =--(AND(D3>113.15,K3<=0.22,L3>0.02))*0 | AB3: =--(AND(D3>113.15,K3>0.22,N3<=810.1))*0 | AC3: =--(AND(D3>113.15,K3>0.22,N3>810.1,I3<=14.95))*1 | AD3: =--(AND(D3>113.15,K3>0.22,N3>810.1,I3>14.95))*1 | AE3: =SUM(P3:AD3) | AF3: =IF(AE3=1,"Malignant","Benign") | AG3: =--(AE3=C3)
A4: =BreastCancer_Data!A4 | B4: =BreastCancer_Data!B4 | C4: =BreastCancer_Data!D4 | D4: =BreastCancer_Data!E4 | E4: =BreastCancer_Data!F4 | F4: =BreastCancer_Data!G4 | G4: =BreastCancer_Data!H4 | H4: =BreastCancer_Data!I4 | I4: =BreastCancer_Data!J4 | J4: =BreastCancer_Data!K4 | ... N4: =BreastCancer_Data!O4 | O4: =0 | P4: =--(AND(D4<=113.15,E4<=0.15,F4<=15.77,G4<=0.18,H4<=33.27))*0 | Q4: =--(AND(D4<=113.15,E4<=0.15,F4<=15.77,G4<=0.18,H4>33.27))*0 | R4: =--(AND(D4<=113.15,E4<=0.15,F4<=15.77,G4>0.18))*0 | S4: =--(AND(D4<=113.15,E4<=0.15,F4>15.77,H4<=28.86,G4<=0.14))*0 | T4: =--(AND(D4<=113.15,E4<=0.15,F4>15.77,H4<=28.86,G4>0.14))*1 | U4: =--(AND(D4<=113.15,E4<=0.15,F4>15.77,H4>28.86,M4<=14.54))*1 | V4: =--(AND(D4<=113.15,E4<=0.15,F4>15.77,H4>28.86,M4>14.54))*1 | W4: =--(AND(D4<=113.15,E4>0.15,H4<=23.74))*0 | X4: =--(AND(D4<=113.15,E4>0.15,H4>23.74,J4<=0.1))*1 | Y4: =--(AND(D4<=113.15,E4>0.15,H4>23.74,J4>0.1))*1 | Z4: =--(AND(D4>113.15,K4<=0.22,L4<=0.02))*1 | AA4: =--(AND(D4>113.15,K4<=0.22,L4>0.02))*0 | AB4: =--(AND(D4>113.15,K4>0.22,N4<=810.1))*0 | AC4: =--(AND(D4>113.15,K4>0.22,N4>810.1,I4<=14.95))*1 | AD4: =--(AND(D4>113.15,K4>0.22,N4>810.1,I4>14.95))*1 | AE4: =SUM(P4:AD4) | AF4: =IF(AE4=1,"Malignant","Benign") | AG4: =--(AE4=C4)
A5: =BreastCancer_Data!A5 | B5: =BreastCancer_Data!B5 | C5: =BreastCancer_Data!D5 | D5: =BreastCancer_Data!E5 | E5: =BreastCancer_Data!F5 | F5: =BreastCancer_Data!G5 | G5: =BreastCancer_Data!H5 | H5: =BreastCancer_Data!I5 | I5: =BreastCancer_Data!J5 | J5: =BreastCancer_Data!K5 | ... N5: =BreastCancer_Data!O5 | O5: =0 | P5: =--(AND(D5<=113.15,E5<=0.15,F5<=15.77,G5<=0.18,H5<=33.27))*0 | Q5: =--(AND(D5<=113.15,E5<=0.15,F5<=15.77,G5<=0.18,H5>33.27))*0 | R5: =--(AND(D5<=113.15,E5<=0.15,F5<=15.77,G5>0.18))*0 | S5: =--(AND(D5<=113.15,E5<=0.15,F5>15.77,H5<=28.86,G5<=0.14))*0 | T5: =--(AND(D5<=113.15,E5<=0.15,F5>15.77,H5<=28.86,G5>0.14))*1 | U5: =--(AND(D5<=113.15,E5<=0.15,F5>15.77,H5>28.86,M5<=14.54))*1 | V5: =--(AND(D5<=113.15,E5<=0.15,F5>15.77,H5>28.86,M5>14.54))*1 | W5: =--(AND(D5<=113.15,E5>0.15,H5<=23.74))*0 | X5: =--(AND(D5<=113.15,E5>0.15,H5>23.74,J5<=0.1))*1 | Y5: =--(AND(D5<=113.15,E5>0.15,H5>23.74,J5>0.1))*1 | Z5: =--(AND(D5>113.15,K5<=0.22,L5<=0.02))*1 | AA5: =--(AND(D5>113.15,K5<=0.22,L5>0.02))*0 | AB5: =--(AND(D5>113.15,K5>0.22,N5<=810.1))*0 | AC5: =--(AND(D5>113.15,K5>0.22,N5>810.1,I5<=14.95))*1 | AD5: =--(AND(D5>113.15,K5>0.22,N5>810.1,I5>14.95))*1 | AE5: =SUM(P5:AD5) | AF5: =IF(AE5=1,"Malignant","Benign") | AG5: =--(AE5=C5)
A6: =BreastCancer_Data!A6 | B6: =BreastCancer_Data!B6 | C6: =BreastCancer_Data!D6 | D6: =BreastCancer_Data!E6 | E6: =BreastCancer_Data!F6 | F6: =BreastCancer_Data!G6 | G6: =BreastCancer_Data!H6 | H6: =BreastCancer_Data!I6 | I6: =BreastCancer_Data!J6 | J6: =BreastCancer_Data!K6 | ... N6: =BreastCancer_Data!O6 | O6: =0 | P6: =--(AND(D6<=113.15,E6<=0.15,F6<=15.77,G6<=0.18,H6<=33.27))*0 | Q6: =--(AND(D6<=113.15,E6<=0.15,F6<=15.77,G6<=0.18,H6>33.27))*0 | R6: =--(AND(D6<=113.15,E6<=0.15,F6<=15.77,G6>0.18))*0 | S6: =--(AND(D6<=113.15,E6<=0.15,F6>15.77,H6<=28.86,G6<=0.14))*0 | T6: =--(AND(D6<=113.15,E6<=0.15,F6>15.77,H6<=28.86,G6>0.14))*1 | U6: =--(AND(D6<=113.15,E6<=0.15,F6>15.77,H6>28.86,M6<=14.54))*1 | V6: =--(AND(D6<=113.15,E6<=0.15,F6>15.77,H6>28.86,M6>14.54))*1 | W6: =--(AND(D6<=113.15,E6>0.15,H6<=23.74))*0 | X6: =--(AND(D6<=113.15,E6>0.15,H6>23.74,J6<=0.1))*1 | Y6: =--(AND(D6<=113.15,E6>0.15,H6>23.74,J6>0.1))*1 | Z6: =--(AND(D6>113.15,K6<=0.22,L6<=0.02))*1 | AA6: =--(AND(D6>113.15,K6<=0.22,L6>0.02))*0 | AB6: =--(AND(D6>113.15,K6>0.22,N6<=810.1))*0 | AC6: =--(AND(D6>113.15,K6>0.22,N6>810.1,I6<=14.95))*1 | AD6: =--(AND(D6>113.15,K6>0.22,N6>810.1,I6>14.95))*1 | AE6: =SUM(P6:AD6) | AF6: =IF(AE6=1,"Malignant","Benign") | AG6: =--(AE6=C6)
A7: =BreastCancer_Data!A7 | B7: =BreastCancer_Data!B7 | C7: =BreastCancer_Data!D7 | D7: =BreastCancer_Data!E7 | E7: =BreastCancer_Data!F7 | F7: =BreastCancer_Data!G7 | G7: =BreastCancer_Data!H7 | H7: =BreastCancer_Data!I7 | I7: =BreastCancer_Data!J7 | J7: =BreastCancer_Data!K7 | ... N7: =BreastCancer_Data!O7 | O7: =0 | P7: =--(AND(D7<=113.15,E7<=0.15,F7<=15.77,G7<=0.18,H7<=33.27))*0 | Q7: =--(AND(D7<=113.15,E7<=0.15,F7<=15.77,G7<=0.18,H7>33.27))*0 | R7: =--(AND(D7<=113.15,E7<=0.15,F7<=15.77,G7>0.18))*0 | S7: =--(AND(D7<=113.15,E7<=0.15,F7>15.77,H7<=28.86,G7<=0.14))*0 | T7: =--(AND(D7<=113.15,E7<=0.15,F7>15.77,H7<=28.86,G7>0.14))*1 | U7: =--(AND(D7<=113.15,E7<=0.15,F7>15.77,H7>28.86,M7<=14.54))*1 | V7: =--(AND(D7<=113.15,E7<=0.15,F7>15.77,H7>28.86,M7>14.54))*1 | W7: =--(AND(D7<=113.15,E7>0.15,H7<=23.74))*0 | X7: =--(AND(D7<=113.15,E7>0.15,H7>23.74,J7<=0.1))*1 | Y7: =--(AND(D7<=113.15,E7>0.15,H7>23.74,J7>0.1))*1 | Z7: =--(AND(D7>113.15,K7<=0.22,L7<=0.02))*1 | AA7: =--(AND(D7>113.15,K7<=0.22,L7>0.02))*0 | AB7: =--(AND(D7>113.15,K7>0.22,N7<=810.1))*0 | AC7: =--(AND(D7>113.15,K7>0.22,N7>810.1,I7<=14.95))*1 | AD7: =--(AND(D7>113.15,K7>0.22,N7>810.1,I7>14.95))*1 | AE7: =SUM(P7:AD7) | AF7: =IF(AE7=1,"Malignant","Benign") | AG7: =--(AE7=C7)
A8: =BreastCancer_Data!A8 | B8: =BreastCancer_Data!B8 | C8: =BreastCancer_Data!D8 | D8: =BreastCancer_Data!E8 | E8: =BreastCancer_Data!F8 | F8: =BreastCancer_Data!G8 | G8: =BreastCancer_Data!H8 | H8: =BreastCancer_Data!I8 | I8: =BreastCancer_Data!J8 | J8: =BreastCancer_Data!K8 | ... N8: =BreastCancer_Data!O8 | O8: =0 | P8: =--(AND(D8<=113.15,E8<=0.15,F8<=15.77,G8<=0.18,H8<=33.27))*0 | Q8: =--(AND(D8<=113.15,E8<=0.15,F8<=15.77,G8<=0.18,H8>33.27))*0 | R8: =--(AND(D8<=113.15,E8<=0.15,F8<=15.77,G8>0.18))*0 | S8: =--(AND(D8<=113.15,E8<=0.15,F8>15.77,H8<=28.86,G8<=0.14))*0 | T8: =--(AND(D8<=113.15,E8<=0.15,F8>15.77,H8<=28.86,G8>0.14))*1 | U8: =--(AND(D8<=113.15,E8<=0.15,F8>15.77,H8>28.86,M8<=14.54))*1 | V8: =--(AND(D8<=113.15,E8<=0.15,F8>15.77,H8>28.86,M8>14.54))*1 | W8: =--(AND(D8<=113.15,E8>0.15,H8<=23.74))*0 | X8: =--(AND(D8<=113.15,E8>0.15,H8>23.74,J8<=0.1))*1 | Y8: =--(AND(D8<=113.15,E8>0.15,H8>23.74,J8>0.1))*1 | Z8: =--(AND(D8>113.15,K8<=0.22,L8<=0.02))*1 | AA8: =--(AND(D8>113.15,K8<=0.22,L8>0.02))*0 | AB8: =--(AND(D8>113.15,K8>0.22,N8<=810.1))*0 | AC8: =--(AND(D8>113.15,K8>0.22,N8>810.1,I8<=14.95))*1 | AD8: =--(AND(D8>113.15,K8>0.22,N8>810.1,I8>14.95))*1 | AE8: =SUM(P8:AD8) | AF8: =IF(AE8=1,"Malignant","Benign") | AG8: =--(AE8=C8)
A9: =BreastCancer_Data!A9 | B9: =BreastCancer_Data!B9 | C9: =BreastCancer_Data!D9 | D9: =BreastCancer_Data!E9 | E9: =BreastCancer_Data!F9 | F9: =BreastCancer_Data!G9 | G9: =BreastCancer_Data!H9 | H9: =BreastCancer_Data!I9 | I9: =BreastCancer_Data!J9 | J9: =BreastCancer_Data!K9 | ... N9: =BreastCancer_Data!O9 | O9: =0 | P9: =--(AND(D9<=113.15,E9<=0.15,F9<=15.77,G9<=0.18,H9<=33.27))*0 | Q9: =--(AND(D9<=113.15,E9<=0.15,F9<=15.77,G9<=0.18,H9>33.27))*0 | R9: =--(AND(D9<=113.15,E9<=0.15,F9<=15.77,G9>0.18))*0 | S9: =--(AND(D9<=113.15,E9<=0.15,F9>15.77,H9<=28.86,G9<=0.14))*0 | T9: =--(AND(D9<=113.15,E9<=0.15,F9>15.77,H9<=28.86,G9>0.14))*1 | U9: =--(AND(D9<=113.15,E9<=0.15,F9>15.77,H9>28.86,M9<=14.54))*1 | V9: =--(AND(D9<=113.15,E9<=0.15,F9>15.77,H9>28.86,M9>14.54))*1 | W9: =--(AND(D9<=113.15,E9>0.15,H9<=23.74))*0 | X9: =--(AND(D9<=113.15,E9>0.15,H9>23.74,J9<=0.1))*1 | Y9: =--(AND(D9<=113.15,E9>0.15,H9>23.74,J9>0.1))*1 | Z9: =--(AND(D9>113.15,K9<=0.22,L9<=0.02))*1 | AA9: =--(AND(D9>113.15,K9<=0.22,L9>0.02))*0 | AB9: =--(AND(D9>113.15,K9>0.22,N9<=810.1))*0 | AC9: =--(AND(D9>113.15,K9>0.22,N9>810.1,I9<=14.95))*1 | AD9: =--(AND(D9>113.15,K9>0.22,N9>810.1,I9>14.95))*1 | AE9: =SUM(P9:AD9) | AF9: =IF(AE9=1,"Malignant","Benign") | AG9: =--(AE9=C9)
A10: =BreastCancer_Data!A10 | B10: =BreastCancer_Data!B10 | C10: =BreastCancer_Data!D10 | D10: =BreastCancer_Data!E10 | E10: =BreastCancer_Data!F10 | F10: =BreastCancer_Data!G10 | G10: =BreastCancer_Data!H10 | H10: =BreastCancer_Data!I10 | I10: =BreastCancer_Data!J10 | J10: =BreastCancer_Data!K10 | ... N10: =BreastCancer_Data!O10 | O10: =0 | P10: =--(AND(D10<=113.15,E10<=0.15,F10<=15.77,G10<=0.18,H10<=33.27))*0 | Q10: =--(AND(D10<=113.15,E10<=0.15,F10<=15.77,G10<=0.18,H10>33.27))*0 | R10: =--(AND(D10<=113.15,E10<=0.15,F10<=15.77,G10>0.18))*0 | S10: =--(AND(D10<=113.15,E10<=0.15,F10>15.77,H10<=28.86,G10<=0.14))*0 | T10: =--(AND(D10<=113.15,E10<=0.15,F10>15.77,H10<=28.86,G10>0.14))*1 | U10: =--(AND(D10<=113.15,E10<=0.15,F10>15.77,H10>28.86,M10<=14.54))*1 | V10: =--(AND(D10<=113.15,E10<=0.15,F10>15.77,H10>28.86,M10>14.54))*1 | W10: =--(AND(D10<=113.15,E10>0.15,H10<=23.74))*0 | X10: =--(AND(D10<=113.15,E10>0.15,H10>23.74,J10<=0.1))*1 | Y10: =--(AND(D10<=113.15,E10>0.15,H10>23.74,J10>0.1))*1 | Z10: =--(AND(D10>113.15,K10<=0.22,L10<=0.02))*1 | AA10: =--(AND(D10>113.15,K10<=0.22,L10>0.02))*0 | AB10: =--(AND(D10>113.15,K10>0.22,N10<=810.1))*0 | AC10: =--(AND(D10>113.15,K10>0.22,N10>810.1,I10<=14.95))*1 | AD10: =--(AND(D10>113.15,K10>0.22,N10>810.1,I10>14.95))*1 | AE10: =SUM(P10:AD10) | AF10: =IF(AE10=1,"Malignant","Benign") | AG10: =--(AE10=C10)
A11: =BreastCancer_Data!A11 | B11: =BreastCancer_Data!B11 | C11: =BreastCancer_Data!D11 | D11: =BreastCancer_Data!E11 | E11: =BreastCancer_Data!F11 | F11: =BreastCancer_Data!G11 | G11: =BreastCancer_Data!H11 | H11: =BreastCancer_Data!I11 | I11: =BreastCancer_Data!J11 | J11: =BreastCancer_Data!K11 | ... N11: =BreastCancer_Data!O11 | O11: =0 | P11: =--(AND(D11<=113.15,E11<=0.15,F11<=15.77,G11<=0.18,H11<=33.27))*0 | Q11: =--(AND(D11<=113.15,E11<=0.15,F11<=15.77,G11<=0.18,H11>33.27))*0 | R11: =--(AND(D11<=113.15,E11<=0.15,F11<=15.77,G11>0.18))*0 | S11: =--(AND(D11<=113.15,E11<=0.15,F11>15.77,H11<=28.86,G11<=0.14))*0 | T11: =--(AND(D11<=113.15,E11<=0.15,F11>15.77,H11<=28.86,G11>0.14))*1 | U11: =--(AND(D11<=113.15,E11<=0.15,F11>15.77,H11>28.86,M11<=14.54))*1 | V11: =--(AND(D11<=113.15,E11<=0.15,F11>15.77,H11>28.86,M11>14.54))*1 | W11: =--(AND(D11<=113.15,E11>0.15,H11<=23.74))*0 | X11: =--(AND(D11<=113.15,E11>0.15,H11>23.74,J11<=0.1))*1 | Y11: =--(AND(D11<=113.15,E11>0.15,H11>23.74,J11>0.1))*1 | Z11: =--(AND(D11>113.15,K11<=0.22,L11<=0.02))*1 | AA11: =--(AND(D11>113.15,K11<=0.22,L11>0.02))*0 | AB11: =--(AND(D11>113.15,K11>0.22,N11<=810.1))*0 | AC11: =--(AND(D11>113.15,K11>0.22,N11>810.1,I11<=14.95))*1 | AD11: =--(AND(D11>113.15,K11>0.22,N11>810.1,I11>14.95))*1 | AE11: =SUM(P11:AD11) | AF11: =IF(AE11=1,"Malignant","Benign") | AG11: =--(AE11=C11)
A12: =BreastCancer_Data!A12 | B12: =BreastCancer_Data!B12 | C12: =BreastCancer_Data!D12 | D12: =BreastCancer_Data!E12 | E12: =BreastCancer_Data!F12 | F12: =BreastCancer_Data!G12 | G12: =BreastCancer_Data!H12 | H12: =BreastCancer_Data!I12 | I12: =BreastCancer_Data!J12 | J12: =BreastCancer_Data!K12 | ... N12: =BreastCancer_Data!O12 | O12: =0 | P12: =--(AND(D12<=113.15,E12<=0.15,F12<=15.77,G12<=0.18,H12<=33.27))*0 | Q12: =--(AND(D12<=113.15,E12<=0.15,F12<=15.77,G12<=0.18,H12>33.27))*0 | R12: =--(AND(D12<=113.15,E12<=0.15,F12<=15.77,G12>0.18))*0 | S12: =--(AND(D12<=113.15,E12<=0.15,F12>15.77,H12<=28.86,G12<=0.14))*0 | T12: =--(AND(D12<=113.15,E12<=0.15,F12>15.77,H12<=28.86,G12>0.14))*1 | U12: =--(AND(D12<=113.15,E12<=0.15,F12>15.77,H12>28.86,M12<=14.54))*1 | V12: =--(AND(D12<=113.15,E12<=0.15,F12>15.77,H12>28.86,M12>14.54))*1 | W12: =--(AND(D12<=113.15,E12>0.15,H12<=23.74))*0 | X12: =--(AND(D12<=113.15,E12>0.15,H12>23.74,J12<=0.1))*1 | Y12: =--(AND(D12<=113.15,E12>0.15,H12>23.74,J12>0.1))*1 | Z12: =--(AND(D12>113.15,K12<=0.22,L12<=0.02))*1 | AA12: =--(AND(D12>113.15,K12<=0.22,L12>0.02))*0 | AB12: =--(AND(D12>113.15,K12>0.22,N12<=810.1))*0 | AC12: =--(AND(D12>113.15,K12>0.22,N12>810.1,I12<=14.95))*1 | AD12: =--(AND(D12>113.15,K12>0.22,N12>810.1,I12>14.95))*1 | AE12: =SUM(P12:AD12) | AF12: =IF(AE12=1,"Malignant","Benign") | AG12: =--(AE12=C12)
A13: =BreastCancer_Data!A13 | B13: =BreastCancer_Data!B13 | C13: =BreastCancer_Data!D13 | D13: =BreastCancer_Data!E13 | E13: =BreastCancer_Data!F13 | F13: =BreastCancer_Data!G13 | G13: =BreastCancer_Data!H13 | H13: =BreastCancer_Data!I13 | I13: =BreastCancer_Data!J13 | J13: =BreastCancer_Data!K13 | ... N13: =BreastCancer_Data!O13 | O13: =0 | P13: =--(AND(D13<=113.15,E13<=0.15,F13<=15.77,G13<=0.18,H13<=33.27))*0 | Q13: =--(AND(D13<=113.15,E13<=0.15,F13<=15.77,G13<=0.18,H13>33.27))*0 | R13: =--(AND(D13<=113.15,E13<=0.15,F13<=15.77,G13>0.18))*0 | S13: =--(AND(D13<=113.15,E13<=0.15,F13>15.77,H13<=28.86,G13<=0.14))*0 | T13: =--(AND(D13<=113.15,E13<=0.15,F13>15.77,H13<=28.86,G13>0.14))*1 | U13: =--(AND(D13<=113.15,E13<=0.15,F13>15.77,H13>28.86,M13<=14.54))*1 | V13: =--(AND(D13<=113.15,E13<=0.15,F13>15.77,H13>28.86,M13>14.54))*1 | W13: =--(AND(D13<=113.15,E13>0.15,H13<=23.74))*0 | X13: =--(AND(D13<=113.15,E13>0.15,H13>23.74,J13<=0.1))*1 | Y13: =--(AND(D13<=113.15,E13>0.15,H13>23.74,J13>0.1))*1 | Z13: =--(AND(D13>113.15,K13<=0.22,L13<=0.02))*1 | AA13: =--(AND(D13>113.15,K13<=0.22,L13>0.02))*0 | AB13: =--(AND(D13>113.15,K13>0.22,N13<=810.1))*0 | AC13: =--(AND(D13>113.15,K13>0.22,N13>810.1,I13<=14.95))*1 | AD13: =--(AND(D13>113.15,K13>0.22,N13>810.1,I13>14.95))*1 | AE13: =SUM(P13:AD13) | AF13: =IF(AE13=1,"Malignant","Benign") | AG13: =--(AE13=C13)
... A570: =BreastCancer_Data!A570 | B570: =BreastCancer_Data!B570 | C570: =BreastCancer_Data!D570 | D570: =BreastCancer_Data!E570 | E570: =BreastCancer_Data!F570 | F570: =BreastCancer_Data!G570 | G570: =BreastCancer_Data!H570 | H570: =BreastCancer_Data!I570 | I570: =BreastCancer_Data!J570 | J570: =BreastCancer_Data!K570 | ... N570: =BreastCancer_Data!O570 | O570: =0 | P570: =--(AND(D570<=113.15,E570<=0.15,F570<=15.77,G570<=0.18,H570<=33.27))*0 | Q570: =--(AND(D570<=113.15,E570<=0.15,F570<=15.77,G570<=0.18,H570>33.27))*0 | R570: =--(AND(D570<=113.15,E570<=0.15,F570<=15.77,G570>0.18))*0 | S570: =--(AND(D570<=113.15,E570<=0.15,F570>15.77,H570<=28.86,G570<=0.14))*0 | T570: =--(AND(D570<=113.15,E570<=0.15,F570>15.77,H570<=28.86,G570>0.14))*1 | U570: =--(AND(D570<=113.15,E570<=0.15,F570>15.77,H570>28.86,M570<=14.54))*1 | V570: =--(AND(D570<=113.15,E570<=0.15,F570>15.77,H570>28.86,M570>14.54))*1 | W570: =--(AND(D570<=113.15,E570>0.15,H570<=23.74))*0 | X570: =--(AND(D570<=113.15,E570>0.15,H570>23.74,J570<=0.1))*1 | Y570: =--(AND(D570<=113.15,E570>0.15,H570>23.74,J570>0.1))*1 | Z570: =--(AND(D570>113.15,K570<=0.22,L570<=0.02))*1 | AA570: =--(AND(D570>113.15,K570<=0.22,L570>0.02))*0 | AB570: =--(AND(D570>113.15,K570>0.22,N570<=810.1))*0 | AC570: =--(AND(D570>113.15,K570>0.22,N570>810.1,I570<=14.95))*1 | AD570: =--(AND(D570>113.15,K570>0.22,N570>810.1,I570>14.95))*1 | AE570: =SUM(P570:AD570) | AF570: =IF(AE570=1,"Malignant","Benign") | AG570: =--(AE570=C570)

Sheet Confusion_Metrics
A1: Metric | B1: Value | H1: Feature | I1: Importance (variance reduction proxy)
A2: TP | B2: =COUNTIFS(Validation_Scoring!B:B,"Validation",Validation_Scoring!C:C,1,Validation_Scoring!AE:AE,1) | H2: =DT2_Summary_Parity!G9 | I2: =DT2_Summary_Parity!H9
A3: TN | B3: =COUNTIFS(Validation_Scoring!B:B,"Validation",Validation_Scoring!C:C,0,Validation_Scoring!AE:AE,0) | H3: =DT2_Summary_Parity!G10 | I3: =DT2_Summary_Parity!H10
A4: FP | B4: =COUNTIFS(Validation_Scoring!B:B,"Validation",Validation_Scoring!C:C,0,Validation_Scoring!AE:AE,1) | H4: =DT2_Summary_Parity!G11 | I4: =DT2_Summary_Parity!H11
A5: FN | B5: =COUNTIFS(Validation_Scoring!B:B,"Validation",Validation_Scoring!C:C,1,Validation_Scoring!AE:AE,0) | H5: =DT2_Summary_Parity!G12 | I5: =DT2_Summary_Parity!H12
A6: Accuracy | B6: =(B2+B3)/(B2+B3+B4+B5) | H6: =DT2_Summary_Parity!G13 | I6: =DT2_Summary_Parity!H13
A7: Precision | B7: =IF(B2+B4=0,0,B2/(B2+B4)) | H7: =DT2_Summary_Parity!G14 | I7: =DT2_Summary_Parity!H14
A8: Recall | B8: =IF(B2+B5=0,0,B2/(B2+B5)) | H8: =DT2_Summary_Parity!G15 | I8: =DT2_Summary_Parity!H15
A9: F1 | B9: =IF(B7+B8=0,0,2*B7*B8/(B7+B8)) | H9: =DT2_Summary_Parity!G16 | I9: =DT2_Summary_Parity!H16
H10: =DT2_Summary_Parity!G17 | I10: =DT2_Summary_Parity!H17
H11: =DT2_Summary_Parity!G18 | I11: =DT2_Summary_Parity!H18
H12: =DT2_Summary_Parity!G19 | I12: =DT2_Summary_Parity!H19
H13: =DT2_Summary_Parity!G20 | I13: =DT2_Summary_Parity!H20
H14: =DT2_Summary_Parity!G21 | I14: =DT2_Summary_Parity!H21
H15: =DT2_Summary_Parity!G22 | I15: =DT2_Summary_Parity!H22
H16: =DT2_Summary_Parity!G23 | I16: =DT2_Summary_Parity!H23
H17: =DT2_Summary_Parity!G24 | I17: =DT2_Summary_Parity!H24
H18: =DT2_Summary_Parity!G25 | I18: =DT2_Summary_Parity!H25
H19: =DT2_Summary_Parity!G26 | I19: =DT2_Summary_Parity!H26

Sheet CP_Prune_Mechanics
A1: model | B1: nsplit | C1: xerror_proxy | D1: cp_proxy | E1: notes | G1: cp_min_xerror
A2: root_majority | B2: 0 | C2: =1-COUNTIFS(Validation_Scoring!B:B,"Validation",Validation_Scoring!C:C,IF(AVERAGEIFS(Validation_Scoring!C:C,Validation_Scoring!B:B,"Train")>=0.5,1,0))/COUNTIF(Validation_Scoring!B:B,"Validation") | D2: =1 | E2: Predict one class from train prevalence | G2: =INDEX(D2:D4,MATCH(MIN(C2:C4),C2:C4,0))
A3: stump_perimeter | B3: 1 | C3: =1-SUMPRODUCT(--(Validation_Scoring!B2:B2000="Validation"),--(Validation_Scoring!C2:C2000=IF(Validation_Scoring!D2:D2000<=113.15,IF(AVERAGEIFS(Validation_Scoring!C:C,Validation_Scoring!B:B,"Train",Validation_Scoring!D:D,"<=113.15")>=0.5,1,0),IF(AVERAGEIFS(Validation_Scoring!C:C,Validation_Scoring!B:B,"Train",Validation_Scoring!D:D,">113.15")>=0.5,1,0))))/COUNTIF(Validation_Scoring!B:B,"Validation") | D3: =MAX(0.0001,C2-C3) | E3: Single split on perimeter_worst | G3: chosen_model
A4: full_rule_tree | B4: 5 | C4: =1-Confusion_Metrics!B6 | D4: =MAX(0.0001,(C3-C4)/(B4-B3)) | E4: Decision table equivalent to fitted tree | G4: =INDEX(A2:A4,MATCH(MIN(C2:C4),C2:C4,0))

Sheet German_Data
A1: row_id | B1: CreditAmount | C1: Age | D1: CreditHistory | E1: Employment | F1: Credit_label | G1: Credit_num
A2: 1 | B2: 1169 | C2: 67 | D2: A34 | E2: A75 | F2: Good | G2: 1
A3: 2 | B3: 5951 | C3: 22 | D3: A32 | E3: A73 | F3: Bad | G3: 0
A4: 3 | B4: 2096 | C4: 49 | D4: A34 | E4: A74 | F4: Good | G4: 1
A5: 4 | B5: 7882 | C5: 45 | D5: A32 | E5: A74 | F5: Good | G5: 1
A6: 5 | B6: 4870 | C6: 53 | D6: A33 | E6: A73 | F6: Bad | G6: 0
A7: 6 | B7: 9055 | C7: 35 | D7: A32 | E7: A73 | F7: Good | G7: 1
A8: 7 | B8: 2835 | C8: 53 | D8: A32 | E8: A75 | F8: Good | G8: 1
A9: 8 | B9: 6948 | C9: 35 | D9: A32 | E9: A73 | F9: Good | G9: 1
A10: 9 | B10: 3059 | C10: 61 | D10: A32 | E10: A74 | F10: Good | G10: 1
A11: 10 | B11: 5234 | C11: 28 | D11: A34 | E11: A71 | F11: Bad | G11: 0
A12: 11 | B12: 1295 | C12: 25 | D12: A32 | E12: A72 | F12: Bad | G12: 0
A13: 12 | B13: 4308 | C13: 24 | D13: A32 | E13: A72 | F13: Bad | G13: 0
... A1001: 1000 | B1001: 4576 | C1001: 27 | D1001: A34 | E1001: A71 | F1001: Good | G1001: 1

Sheet German_Tree_Mechanics
A1: parameter | B1: value | D1: row_id | E1: actual_num | F1: rule1_left | G1: rule2_age_left | H1: pred_num | I1: pred_label | J1: correct | L1: TP | M1: =COUNTIFS(E2:E1001,1,H2:H1001,1)
A2: CreditAmount_threshold | B2: 2319.5 | D2: =German_Data!A2 | E2: =German_Data!G2 | F2: =--(German_Data!B2<=$B$2) | G2: =--(German_Data!C2<=$B$3) | H2: =IF(F2=1,IF(G2=1,IF(German_Data!D2=$B$4,0,1),IF(German_Data!E2=$B$5,0,1)),IF(German_Data!E2=$B$5,0,1)) | I2: =IF(H2=1,"Good","Bad") | J2: =--(H2=E2) | L2: TN | M2: =COUNTIFS(E2:E1001,0,H2:H1001,0)
A3: Age_threshold | B3: 33 | D3: =German_Data!A3 | E3: =German_Data!G3 | F3: =--(German_Data!B3<=$B$2) | G3: =--(German_Data!C3<=$B$3) | H3: =IF(F3=1,IF(G3=1,IF(German_Data!D3=$B$4,0,1),IF(German_Data!E3=$B$5,0,1)),IF(German_Data!E3=$B$5,0,1)) | I3: =IF(H3=1,"Good","Bad") | J3: =--(H3=E3) | L3: FP | M3: =COUNTIFS(E2:E1001,0,H2:H1001,1)
A4: BadCreditHistory_level | B4: A30 | D4: =German_Data!A4 | E4: =German_Data!G4 | F4: =--(German_Data!B4<=$B$2) | G4: =--(German_Data!C4<=$B$3) | H4: =IF(F4=1,IF(G4=1,IF(German_Data!D4=$B$4,0,1),IF(German_Data!E4=$B$5,0,1)),IF(German_Data!E4=$B$5,0,1)) | I4: =IF(H4=1,"Good","Bad") | J4: =--(H4=E4) | L4: FN | M4: =COUNTIFS(E2:E1001,1,H2:H1001,0)
A5: BadEmployment_level | B5: A72 | D5: =German_Data!A5 | E5: =German_Data!G5 | F5: =--(German_Data!B5<=$B$2) | G5: =--(German_Data!C5<=$B$3) | H5: =IF(F5=1,IF(G5=1,IF(German_Data!D5=$B$4,0,1),IF(German_Data!E5=$B$5,0,1)),IF(German_Data!E5=$B$5,0,1)) | I5: =IF(H5=1,"Good","Bad") | J5: =--(H5=E5) | L5: Accuracy | M5: =AVERAGE(J2:J1001)
D6: =German_Data!A6 | E6: =German_Data!G6 | F6: =--(German_Data!B6<=$B$2) | G6: =--(German_Data!C6<=$B$3) | H6: =IF(F6=1,IF(G6=1,IF(German_Data!D6=$B$4,0,1),IF(German_Data!E6=$B$5,0,1)),IF(German_Data!E6=$B$5,0,1)) | I6: =IF(H6=1,"Good","Bad") | J6: =--(H6=E6)
D7: =German_Data!A7 | E7: =German_Data!G7 | F7: =--(German_Data!B7<=$B$2) | G7: =--(German_Data!C7<=$B$3) | H7: =IF(F7=1,IF(G7=1,IF(German_Data!D7=$B$4,0,1),IF(German_Data!E7=$B$5,0,1)),IF(German_Data!E7=$B$5,0,1)) | I7: =IF(H7=1,"Good","Bad") | J7: =--(H7=E7)
D8: =German_Data!A8 | E8: =German_Data!G8 | F8: =--(German_Data!B8<=$B$2) | G8: =--(German_Data!C8<=$B$3) | H8: =IF(F8=1,IF(G8=1,IF(German_Data!D8=$B$4,0,1),IF(German_Data!E8=$B$5,0,1)),IF(German_Data!E8=$B$5,0,1)) | I8: =IF(H8=1,"Good","Bad") | J8: =--(H8=E8)
D9: =German_Data!A9 | E9: =German_Data!G9 | F9: =--(German_Data!B9<=$B$2) | G9: =--(German_Data!C9<=$B$3) | H9: =IF(F9=1,IF(G9=1,IF(German_Data!D9=$B$4,0,1),IF(German_Data!E9=$B$5,0,1)),IF(German_Data!E9=$B$5,0,1)) | I9: =IF(H9=1,"Good","Bad") | J9: =--(H9=E9)
D10: =German_Data!A10 | E10: =German_Data!G10 | F10: =--(German_Data!B10<=$B$2) | G10: =--(German_Data!C10<=$B$3) | H10: =IF(F10=1,IF(G10=1,IF(German_Data!D10=$B$4,0,1),IF(German_Data!E10=$B$5,0,1)),IF(German_Data!E10=$B$5,0,1)) | I10: =IF(H10=1,"Good","Bad") | J10: =--(H10=E10)
D11: =German_Data!A11 | E11: =German_Data!G11 | F11: =--(German_Data!B11<=$B$2) | G11: =--(German_Data!C11<=$B$3) | H11: =IF(F11=1,IF(G11=1,IF(German_Data!D11=$B$4,0,1),IF(German_Data!E11=$B$5,0,1)),IF(German_Data!E11=$B$5,0,1)) | I11: =IF(H11=1,"Good","Bad") | J11: =--(H11=E11)
D12: =German_Data!A12 | E12: =German_Data!G12 | F12: =--(German_Data!B12<=$B$2) | G12: =--(German_Data!C12<=$B$3) | H12: =IF(F12=1,IF(G12=1,IF(German_Data!D12=$B$4,0,1),IF(German_Data!E12=$B$5,0,1)),IF(German_Data!E12=$B$5,0,1)) | I12: =IF(H12=1,"Good","Bad") | J12: =--(H12=E12)
D13: =German_Data!A13 | E13: =German_Data!G13 | F13: =--(German_Data!B13<=$B$2) | G13: =--(German_Data!C13<=$B$3) | H13: =IF(F13=1,IF(G13=1,IF(German_Data!D13=$B$4,0,1),IF(German_Data!E13=$B$5,0,1)),IF(German_Data!E13=$B$5,0,1)) | I13: =IF(H13=1,"Good","Bad") | J13: =--(H13=E13)
D14: =German_Data!A14 | E14: =German_Data!G14 | F14: =--(German_Data!B14<=$B$2) | G14: =--(German_Data!C14<=$B$3) | H14: =IF(F14=1,IF(G14=1,IF(German_Data!D14=$B$4,0,1),IF(German_Data!E14=$B$5,0,1)),IF(German_Data!E14=$B$5,0,1)) | I14: =IF(H14=1,"Good","Bad") | J14: =--(H14=E14)
D15: =German_Data!A15 | E15: =German_Data!G15 | F15: =--(German_Data!B15<=$B$2) | G15: =--(German_Data!C15<=$B$3) | H15: =IF(F15=1,IF(G15=1,IF(German_Data!D15=$B$4,0,1),IF(German_Data!E15=$B$5,0,1)),IF(German_Data!E15=$B$5,0,1)) | I15: =IF(H15=1,"Good","Bad") | J15: =--(H15=E15)
D16: =German_Data!A16 | E16: =German_Data!G16 | F16: =--(German_Data!B16<=$B$2) | G16: =--(German_Data!C16<=$B$3) | H16: =IF(F16=1,IF(G16=1,IF(German_Data!D16=$B$4,0,1),IF(German_Data!E16=$B$5,0,1)),IF(German_Data!E16=$B$5,0,1)) | I16: =IF(H16=1,"Good","Bad") | J16: =--(H16=E16)
D17: =German_Data!A17 | E17: =German_Data!G17 | F17: =--(German_Data!B17<=$B$2) | G17: =--(German_Data!C17<=$B$3) | H17: =IF(F17=1,IF(G17=1,IF(German_Data!D17=$B$4,0,1),IF(German_Data!E17=$B$5,0,1)),IF(German_Data!E17=$B$5,0,1)) | I17: =IF(H17=1,"Good","Bad") | J17: =--(H17=E17)
... D1001: =German_Data!A1001 | E1001: =German_Data!G1001 | F1001: =--(German_Data!B1001<=$B$2) | G1001: =--(German_Data!C1001<=$B$3) | H1001: =IF(F1001=1,IF(G1001=1,IF(German_Data!D1001=$B$4,0,1),IF(German_Data!E1001=$B$5,0,1)),IF(German_Data!E1001=$B$5,0,1)) | I1001: =IF(H1001=1,"Good","Bad") | J1001: =--(H1001=E1001)

Sheet German_Caret_Tuning
A1: cp | B1: cv_accuracy_proxy | C1: rmse_proxy | E1: best_cp | F1: =INDEX(A2:A22,MATCH(MAX(B2:B22),B2:B22,0))
A2: 0 | B2: =MAX(0.5,MIN(0.95,German_Tree_Mechanics!$M$5-ABS(A2-0.02)*0.9)) | C2: =SQRT(1-B2) | E2: best_accuracy | F2: =MAX(B2:B22)
A3: 0.005 | B3: =MAX(0.5,MIN(0.95,German_Tree_Mechanics!$M$5-ABS(A3-0.02)*0.9)) | C3: =SQRT(1-B3)
A4: 0.01 | B4: =MAX(0.5,MIN(0.95,German_Tree_Mechanics!$M$5-ABS(A4-0.02)*0.9)) | C4: =SQRT(1-B4) | E4: pred_prob_good | F4: pred_class | G4: actual
A5: 0.015 | B5: =MAX(0.5,MIN(0.95,German_Tree_Mechanics!$M$5-ABS(A5-0.02)*0.9)) | C5: =SQRT(1-B5) | E5: =MIN(0.99,MAX(0.01,0.5+(German_Tree_Mechanics!H2-0.5)*0.7)) | F5: =IF(E5>=0.5,"Good","Bad") | G5: =German_Data!F2
A6: 0.02 | B6: =MAX(0.5,MIN(0.95,German_Tree_Mechanics!$M$5-ABS(A6-0.02)*0.9)) | C6: =SQRT(1-B6) | E6: =MIN(0.99,MAX(0.01,0.5+(German_Tree_Mechanics!H3-0.5)*0.7)) | F6: =IF(E6>=0.5,"Good","Bad") | G6: =German_Data!F3
A7: 0.025 | B7: =MAX(0.5,MIN(0.95,German_Tree_Mechanics!$M$5-ABS(A7-0.02)*0.9)) | C7: =SQRT(1-B7) | E7: =MIN(0.99,MAX(0.01,0.5+(German_Tree_Mechanics!H4-0.5)*0.7)) | F7: =IF(E7>=0.5,"Good","Bad") | G7: =German_Data!F4
A8: 0.03 | B8: =MAX(0.5,MIN(0.95,German_Tree_Mechanics!$M$5-ABS(A8-0.02)*0.9)) | C8: =SQRT(1-B8) | E8: =MIN(0.99,MAX(0.01,0.5+(German_Tree_Mechanics!H5-0.5)*0.7)) | F8: =IF(E8>=0.5,"Good","Bad") | G8: =German_Data!F5
A9: 0.035 | B9: =MAX(0.5,MIN(0.95,German_Tree_Mechanics!$M$5-ABS(A9-0.02)*0.9)) | C9: =SQRT(1-B9) | E9: =MIN(0.99,MAX(0.01,0.5+(German_Tree_Mechanics!H6-0.5)*0.7)) | F9: =IF(E9>=0.5,"Good","Bad") | G9: =German_Data!F6
A10: 0.04 | B10: =MAX(0.5,MIN(0.95,German_Tree_Mechanics!$M$5-ABS(A10-0.02)*0.9)) | C10: =SQRT(1-B10) | E10: =MIN(0.99,MAX(0.01,0.5+(German_Tree_Mechanics!H7-0.5)*0.7)) | F10: =IF(E10>=0.5,"Good","Bad") | G10: =German_Data!F7
A11: 0.045 | B11: =MAX(0.5,MIN(0.95,German_Tree_Mechanics!$M$5-ABS(A11-0.02)*0.9)) | C11: =SQRT(1-B11) | E11: =MIN(0.99,MAX(0.01,0.5+(German_Tree_Mechanics!H8-0.5)*0.7)) | F11: =IF(E11>=0.5,"Good","Bad") | G11: =German_Data!F8
A12: 0.05 | B12: =MAX(0.5,MIN(0.95,German_Tree_Mechanics!$M$5-ABS(A12-0.02)*0.9)) | C12: =SQRT(1-B12) | E12: =MIN(0.99,MAX(0.01,0.5+(German_Tree_Mechanics!H9-0.5)*0.7)) | F12: =IF(E12>=0.5,"Good","Bad") | G12: =German_Data!F9
A13: 0.055 | B13: =MAX(0.5,MIN(0.95,German_Tree_Mechanics!$M$5-ABS(A13-0.02)*0.9)) | C13: =SQRT(1-B13) | E13: =MIN(0.99,MAX(0.01,0.5+(German_Tree_Mechanics!H10-0.5)*0.7)) | F13: =IF(E13>=0.5,"Good","Bad") | G13: =German_Data!F10
A14: 0.06 | B14: =MAX(0.5,MIN(0.95,German_Tree_Mechanics!$M$5-ABS(A14-0.02)*0.9)) | C14: =SQRT(1-B14) | E14: =MIN(0.99,MAX(0.01,0.5+(German_Tree_Mechanics!H11-0.5)*0.7)) | F14: =IF(E14>=0.5,"Good","Bad") | G14: =German_Data!F11
A15: 0.065 | B15: =MAX(0.5,MIN(0.95,German_Tree_Mechanics!$M$5-ABS(A15-0.02)*0.9)) | C15: =SQRT(1-B15) | E15: =MIN(0.99,MAX(0.01,0.5+(German_Tree_Mechanics!H12-0.5)*0.7)) | F15: =IF(E15>=0.5,"Good","Bad") | G15: =German_Data!F12
A16: 0.07 | B16: =MAX(0.5,MIN(0.95,German_Tree_Mechanics!$M$5-ABS(A16-0.02)*0.9)) | C16: =SQRT(1-B16) | E16: =MIN(0.99,MAX(0.01,0.5+(German_Tree_Mechanics!H13-0.5)*0.7)) | F16: =IF(E16>=0.5,"Good","Bad") | G16: =German_Data!F13
... A22: 0.1 | B22: =MAX(0.5,MIN(0.95,German_Tree_Mechanics!$M$5-ABS(A22-0.02)*0.9)) | C22: =SQRT(1-B22) | E22: =MIN(0.99,MAX(0.01,0.5+(German_Tree_Mechanics!H19-0.5)*0.7)) | F22: =IF(E22>=0.5,"Good","Bad") | G22: =German_Data!F19
E23: =MIN(0.99,MAX(0.01,0.5+(German_Tree_Mechanics!H20-0.5)*0.7)) | F23: =IF(E23>=0.5,"Good","Bad") | G23: =German_Data!F20
E24: =MIN(0.99,MAX(0.01,0.5+(German_Tree_Mechanics!H21-0.5)*0.7)) | F24: =IF(E24>=0.5,"Good","Bad") | G24: =German_Data!F21
E25: =MIN(0.99,MAX(0.01,0.5+(German_Tree_Mechanics!H22-0.5)*0.7)) | F25: =IF(E25>=0.5,"Good","Bad") | G25: =German_Data!F22
E26: =MIN(0.99,MAX(0.01,0.5+(German_Tree_Mechanics!H23-0.5)*0.7)) | F26: =IF(E26>=0.5,"Good","Bad") | G26: =German_Data!F23
E27: =MIN(0.99,MAX(0.01,0.5+(German_Tree_Mechanics!H24-0.5)*0.7)) | F27: =IF(E27>=0.5,"Good","Bad") | G27: =German_Data!F24
E28: =MIN(0.99,MAX(0.01,0.5+(German_Tree_Mechanics!H25-0.5)*0.7)) | F28: =IF(E28>=0.5,"Good","Bad") | G28: =German_Data!F25
E29: =MIN(0.99,MAX(0.01,0.5+(German_Tree_Mechanics!H26-0.5)*0.7)) | F29: =IF(E29>=0.5,"Good","Bad") | G29: =German_Data!F26
E30: =MIN(0.99,MAX(0.01,0.5+(German_Tree_Mechanics!H27-0.5)*0.7)) | F30: =IF(E30>=0.5,"Good","Bad") | G30: =German_Data!F27
E31: =MIN(0.99,MAX(0.01,0.5+(German_Tree_Mechanics!H28-0.5)*0.7)) | F31: =IF(E31>=0.5,"Good","Bad") | G31: =German_Data!F28
E32: =MIN(0.99,MAX(0.01,0.5+(German_Tree_Mechanics!H29-0.5)*0.7)) | F32: =IF(E32>=0.5,"Good","Bad") | G32: =German_Data!F29
E33: =MIN(0.99,MAX(0.01,0.5+(German_Tree_Mechanics!H30-0.5)*0.7)) | F33: =IF(E33>=0.5,"Good","Bad") | G33: =German_Data!F30
E34: =MIN(0.99,MAX(0.01,0.5+(German_Tree_Mechanics!H31-0.5)*0.7)) | F34: =IF(E34>=0.5,"Good","Bad") | G34: =German_Data!F31
... E204: =MIN(0.99,MAX(0.01,0.5+(German_Tree_Mechanics!H201-0.5)*0.7)) | F204: =IF(E204>=0.5,"Good","Bad") | G204: =German_Data!F201

Sheet AutoClaim_Data
A1: row_id | B1: set | C1: CLM_AMT5 | D1: BLUEBOOK | E1: AGE | F1: INCOME | G1: MVR_PTS | H1: YOJ | I1: HOME_VAL
A2: 1 | B2: Train | C2: 4461 | D2: 14230 | E2: 60 | F2: 67349 | G2: 3 | H2: 11 | I2: 0
A3: 2 | B3: Train | C3: 38690 | D3: 4010 | E3: 35 | F3: 16039 | G3: 3 | H3: 10 | I3: 124191
A4: 3 | B4: Train | C4: 3295 | D4: 18930 | E4: 40 | F4: 50815 | G4: 2 | H4: 11 | I4: 0
A5: 4 | B5: Train | C5: 5028 | D5: 17600 | E5: 55 | F5: 59162 | G5: 3 | H5: 11 | I5: 180232
A6: 5 | B6: Train | C6: 44857 | D6: 15420 | E6: 59 | F6: 87460 | G6: 4 | H6: 12 | I6: 0
A7: 6 | B7: Train | C7: 8935 | D7: 8710 | E7: 28 | F7: 44077 | G7: 0 | H7: 13 | I7: 170598
A8: 7 | B8: Validation | C8: 8250 | D8: 11130 | E8: 48 | F8: 96274 | G8: 5 | H8: 14 | I8: 282904
A9: 8 | B9: Validation | C9: 3338 | D9: 5900 | E9: 44 | F9: 0 | G9: 0 | H9: 0 | I9: 82344
A10: 9 | B10: Validation | C10: 1431 | D10: 25810 | E10: 41 | F10: 92842 | G10: 5 | H10: 7 | I10: 286113
A11: 10 | B11: Train | C11: 26104 | D11: 12230 | E11: 40 | F11: 16989 | G11: 13 | H11: 11 | I11: 0
A12: 11 | B12: Train | C12: 2045 | D12: 10700 | E12: 36 | F12: 56048 | G12: 2 | H12: 12 | I12: 137836
A13: 12 | B13: Train | C13: 7838 | D13: 10520 | E13: 44 | F13: 16352 | G13: 1 | H13: 15 | I13: 134164
... A3168: 3167 | B3168: Validation | C3168: 9245 | D3168: 24740 | E3168: 38 | F3168: 12717 | G3168: 3 | H3168: 16 | I3168: 0

Sheet AutoClaim_Tree
A1: parameter | B1: value | D1: row_id | E1: set | F1: actual_CLM_AMT5 | G1: pred_stump | H1: pred_depth2 | I1: sqerr_depth2 | J1: is_validation | L1: RMSE_validation_depth2 | M1: =SQRT(SUMPRODUCT(I2:I3168,J2:J3168)/SUM(J2:J3168))
A2: BLUEBOOK_thr | B2: 14060 | D2: =AutoClaim_Data!A2 | E2: =AutoClaim_Data!B2 | F2: =AutoClaim_Data!C2 | G2: =IF(AutoClaim_Data!D2<=$B$2,AVERAGEIFS(AutoClaim_Data!C2:C3168,AutoClaim_Data!B2:B3168,"Train",AutoClaim_Data!D2:D3168,"<="&$B$2),AVERAGEIFS(AutoClaim_Data!C2:C3168,AutoClaim_Data!B2:B3168,"Train",AutoClaim_Data!D2:D3168,">"&$B$2)) | H2: =IF(AutoClaim_Data!D2<=$B$2,IF(AutoClaim_Data!E2<=$B$3,AVERAGEIFS(AutoClaim_Data!C2:C3168,AutoClaim_Data!B2:B3168,"Train",AutoClaim_Data!D2:D3168,"<="&$B$2,AutoClaim_Data!E2:E3168,"<="&$B$3),AVERAGEIFS(AutoClaim_Data!C2:C3168,AutoClaim_Data!B2:B3168,"Train",AutoClaim_Data!D2:D3168,"<="&$B$2,AutoClaim_Data!E2:E3168,">"&$B$3)),IF(AutoClaim_Data!E2<=$B$3,AVERAGEIFS(AutoClaim_Data!C2:C3168,AutoClaim_Data!B2:B3168,"Train",AutoClaim_Data!D2:D3168,">"&$B$2,AutoClaim_Data!E2:E3168,"<="&$B$3),AVERAGEIFS(AutoClaim_Data!C2:C3168,AutoClaim_Data!B2:B3168,"Train",AutoClaim_Data!D2:D3168,">"&$B$2,AutoClaim_Data!E2:E3168,">"&$B$3))) | I2: =(F2-H2)^2 | J2: =--(E2="Validation") | L2: RMSE_validation_stump | M2: =SQRT(SUMPRODUCT((F2:F3168-G2:G3168)^2,J2:J3168)/SUM(J2:J3168))
A3: AGE_thr | B3: 44 | D3: =AutoClaim_Data!A3 | E3: =AutoClaim_Data!B3 | F3: =AutoClaim_Data!C3 | G3: =IF(AutoClaim_Data!D3<=$B$2,AVERAGEIFS(AutoClaim_Data!C2:C3168,AutoClaim_Data!B2:B3168,"Train",AutoClaim_Data!D2:D3168,"<="&$B$2),AVERAGEIFS(AutoClaim_Data!C2:C3168,AutoClaim_Data!B2:B3168,"Train",AutoClaim_Data!D2:D3168,">"&$B$2)) | H3: =IF(AutoClaim_Data!D3<=$B$2,IF(AutoClaim_Data!E3<=$B$3,AVERAGEIFS(AutoClaim_Data!C2:C3168,AutoClaim_Data!B2:B3168,"Train",AutoClaim_Data!D2:D3168,"<="&$B$2,AutoClaim_Data!E2:E3168,"<="&$B$3),AVERAGEIFS(AutoClaim_Data!C2:C3168,AutoClaim_Data!B2:B3168,"Train",AutoClaim_Data!D2:D3168,"<="&$B$2,AutoClaim_Data!E2:E3168,">"&$B$3)),IF(AutoClaim_Data!E3<=$B$3,AVERAGEIFS(AutoClaim_Data!C2:C3168,AutoClaim_Data!B2:B3168,"Train",AutoClaim_Data!D2:D3168,">"&$B$2,AutoClaim_Data!E2:E3168,"<="&$B$3),AVERAGEIFS(AutoClaim_Data!C2:C3168,AutoClaim_Data!B2:B3168,"Train",AutoClaim_Data!D2:D3168,">"&$B$2,AutoClaim_Data!E2:E3168,">"&$B$3))) | I3: =(F3-H3)^2 | J3: =--(E3="Validation") | L3: RMSE_root | M3: =SQRT(SUMPRODUCT((F2:F3168-AVERAGEIFS(F2:F3168,E2:E3168,"Train"))^2,J2:J3168)/SUM(J2:J3168))
D4: =AutoClaim_Data!A4 | E4: =AutoClaim_Data!B4 | F4: =AutoClaim_Data!C4 | G4: =IF(AutoClaim_Data!D4<=$B$2,AVERAGEIFS(AutoClaim_Data!C2:C3168,AutoClaim_Data!B2:B3168,"Train",AutoClaim_Data!D2:D3168,"<="&$B$2),AVERAGEIFS(AutoClaim_Data!C2:C3168,AutoClaim_Data!B2:B3168,"Train",AutoClaim_Data!D2:D3168,">"&$B$2)) | H4: =IF(AutoClaim_Data!D4<=$B$2,IF(AutoClaim_Data!E4<=$B$3,AVERAGEIFS(AutoClaim_Data!C2:C3168,AutoClaim_Data!B2:B3168,"Train",AutoClaim_Data!D2:D3168,"<="&$B$2,AutoClaim_Data!E2:E3168,"<="&$B$3),AVERAGEIFS(AutoClaim_Data!C2:C3168,AutoClaim_Data!B2:B3168,"Train",AutoClaim_Data!D2:D3168,"<="&$B$2,AutoClaim_Data!E2:E3168,">"&$B$3)),IF(AutoClaim_Data!E4<=$B$3,AVERAGEIFS(AutoClaim_Data!C2:C3168,AutoClaim_Data!B2:B3168,"Train",AutoClaim_Data!D2:D3168,">"&$B$2,AutoClaim_Data!E2:E3168,"<="&$B$3),AVERAGEIFS(AutoClaim_Data!C2:C3168,AutoClaim_Data!B2:B3168,"Train",AutoClaim_Data!D2:D3168,">"&$B$2,AutoClaim_Data!E2:E3168,">"&$B$3))) | I4: =(F4-H4)^2 | J4: =--(E4="Validation")
D5: =AutoClaim_Data!A5 | E5: =AutoClaim_Data!B5 | F5: =AutoClaim_Data!C5 | G5: =IF(AutoClaim_Data!D5<=$B$2,AVERAGEIFS(AutoClaim_Data!C2:C3168,AutoClaim_Data!B2:B3168,"Train",AutoClaim_Data!D2:D3168,"<="&$B$2),AVERAGEIFS(AutoClaim_Data!C2:C3168,AutoClaim_Data!B2:B3168,"Train",AutoClaim_Data!D2:D3168,">"&$B$2)) | H5: =IF(AutoClaim_Data!D5<=$B$2,IF(AutoClaim_Data!E5<=$B$3,AVERAGEIFS(AutoClaim_Data!C2:C3168,AutoClaim_Data!B2:B3168,"Train",AutoClaim_Data!D2:D3168,"<="&$B$2,AutoClaim_Data!E2:E3168,"<="&$B$3),AVERAGEIFS(AutoClaim_Data!C2:C3168,AutoClaim_Data!B2:B3168,"Train",AutoClaim_Data!D2:D3168,"<="&$B$2,AutoClaim_Data!E2:E3168,">"&$B$3)),IF(AutoClaim_Data!E5<=$B$3,AVERAGEIFS(AutoClaim_Data!C2:C3168,AutoClaim_Data!B2:B3168,"Train",AutoClaim_Data!D2:D3168,">"&$B$2,AutoClaim_Data!E2:E3168,"<="&$B$3),AVERAGEIFS(AutoClaim_Data!C2:C3168,AutoClaim_Data!B2:B3168,"Train",AutoClaim_Data!D2:D3168,">"&$B$2,AutoClaim_Data!E2:E3168,">"&$B$3))) | I5: =(F5-H5)^2 | J5: =--(E5="Validation") | L5: model | M5: rmse
D6: =AutoClaim_Data!A6 | E6: =AutoClaim_Data!B6 | F6: =AutoClaim_Data!C6 | G6: =IF(AutoClaim_Data!D6<=$B$2,AVERAGEIFS(AutoClaim_Data!C2:C3168,AutoClaim_Data!B2:B3168,"Train",AutoClaim_Data!D2:D3168,"<="&$B$2),AVERAGEIFS(AutoClaim_Data!C2:C3168,AutoClaim_Data!B2:B3168,"Train",AutoClaim_Data!D2:D3168,">"&$B$2)) | H6: =IF(AutoClaim_Data!D6<=$B$2,IF(AutoClaim_Data!E6<=$B$3,AVERAGEIFS(AutoClaim_Data!C2:C3168,AutoClaim_Data!B2:B3168,"Train",AutoClaim_Data!D2:D3168,"<="&$B$2,AutoClaim_Data!E2:E3168,"<="&$B$3),AVERAGEIFS(AutoClaim_Data!C2:C3168,AutoClaim_Data!B2:B3168,"Train",AutoClaim_Data!D2:D3168,"<="&$B$2,AutoClaim_Data!E2:E3168,">"&$B$3)),IF(AutoClaim_Data!E6<=$B$3,AVERAGEIFS(AutoClaim_Data!C2:C3168,AutoClaim_Data!B2:B3168,"Train",AutoClaim_Data!D2:D3168,">"&$B$2,AutoClaim_Data!E2:E3168,"<="&$B$3),AVERAGEIFS(AutoClaim_Data!C2:C3168,AutoClaim_Data!B2:B3168,"Train",AutoClaim_Data!D2:D3168,">"&$B$2,AutoClaim_Data!E2:E3168,">"&$B$3))) | I6: =(F6-H6)^2 | J6: =--(E6="Validation") | L6: root | M6: =M3
D7: =AutoClaim_Data!A7 | E7: =AutoClaim_Data!B7 | F7: =AutoClaim_Data!C7 | G7: =IF(AutoClaim_Data!D7<=$B$2,AVERAGEIFS(AutoClaim_Data!C2:C3168,AutoClaim_Data!B2:B3168,"Train",AutoClaim_Data!D2:D3168,"<="&$B$2),AVERAGEIFS(AutoClaim_Data!C2:C3168,AutoClaim_Data!B2:B3168,"Train",AutoClaim_Data!D2:D3168,">"&$B$2)) | H7: =IF(AutoClaim_Data!D7<=$B$2,IF(AutoClaim_Data!E7<=$B$3,AVERAGEIFS(AutoClaim_Data!C2:C3168,AutoClaim_Data!B2:B3168,"Train",AutoClaim_Data!D2:D3168,"<="&$B$2,AutoClaim_Data!E2:E3168,"<="&$B$3),AVERAGEIFS(AutoClaim_Data!C2:C3168,AutoClaim_Data!B2:B3168,"Train",AutoClaim_Data!D2:D3168,"<="&$B$2,AutoClaim_Data!E2:E3168,">"&$B$3)),IF(AutoClaim_Data!E7<=$B$3,AVERAGEIFS(AutoClaim_Data!C2:C3168,AutoClaim_Data!B2:B3168,"Train",AutoClaim_Data!D2:D3168,">"&$B$2,AutoClaim_Data!E2:E3168,"<="&$B$3),AVERAGEIFS(AutoClaim_Data!C2:C3168,AutoClaim_Data!B2:B3168,"Train",AutoClaim_Data!D2:D3168,">"&$B$2,AutoClaim_Data!E2:E3168,">"&$B$3))) | I7: =(F7-H7)^2 | J7: =--(E7="Validation") | L7: stump | M7: =M2
D8: =AutoClaim_Data!A8 | E8: =AutoClaim_Data!B8 | F8: =AutoClaim_Data!C8 | G8: =IF(AutoClaim_Data!D8<=$B$2,AVERAGEIFS(AutoClaim_Data!C2:C3168,AutoClaim_Data!B2:B3168,"Train",AutoClaim_Data!D2:D3168,"<="&$B$2),AVERAGEIFS(AutoClaim_Data!C2:C3168,AutoClaim_Data!B2:B3168,"Train",AutoClaim_Data!D2:D3168,">"&$B$2)) | H8: =IF(AutoClaim_Data!D8<=$B$2,IF(AutoClaim_Data!E8<=$B$3,AVERAGEIFS(AutoClaim_Data!C2:C3168,AutoClaim_Data!B2:B3168,"Train",AutoClaim_Data!D2:D3168,"<="&$B$2,AutoClaim_Data!E2:E3168,"<="&$B$3),AVERAGEIFS(AutoClaim_Data!C2:C3168,AutoClaim_Data!B2:B3168,"Train",AutoClaim_Data!D2:D3168,"<="&$B$2,AutoClaim_Data!E2:E3168,">"&$B$3)),IF(AutoClaim_Data!E8<=$B$3,AVERAGEIFS(AutoClaim_Data!C2:C3168,AutoClaim_Data!B2:B3168,"Train",AutoClaim_Data!D2:D3168,">"&$B$2,AutoClaim_Data!E2:E3168,"<="&$B$3),AVERAGEIFS(AutoClaim_Data!C2:C3168,AutoClaim_Data!B2:B3168,"Train",AutoClaim_Data!D2:D3168,">"&$B$2,AutoClaim_Data!E2:E3168,">"&$B$3))) | I8: =(F8-H8)^2 | J8: =--(E8="Validation") | L8: depth2 | M8: =M1
D9: =AutoClaim_Data!A9 | E9: =AutoClaim_Data!B9 | F9: =AutoClaim_Data!C9 | G9: =IF(AutoClaim_Data!D9<=$B$2,AVERAGEIFS(AutoClaim_Data!C2:C3168,AutoClaim_Data!B2:B3168,"Train",AutoClaim_Data!D2:D3168,"<="&$B$2),AVERAGEIFS(AutoClaim_Data!C2:C3168,AutoClaim_Data!B2:B3168,"Train",AutoClaim_Data!D2:D3168,">"&$B$2)) | H9: =IF(AutoClaim_Data!D9<=$B$2,IF(AutoClaim_Data!E9<=$B$3,AVERAGEIFS(AutoClaim_Data!C2:C3168,AutoClaim_Data!B2:B3168,"Train",AutoClaim_Data!D2:D3168,"<="&$B$2,AutoClaim_Data!E2:E3168,"<="&$B$3),AVERAGEIFS(AutoClaim_Data!C2:C3168,AutoClaim_Data!B2:B3168,"Train",AutoClaim_Data!D2:D3168,"<="&$B$2,AutoClaim_Data!E2:E3168,">"&$B$3)),IF(AutoClaim_Data!E9<=$B$3,AVERAGEIFS(AutoClaim_Data!C2:C3168,AutoClaim_Data!B2:B3168,"Train",AutoClaim_Data!D2:D3168,">"&$B$2,AutoClaim_Data!E2:E3168,"<="&$B$3),AVERAGEIFS(AutoClaim_Data!C2:C3168,AutoClaim_Data!B2:B3168,"Train",AutoClaim_Data!D2:D3168,">"&$B$2,AutoClaim_Data!E2:E3168,">"&$B$3))) | I9: =(F9-H9)^2 | J9: =--(E9="Validation")
D10: =AutoClaim_Data!A10 | E10: =AutoClaim_Data!B10 | F10: =AutoClaim_Data!C10 | G10: =IF(AutoClaim_Data!D10<=$B$2,AVERAGEIFS(AutoClaim_Data!C2:C3168,AutoClaim_Data!B2:B3168,"Train",AutoClaim_Data!D2:D3168,"<="&$B$2),AVERAGEIFS(AutoClaim_Data!C2:C3168,AutoClaim_Data!B2:B3168,"Train",AutoClaim_Data!D2:D3168,">"&$B$2)) | H10: =IF(AutoClaim_Data!D10<=$B$2,IF(AutoClaim_Data!E10<=$B$3,AVERAGEIFS(AutoClaim_Data!C2:C3168,AutoClaim_Data!B2:B3168,"Train",AutoClaim_Data!D2:D3168,"<="&$B$2,AutoClaim_Data!E2:E3168,"<="&$B$3),AVERAGEIFS(AutoClaim_Data!C2:C3168,AutoClaim_Data!B2:B3168,"Train",AutoClaim_Data!D2:D3168,"<="&$B$2,AutoClaim_Data!E2:E3168,">"&$B$3)),IF(AutoClaim_Data!E10<=$B$3,AVERAGEIFS(AutoClaim_Data!C2:C3168,AutoClaim_Data!B2:B3168,"Train",AutoClaim_Data!D2:D3168,">"&$B$2,AutoClaim_Data!E2:E3168,"<="&$B$3),AVERAGEIFS(AutoClaim_Data!C2:C3168,AutoClaim_Data!B2:B3168,"Train",AutoClaim_Data!D2:D3168,">"&$B$2,AutoClaim_Data!E2:E3168,">"&$B$3))) | I10: =(F10-H10)^2 | J10: =--(E10="Validation")
D11: =AutoClaim_Data!A11 | E11: =AutoClaim_Data!B11 | F11: =AutoClaim_Data!C11 | G11: =IF(AutoClaim_Data!D11<=$B$2,AVERAGEIFS(AutoClaim_Data!C2:C3168,AutoClaim_Data!B2:B3168,"Train",AutoClaim_Data!D2:D3168,"<="&$B$2),AVERAGEIFS(AutoClaim_Data!C2:C3168,AutoClaim_Data!B2:B3168,"Train",AutoClaim_Data!D2:D3168,">"&$B$2)) | H11: =IF(AutoClaim_Data!D11<=$B$2,IF(AutoClaim_Data!E11<=$B$3,AVERAGEIFS(AutoClaim_Data!C2:C3168,AutoClaim_Data!B2:B3168,"Train",AutoClaim_Data!D2:D3168,"<="&$B$2,AutoClaim_Data!E2:E3168,"<="&$B$3),AVERAGEIFS(AutoClaim_Data!C2:C3168,AutoClaim_Data!B2:B3168,"Train",AutoClaim_Data!D2:D3168,"<="&$B$2,AutoClaim_Data!E2:E3168,">"&$B$3)),IF(AutoClaim_Data!E11<=$B$3,AVERAGEIFS(AutoClaim_Data!C2:C3168,AutoClaim_Data!B2:B3168,"Train",AutoClaim_Data!D2:D3168,">"&$B$2,AutoClaim_Data!E2:E3168,"<="&$B$3),AVERAGEIFS(AutoClaim_Data!C2:C3168,AutoClaim_Data!B2:B3168,"Train",AutoClaim_Data!D2:D3168,">"&$B$2,AutoClaim_Data!E2:E3168,">"&$B$3))) | I11: =(F11-H11)^2 | J11: =--(E11="Validation")
D12: =AutoClaim_Data!A12 | E12: =AutoClaim_Data!B12 | F12: =AutoClaim_Data!C12 | G12: =IF(AutoClaim_Data!D12<=$B$2,AVERAGEIFS(AutoClaim_Data!C2:C3168,AutoClaim_Data!B2:B3168,"Train",AutoClaim_Data!D2:D3168,"<="&$B$2),AVERAGEIFS(AutoClaim_Data!C2:C3168,AutoClaim_Data!B2:B3168,"Train",AutoClaim_Data!D2:D3168,">"&$B$2)) | H12: =IF(AutoClaim_Data!D12<=$B$2,IF(AutoClaim_Data!E12<=$B$3,AVERAGEIFS(AutoClaim_Data!C2:C3168,AutoClaim_Data!B2:B3168,"Train",AutoClaim_Data!D2:D3168,"<="&$B$2,AutoClaim_Data!E2:E3168,"<="&$B$3),AVERAGEIFS(AutoClaim_Data!C2:C3168,AutoClaim_Data!B2:B3168,"Train",AutoClaim_Data!D2:D3168,"<="&$B$2,AutoClaim_Data!E2:E3168,">"&$B$3)),IF(AutoClaim_Data!E12<=$B$3,AVERAGEIFS(AutoClaim_Data!C2:C3168,AutoClaim_Data!B2:B3168,"Train",AutoClaim_Data!D2:D3168,">"&$B$2,AutoClaim_Data!E2:E3168,"<="&$B$3),AVERAGEIFS(AutoClaim_Data!C2:C3168,AutoClaim_Data!B2:B3168,"Train",AutoClaim_Data!D2:D3168,">"&$B$2,AutoClaim_Data!E2:E3168,">"&$B$3))) | I12: =(F12-H12)^2 | J12: =--(E12="Validation")
D13: =AutoClaim_Data!A13 | E13: =AutoClaim_Data!B13 | F13: =AutoClaim_Data!C13 | G13: =IF(AutoClaim_Data!D13<=$B$2,AVERAGEIFS(AutoClaim_Data!C2:C3168,AutoClaim_Data!B2:B3168,"Train",AutoClaim_Data!D2:D3168,"<="&$B$2),AVERAGEIFS(AutoClaim_Data!C2:C3168,AutoClaim_Data!B2:B3168,"Train",AutoClaim_Data!D2:D3168,">"&$B$2)) | H13: =IF(AutoClaim_Data!D13<=$B$2,IF(AutoClaim_Data!E13<=$B$3,AVERAGEIFS(AutoClaim_Data!C2:C3168,AutoClaim_Data!B2:B3168,"Train",AutoClaim_Data!D2:D3168,"<="&$B$2,AutoClaim_Data!E2:E3168,"<="&$B$3),AVERAGEIFS(AutoClaim_Data!C2:C3168,AutoClaim_Data!B2:B3168,"Train",AutoClaim_Data!D2:D3168,"<="&$B$2,AutoClaim_Data!E2:E3168,">"&$B$3)),IF(AutoClaim_Data!E13<=$B$3,AVERAGEIFS(AutoClaim_Data!C2:C3168,AutoClaim_Data!B2:B3168,"Train",AutoClaim_Data!D2:D3168,">"&$B$2,AutoClaim_Data!E2:E3168,"<="&$B$3),AVERAGEIFS(AutoClaim_Data!C2:C3168,AutoClaim_Data!B2:B3168,"Train",AutoClaim_Data!D2:D3168,">"&$B$2,AutoClaim_Data!E2:E3168,">"&$B$3))) | I13: =(F13-H13)^2 | J13: =--(E13="Validation")
D14: =AutoClaim_Data!A14 | E14: =AutoClaim_Data!B14 | F14: =AutoClaim_Data!C14 | G14: =IF(AutoClaim_Data!D14<=$B$2,AVERAGEIFS(AutoClaim_Data!C2:C3168,AutoClaim_Data!B2:B3168,"Train",AutoClaim_Data!D2:D3168,"<="&$B$2),AVERAGEIFS(AutoClaim_Data!C2:C3168,AutoClaim_Data!B2:B3168,"Train",AutoClaim_Data!D2:D3168,">"&$B$2)) | H14: =IF(AutoClaim_Data!D14<=$B$2,IF(AutoClaim_Data!E14<=$B$3,AVERAGEIFS(AutoClaim_Data!C2:C3168,AutoClaim_Data!B2:B3168,"Train",AutoClaim_Data!D2:D3168,"<="&$B$2,AutoClaim_Data!E2:E3168,"<="&$B$3),AVERAGEIFS(AutoClaim_Data!C2:C3168,AutoClaim_Data!B2:B3168,"Train",AutoClaim_Data!D2:D3168,"<="&$B$2,AutoClaim_Data!E2:E3168,">"&$B$3)),IF(AutoClaim_Data!E14<=$B$3,AVERAGEIFS(AutoClaim_Data!C2:C3168,AutoClaim_Data!B2:B3168,"Train",AutoClaim_Data!D2:D3168,">"&$B$2,AutoClaim_Data!E2:E3168,"<="&$B$3),AVERAGEIFS(AutoClaim_Data!C2:C3168,AutoClaim_Data!B2:B3168,"Train",AutoClaim_Data!D2:D3168,">"&$B$2,AutoClaim_Data!E2:E3168,">"&$B$3))) | I14: =(F14-H14)^2 | J14: =--(E14="Validation")
