Workbook

Sheet README
A1: sheet | B1: purpose
A2: Insurance_Data | B2: Chunk 1 data load, factor recode, and AvgClaims helper.
A3: Design_Matrix | B3: Dummy-variable design matrix used by all model mechanics.
A4: Poisson_No_Offset | B4: Chunk 2 mod1: Poisson without offset, gradient mechanics in formulas.
A5: Poisson_With_Offset | B5: Chunk 2 mod2: Poisson with log(Holders) offset, formula-only mechanics.
A6: Gaussian_Models | B6: Chunk 3 mod3/mod4/mod5 OLS and weighted least squares via matrix formulas.
A7: Model_Comparison | B7: SSE comparison matching sse1..sse5 with charts.
A10: All calculations are performed with Excel formulas.

Sheet Insurance_Data
A1: row_id | B1: District_raw | C1: District_factor | D1: Group | E1: Age | F1: Holders | G1: Claims | H1: AvgClaims
A2: 1 | B2: 1 | C2: 1 | D2: <1l | E2: <25 | F2: 197 | G2: 38 | H2: =IFERROR(G2/F2,0) -> 0.1928934
A3: 2 | B3: 1 | C3: 1 | D3: <1l | E3: 25-29 | F3: 264 | G3: 35 | H3: =IFERROR(G3/F3,0) -> 0.13257576
A4: 3 | B4: 1 | C4: 1 | D4: <1l | E4: 30-35 | F4: 246 | G4: 20 | H4: =IFERROR(G4/F4,0) -> 0.081300813
A5: 4 | B5: 1 | C5: 1 | D5: <1l | E5: >35 | F5: 1680 | G5: 156 | H5: =IFERROR(G5/F5,0) -> 0.092857143
A6: 5 | B6: 1 | C6: 1 | D6: 1-1.5l | E6: <25 | F6: 284 | G6: 63 | H6: =IFERROR(G6/F6,0) -> 0.22183099
A7: 6 | B7: 1 | C7: 1 | D7: 1-1.5l | E7: 25-29 | F7: 536 | G7: 84 | H7: =IFERROR(G7/F7,0) -> 0.15671642
A8: 7 | B8: 1 | C8: 1 | D8: 1-1.5l | E8: 30-35 | F8: 696 | G8: 89 | H8: =IFERROR(G8/F8,0) -> 0.12787356
A9: 8 | B9: 1 | C9: 1 | D9: 1-1.5l | E9: >35 | F9: 3582 | G9: 400 | H9: =IFERROR(G9/F9,0) -> 0.11166946
A10: 9 | B10: 1 | C10: 1 | D10: 1.5-2l | E10: <25 | F10: 133 | G10: 19 | H10: =IFERROR(G10/F10,0) -> 0.14285714
A11: 10 | B11: 1 | C11: 1 | D11: 1.5-2l | E11: 25-29 | F11: 286 | G11: 52 | H11: =IFERROR(G11/F11,0) -> 0.18181818
A12: 11 | B12: 1 | C12: 1 | D12: 1.5-2l | E12: 30-35 | F12: 355 | G12: 74 | H12: =IFERROR(G12/F12,0) -> 0.2084507
A13: 12 | B13: 1 | C13: 1 | D13: 1.5-2l | E13: >35 | F13: 1640 | G13: 233 | H13: =IFERROR(G13/F13,0) -> 0.14207317
... A65: 64 | B65: 4 | C65: 4 | D65: >2l | E65: >35 | F65: 114 | G65: 33 | H65: =IFERROR(G65/F65,0) -> 0.28947368

Sheet Design_Matrix
A1: row_id | B1: Intercept | C1: District_2 | D1: District_3 | E1: District_4 | F1: Group_1-1.5l | G1: Group_1.5-2l | H1: Group_>2l | I1: Age_25-29 | J1: Age_30-35 | K1: Age_>35 | L1: Claims | M1: Holders | N1: AvgClaims
A2: =Insurance_Data!A2 -> 1 | B2: 1 | C2: =--(Insurance_Data!C2="2") -> 0 | D2: =--(Insurance_Data!C2="3") -> 0 | E2: =--(Insurance_Data!C2="4") -> 0 | F2: =--(Insurance_Data!D2="1-1.5l") -> 0 | G2: =--(Insurance_Data!D2="1.5-2l") -> 0 | H2: =--(Insurance_Data!D2=">2l") -> 0 | I2: =--(Insurance_Data!E2="25-29") -> 0 | J2: =--(Insurance_Data!E2="30-35") -> 0 | K2: =--(Insurance_Data!E2=">35") -> 0 | L2: =Insurance_Data!G2 -> 38 | M2: =Insurance_Data!F2 -> 197 | N2: =Insurance_Data!H2 -> 0.1928934
A3: =Insurance_Data!A3 -> 2 | B3: 1 | C3: =--(Insurance_Data!C3="2") -> 0 | D3: =--(Insurance_Data!C3="3") -> 0 | E3: =--(Insurance_Data!C3="4") -> 0 | F3: =--(Insurance_Data!D3="1-1.5l") -> 0 | G3: =--(Insurance_Data!D3="1.5-2l") -> 0 | H3: =--(Insurance_Data!D3=">2l") -> 0 | I3: =--(Insurance_Data!E3="25-29") -> 1 | J3: =--(Insurance_Data!E3="30-35") -> 0 | K3: =--(Insurance_Data!E3=">35") -> 0 | L3: =Insurance_Data!G3 -> 35 | M3: =Insurance_Data!F3 -> 264 | N3: =Insurance_Data!H3 -> 0.13257576
A4: =Insurance_Data!A4 -> 3 | B4: 1 | C4: =--(Insurance_Data!C4="2") -> 0 | D4: =--(Insurance_Data!C4="3") -> 0 | E4: =--(Insurance_Data!C4="4") -> 0 | F4: =--(Insurance_Data!D4="1-1.5l") -> 0 | G4: =--(Insurance_Data!D4="1.5-2l") -> 0 | H4: =--(Insurance_Data!D4=">2l") -> 0 | I4: =--(Insurance_Data!E4="25-29") -> 0 | J4: =--(Insurance_Data!E4="30-35") -> 1 | K4: =--(Insurance_Data!E4=">35") -> 0 | L4: =Insurance_Data!G4 -> 20 | M4: =Insurance_Data!F4 -> 246 | N4: =Insurance_Data!H4 -> 0.081300813
A5: =Insurance_Data!A5 -> 4 | B5: 1 | C5: =--(Insurance_Data!C5="2") -> 0 | D5: =--(Insurance_Data!C5="3") -> 0 | E5: =--(Insurance_Data!C5="4") -> 0 | F5: =--(Insurance_Data!D5="1-1.5l") -> 0 | G5: =--(Insurance_Data!D5="1.5-2l") -> 0 | H5: =--(Insurance_Data!D5=">2l") -> 0 | I5: =--(Insurance_Data!E5="25-29") -> 0 | J5: =--(Insurance_Data!E5="30-35") -> 0 | K5: =--(Insurance_Data!E5=">35") -> 1 | L5: =Insurance_Data!G5 -> 156 | M5: =Insurance_Data!F5 -> 1680 | N5: =Insurance_Data!H5 -> 0.092857143
A6: =Insurance_Data!A6 -> 5 | B6: 1 | C6: =--(Insurance_Data!C6="2") -> 0 | D6: =--(Insurance_Data!C6="3") -> 0 | E6: =--(Insurance_Data!C6="4") -> 0 | F6: =--(Insurance_Data!D6="1-1.5l") -> 1 | G6: =--(Insurance_Data!D6="1.5-2l") -> 0 | H6: =--(Insurance_Data!D6=">2l") -> 0 | I6: =--(Insurance_Data!E6="25-29") -> 0 | J6: =--(Insurance_Data!E6="30-35") -> 0 | K6: =--(Insurance_Data!E6=">35") -> 0 | L6: =Insurance_Data!G6 -> 63 | M6: =Insurance_Data!F6 -> 284 | N6: =Insurance_Data!H6 -> 0.22183099
A7: =Insurance_Data!A7 -> 6 | B7: 1 | C7: =--(Insurance_Data!C7="2") -> 0 | D7: =--(Insurance_Data!C7="3") -> 0 | E7: =--(Insurance_Data!C7="4") -> 0 | F7: =--(Insurance_Data!D7="1-1.5l") -> 1 | G7: =--(Insurance_Data!D7="1.5-2l") -> 0 | H7: =--(Insurance_Data!D7=">2l") -> 0 | I7: =--(Insurance_Data!E7="25-29") -> 1 | J7: =--(Insurance_Data!E7="30-35") -> 0 | K7: =--(Insurance_Data!E7=">35") -> 0 | L7: =Insurance_Data!G7 -> 84 | M7: =Insurance_Data!F7 -> 536 | N7: =Insurance_Data!H7 -> 0.15671642
A8: =Insurance_Data!A8 -> 7 | B8: 1 | C8: =--(Insurance_Data!C8="2") -> 0 | D8: =--(Insurance_Data!C8="3") -> 0 | E8: =--(Insurance_Data!C8="4") -> 0 | F8: =--(Insurance_Data!D8="1-1.5l") -> 1 | G8: =--(Insurance_Data!D8="1.5-2l") -> 0 | H8: =--(Insurance_Data!D8=">2l") -> 0 | I8: =--(Insurance_Data!E8="25-29") -> 0 | J8: =--(Insurance_Data!E8="30-35") -> 1 | K8: =--(Insurance_Data!E8=">35") -> 0 | L8: =Insurance_Data!G8 -> 89 | M8: =Insurance_Data!F8 -> 696 | N8: =Insurance_Data!H8 -> 0.12787356
A9: =Insurance_Data!A9 -> 8 | B9: 1 | C9: =--(Insurance_Data!C9="2") -> 0 | D9: =--(Insurance_Data!C9="3") -> 0 | E9: =--(Insurance_Data!C9="4") -> 0 | F9: =--(Insurance_Data!D9="1-1.5l") -> 1 | G9: =--(Insurance_Data!D9="1.5-2l") -> 0 | H9: =--(Insurance_Data!D9=">2l") -> 0 | I9: =--(Insurance_Data!E9="25-29") -> 0 | J9: =--(Insurance_Data!E9="30-35") -> 0 | K9: =--(Insurance_Data!E9=">35") -> 1 | L9: =Insurance_Data!G9 -> 400 | M9: =Insurance_Data!F9 -> 3582 | N9: =Insurance_Data!H9 -> 0.11166946
A10: =Insurance_Data!A10 -> 9 | B10: 1 | C10: =--(Insurance_Data!C10="2") -> 0 | D10: =--(Insurance_Data!C10="3") -> 0 | E10: =--(Insurance_Data!C10="4") -> 0 | F10: =--(Insurance_Data!D10="1-1.5l") -> 0 | G10: =--(Insurance_Data!D10="1.5-2l") -> 1 | H10: =--(Insurance_Data!D10=">2l") -> 0 | I10: =--(Insurance_Data!E10="25-29") -> 0 | J10: =--(Insurance_Data!E10="30-35") -> 0 | K10: =--(Insurance_Data!E10=">35") -> 0 | L10: =Insurance_Data!G10 -> 19 | M10: =Insurance_Data!F10 -> 133 | N10: =Insurance_Data!H10 -> 0.14285714
A11: =Insurance_Data!A11 -> 10 | B11: 1 | C11: =--(Insurance_Data!C11="2") -> 0 | D11: =--(Insurance_Data!C11="3") -> 0 | E11: =--(Insurance_Data!C11="4") -> 0 | F11: =--(Insurance_Data!D11="1-1.5l") -> 0 | G11: =--(Insurance_Data!D11="1.5-2l") -> 1 | H11: =--(Insurance_Data!D11=">2l") -> 0 | I11: =--(Insurance_Data!E11="25-29") -> 1 | J11: =--(Insurance_Data!E11="30-35") -> 0 | K11: =--(Insurance_Data!E11=">35") -> 0 | L11: =Insurance_Data!G11 -> 52 | M11: =Insurance_Data!F11 -> 286 | N11: =Insurance_Data!H11 -> 0.18181818
A12: =Insurance_Data!A12 -> 11 | B12: 1 | C12: =--(Insurance_Data!C12="2") -> 0 | D12: =--(Insurance_Data!C12="3") -> 0 | E12: =--(Insurance_Data!C12="4") -> 0 | F12: =--(Insurance_Data!D12="1-1.5l") -> 0 | G12: =--(Insurance_Data!D12="1.5-2l") -> 1 | H12: =--(Insurance_Data!D12=">2l") -> 0 | I12: =--(Insurance_Data!E12="25-29") -> 0 | J12: =--(Insurance_Data!E12="30-35") -> 1 | K12: =--(Insurance_Data!E12=">35") -> 0 | L12: =Insurance_Data!G12 -> 74 | M12: =Insurance_Data!F12 -> 355 | N12: =Insurance_Data!H12 -> 0.2084507
A13: =Insurance_Data!A13 -> 12 | B13: 1 | C13: =--(Insurance_Data!C13="2") -> 0 | D13: =--(Insurance_Data!C13="3") -> 0 | E13: =--(Insurance_Data!C13="4") -> 0 | F13: =--(Insurance_Data!D13="1-1.5l") -> 0 | G13: =--(Insurance_Data!D13="1.5-2l") -> 1 | H13: =--(Insurance_Data!D13=">2l") -> 0 | I13: =--(Insurance_Data!E13="25-29") -> 0 | J13: =--(Insurance_Data!E13="30-35") -> 0 | K13: =--(Insurance_Data!E13=">35") -> 1 | L13: =Insurance_Data!G13 -> 233 | M13: =Insurance_Data!F13 -> 1640 | N13: =Insurance_Data!H13 -> 0.14207317
... A65: =Insurance_Data!A65 -> 64 | B65: 1 | C65: =--(Insurance_Data!C65="2") -> 0 | D65: =--(Insurance_Data!C65="3") -> 0 | E65: =--(Insurance_Data!C65="4") -> 1 | F65: =--(Insurance_Data!D65="1-1.5l") -> 0 | G65: =--(Insurance_Data!D65="1.5-2l") -> 0 | H65: =--(Insurance_Data!D65=">2l") -> 1 | I65: =--(Insurance_Data!E65="25-29") -> 0 | J65: =--(Insurance_Data!E65="30-35") -> 0 | K65: =--(Insurance_Data!E65=">35") -> 1 | L65: =Insurance_Data!G65 -> 33 | M65: =Insurance_Data!F65 -> 114 | N65: =Insurance_Data!H65 -> 0.28947368

Sheet Poisson_No_Offset
A1: learning_rate | B1: 1e-05
A2: iterations | B2: 8
A4: coef | B4: iter_0 | C4: iter_1 | D4: iter_2 | E4: iter_3 | F4: iter_4 | G4: iter_5 | H4: iter_6 | I4: iter_7 | J4: iter_8 | L4: Row mechanics by iteration
A5: Intercept | B5: 0 | C5: =IFERROR(B5+$B$1*B75/COUNT(Design_Matrix!A2:A65),B5) -> 0.00048234375 | D5: =IFERROR(C5+$B$1*C75/COUNT(Design_Matrix!A2:A65),C5) -> 0.0009646875 | E5: =IFERROR(D5+$B$1*D75/COUNT(Design_Matrix!A2:A65),D5) -> 0.0014470312 | F5: =IFERROR(E5+$B$1*E75/COUNT(Design_Matrix!A2:A65),E5) -> 0.001929375 | G5: =IFERROR(F5+$B$1*F75/COUNT(Design_Matrix!A2:A65),F5) -> 0.0024117188 | H5: =IFERROR(G5+$B$1*G75/COUNT(Design_Matrix!A2:A65),G5) -> 0.0028940625 | I5: =IFERROR(H5+$B$1*H75/COUNT(Design_Matrix!A2:A65),H5) -> 0.0033764063 | J5: =IFERROR(I5+$B$1*I75/COUNT(Design_Matrix!A2:A65),I5) -> 0.00385875 | L5: eta_iter_0 | M5: mu_iter_0 | N5: eta_iter_1 | O5: mu_iter_1 | P5: eta_iter_2 | Q5: mu_iter_2 | R5: eta_iter_3 | S5: mu_iter_3 | T5: eta_iter_4 | U5: mu_iter_4 | V5: eta_iter_5 | W5: mu_iter_5 | X5: eta_iter_6 | Y5: mu_iter_6 | Z5: eta_iter_7 | AA5: mu_iter_7 | AB5: eta_iter_8 | AC5: mu_iter_8
A6: District_2 | B6: 0 | C6: =IFERROR(B6+$B$1*B76/COUNT(Design_Matrix!A2:A65),B6) -> 0.00013671875 | D6: =IFERROR(C6+$B$1*C76/COUNT(Design_Matrix!A2:A65),C6) -> 0.0002734375 | E6: =IFERROR(D6+$B$1*D76/COUNT(Design_Matrix!A2:A65),D6) -> 0.00041015625 | F6: =IFERROR(E6+$B$1*E76/COUNT(Design_Matrix!A2:A65),E6) -> 0.000546875 | G6: =IFERROR(F6+$B$1*F76/COUNT(Design_Matrix!A2:A65),F6) -> 0.00068359375 | H6: =IFERROR(G6+$B$1*G76/COUNT(Design_Matrix!A2:A65),G6) -> 0.0008203125 | I6: =IFERROR(H6+$B$1*H76/COUNT(Design_Matrix!A2:A65),H6) -> 0.00095703125 | J6: =IFERROR(I6+$B$1*I76/COUNT(Design_Matrix!A2:A65),I6) -> 0.00109375 | L6: =IFERROR(SUMPRODUCT(Design_Matrix!B2:K2,$B$5:$B$14),0) -> 0 | M6: =EXP(MAX(-50,MIN(50,L6))) -> 1 | N6: =IFERROR(SUMPRODUCT(Design_Matrix!B2:K2,$C$5:$C$14),0) -> 0 | O6: =EXP(MAX(-50,MIN(50,N6))) -> 1 | P6: =IFERROR(SUMPRODUCT(Design_Matrix!B2:K2,$D$5:$D$14),0) -> 0 | Q6: =EXP(MAX(-50,MIN(50,P6))) -> 1 | R6: =IFERROR(SUMPRODUCT(Design_Matrix!B2:K2,$E$5:$E$14),0) -> 0 | S6: =EXP(MAX(-50,MIN(50,R6))) -> 1 | T6: =IFERROR(SUMPRODUCT(Design_Matrix!B2:K2,$F$5:$F$14),0) -> 0 | U6: =EXP(MAX(-50,MIN(50,T6))) -> 1 | V6: =IFERROR(SUMPRODUCT(Design_Matrix!B2:K2,$G$5:$G$14),0) -> 0 | W6: =EXP(MAX(-50,MIN(50,V6))) -> 1 | X6: =IFERROR(SUMPRODUCT(Design_Matrix!B2:K2,$H$5:$H$14),0) -> 0 | Y6: =EXP(MAX(-50,MIN(50,X6))) -> 1 | Z6: =IFERROR(SUMPRODUCT(Design_Matrix!B2:K2,$I$5:$I$14),0) -> 0 | AA6: =EXP(MAX(-50,MIN(50,Z6))) -> 1 | AB6: =IFERROR(SUMPRODUCT(Design_Matrix!B2:K2,$J$5:$J$14),0) -> 0 | AC6: =EXP(MAX(-50,MIN(50,AB6))) -> 1
A7: District_3 | B7: 0 | C7: =IFERROR(B7+$B$1*B77/COUNT(Design_Matrix!A2:A65),B7) -> 8.390625e-05 | D7: =IFERROR(C7+$B$1*C77/COUNT(Design_Matrix!A2:A65),C7) -> 0.0001678125 | E7: =IFERROR(D7+$B$1*D77/COUNT(Design_Matrix!A2:A65),D7) -> 0.00025171875 | F7: =IFERROR(E7+$B$1*E77/COUNT(Design_Matrix!A2:A65),E7) -> 0.000335625 | G7: =IFERROR(F7+$B$1*F77/COUNT(Design_Matrix!A2:A65),F7) -> 0.00041953125 | H7: =IFERROR(G7+$B$1*G77/COUNT(Design_Matrix!A2:A65),G7) -> 0.0005034375 | I7: =IFERROR(H7+$B$1*H77/COUNT(Design_Matrix!A2:A65),H7) -> 0.00058734375 | J7: =IFERROR(I7+$B$1*I77/COUNT(Design_Matrix!A2:A65),I7) -> 0.00067125 | L7: =IFERROR(SUMPRODUCT(Design_Matrix!B3:K3,$B$5:$B$14),0) -> 0 | M7: =EXP(MAX(-50,MIN(50,L7))) -> 1 | N7: =IFERROR(SUMPRODUCT(Design_Matrix!B3:K3,$C$5:$C$14),0) -> 0 | O7: =EXP(MAX(-50,MIN(50,N7))) -> 1 | P7: =IFERROR(SUMPRODUCT(Design_Matrix!B3:K3,$D$5:$D$14),0) -> 0 | Q7: =EXP(MAX(-50,MIN(50,P7))) -> 1 | R7: =IFERROR(SUMPRODUCT(Design_Matrix!B3:K3,$E$5:$E$14),0) -> 0 | S7: =EXP(MAX(-50,MIN(50,R7))) -> 1 | T7: =IFERROR(SUMPRODUCT(Design_Matrix!B3:K3,$F$5:$F$14),0) -> 0 | U7: =EXP(MAX(-50,MIN(50,T7))) -> 1 | V7: =IFERROR(SUMPRODUCT(Design_Matrix!B3:K3,$G$5:$G$14),0) -> 0 | W7: =EXP(MAX(-50,MIN(50,V7))) -> 1 | X7: =IFERROR(SUMPRODUCT(Design_Matrix!B3:K3,$H$5:$H$14),0) -> 0 | Y7: =EXP(MAX(-50,MIN(50,X7))) -> 1 | Z7: =IFERROR(SUMPRODUCT(Design_Matrix!B3:K3,$I$5:$I$14),0) -> 0 | AA7: =EXP(MAX(-50,MIN(50,Z7))) -> 1 | AB7: =IFERROR(SUMPRODUCT(Design_Matrix!B3:K3,$J$5:$J$14),0) -> 0 | AC7: =EXP(MAX(-50,MIN(50,AB7))) -> 1
A8: District_4 | B8: 0 | C8: =IFERROR(B8+$B$1*B78/COUNT(Design_Matrix!A2:A65),B8) -> 4.84375e-05 | D8: =IFERROR(C8+$B$1*C78/COUNT(Design_Matrix!A2:A65),C8) -> 9.6875e-05 | E8: =IFERROR(D8+$B$1*D78/COUNT(Design_Matrix!A2:A65),D8) -> 0.0001453125 | F8: =IFERROR(E8+$B$1*E78/COUNT(Design_Matrix!A2:A65),E8) -> 0.00019375 | G8: =IFERROR(F8+$B$1*F78/COUNT(Design_Matrix!A2:A65),F8) -> 0.0002421875 | H8: =IFERROR(G8+$B$1*G78/COUNT(Design_Matrix!A2:A65),G8) -> 0.000290625 | I8: =IFERROR(H8+$B$1*H78/COUNT(Design_Matrix!A2:A65),H8) -> 0.0003390625 | J8: =IFERROR(I8+$B$1*I78/COUNT(Design_Matrix!A2:A65),I8) -> 0.0003875 | L8: =IFERROR(SUMPRODUCT(Design_Matrix!B4:K4,$B$5:$B$14),0) -> 0 | M8: =EXP(MAX(-50,MIN(50,L8))) -> 1 | N8: =IFERROR(SUMPRODUCT(Design_Matrix!B4:K4,$C$5:$C$14),0) -> 0 | O8: =EXP(MAX(-50,MIN(50,N8))) -> 1 | P8: =IFERROR(SUMPRODUCT(Design_Matrix!B4:K4,$D$5:$D$14),0) -> 0 | Q8: =EXP(MAX(-50,MIN(50,P8))) -> 1 | R8: =IFERROR(SUMPRODUCT(Design_Matrix!B4:K4,$E$5:$E$14),0) -> 0 | S8: =EXP(MAX(-50,MIN(50,R8))) -> 1 | T8: =IFERROR(SUMPRODUCT(Design_Matrix!B4:K4,$F$5:$F$14),0) -> 0 | U8: =EXP(MAX(-50,MIN(50,T8))) -> 1 | V8: =IFERROR(SUMPRODUCT(Design_Matrix!B4:K4,$G$5:$G$14),0) -> 0 | W8: =EXP(MAX(-50,MIN(50,V8))) -> 1 | X8: =IFERROR(SUMPRODUCT(Design_Matrix!B4:K4,$H$5:$H$14),0) -> 0 | Y8: =EXP(MAX(-50,MIN(50,X8))) -> 1 | Z8: =IFERROR(SUMPRODUCT(Design_Matrix!B4:K4,$I$5:$I$14),0) -> 0 | AA8: =EXP(MAX(-50,MIN(50,Z8))) -> 1 | AB8: =IFERROR(SUMPRODUCT(Design_Matrix!B4:K4,$J$5:$J$14),0) -> 0 | AC8: =EXP(MAX(-50,MIN(50,AB8))) -> 1
A9: Group_1-1.5l | B9: 0 | C9: =IFERROR(B9+$B$1*B79/COUNT(Design_Matrix!A2:A65),B9) -> 0.0002240625 | D9: =IFERROR(C9+$B$1*C79/COUNT(Design_Matrix!A2:A65),C9) -> 0.000448125 | E9: =IFERROR(D9+$B$1*D79/COUNT(Design_Matrix!A2:A65),D9) -> 0.0006721875 | F9: =IFERROR(E9+$B$1*E79/COUNT(Design_Matrix!A2:A65),E9) -> 0.00089625 | G9: =IFERROR(F9+$B$1*F79/COUNT(Design_Matrix!A2:A65),F9) -> 0.0011203125 | H9: =IFERROR(G9+$B$1*G79/COUNT(Design_Matrix!A2:A65),G9) -> 0.001344375 | I9: =IFERROR(H9+$B$1*H79/COUNT(Design_Matrix!A2:A65),H9) -> 0.0015684375 | J9: =IFERROR(I9+$B$1*I79/COUNT(Design_Matrix!A2:A65),I9) -> 0.0017925 | L9: =IFERROR(SUMPRODUCT(Design_Matrix!B5:K5,$B$5:$B$14),0) -> 0 | M9: =EXP(MAX(-50,MIN(50,L9))) -> 1 | N9: =IFERROR(SUMPRODUCT(Design_Matrix!B5:K5,$C$5:$C$14),0) -> 0 | O9: =EXP(MAX(-50,MIN(50,N9))) -> 1 | P9: =IFERROR(SUMPRODUCT(Design_Matrix!B5:K5,$D$5:$D$14),0) -> 0 | Q9: =EXP(MAX(-50,MIN(50,P9))) -> 1 | R9: =IFERROR(SUMPRODUCT(Design_Matrix!B5:K5,$E$5:$E$14),0) -> 0 | S9: =EXP(MAX(-50,MIN(50,R9))) -> 1 | T9: =IFERROR(SUMPRODUCT(Design_Matrix!B5:K5,$F$5:$F$14),0) -> 0 | U9: =EXP(MAX(-50,MIN(50,T9))) -> 1 | V9: =IFERROR(SUMPRODUCT(Design_Matrix!B5:K5,$G$5:$G$14),0) -> 0 | W9: =EXP(MAX(-50,MIN(50,V9))) -> 1 | X9: =IFERROR(SUMPRODUCT(Design_Matrix!B5:K5,$H$5:$H$14),0) -> 0 | Y9: =EXP(MAX(-50,MIN(50,X9))) -> 1 | Z9: =IFERROR(SUMPRODUCT(Design_Matrix!B5:K5,$I$5:$I$14),0) -> 0 | AA9: =EXP(MAX(-50,MIN(50,Z9))) -> 1 | AB9: =IFERROR(SUMPRODUCT(Design_Matrix!B5:K5,$J$5:$J$14),0) -> 0 | AC9: =EXP(MAX(-50,MIN(50,AB9))) -> 1
A10: Group_1.5-2l | B10: 0 | C10: =IFERROR(B10+$B$1*B80/COUNT(Design_Matrix!A2:A65),B10) -> 0.00013234375 | D10: =IFERROR(C10+$B$1*C80/COUNT(Design_Matrix!A2:A65),C10) -> 0.0002646875 | E10: =IFERROR(D10+$B$1*D80/COUNT(Design_Matrix!A2:A65),D10) -> 0.00039703125 | F10: =IFERROR(E10+$B$1*E80/COUNT(Design_Matrix!A2:A65),E10) -> 0.000529375 | G10: =IFERROR(F10+$B$1*F80/COUNT(Design_Matrix!A2:A65),F10) -> 0.00066171875 | H10: =IFERROR(G10+$B$1*G80/COUNT(Design_Matrix!A2:A65),G10) -> 0.0007940625 | I10: =IFERROR(H10+$B$1*H80/COUNT(Design_Matrix!A2:A65),H10) -> 0.00092640625 | J10: =IFERROR(I10+$B$1*I80/COUNT(Design_Matrix!A2:A65),I10) -> 0.00105875 | L10: =IFERROR(SUMPRODUCT(Design_Matrix!B6:K6,$B$5:$B$14),0) -> 0 | M10: =EXP(MAX(-50,MIN(50,L10))) -> 1 | N10: =IFERROR(SUMPRODUCT(Design_Matrix!B6:K6,$C$5:$C$14),0) -> 0 | O10: =EXP(MAX(-50,MIN(50,N10))) -> 1 | P10: =IFERROR(SUMPRODUCT(Design_Matrix!B6:K6,$D$5:$D$14),0) -> 0 | Q10: =EXP(MAX(-50,MIN(50,P10))) -> 1 | R10: =IFERROR(SUMPRODUCT(Design_Matrix!B6:K6,$E$5:$E$14),0) -> 0 | S10: =EXP(MAX(-50,MIN(50,R10))) -> 1 | T10: =IFERROR(SUMPRODUCT(Design_Matrix!B6:K6,$F$5:$F$14),0) -> 0 | U10: =EXP(MAX(-50,MIN(50,T10))) -> 1 | V10: =IFERROR(SUMPRODUCT(Design_Matrix!B6:K6,$G$5:$G$14),0) -> 0 | W10: =EXP(MAX(-50,MIN(50,V10))) -> 1 | X10: =IFERROR(SUMPRODUCT(Design_Matrix!B6:K6,$H$5:$H$14),0) -> 0 | Y10: =EXP(MAX(-50,MIN(50,X10))) -> 1 | Z10: =IFERROR(SUMPRODUCT(Design_Matrix!B6:K6,$I$5:$I$14),0) -> 0 | AA10: =EXP(MAX(-50,MIN(50,Z10))) -> 1 | AB10: =IFERROR(SUMPRODUCT(Design_Matrix!B6:K6,$J$5:$J$14),0) -> 0 | AC10: =EXP(MAX(-50,MIN(50,AB10))) -> 1
A11: Group_>2l | B11: 0 | C11: =IFERROR(B11+$B$1*B81/COUNT(Design_Matrix!A2:A65),B11) -> 4.421875e-05 | D11: =IFERROR(C11+$B$1*C81/COUNT(Design_Matrix!A2:A65),C11) -> 8.84375e-05 | E11: =IFERROR(D11+$B$1*D81/COUNT(Design_Matrix!A2:A65),D11) -> 0.00013265625 | F11: =IFERROR(E11+$B$1*E81/COUNT(Design_Matrix!A2:A65),E11) -> 0.000176875 | G11: =IFERROR(F11+$B$1*F81/COUNT(Design_Matrix!A2:A65),F11) -> 0.00022109375 | H11: =IFERROR(G11+$B$1*G81/COUNT(Design_Matrix!A2:A65),G11) -> 0.0002653125 | I11: =IFERROR(H11+$B$1*H81/COUNT(Design_Matrix!A2:A65),H11) -> 0.00030953125 | J11: =IFERROR(I11+$B$1*I81/COUNT(Design_Matrix!A2:A65),I11) -> 0.00035375 | L11: =IFERROR(SUMPRODUCT(Design_Matrix!B7:K7,$B$5:$B$14),0) -> 0 | M11: =EXP(MAX(-50,MIN(50,L11))) -> 1 | N11: =IFERROR(SUMPRODUCT(Design_Matrix!B7:K7,$C$5:$C$14),0) -> 0 | O11: =EXP(MAX(-50,MIN(50,N11))) -> 1 | P11: =IFERROR(SUMPRODUCT(Design_Matrix!B7:K7,$D$5:$D$14),0) -> 0 | Q11: =EXP(MAX(-50,MIN(50,P11))) -> 1 | R11: =IFERROR(SUMPRODUCT(Design_Matrix!B7:K7,$E$5:$E$14),0) -> 0 | S11: =EXP(MAX(-50,MIN(50,R11))) -> 1 | T11: =IFERROR(SUMPRODUCT(Design_Matrix!B7:K7,$F$5:$F$14),0) -> 0 | U11: =EXP(MAX(-50,MIN(50,T11))) -> 1 | V11: =IFERROR(SUMPRODUCT(Design_Matrix!B7:K7,$G$5:$G$14),0) -> 0 | W11: =EXP(MAX(-50,MIN(50,V11))) -> 1 | X11: =IFERROR(SUMPRODUCT(Design_Matrix!B7:K7,$H$5:$H$14),0) -> 0 | Y11: =EXP(MAX(-50,MIN(50,X11))) -> 1 | Z11: =IFERROR(SUMPRODUCT(Design_Matrix!B7:K7,$I$5:$I$14),0) -> 0 | AA11: =EXP(MAX(-50,MIN(50,Z11))) -> 1 | AB11: =IFERROR(SUMPRODUCT(Design_Matrix!B7:K7,$J$5:$J$14),0) -> 0 | AC11: =EXP(MAX(-50,MIN(50,AB11))) -> 1
A12: Age_25-29 | B12: 0 | C12: =IFERROR(B12+$B$1*B82/COUNT(Design_Matrix!A2:A65),B12) -> 6.0625e-05 | D12: =IFERROR(C12+$B$1*C82/COUNT(Design_Matrix!A2:A65),C12) -> 0.00012125 | E12: =IFERROR(D12+$B$1*D82/COUNT(Design_Matrix!A2:A65),D12) -> 0.000181875 | F12: =IFERROR(E12+$B$1*E82/COUNT(Design_Matrix!A2:A65),E12) -> 0.0002425 | G12: =IFERROR(F12+$B$1*F82/COUNT(Design_Matrix!A2:A65),F12) -> 0.000303125 | H12: =IFERROR(G12+$B$1*G82/COUNT(Design_Matrix!A2:A65),G12) -> 0.00036375 | I12: =IFERROR(H12+$B$1*H82/COUNT(Design_Matrix!A2:A65),H12) -> 0.000424375 | J12: =IFERROR(I12+$B$1*I82/COUNT(Design_Matrix!A2:A65),I12) -> 0.000485 | L12: =IFERROR(SUMPRODUCT(Design_Matrix!B8:K8,$B$5:$B$14),0) -> 0 | M12: =EXP(MAX(-50,MIN(50,L12))) -> 1 | N12: =IFERROR(SUMPRODUCT(Design_Matrix!B8:K8,$C$5:$C$14),0) -> 0 | O12: =EXP(MAX(-50,MIN(50,N12))) -> 1 | P12: =IFERROR(SUMPRODUCT(Design_Matrix!B8:K8,$D$5:$D$14),0) -> 0 | Q12: =EXP(MAX(-50,MIN(50,P12))) -> 1 | R12: =IFERROR(SUMPRODUCT(Design_Matrix!B8:K8,$E$5:$E$14),0) -> 0 | S12: =EXP(MAX(-50,MIN(50,R12))) -> 1 | T12: =IFERROR(SUMPRODUCT(Design_Matrix!B8:K8,$F$5:$F$14),0) -> 0 | U12: =EXP(MAX(-50,MIN(50,T12))) -> 1 | V12: =IFERROR(SUMPRODUCT(Design_Matrix!B8:K8,$G$5:$G$14),0) -> 0 | W12: =EXP(MAX(-50,MIN(50,V12))) -> 1 | X12: =IFERROR(SUMPRODUCT(Design_Matrix!B8:K8,$H$5:$H$14),0) -> 0 | Y12: =EXP(MAX(-50,MIN(50,X12))) -> 1 | Z12: =IFERROR(SUMPRODUCT(Design_Matrix!B8:K8,$I$5:$I$14),0) -> 0 | AA12: =EXP(MAX(-50,MIN(50,Z12))) -> 1 | AB12: =IFERROR(SUMPRODUCT(Design_Matrix!B8:K8,$J$5:$J$14),0) -> 0 | AC12: =EXP(MAX(-50,MIN(50,AB12))) -> 1
A13: Age_30-35 | B13: 0 | C13: =IFERROR(B13+$B$1*B83/COUNT(Design_Matrix!A2:A65),B13) -> 6.828125e-05 | D13: =IFERROR(C13+$B$1*C83/COUNT(Design_Matrix!A2:A65),C13) -> 0.0001365625 | E13: =IFERROR(D13+$B$1*D83/COUNT(Design_Matrix!A2:A65),D13) -> 0.00020484375 | F13: =IFERROR(E13+$B$1*E83/COUNT(Design_Matrix!A2:A65),E13) -> 0.000273125 | G13: =IFERROR(F13+$B$1*F83/COUNT(Design_Matrix!A2:A65),F13) -> 0.00034140625 | H13: =IFERROR(G13+$B$1*G83/COUNT(Design_Matrix!A2:A65),G13) -> 0.0004096875 | I13: =IFERROR(H13+$B$1*H83/COUNT(Design_Matrix!A2:A65),H13) -> 0.00047796875 | J13: =IFERROR(I13+$B$1*I83/COUNT(Design_Matrix!A2:A65),I13) -> 0.00054625 | L13: =IFERROR(SUMPRODUCT(Design_Matrix!B9:K9,$B$5:$B$14),0) -> 0 | M13: =EXP(MAX(-50,MIN(50,L13))) -> 1 | N13: =IFERROR(SUMPRODUCT(Design_Matrix!B9:K9,$C$5:$C$14),0) -> 0 | O13: =EXP(MAX(-50,MIN(50,N13))) -> 1 | P13: =IFERROR(SUMPRODUCT(Design_Matrix!B9:K9,$D$5:$D$14),0) -> 0 | Q13: =EXP(MAX(-50,MIN(50,P13))) -> 1 | R13: =IFERROR(SUMPRODUCT(Design_Matrix!B9:K9,$E$5:$E$14),0) -> 0 | S13: =EXP(MAX(-50,MIN(50,R13))) -> 1 | T13: =IFERROR(SUMPRODUCT(Design_Matrix!B9:K9,$F$5:$F$14),0) -> 0 | U13: =EXP(MAX(-50,MIN(50,T13))) -> 1 | V13: =IFERROR(SUMPRODUCT(Design_Matrix!B9:K9,$G$5:$G$14),0) -> 0 | W13: =EXP(MAX(-50,MIN(50,V13))) -> 1 | X13: =IFERROR(SUMPRODUCT(Design_Matrix!B9:K9,$H$5:$H$14),0) -> 0 | Y13: =EXP(MAX(-50,MIN(50,X13))) -> 1 | Z13: =IFERROR(SUMPRODUCT(Design_Matrix!B9:K9,$I$5:$I$14),0) -> 0 | AA13: =EXP(MAX(-50,MIN(50,Z13))) -> 1 | AB13: =IFERROR(SUMPRODUCT(Design_Matrix!B9:K9,$J$5:$J$14),0) -> 0 | AC13: =EXP(MAX(-50,MIN(50,AB13))) -> 1
A14: Age_>35 | B14: 0 | C14: =IFERROR(B14+$B$1*B84/COUNT(Design_Matrix!A2:A65),B14) -> 0.00032015625 | D14: =IFERROR(C14+$B$1*C84/COUNT(Design_Matrix!A2:A65),C14) -> 0.0006403125 | E14: =IFERROR(D14+$B$1*D84/COUNT(Design_Matrix!A2:A65),D14) -> 0.00096046875 | F14: =IFERROR(E14+$B$1*E84/COUNT(Design_Matrix!A2:A65),E14) -> 0.001280625 | G14: =IFERROR(F14+$B$1*F84/COUNT(Design_Matrix!A2:A65),F14) -> 0.0016007813 | H14: =IFERROR(G14+$B$1*G84/COUNT(Design_Matrix!A2:A65),G14) -> 0.0019209375 | I14: =IFERROR(H14+$B$1*H84/COUNT(Design_Matrix!A2:A65),H14) -> 0.0022410938 | J14: =IFERROR(I14+$B$1*I84/COUNT(Design_Matrix!A2:A65),I14) -> 0.00256125 | L14: =IFERROR(SUMPRODUCT(Design_Matrix!B10:K10,$B$5:$B$14),0) -> 0 | M14: =EXP(MAX(-50,MIN(50,L14))) -> 1 | N14: =IFERROR(SUMPRODUCT(Design_Matrix!B10:K10,$C$5:$C$14),0) -> 0 | O14: =EXP(MAX(-50,MIN(50,N14))) -> 1 | P14: =IFERROR(SUMPRODUCT(Design_Matrix!B10:K10,$D$5:$D$14),0) -> 0 | Q14: =EXP(MAX(-50,MIN(50,P14))) -> 1 | R14: =IFERROR(SUMPRODUCT(Design_Matrix!B10:K10,$E$5:$E$14),0) -> 0 | S14: =EXP(MAX(-50,MIN(50,R14))) -> 1 | T14: =IFERROR(SUMPRODUCT(Design_Matrix!B10:K10,$F$5:$F$14),0) -> 0 | U14: =EXP(MAX(-50,MIN(50,T14))) -> 1 | V14: =IFERROR(SUMPRODUCT(Design_Matrix!B10:K10,$G$5:$G$14),0) -> 0 | W14: =EXP(MAX(-50,MIN(50,V14))) -> 1 | X14: =IFERROR(SUMPRODUCT(Design_Matrix!B10:K10,$H$5:$H$14),0) -> 0 | Y14: =EXP(MAX(-50,MIN(50,X14))) -> 1 | Z14: =IFERROR(SUMPRODUCT(Design_Matrix!B10:K10,$I$5:$I$14),0) -> 0 | AA14: =EXP(MAX(-50,MIN(50,Z14))) -> 1 | AB14: =IFERROR(SUMPRODUCT(Design_Matrix!B10:K10,$J$5:$J$14),0) -> 0 | AC14: =EXP(MAX(-50,MIN(50,AB14))) -> 1
L15: =IFERROR(SUMPRODUCT(Design_Matrix!B11:K11,$B$5:$B$14),0) -> 0 | M15: =EXP(MAX(-50,MIN(50,L15))) -> 1 | N15: =IFERROR(SUMPRODUCT(Design_Matrix!B11:K11,$C$5:$C$14),0) -> 0 | O15: =EXP(MAX(-50,MIN(50,N15))) -> 1 | P15: =IFERROR(SUMPRODUCT(Design_Matrix!B11:K11,$D$5:$D$14),0) -> 0 | Q15: =EXP(MAX(-50,MIN(50,P15))) -> 1 | R15: =IFERROR(SUMPRODUCT(Design_Matrix!B11:K11,$E$5:$E$14),0) -> 0 | S15: =EXP(MAX(-50,MIN(50,R15))) -> 1 | T15: =IFERROR(SUMPRODUCT(Design_Matrix!B11:K11,$F$5:$F$14),0) -> 0 | U15: =EXP(MAX(-50,MIN(50,T15))) -> 1 | V15: =IFERROR(SUMPRODUCT(Design_Matrix!B11:K11,$G$5:$G$14),0) -> 0 | W15: =EXP(MAX(-50,MIN(50,V15))) -> 1 | X15: =IFERROR(SUMPRODUCT(Design_Matrix!B11:K11,$H$5:$H$14),0) -> 0 | Y15: =EXP(MAX(-50,MIN(50,X15))) -> 1 | Z15: =IFERROR(SUMPRODUCT(Design_Matrix!B11:K11,$I$5:$I$14),0) -> 0 | AA15: =EXP(MAX(-50,MIN(50,Z15))) -> 1 | AB15: =IFERROR(SUMPRODUCT(Design_Matrix!B11:K11,$J$5:$J$14),0) -> 0 | AC15: =EXP(MAX(-50,MIN(50,AB15))) -> 1
L16: =IFERROR(SUMPRODUCT(Design_Matrix!B12:K12,$B$5:$B$14),0) -> 0 | M16: =EXP(MAX(-50,MIN(50,L16))) -> 1 | N16: =IFERROR(SUMPRODUCT(Design_Matrix!B12:K12,$C$5:$C$14),0) -> 0 | O16: =EXP(MAX(-50,MIN(50,N16))) -> 1 | P16: =IFERROR(SUMPRODUCT(Design_Matrix!B12:K12,$D$5:$D$14),0) -> 0 | Q16: =EXP(MAX(-50,MIN(50,P16))) -> 1 | R16: =IFERROR(SUMPRODUCT(Design_Matrix!B12:K12,$E$5:$E$14),0) -> 0 | S16: =EXP(MAX(-50,MIN(50,R16))) -> 1 | T16: =IFERROR(SUMPRODUCT(Design_Matrix!B12:K12,$F$5:$F$14),0) -> 0 | U16: =EXP(MAX(-50,MIN(50,T16))) -> 1 | V16: =IFERROR(SUMPRODUCT(Design_Matrix!B12:K12,$G$5:$G$14),0) -> 0 | W16: =EXP(MAX(-50,MIN(50,V16))) -> 1 | X16: =IFERROR(SUMPRODUCT(Design_Matrix!B12:K12,$H$5:$H$14),0) -> 0 | Y16: =EXP(MAX(-50,MIN(50,X16))) -> 1 | Z16: =IFERROR(SUMPRODUCT(Design_Matrix!B12:K12,$I$5:$I$14),0) -> 0 | AA16: =EXP(MAX(-50,MIN(50,Z16))) -> 1 | AB16: =IFERROR(SUMPRODUCT(Design_Matrix!B12:K12,$J$5:$J$14),0) -> 0 | AC16: =EXP(MAX(-50,MIN(50,AB16))) -> 1
L17: =IFERROR(SUMPRODUCT(Design_Matrix!B13:K13,$B$5:$B$14),0) -> 0 | M17: =EXP(MAX(-50,MIN(50,L17))) -> 1 | N17: =IFERROR(SUMPRODUCT(Design_Matrix!B13:K13,$C$5:$C$14),0) -> 0 | O17: =EXP(MAX(-50,MIN(50,N17))) -> 1 | P17: =IFERROR(SUMPRODUCT(Design_Matrix!B13:K13,$D$5:$D$14),0) -> 0 | Q17: =EXP(MAX(-50,MIN(50,P17))) -> 1 | R17: =IFERROR(SUMPRODUCT(Design_Matrix!B13:K13,$E$5:$E$14),0) -> 0 | S17: =EXP(MAX(-50,MIN(50,R17))) -> 1 | T17: =IFERROR(SUMPRODUCT(Design_Matrix!B13:K13,$F$5:$F$14),0) -> 0 | U17: =EXP(MAX(-50,MIN(50,T17))) -> 1 | V17: =IFERROR(SUMPRODUCT(Design_Matrix!B13:K13,$G$5:$G$14),0) -> 0 | W17: =EXP(MAX(-50,MIN(50,V17))) -> 1 | X17: =IFERROR(SUMPRODUCT(Design_Matrix!B13:K13,$H$5:$H$14),0) -> 0 | Y17: =EXP(MAX(-50,MIN(50,X17))) -> 1 | Z17: =IFERROR(SUMPRODUCT(Design_Matrix!B13:K13,$I$5:$I$14),0) -> 0 | AA17: =EXP(MAX(-50,MIN(50,Z17))) -> 1 | AB17: =IFERROR(SUMPRODUCT(Design_Matrix!B13:K13,$J$5:$J$14),0) -> 0 | AC17: =EXP(MAX(-50,MIN(50,AB17))) -> 1
L18: =IFERROR(SUMPRODUCT(Design_Matrix!B14:K14,$B$5:$B$14),0) -> 0 | M18: =EXP(MAX(-50,MIN(50,L18))) -> 1 | N18: =IFERROR(SUMPRODUCT(Design_Matrix!B14:K14,$C$5:$C$14),0) -> 0 | O18: =EXP(MAX(-50,MIN(50,N18))) -> 1 | P18: =IFERROR(SUMPRODUCT(Design_Matrix!B14:K14,$D$5:$D$14),0) -> 0 | Q18: =EXP(MAX(-50,MIN(50,P18))) -> 1 | R18: =IFERROR(SUMPRODUCT(Design_Matrix!B14:K14,$E$5:$E$14),0) -> 0 | S18: =EXP(MAX(-50,MIN(50,R18))) -> 1 | T18: =IFERROR(SUMPRODUCT(Design_Matrix!B14:K14,$F$5:$F$14),0) -> 0 | U18: =EXP(MAX(-50,MIN(50,T18))) -> 1 | V18: =IFERROR(SUMPRODUCT(Design_Matrix!B14:K14,$G$5:$G$14),0) -> 0 | W18: =EXP(MAX(-50,MIN(50,V18))) -> 1 | X18: =IFERROR(SUMPRODUCT(Design_Matrix!B14:K14,$H$5:$H$14),0) -> 0 | Y18: =EXP(MAX(-50,MIN(50,X18))) -> 1 | Z18: =IFERROR(SUMPRODUCT(Design_Matrix!B14:K14,$I$5:$I$14),0) -> 0 | AA18: =EXP(MAX(-50,MIN(50,Z18))) -> 1 | AB18: =IFERROR(SUMPRODUCT(Design_Matrix!B14:K14,$J$5:$J$14),0) -> 0 | AC18: =EXP(MAX(-50,MIN(50,AB18))) -> 1
L19: =IFERROR(SUMPRODUCT(Design_Matrix!B15:K15,$B$5:$B$14),0) -> 0 | M19: =EXP(MAX(-50,MIN(50,L19))) -> 1 | N19: =IFERROR(SUMPRODUCT(Design_Matrix!B15:K15,$C$5:$C$14),0) -> 0 | O19: =EXP(MAX(-50,MIN(50,N19))) -> 1 | P19: =IFERROR(SUMPRODUCT(Design_Matrix!B15:K15,$D$5:$D$14),0) -> 0 | Q19: =EXP(MAX(-50,MIN(50,P19))) -> 1 | R19: =IFERROR(SUMPRODUCT(Design_Matrix!B15:K15,$E$5:$E$14),0) -> 0 | S19: =EXP(MAX(-50,MIN(50,R19))) -> 1 | T19: =IFERROR(SUMPRODUCT(Design_Matrix!B15:K15,$F$5:$F$14),0) -> 0 | U19: =EXP(MAX(-50,MIN(50,T19))) -> 1 | V19: =IFERROR(SUMPRODUCT(Design_Matrix!B15:K15,$G$5:$G$14),0) -> 0 | W19: =EXP(MAX(-50,MIN(50,V19))) -> 1 | X19: =IFERROR(SUMPRODUCT(Design_Matrix!B15:K15,$H$5:$H$14),0) -> 0 | Y19: =EXP(MAX(-50,MIN(50,X19))) -> 1 | Z19: =IFERROR(SUMPRODUCT(Design_Matrix!B15:K15,$I$5:$I$14),0) -> 0 | AA19: =EXP(MAX(-50,MIN(50,Z19))) -> 1 | AB19: =IFERROR(SUMPRODUCT(Design_Matrix!B15:K15,$J$5:$J$14),0) -> 0 | AC19: =EXP(MAX(-50,MIN(50,AB19))) -> 1
L20: =IFERROR(SUMPRODUCT(Design_Matrix!B16:K16,$B$5:$B$14),0) -> 0 | M20: =EXP(MAX(-50,MIN(50,L20))) -> 1 | N20: =IFERROR(SUMPRODUCT(Design_Matrix!B16:K16,$C$5:$C$14),0) -> 0 | O20: =EXP(MAX(-50,MIN(50,N20))) -> 1 | P20: =IFERROR(SUMPRODUCT(Design_Matrix!B16:K16,$D$5:$D$14),0) -> 0 | Q20: =EXP(MAX(-50,MIN(50,P20))) -> 1 | R20: =IFERROR(SUMPRODUCT(Design_Matrix!B16:K16,$E$5:$E$14),0) -> 0 | S20: =EXP(MAX(-50,MIN(50,R20))) -> 1 | T20: =IFERROR(SUMPRODUCT(Design_Matrix!B16:K16,$F$5:$F$14),0) -> 0 | U20: =EXP(MAX(-50,MIN(50,T20))) -> 1 | V20: =IFERROR(SUMPRODUCT(Design_Matrix!B16:K16,$G$5:$G$14),0) -> 0 | W20: =EXP(MAX(-50,MIN(50,V20))) -> 1 | X20: =IFERROR(SUMPRODUCT(Design_Matrix!B16:K16,$H$5:$H$14),0) -> 0 | Y20: =EXP(MAX(-50,MIN(50,X20))) -> 1 | Z20: =IFERROR(SUMPRODUCT(Design_Matrix!B16:K16,$I$5:$I$14),0) -> 0 | AA20: =EXP(MAX(-50,MIN(50,Z20))) -> 1 | AB20: =IFERROR(SUMPRODUCT(Design_Matrix!B16:K16,$J$5:$J$14),0) -> 0 | AC20: =EXP(MAX(-50,MIN(50,AB20))) -> 1
L21: =IFERROR(SUMPRODUCT(Design_Matrix!B17:K17,$B$5:$B$14),0) -> 0 | M21: =EXP(MAX(-50,MIN(50,L21))) -> 1 | N21: =IFERROR(SUMPRODUCT(Design_Matrix!B17:K17,$C$5:$C$14),0) -> 0 | O21: =EXP(MAX(-50,MIN(50,N21))) -> 1 | P21: =IFERROR(SUMPRODUCT(Design_Matrix!B17:K17,$D$5:$D$14),0) -> 0 | Q21: =EXP(MAX(-50,MIN(50,P21))) -> 1 | R21: =IFERROR(SUMPRODUCT(Design_Matrix!B17:K17,$E$5:$E$14),0) -> 0 | S21: =EXP(MAX(-50,MIN(50,R21))) -> 1 | T21: =IFERROR(SUMPRODUCT(Design_Matrix!B17:K17,$F$5:$F$14),0) -> 0 | U21: =EXP(MAX(-50,MIN(50,T21))) -> 1 | V21: =IFERROR(SUMPRODUCT(Design_Matrix!B17:K17,$G$5:$G$14),0) -> 0 | W21: =EXP(MAX(-50,MIN(50,V21))) -> 1 | X21: =IFERROR(SUMPRODUCT(Design_Matrix!B17:K17,$H$5:$H$14),0) -> 0 | Y21: =EXP(MAX(-50,MIN(50,X21))) -> 1 | Z21: =IFERROR(SUMPRODUCT(Design_Matrix!B17:K17,$I$5:$I$14),0) -> 0 | AA21: =EXP(MAX(-50,MIN(50,Z21))) -> 1 | AB21: =IFERROR(SUMPRODUCT(Design_Matrix!B17:K17,$J$5:$J$14),0) -> 0 | AC21: =EXP(MAX(-50,MIN(50,AB21))) -> 1
L22: =IFERROR(SUMPRODUCT(Design_Matrix!B18:K18,$B$5:$B$14),0) -> 0 | M22: =EXP(MAX(-50,MIN(50,L22))) -> 1 | N22: =IFERROR(SUMPRODUCT(Design_Matrix!B18:K18,$C$5:$C$14),0) -> 0 | O22: =EXP(MAX(-50,MIN(50,N22))) -> 1 | P22: =IFERROR(SUMPRODUCT(Design_Matrix!B18:K18,$D$5:$D$14),0) -> 0 | Q22: =EXP(MAX(-50,MIN(50,P22))) -> 1 | R22: =IFERROR(SUMPRODUCT(Design_Matrix!B18:K18,$E$5:$E$14),0) -> 0 | S22: =EXP(MAX(-50,MIN(50,R22))) -> 1 | T22: =IFERROR(SUMPRODUCT(Design_Matrix!B18:K18,$F$5:$F$14),0) -> 0 | U22: =EXP(MAX(-50,MIN(50,T22))) -> 1 | V22: =IFERROR(SUMPRODUCT(Design_Matrix!B18:K18,$G$5:$G$14),0) -> 0 | W22: =EXP(MAX(-50,MIN(50,V22))) -> 1 | X22: =IFERROR(SUMPRODUCT(Design_Matrix!B18:K18,$H$5:$H$14),0) -> 0 | Y22: =EXP(MAX(-50,MIN(50,X22))) -> 1 | Z22: =IFERROR(SUMPRODUCT(Design_Matrix!B18:K18,$I$5:$I$14),0) -> 0 | AA22: =EXP(MAX(-50,MIN(50,Z22))) -> 1 | AB22: =IFERROR(SUMPRODUCT(Design_Matrix!B18:K18,$J$5:$J$14),0) -> 0 | AC22: =EXP(MAX(-50,MIN(50,AB22))) -> 1
L23: =IFERROR(SUMPRODUCT(Design_Matrix!B19:K19,$B$5:$B$14),0) -> 0 | M23: =EXP(MAX(-50,MIN(50,L23))) -> 1 | N23: =IFERROR(SUMPRODUCT(Design_Matrix!B19:K19,$C$5:$C$14),0) -> 0 | O23: =EXP(MAX(-50,MIN(50,N23))) -> 1 | P23: =IFERROR(SUMPRODUCT(Design_Matrix!B19:K19,$D$5:$D$14),0) -> 0 | Q23: =EXP(MAX(-50,MIN(50,P23))) -> 1 | R23: =IFERROR(SUMPRODUCT(Design_Matrix!B19:K19,$E$5:$E$14),0) -> 0 | S23: =EXP(MAX(-50,MIN(50,R23))) -> 1 | T23: =IFERROR(SUMPRODUCT(Design_Matrix!B19:K19,$F$5:$F$14),0) -> 0 | U23: =EXP(MAX(-50,MIN(50,T23))) -> 1 | V23: =IFERROR(SUMPRODUCT(Design_Matrix!B19:K19,$G$5:$G$14),0) -> 0 | W23: =EXP(MAX(-50,MIN(50,V23))) -> 1 | X23: =IFERROR(SUMPRODUCT(Design_Matrix!B19:K19,$H$5:$H$14),0) -> 0 | Y23: =EXP(MAX(-50,MIN(50,X23))) -> 1 | Z23: =IFERROR(SUMPRODUCT(Design_Matrix!B19:K19,$I$5:$I$14),0) -> 0 | AA23: =EXP(MAX(-50,MIN(50,Z23))) -> 1 | AB23: =IFERROR(SUMPRODUCT(Design_Matrix!B19:K19,$J$5:$J$14),0) -> 0 | AC23: =EXP(MAX(-50,MIN(50,AB23))) -> 1
L24: =IFERROR(SUMPRODUCT(Design_Matrix!B20:K20,$B$5:$B$14),0) -> 0 | M24: =EXP(MAX(-50,MIN(50,L24))) -> 1 | N24: =IFERROR(SUMPRODUCT(Design_Matrix!B20:K20,$C$5:$C$14),0) -> 0 | O24: =EXP(MAX(-50,MIN(50,N24))) -> 1 | P24: =IFERROR(SUMPRODUCT(Design_Matrix!B20:K20,$D$5:$D$14),0) -> 0 | Q24: =EXP(MAX(-50,MIN(50,P24))) -> 1 | R24: =IFERROR(SUMPRODUCT(Design_Matrix!B20:K20,$E$5:$E$14),0) -> 0 | S24: =EXP(MAX(-50,MIN(50,R24))) -> 1 | T24: =IFERROR(SUMPRODUCT(Design_Matrix!B20:K20,$F$5:$F$14),0) -> 0 | U24: =EXP(MAX(-50,MIN(50,T24))) -> 1 | V24: =IFERROR(SUMPRODUCT(Design_Matrix!B20:K20,$G$5:$G$14),0) -> 0 | W24: =EXP(MAX(-50,MIN(50,V24))) -> 1 | X24: =IFERROR(SUMPRODUCT(Design_Matrix!B20:K20,$H$5:$H$14),0) -> 0 | Y24: =EXP(MAX(-50,MIN(50,X24))) -> 1 | Z24: =IFERROR(SUMPRODUCT(Design_Matrix!B20:K20,$I$5:$I$14),0) -> 0 | AA24: =EXP(MAX(-50,MIN(50,Z24))) -> 1 | AB24: =IFERROR(SUMPRODUCT(Design_Matrix!B20:K20,$J$5:$J$14),0) -> 0 | AC24: =EXP(MAX(-50,MIN(50,AB24))) -> 1
L25: =IFERROR(SUMPRODUCT(Design_Matrix!B21:K21,$B$5:$B$14),0) -> 0 | M25: =EXP(MAX(-50,MIN(50,L25))) -> 1 | N25: =IFERROR(SUMPRODUCT(Design_Matrix!B21:K21,$C$5:$C$14),0) -> 0 | O25: =EXP(MAX(-50,MIN(50,N25))) -> 1 | P25: =IFERROR(SUMPRODUCT(Design_Matrix!B21:K21,$D$5:$D$14),0) -> 0 | Q25: =EXP(MAX(-50,MIN(50,P25))) -> 1 | R25: =IFERROR(SUMPRODUCT(Design_Matrix!B21:K21,$E$5:$E$14),0) -> 0 | S25: =EXP(MAX(-50,MIN(50,R25))) -> 1 | T25: =IFERROR(SUMPRODUCT(Design_Matrix!B21:K21,$F$5:$F$14),0) -> 0 | U25: =EXP(MAX(-50,MIN(50,T25))) -> 1 | V25: =IFERROR(SUMPRODUCT(Design_Matrix!B21:K21,$G$5:$G$14),0) -> 0 | W25: =EXP(MAX(-50,MIN(50,V25))) -> 1 | X25: =IFERROR(SUMPRODUCT(Design_Matrix!B21:K21,$H$5:$H$14),0) -> 0 | Y25: =EXP(MAX(-50,MIN(50,X25))) -> 1 | Z25: =IFERROR(SUMPRODUCT(Design_Matrix!B21:K21,$I$5:$I$14),0) -> 0 | AA25: =EXP(MAX(-50,MIN(50,Z25))) -> 1 | AB25: =IFERROR(SUMPRODUCT(Design_Matrix!B21:K21,$J$5:$J$14),0) -> 0 | AC25: =EXP(MAX(-50,MIN(50,AB25))) -> 1
L26: =IFERROR(SUMPRODUCT(Design_Matrix!B22:K22,$B$5:$B$14),0) -> 0 | M26: =EXP(MAX(-50,MIN(50,L26))) -> 1 | N26: =IFERROR(SUMPRODUCT(Design_Matrix!B22:K22,$C$5:$C$14),0) -> 0 | O26: =EXP(MAX(-50,MIN(50,N26))) -> 1 | P26: =IFERROR(SUMPRODUCT(Design_Matrix!B22:K22,$D$5:$D$14),0) -> 0 | Q26: =EXP(MAX(-50,MIN(50,P26))) -> 1 | R26: =IFERROR(SUMPRODUCT(Design_Matrix!B22:K22,$E$5:$E$14),0) -> 0 | S26: =EXP(MAX(-50,MIN(50,R26))) -> 1 | T26: =IFERROR(SUMPRODUCT(Design_Matrix!B22:K22,$F$5:$F$14),0) -> 0 | U26: =EXP(MAX(-50,MIN(50,T26))) -> 1 | V26: =IFERROR(SUMPRODUCT(Design_Matrix!B22:K22,$G$5:$G$14),0) -> 0 | W26: =EXP(MAX(-50,MIN(50,V26))) -> 1 | X26: =IFERROR(SUMPRODUCT(Design_Matrix!B22:K22,$H$5:$H$14),0) -> 0 | Y26: =EXP(MAX(-50,MIN(50,X26))) -> 1 | Z26: =IFERROR(SUMPRODUCT(Design_Matrix!B22:K22,$I$5:$I$14),0) -> 0 | AA26: =EXP(MAX(-50,MIN(50,Z26))) -> 1 | AB26: =IFERROR(SUMPRODUCT(Design_Matrix!B22:K22,$J$5:$J$14),0) -> 0 | AC26: =EXP(MAX(-50,MIN(50,AB26))) -> 1
... L69: =IFERROR(SUMPRODUCT(Design_Matrix!B65:K65,$B$5:$B$14),0) -> 0 | M69: =EXP(MAX(-50,MIN(50,L69))) -> 1 | N69: =IFERROR(SUMPRODUCT(Design_Matrix!B65:K65,$C$5:$C$14),0) -> 0 | O69: =EXP(MAX(-50,MIN(50,N69))) -> 1 | P69: =IFERROR(SUMPRODUCT(Design_Matrix!B65:K65,$D$5:$D$14),0) -> 0 | Q69: =EXP(MAX(-50,MIN(50,P69))) -> 1 | R69: =IFERROR(SUMPRODUCT(Design_Matrix!B65:K65,$E$5:$E$14),0) -> 0 | S69: =EXP(MAX(-50,MIN(50,R69))) -> 1 | T69: =IFERROR(SUMPRODUCT(Design_Matrix!B65:K65,$F$5:$F$14),0) -> 0 | U69: =EXP(MAX(-50,MIN(50,T69))) -> 1 | V69: =IFERROR(SUMPRODUCT(Design_Matrix!B65:K65,$G$5:$G$14),0) -> 0 | W69: =EXP(MAX(-50,MIN(50,V69))) -> 1 | X69: =IFERROR(SUMPRODUCT(Design_Matrix!B65:K65,$H$5:$H$14),0) -> 0 | Y69: =EXP(MAX(-50,MIN(50,X69))) -> 1 | Z69: =IFERROR(SUMPRODUCT(Design_Matrix!B65:K65,$I$5:$I$14),0) -> 0 | AA69: =EXP(MAX(-50,MIN(50,Z69))) -> 1 | AB69: =IFERROR(SUMPRODUCT(Design_Matrix!B65:K65,$J$5:$J$14),0) -> 0 | AC69: =EXP(MAX(-50,MIN(50,AB69))) -> 1
A73: Gradient block (score equations)
A74: coef | B74: g_iter_0 | C74: g_iter_1 | D74: g_iter_2 | E74: g_iter_3 | F74: g_iter_4 | G74: g_iter_5 | H74: g_iter_6 | I74: g_iter_7
A75: Intercept | B75: =IFERROR(SUMPRODUCT(Design_Matrix!B2:B65,Design_Matrix!L2:L65)-SUMPRODUCT(Design_Matrix!B2:B65,M6:M69),0) -> 3087 | C75: =IFERROR(SUMPRODUCT(Design_Matrix!B2:B65,Design_Matrix!L2:L65)-SUMPRODUCT(Design_Matrix!B2:B65,O6:O69),0) -> 3087 | D75: =IFERROR(SUMPRODUCT(Design_Matrix!B2:B65,Design_Matrix!L2:L65)-SUMPRODUCT(Design_Matrix!B2:B65,Q6:Q69),0) -> 3087 | E75: =IFERROR(SUMPRODUCT(Design_Matrix!B2:B65,Design_Matrix!L2:L65)-SUMPRODUCT(Design_Matrix!B2:B65,S6:S69),0) -> 3087 | F75: =IFERROR(SUMPRODUCT(Design_Matrix!B2:B65,Design_Matrix!L2:L65)-SUMPRODUCT(Design_Matrix!B2:B65,U6:U69),0) -> 3087 | G75: =IFERROR(SUMPRODUCT(Design_Matrix!B2:B65,Design_Matrix!L2:L65)-SUMPRODUCT(Design_Matrix!B2:B65,W6:W69),0) -> 3087 | H75: =IFERROR(SUMPRODUCT(Design_Matrix!B2:B65,Design_Matrix!L2:L65)-SUMPRODUCT(Design_Matrix!B2:B65,Y6:Y69),0) -> 3087 | I75: =IFERROR(SUMPRODUCT(Design_Matrix!B2:B65,Design_Matrix!L2:L65)-SUMPRODUCT(Design_Matrix!B2:B65,AA6:AA69),0) -> 3087
A76: District_2 | B76: =IFERROR(SUMPRODUCT(Design_Matrix!C2:C65,Design_Matrix!L2:L65)-SUMPRODUCT(Design_Matrix!C2:C65,M6:M69),0) -> 875 | C76: =IFERROR(SUMPRODUCT(Design_Matrix!C2:C65,Design_Matrix!L2:L65)-SUMPRODUCT(Design_Matrix!C2:C65,O6:O69),0) -> 875 | D76: =IFERROR(SUMPRODUCT(Design_Matrix!C2:C65,Design_Matrix!L2:L65)-SUMPRODUCT(Design_Matrix!C2:C65,Q6:Q69),0) -> 875 | E76: =IFERROR(SUMPRODUCT(Design_Matrix!C2:C65,Design_Matrix!L2:L65)-SUMPRODUCT(Design_Matrix!C2:C65,S6:S69),0) -> 875 | F76: =IFERROR(SUMPRODUCT(Design_Matrix!C2:C65,Design_Matrix!L2:L65)-SUMPRODUCT(Design_Matrix!C2:C65,U6:U69),0) -> 875 | G76: =IFERROR(SUMPRODUCT(Design_Matrix!C2:C65,Design_Matrix!L2:L65)-SUMPRODUCT(Design_Matrix!C2:C65,W6:W69),0) -> 875 | H76: =IFERROR(SUMPRODUCT(Design_Matrix!C2:C65,Design_Matrix!L2:L65)-SUMPRODUCT(Design_Matrix!C2:C65,Y6:Y69),0) -> 875 | I76: =IFERROR(SUMPRODUCT(Design_Matrix!C2:C65,Design_Matrix!L2:L65)-SUMPRODUCT(Design_Matrix!C2:C65,AA6:AA69),0) -> 875
A77: District_3 | B77: =IFERROR(SUMPRODUCT(Design_Matrix!D2:D65,Design_Matrix!L2:L65)-SUMPRODUCT(Design_Matrix!D2:D65,M6:M69),0) -> 537 | C77: =IFERROR(SUMPRODUCT(Design_Matrix!D2:D65,Design_Matrix!L2:L65)-SUMPRODUCT(Design_Matrix!D2:D65,O6:O69),0) -> 537 | D77: =IFERROR(SUMPRODUCT(Design_Matrix!D2:D65,Design_Matrix!L2:L65)-SUMPRODUCT(Design_Matrix!D2:D65,Q6:Q69),0) -> 537 | E77: =IFERROR(SUMPRODUCT(Design_Matrix!D2:D65,Design_Matrix!L2:L65)-SUMPRODUCT(Design_Matrix!D2:D65,S6:S69),0) -> 537 | F77: =IFERROR(SUMPRODUCT(Design_Matrix!D2:D65,Design_Matrix!L2:L65)-SUMPRODUCT(Design_Matrix!D2:D65,U6:U69),0) -> 537 | G77: =IFERROR(SUMPRODUCT(Design_Matrix!D2:D65,Design_Matrix!L2:L65)-SUMPRODUCT(Design_Matrix!D2:D65,W6:W69),0) -> 537 | H77: =IFERROR(SUMPRODUCT(Design_Matrix!D2:D65,Design_Matrix!L2:L65)-SUMPRODUCT(Design_Matrix!D2:D65,Y6:Y69),0) -> 537 | I77: =IFERROR(SUMPRODUCT(Design_Matrix!D2:D65,Design_Matrix!L2:L65)-SUMPRODUCT(Design_Matrix!D2:D65,AA6:AA69),0) -> 537
A78: District_4 | B78: =IFERROR(SUMPRODUCT(Design_Matrix!E2:E65,Design_Matrix!L2:L65)-SUMPRODUCT(Design_Matrix!E2:E65,M6:M69),0) -> 310 | C78: =IFERROR(SUMPRODUCT(Design_Matrix!E2:E65,Design_Matrix!L2:L65)-SUMPRODUCT(Design_Matrix!E2:E65,O6:O69),0) -> 310 | D78: =IFERROR(SUMPRODUCT(Design_Matrix!E2:E65,Design_Matrix!L2:L65)-SUMPRODUCT(Design_Matrix!E2:E65,Q6:Q69),0) -> 310 | E78: =IFERROR(SUMPRODUCT(Design_Matrix!E2:E65,Design_Matrix!L2:L65)-SUMPRODUCT(Design_Matrix!E2:E65,S6:S69),0) -> 310 | F78: =IFERROR(SUMPRODUCT(Design_Matrix!E2:E65,Design_Matrix!L2:L65)-SUMPRODUCT(Design_Matrix!E2:E65,U6:U69),0) -> 310 | G78: =IFERROR(SUMPRODUCT(Design_Matrix!E2:E65,Design_Matrix!L2:L65)-SUMPRODUCT(Design_Matrix!E2:E65,W6:W69),0) -> 310 | H78: =IFERROR(SUMPRODUCT(Design_Matrix!E2:E65,Design_Matrix!L2:L65)-SUMPRODUCT(Design_Matrix!E2:E65,Y6:Y69),0) -> 310 | I78: =IFERROR(SUMPRODUCT(Design_Matrix!E2:E65,Design_Matrix!L2:L65)-SUMPRODUCT(Design_Matrix!E2:E65,AA6:AA69),0) -> 310
A79: Group_1-1.5l | B79: =IFERROR(SUMPRODUCT(Design_Matrix!F2:F65,Design_Matrix!L2:L65)-SUMPRODUCT(Design_Matrix!F2:F65,M6:M69),0) -> 1434 | C79: =IFERROR(SUMPRODUCT(Design_Matrix!F2:F65,Design_Matrix!L2:L65)-SUMPRODUCT(Design_Matrix!F2:F65,O6:O69),0) -> 1434 | D79: =IFERROR(SUMPRODUCT(Design_Matrix!F2:F65,Design_Matrix!L2:L65)-SUMPRODUCT(Design_Matrix!F2:F65,Q6:Q69),0) -> 1434 | E79: =IFERROR(SUMPRODUCT(Design_Matrix!F2:F65,Design_Matrix!L2:L65)-SUMPRODUCT(Design_Matrix!F2:F65,S6:S69),0) -> 1434 | F79: =IFERROR(SUMPRODUCT(Design_Matrix!F2:F65,Design_Matrix!L2:L65)-SUMPRODUCT(Design_Matrix!F2:F65,U6:U69),0) -> 1434 | G79: =IFERROR(SUMPRODUCT(Design_Matrix!F2:F65,Design_Matrix!L2:L65)-SUMPRODUCT(Design_Matrix!F2:F65,W6:W69),0) -> 1434 | H79: =IFERROR(SUMPRODUCT(Design_Matrix!F2:F65,Design_Matrix!L2:L65)-SUMPRODUCT(Design_Matrix!F2:F65,Y6:Y69),0) -> 1434 | I79: =IFERROR(SUMPRODUCT(Design_Matrix!F2:F65,Design_Matrix!L2:L65)-SUMPRODUCT(Design_Matrix!F2:F65,AA6:AA69),0) -> 1434
A80: Group_1.5-2l | B80: =IFERROR(SUMPRODUCT(Design_Matrix!G2:G65,Design_Matrix!L2:L65)-SUMPRODUCT(Design_Matrix!G2:G65,M6:M69),0) -> 847 | C80: =IFERROR(SUMPRODUCT(Design_Matrix!G2:G65,Design_Matrix!L2:L65)-SUMPRODUCT(Design_Matrix!G2:G65,O6:O69),0) -> 847 | D80: =IFERROR(SUMPRODUCT(Design_Matrix!G2:G65,Design_Matrix!L2:L65)-SUMPRODUCT(Design_Matrix!G2:G65,Q6:Q69),0) -> 847 | E80: =IFERROR(SUMPRODUCT(Design_Matrix!G2:G65,Design_Matrix!L2:L65)-SUMPRODUCT(Design_Matrix!G2:G65,S6:S69),0) -> 847 | F80: =IFERROR(SUMPRODUCT(Design_Matrix!G2:G65,Design_Matrix!L2:L65)-SUMPRODUCT(Design_Matrix!G2:G65,U6:U69),0) -> 847 | G80: =IFERROR(SUMPRODUCT(Design_Matrix!G2:G65,Design_Matrix!L2:L65)-SUMPRODUCT(Design_Matrix!G2:G65,W6:W69),0) -> 847 | H80: =IFERROR(SUMPRODUCT(Design_Matrix!G2:G65,Design_Matrix!L2:L65)-SUMPRODUCT(Design_Matrix!G2:G65,Y6:Y69),0) -> 847 | I80: =IFERROR(SUMPRODUCT(Design_Matrix!G2:G65,Design_Matrix!L2:L65)-SUMPRODUCT(Design_Matrix!G2:G65,AA6:AA69),0) -> 847
A81: Group_>2l | B81: =IFERROR(SUMPRODUCT(Design_Matrix!H2:H65,Design_Matrix!L2:L65)-SUMPRODUCT(Design_Matrix!H2:H65,M6:M69),0) -> 283 | C81: =IFERROR(SUMPRODUCT(Design_Matrix!H2:H65,Design_Matrix!L2:L65)-SUMPRODUCT(Design_Matrix!H2:H65,O6:O69),0) -> 283 | D81: =IFERROR(SUMPRODUCT(Design_Matrix!H2:H65,Design_Matrix!L2:L65)-SUMPRODUCT(Design_Matrix!H2:H65,Q6:Q69),0) -> 283 | E81: =IFERROR(SUMPRODUCT(Design_Matrix!H2:H65,Design_Matrix!L2:L65)-SUMPRODUCT(Design_Matrix!H2:H65,S6:S69),0) -> 283 | F81: =IFERROR(SUMPRODUCT(Design_Matrix!H2:H65,Design_Matrix!L2:L65)-SUMPRODUCT(Design_Matrix!H2:H65,U6:U69),0) -> 283 | G81: =IFERROR(SUMPRODUCT(Design_Matrix!H2:H65,Design_Matrix!L2:L65)-SUMPRODUCT(Design_Matrix!H2:H65,W6:W69),0) -> 283 | H81: =IFERROR(SUMPRODUCT(Design_Matrix!H2:H65,Design_Matrix!L2:L65)-SUMPRODUCT(Design_Matrix!H2:H65,Y6:Y69),0) -> 283 | I81: =IFERROR(SUMPRODUCT(Design_Matrix!H2:H65,Design_Matrix!L2:L65)-SUMPRODUCT(Design_Matrix!H2:H65,AA6:AA69),0) -> 283
A82: Age_25-29 | B82: =IFERROR(SUMPRODUCT(Design_Matrix!I2:I65,Design_Matrix!L2:L65)-SUMPRODUCT(Design_Matrix!I2:I65,M6:M69),0) -> 388 | C82: =IFERROR(SUMPRODUCT(Design_Matrix!I2:I65,Design_Matrix!L2:L65)-SUMPRODUCT(Design_Matrix!I2:I65,O6:O69),0) -> 388 | D82: =IFERROR(SUMPRODUCT(Design_Matrix!I2:I65,Design_Matrix!L2:L65)-SUMPRODUCT(Design_Matrix!I2:I65,Q6:Q69),0) -> 388 | E82: =IFERROR(SUMPRODUCT(Design_Matrix!I2:I65,Design_Matrix!L2:L65)-SUMPRODUCT(Design_Matrix!I2:I65,S6:S69),0) -> 388 | F82: =IFERROR(SUMPRODUCT(Design_Matrix!I2:I65,Design_Matrix!L2:L65)-SUMPRODUCT(Design_Matrix!I2:I65,U6:U69),0) -> 388 | G82: =IFERROR(SUMPRODUCT(Design_Matrix!I2:I65,Design_Matrix!L2:L65)-SUMPRODUCT(Design_Matrix!I2:I65,W6:W69),0) -> 388 | H82: =IFERROR(SUMPRODUCT(Design_Matrix!I2:I65,Design_Matrix!L2:L65)-SUMPRODUCT(Design_Matrix!I2:I65,Y6:Y69),0) -> 388 | I82: =IFERROR(SUMPRODUCT(Design_Matrix!I2:I65,Design_Matrix!L2:L65)-SUMPRODUCT(Design_Matrix!I2:I65,AA6:AA69),0) -> 388
A83: Age_30-35 | B83: =IFERROR(SUMPRODUCT(Design_Matrix!J2:J65,Design_Matrix!L2:L65)-SUMPRODUCT(Design_Matrix!J2:J65,M6:M69),0) -> 437 | C83: =IFERROR(SUMPRODUCT(Design_Matrix!J2:J65,Design_Matrix!L2:L65)-SUMPRODUCT(Design_Matrix!J2:J65,O6:O69),0) -> 437 | D83: =IFERROR(SUMPRODUCT(Design_Matrix!J2:J65,Design_Matrix!L2:L65)-SUMPRODUCT(Design_Matrix!J2:J65,Q6:Q69),0) -> 437 | E83: =IFERROR(SUMPRODUCT(Design_Matrix!J2:J65,Design_Matrix!L2:L65)-SUMPRODUCT(Design_Matrix!J2:J65,S6:S69),0) -> 437 | F83: =IFERROR(SUMPRODUCT(Design_Matrix!J2:J65,Design_Matrix!L2:L65)-SUMPRODUCT(Design_Matrix!J2:J65,U6:U69),0) -> 437 | G83: =IFERROR(SUMPRODUCT(Design_Matrix!J2:J65,Design_Matrix!L2:L65)-SUMPRODUCT(Design_Matrix!J2:J65,W6:W69),0) -> 437 | H83: =IFERROR(SUMPRODUCT(Design_Matrix!J2:J65,Design_Matrix!L2:L65)-SUMPRODUCT(Design_Matrix!J2:J65,Y6:Y69),0) -> 437 | I83: =IFERROR(SUMPRODUCT(Design_Matrix!J2:J65,Design_Matrix!L2:L65)-SUMPRODUCT(Design_Matrix!J2:J65,AA6:AA69),0) -> 437
A84: Age_>35 | B84: =IFERROR(SUMPRODUCT(Design_Matrix!K2:K65,Design_Matrix!L2:L65)-SUMPRODUCT(Design_Matrix!K2:K65,M6:M69),0) -> 2049 | C84: =IFERROR(SUMPRODUCT(Design_Matrix!K2:K65,Design_Matrix!L2:L65)-SUMPRODUCT(Design_Matrix!K2:K65,O6:O69),0) -> 2049 | D84: =IFERROR(SUMPRODUCT(Design_Matrix!K2:K65,Design_Matrix!L2:L65)-SUMPRODUCT(Design_Matrix!K2:K65,Q6:Q69),0) -> 2049 | E84: =IFERROR(SUMPRODUCT(Design_Matrix!K2:K65,Design_Matrix!L2:L65)-SUMPRODUCT(Design_Matrix!K2:K65,S6:S69),0) -> 2049 | F84: =IFERROR(SUMPRODUCT(Design_Matrix!K2:K65,Design_Matrix!L2:L65)-SUMPRODUCT(Design_Matrix!K2:K65,U6:U69),0) -> 2049 | G84: =IFERROR(SUMPRODUCT(Design_Matrix!K2:K65,Design_Matrix!L2:L65)-SUMPRODUCT(Design_Matrix!K2:K65,W6:W69),0) -> 2049 | H84: =IFERROR(SUMPRODUCT(Design_Matrix!K2:K65,Design_Matrix!L2:L65)-SUMPRODUCT(Design_Matrix!K2:K65,Y6:Y69),0) -> 2049 | I84: =IFERROR(SUMPRODUCT(Design_Matrix!K2:K65,Design_Matrix!L2:L65)-SUMPRODUCT(Design_Matrix!K2:K65,AA6:AA69),0) -> 2049
A90: SSE | B90: =SUMXMY2(Design_Matrix!L2:L65,AC6:AC69) -> 467937 | D90: iter | E90: sse_iter
A91: mean_pred | B91: =AVERAGE(AC6:AC69) -> 1 | D91: 0 | E91: =SUMXMY2(Design_Matrix!L2:L65,M6:M69) -> 467937
...

Sheet Poisson_With_Offset
A1: learning_rate | B1: 1e-05
A2: iterations | B2: 8
A4: coef | B4: iter_0 | C4: iter_1 | D4: iter_2 | E4: iter_3 | F4: iter_4 | G4: iter_5 | H4: iter_6 | I4: iter_7 | J4: iter_8 | L4: Row mechanics by iteration
A5: Intercept | B5: 0 | C5: =IFERROR(B5+$B$1*B75/COUNT(Design_Matrix!A2:A65),B5) -> -0.0031575 | D5: =IFERROR(C5+$B$1*C75/COUNT(Design_Matrix!A2:A65),C5) -> -0.006315 | E5: =IFERROR(D5+$B$1*D75/COUNT(Design_Matrix!A2:A65),D5) -> -0.0094725 | F5: =IFERROR(E5+$B$1*E75/COUNT(Design_Matrix!A2:A65),E5) -> -0.01263 | G5: =IFERROR(F5+$B$1*F75/COUNT(Design_Matrix!A2:A65),F5) -> -0.0157875 | H5: =IFERROR(G5+$B$1*G75/COUNT(Design_Matrix!A2:A65),G5) -> -0.018945 | I5: =IFERROR(H5+$B$1*H75/COUNT(Design_Matrix!A2:A65),H5) -> -0.0221025 | J5: =IFERROR(I5+$B$1*I75/COUNT(Design_Matrix!A2:A65),I5) -> -0.02526 | L5: eta_iter_0 | M5: mu_iter_0 | N5: eta_iter_1 | O5: mu_iter_1 | P5: eta_iter_2 | Q5: mu_iter_2 | R5: eta_iter_3 | S5: mu_iter_3 | T5: eta_iter_4 | U5: mu_iter_4 | V5: eta_iter_5 | W5: mu_iter_5 | X5: eta_iter_6 | Y5: mu_iter_6 | Z5: eta_iter_7 | AA5: mu_iter_7 | AB5: eta_iter_8 | AC5: mu_iter_8
A6: District_2 | B6: 0 | C6: =IFERROR(B6+$B$1*B76/COUNT(Design_Matrix!A2:A65),B6) -> -0.0009003125 | D6: =IFERROR(C6+$B$1*C76/COUNT(Design_Matrix!A2:A65),C6) -> -0.001800625 | E6: =IFERROR(D6+$B$1*D76/COUNT(Design_Matrix!A2:A65),D6) -> -0.0027009375 | F6: =IFERROR(E6+$B$1*E76/COUNT(Design_Matrix!A2:A65),E6) -> -0.00360125 | G6: =IFERROR(F6+$B$1*F76/COUNT(Design_Matrix!A2:A65),F6) -> -0.0045015625 | H6: =IFERROR(G6+$B$1*G76/COUNT(Design_Matrix!A2:A65),G6) -> -0.005401875 | I6: =IFERROR(H6+$B$1*H76/COUNT(Design_Matrix!A2:A65),H6) -> -0.0063021875 | J6: =IFERROR(I6+$B$1*I76/COUNT(Design_Matrix!A2:A65),I6) -> -0.0072025 | L6: =IFERROR(SUMPRODUCT(Design_Matrix!B2:K2,$B$5:$B$14),0)+IFERROR(LN(Design_Matrix!M2),0) -> 5.2832037 | M6: =EXP(MAX(-50,MIN(50,L6))) -> 197 | N6: =IFERROR(SUMPRODUCT(Design_Matrix!B2:K2,$C$5:$C$14),0)+IFERROR(LN(Design_Matrix!M2),0) -> 5.2832037 | O6: =EXP(MAX(-50,MIN(50,N6))) -> 197 | P6: =IFERROR(SUMPRODUCT(Design_Matrix!B2:K2,$D$5:$D$14),0)+IFERROR(LN(Design_Matrix!M2),0) -> 5.2832037 | Q6: =EXP(MAX(-50,MIN(50,P6))) -> 197 | R6: =IFERROR(SUMPRODUCT(Design_Matrix!B2:K2,$E$5:$E$14),0)+IFERROR(LN(Design_Matrix!M2),0) -> 5.2832037 | S6: =EXP(MAX(-50,MIN(50,R6))) -> 197 | T6: =IFERROR(SUMPRODUCT(Design_Matrix!B2:K2,$F$5:$F$14),0)+IFERROR(LN(Design_Matrix!M2),0) -> 5.2832037 | U6: =EXP(MAX(-50,MIN(50,T6))) -> 197 | V6: =IFERROR(SUMPRODUCT(Design_Matrix!B2:K2,$G$5:$G$14),0)+IFERROR(LN(Design_Matrix!M2),0) -> 5.2832037 | W6: =EXP(MAX(-50,MIN(50,V6))) -> 197 | X6: =IFERROR(SUMPRODUCT(Design_Matrix!B2:K2,$H$5:$H$14),0)+IFERROR(LN(Design_Matrix!M2),0) -> 5.2832037 | Y6: =EXP(MAX(-50,MIN(50,X6))) -> 197 | Z6: =IFERROR(SUMPRODUCT(Design_Matrix!B2:K2,$I$5:$I$14),0)+IFERROR(LN(Design_Matrix!M2),0) -> 5.2832037 | AA6: =EXP(MAX(-50,MIN(50,Z6))) -> 197 | AB6: =IFERROR(SUMPRODUCT(Design_Matrix!B2:K2,$J$5:$J$14),0)+IFERROR(LN(Design_Matrix!M2),0) -> 5.2832037 | AC6: =EXP(MAX(-50,MIN(50,AB6))) -> 197
A7: District_3 | B7: 0 | C7: =IFERROR(B7+$B$1*B77/COUNT(Design_Matrix!A2:A65),B7) -> -0.0005646875 | D7: =IFERROR(C7+$B$1*C77/COUNT(Design_Matrix!A2:A65),C7) -> -0.001129375 | E7: =IFERROR(D7+$B$1*D77/COUNT(Design_Matrix!A2:A65),D7) -> -0.0016940625 | F7: =IFERROR(E7+$B$1*E77/COUNT(Design_Matrix!A2:A65),E7) -> -0.00225875 | G7: =IFERROR(F7+$B$1*F77/COUNT(Design_Matrix!A2:A65),F7) -> -0.0028234375 | H7: =IFERROR(G7+$B$1*G77/COUNT(Design_Matrix!A2:A65),G7) -> -0.003388125 | I7: =IFERROR(H7+$B$1*H77/COUNT(Design_Matrix!A2:A65),H7) -> -0.0039528125 | J7: =IFERROR(I7+$B$1*I77/COUNT(Design_Matrix!A2:A65),I7) -> -0.0045175 | L7: =IFERROR(SUMPRODUCT(Design_Matrix!B3:K3,$B$5:$B$14),0)+IFERROR(LN(Design_Matrix!M3),0) -> 5.5759491 | M7: =EXP(MAX(-50,MIN(50,L7))) -> 264 | N7: =IFERROR(SUMPRODUCT(Design_Matrix!B3:K3,$C$5:$C$14),0)+IFERROR(LN(Design_Matrix!M3),0) -> 5.5759491 | O7: =EXP(MAX(-50,MIN(50,N7))) -> 264 | P7: =IFERROR(SUMPRODUCT(Design_Matrix!B3:K3,$D$5:$D$14),0)+IFERROR(LN(Design_Matrix!M3),0) -> 5.5759491 | Q7: =EXP(MAX(-50,MIN(50,P7))) -> 264 | R7: =IFERROR(SUMPRODUCT(Design_Matrix!B3:K3,$E$5:$E$14),0)+IFERROR(LN(Design_Matrix!M3),0) -> 5.5759491 | S7: =EXP(MAX(-50,MIN(50,R7))) -> 264 | T7: =IFERROR(SUMPRODUCT(Design_Matrix!B3:K3,$F$5:$F$14),0)+IFERROR(LN(Design_Matrix!M3),0) -> 5.5759491 | U7: =EXP(MAX(-50,MIN(50,T7))) -> 264 | V7: =IFERROR(SUMPRODUCT(Design_Matrix!B3:K3,$G$5:$G$14),0)+IFERROR(LN(Design_Matrix!M3),0) -> 5.5759491 | W7: =EXP(MAX(-50,MIN(50,V7))) -> 264 | X7: =IFERROR(SUMPRODUCT(Design_Matrix!B3:K3,$H$5:$H$14),0)+IFERROR(LN(Design_Matrix!M3),0) -> 5.5759491 | Y7: =EXP(MAX(-50,MIN(50,X7))) -> 264 | Z7: =IFERROR(SUMPRODUCT(Design_Matrix!B3:K3,$I$5:$I$14),0)+IFERROR(LN(Design_Matrix!M3),0) -> 5.5759491 | AA7: =EXP(MAX(-50,MIN(50,Z7))) -> 264 | AB7: =IFERROR(SUMPRODUCT(Design_Matrix!B3:K3,$J$5:$J$14),0)+IFERROR(LN(Design_Matrix!M3),0) -> 5.5759491 | AC7: =EXP(MAX(-50,MIN(50,AB7))) -> 264
A8: District_4 | B8: 0 | C8: =IFERROR(B8+$B$1*B78/COUNT(Design_Matrix!A2:A65),B8) -> -0.000260625 | D8: =IFERROR(C8+$B$1*C78/COUNT(Design_Matrix!A2:A65),C8) -> -0.00052125 | E8: =IFERROR(D8+$B$1*D78/COUNT(Design_Matrix!A2:A65),D8) -> -0.000781875 | F8: =IFERROR(E8+$B$1*E78/COUNT(Design_Matrix!A2:A65),E8) -> -0.0010425 | G8: =IFERROR(F8+$B$1*F78/COUNT(Design_Matrix!A2:A65),F8) -> -0.001303125 | H8: =IFERROR(G8+$B$1*G78/COUNT(Design_Matrix!A2:A65),G8) -> -0.00156375 | I8: =IFERROR(H8+$B$1*H78/COUNT(Design_Matrix!A2:A65),H8) -> -0.001824375 | J8: =IFERROR(I8+$B$1*I78/COUNT(Design_Matrix!A2:A65),I8) -> -0.002085 | L8: =IFERROR(SUMPRODUCT(Design_Matrix!B4:K4,$B$5:$B$14),0)+IFERROR(LN(Design_Matrix!M4),0) -> 5.5053315 | M8: =EXP(MAX(-50,MIN(50,L8))) -> 246 | N8: =IFERROR(SUMPRODUCT(Design_Matrix!B4:K4,$C$5:$C$14),0)+IFERROR(LN(Design_Matrix!M4),0) -> 5.5053315 | O8: =EXP(MAX(-50,MIN(50,N8))) -> 246 | P8: =IFERROR(SUMPRODUCT(Design_Matrix!B4:K4,$D$5:$D$14),0)+IFERROR(LN(Design_Matrix!M4),0) -> 5.5053315 | Q8: =EXP(MAX(-50,MIN(50,P8))) -> 246 | R8: =IFERROR(SUMPRODUCT(Design_Matrix!B4:K4,$E$5:$E$14),0)+IFERROR(LN(Design_Matrix!M4),0) -> 5.5053315 | S8: =EXP(MAX(-50,MIN(50,R8))) -> 246 | T8: =IFERROR(SUMPRODUCT(Design_Matrix!B4:K4,$F$5:$F$14),0)+IFERROR(LN(Design_Matrix!M4),0) -> 5.5053315 | U8: =EXP(MAX(-50,MIN(50,T8))) -> 246 | V8: =IFERROR(SUMPRODUCT(Design_Matrix!B4:K4,$G$5:$G$14),0)+IFERROR(LN(Design_Matrix!M4),0) -> 5.5053315 | W8: =EXP(MAX(-50,MIN(50,V8))) -> 246 | X8: =IFERROR(SUMPRODUCT(Design_Matrix!B4:K4,$H$5:$H$14),0)+IFERROR(LN(Design_Matrix!M4),0) -> 5.5053315 | Y8: =EXP(MAX(-50,MIN(50,X8))) -> 246 | Z8: =IFERROR(SUMPRODUCT(Design_Matrix!B4:K4,$I$5:$I$14),0)+IFERROR(LN(Design_Matrix!M4),0) -> 5.5053315 | AA8: =EXP(MAX(-50,MIN(50,Z8))) -> 246 | AB8: =IFERROR(SUMPRODUCT(Design_Matrix!B4:K4,$J$5:$J$14),0)+IFERROR(LN(Design_Matrix!M4),0) -> 5.5053315 | AC8: =EXP(MAX(-50,MIN(50,AB8))) -> 246
A9: Group_1-1.5l | B9: 0 | C9: =IFERROR(B9+$B$1*B79/COUNT(Design_Matrix!A2:A65),B9) -> -0.0015645313 | D9: =IFERROR(C9+$B$1*C79/COUNT(Design_Matrix!A2:A65),C9) -> -0.0031290625 | E9: =IFERROR(D9+$B$1*D79/COUNT(Design_Matrix!A2:A65),D9) -> -0.0046935938 | F9: =IFERROR(E9+$B$1*E79/COUNT(Design_Matrix!A2:A65),E9) -> -0.006258125 | G9: =IFERROR(F9+$B$1*F79/COUNT(Design_Matrix!A2:A65),F9) -> -0.0078226563 | H9: =IFERROR(G9+$B$1*G79/COUNT(Design_Matrix!A2:A65),G9) -> -0.0093871875 | I9: =IFERROR(H9+$B$1*H79/COUNT(Design_Matrix!A2:A65),H9) -> -0.010951719 | J9: =IFERROR(I9+$B$1*I79/COUNT(Design_Matrix!A2:A65),I9) -> -0.01251625 | L9: =IFERROR(SUMPRODUCT(Design_Matrix!B5:K5,$B$5:$B$14),0)+IFERROR(LN(Design_Matrix!M5),0) -> 7.4265491 | M9: =EXP(MAX(-50,MIN(50,L9))) -> 1680 | N9: =IFERROR(SUMPRODUCT(Design_Matrix!B5:K5,$C$5:$C$14),0)+IFERROR(LN(Design_Matrix!M5),0) -> 7.4265491 | O9: =EXP(MAX(-50,MIN(50,N9))) -> 1680 | P9: =IFERROR(SUMPRODUCT(Design_Matrix!B5:K5,$D$5:$D$14),0)+IFERROR(LN(Design_Matrix!M5),0) -> 7.4265491 | Q9: =EXP(MAX(-50,MIN(50,P9))) -> 1680 | R9: =IFERROR(SUMPRODUCT(Design_Matrix!B5:K5,$E$5:$E$14),0)+IFERROR(LN(Design_Matrix!M5),0) -> 7.4265491 | S9: =EXP(MAX(-50,MIN(50,R9))) -> 1680 | T9: =IFERROR(SUMPRODUCT(Design_Matrix!B5:K5,$F$5:$F$14),0)+IFERROR(LN(Design_Matrix!M5),0) -> 7.4265491 | U9: =EXP(MAX(-50,MIN(50,T9))) -> 1680 | V9: =IFERROR(SUMPRODUCT(Design_Matrix!B5:K5,$G$5:$G$14),0)+IFERROR(LN(Design_Matrix!M5),0) -> 7.4265491 | W9: =EXP(MAX(-50,MIN(50,V9))) -> 1680 | X9: =IFERROR(SUMPRODUCT(Design_Matrix!B5:K5,$H$5:$H$14),0)+IFERROR(LN(Design_Matrix!M5),0) -> 7.4265491 | Y9: =EXP(MAX(-50,MIN(50,X9))) -> 1680 | Z9: =IFERROR(SUMPRODUCT(Design_Matrix!B5:K5,$I$5:$I$14),0)+IFERROR(LN(Design_Matrix!M5),0) -> 7.4265491 | AA9: =EXP(MAX(-50,MIN(50,Z9))) -> 1680 | AB9: =IFERROR(SUMPRODUCT(Design_Matrix!B5:K5,$J$5:$J$14),0)+IFERROR(LN(Design_Matrix!M5),0) -> 7.4265491 | AC9: =EXP(MAX(-50,MIN(50,AB9))) -> 1680
A10: Group_1.5-2l | B10: 0 | C10: =IFERROR(B10+$B$1*B80/COUNT(Design_Matrix!A2:A65),B10) -> -0.00070421875 | D10: =IFERROR(C10+$B$1*C80/COUNT(Design_Matrix!A2:A65),C10) -> -0.0014084375 | E10: =IFERROR(D10+$B$1*D80/COUNT(Design_Matrix!A2:A65),D10) -> -0.0021126562 | F10: =IFERROR(E10+$B$1*E80/COUNT(Design_Matrix!A2:A65),E10) -> -0.002816875 | G10: =IFERROR(F10+$B$1*F80/COUNT(Design_Matrix!A2:A65),F10) -> -0.0035210937 | H10: =IFERROR(G10+$B$1*G80/COUNT(Design_Matrix!A2:A65),G10) -> -0.0042253125 | I10: =IFERROR(H10+$B$1*H80/COUNT(Design_Matrix!A2:A65),H10) -> -0.0049295312 | J10: =IFERROR(I10+$B$1*I80/COUNT(Design_Matrix!A2:A65),I10) -> -0.00563375 | L10: =IFERROR(SUMPRODUCT(Design_Matrix!B6:K6,$B$5:$B$14),0)+IFERROR(LN(Design_Matrix!M6),0) -> 5.6489742 | M10: =EXP(MAX(-50,MIN(50,L10))) -> 284 | N10: =IFERROR(SUMPRODUCT(Design_Matrix!B6:K6,$C$5:$C$14),0)+IFERROR(LN(Design_Matrix!M6),0) -> 5.6489742 | O10: =EXP(MAX(-50,MIN(50,N10))) -> 284 | P10: =IFERROR(SUMPRODUCT(Design_Matrix!B6:K6,$D$5:$D$14),0)+IFERROR(LN(Design_Matrix!M6),0) -> 5.6489742 | Q10: =EXP(MAX(-50,MIN(50,P10))) -> 284 | R10: =IFERROR(SUMPRODUCT(Design_Matrix!B6:K6,$E$5:$E$14),0)+IFERROR(LN(Design_Matrix!M6),0) -> 5.6489742 | S10: =EXP(MAX(-50,MIN(50,R10))) -> 284 | T10: =IFERROR(SUMPRODUCT(Design_Matrix!B6:K6,$F$5:$F$14),0)+IFERROR(LN(Design_Matrix!M6),0) -> 5.6489742 | U10: =EXP(MAX(-50,MIN(50,T10))) -> 284 | V10: =IFERROR(SUMPRODUCT(Design_Matrix!B6:K6,$G$5:$G$14),0)+IFERROR(LN(Design_Matrix!M6),0) -> 5.6489742 | W10: =EXP(MAX(-50,MIN(50,V10))) -> 284 | X10: =IFERROR(SUMPRODUCT(Design_Matrix!B6:K6,$H$5:$H$14),0)+IFERROR(LN(Design_Matrix!M6),0) -> 5.6489742 | Y10: =EXP(MAX(-50,MIN(50,X10))) -> 284 | Z10: =IFERROR(SUMPRODUCT(Design_Matrix!B6:K6,$I$5:$I$14),0)+IFERROR(LN(Design_Matrix!M6),0) -> 5.6489742 | AA10: =EXP(MAX(-50,MIN(50,Z10))) -> 284 | AB10: =IFERROR(SUMPRODUCT(Design_Matrix!B6:K6,$J$5:$J$14),0)+IFERROR(LN(Design_Matrix!M6),0) -> 5.6489742 | AC10: =EXP(MAX(-50,MIN(50,AB10))) -> 284
