Workbook

Sheet README
A1: sheet | B1: purpose
A2: Data_USArrests | B2: Raw USArrests data only.
A3: Scale_PCA_Mechanics | B3: Scaling, correlation matrix, PC1 power iteration, scores/PVE via formulas.
A4: Plot_Parity_6_1 | B4: 6.1 visual parity charts: histograms, PVE/CumPVE, biplot-style views.
A5: KMeans_6_2 | B5: Formula-based k=3 clustering iteration and elbow proxy.
A6: Cluster_Summary | B6: Formula-based grouped means by final k=3 cluster.
A7: Distance_HC_Mechanics | B7: Pairwise distances, closest pair, and linkage metric mechanics.
A8: Plot_Parity_6_2 | B8: 6.2 visual parity charts: cluster PC plot + linkage profiles.
A9: Credit_PCA_Mechanics | B9: Limit/Rating PCA mechanics with formulas.
A10: Summary | B10: Key checks and metrics from all tabs.

Sheet Data_USArrests
A1: id | B1: state | C1: Murder | D1: Assault | E1: UrbanPop | F1: Rape
A2: 1 | B2: Alabama | C2: 13.2 | D2: 236 | E2: 58 | F2: 21.2
A3: 2 | B3: Alaska | C3: 10 | D3: 263 | E3: 48 | F3: 44.5
A4: 3 | B4: Arizona | C4: 8.1 | D4: 294 | E4: 80 | F4: 31
A5: 4 | B5: Arkansas | C5: 8.8 | D5: 190 | E5: 50 | F5: 19.5
A6: 5 | B6: California | C6: 9 | D6: 276 | E6: 91 | F6: 40.6
A7: 6 | B7: Colorado | C7: 7.9 | D7: 204 | E7: 78 | F7: 38.7
A8: 7 | B8: Connecticut | C8: 3.3 | D8: 110 | E8: 77 | F8: 11.1
A9: 8 | B9: Delaware | C9: 5.9 | D9: 238 | E9: 72 | F9: 15.8
A10: 9 | B10: Florida | C10: 15.4 | D10: 335 | E10: 80 | F10: 31.9
A11: 10 | B11: Georgia | C11: 17.4 | D11: 211 | E11: 60 | F11: 25.8
A12: 11 | B12: Hawaii | C12: 5.3 | D12: 46 | E12: 83 | F12: 20.2
A13: 12 | B13: Idaho | C13: 2.6 | D13: 120 | E13: 54 | F13: 14.2
... A51: 50 | B51: Wyoming | C51: 6.8 | D51: 161 | E51: 60 | F51: 15.6

Sheet Scale_PCA_Mechanics
A1: id | B1: Murder | C1: Assault | D1: UrbanPop | E1: Rape | G1: z_Murder | H1: z_Assault | I1: z_UrbanPop | J1: z_Rape | L1: PC1_score | M1: Correlation Matrix R | Z1: PC2_score | AA1: Deflated matrix for PC2
A2: =Data_USArrests!A2 | B2: =Data_USArrests!C2 | C2: =Data_USArrests!D2 | D2: =Data_USArrests!E2 | E2: =Data_USArrests!F2 | G2: =(B2-$B$54)/$B$55 | H2: =(C2-$C$54)/$C$55 | I2: =(D2-$D$54)/$D$55 | J2: =(E2-$E$54)/$E$55 | L2: =SUMPRODUCT(G2:J2,$M$33:$P$33) | M2: Murder | N2: Assault | O2: UrbanPop | P2: Rape | Z2: =SUMPRODUCT(G2:J2,$AB$33:$AE$33)
A3: =Data_USArrests!A3 | B3: =Data_USArrests!C3 | C3: =Data_USArrests!D3 | D3: =Data_USArrests!E3 | E3: =Data_USArrests!F3 | G3: =(B3-$B$54)/$B$55 | H3: =(C3-$C$54)/$C$55 | I3: =(D3-$D$54)/$D$55 | J3: =(E3-$E$54)/$E$55 | L3: =SUMPRODUCT(G3:J3,$M$33:$P$33) | M3: =SUMPRODUCT(G2:G51,G2:G51)/(COUNT(G2:G51)-1) | N3: =SUMPRODUCT(G2:G51,H2:H51)/(COUNT(G2:G51)-1) | O3: =SUMPRODUCT(G2:G51,I2:I51)/(COUNT(G2:G51)-1) | P3: =SUMPRODUCT(G2:G51,J2:J51)/(COUNT(G2:G51)-1) | Z3: =SUMPRODUCT(G3:J3,$AB$33:$AE$33) | AA3: =M3-$M$34*$M$33*$M$33 | AB3: =N3-$M$34*$M$33*$N$33 | AC3: =O3-$M$34*$M$33*$O$33 | AD3: =P3-$M$34*$M$33*$P$33
A4: =Data_USArrests!A4 | B4: =Data_USArrests!C4 | C4: =Data_USArrests!D4 | D4: =Data_USArrests!E4 | E4: =Data_USArrests!F4 | G4: =(B4-$B$54)/$B$55 | H4: =(C4-$C$54)/$C$55 | I4: =(D4-$D$54)/$D$55 | J4: =(E4-$E$54)/$E$55 | L4: =SUMPRODUCT(G4:J4,$M$33:$P$33) | M4: =SUMPRODUCT(H2:H51,G2:G51)/(COUNT(H2:H51)-1) | N4: =SUMPRODUCT(H2:H51,H2:H51)/(COUNT(H2:H51)-1) | O4: =SUMPRODUCT(H2:H51,I2:I51)/(COUNT(H2:H51)-1) | P4: =SUMPRODUCT(H2:H51,J2:J51)/(COUNT(H2:H51)-1) | Z4: =SUMPRODUCT(G4:J4,$AB$33:$AE$33) | AA4: =M4-$M$34*$N$33*$M$33 | AB4: =N4-$M$34*$N$33*$N$33 | AC4: =O4-$M$34*$N$33*$O$33 | AD4: =P4-$M$34*$N$33*$P$33
A5: =Data_USArrests!A5 | B5: =Data_USArrests!C5 | C5: =Data_USArrests!D5 | D5: =Data_USArrests!E5 | E5: =Data_USArrests!F5 | G5: =(B5-$B$54)/$B$55 | H5: =(C5-$C$54)/$C$55 | I5: =(D5-$D$54)/$D$55 | J5: =(E5-$E$54)/$E$55 | L5: =SUMPRODUCT(G5:J5,$M$33:$P$33) | M5: =SUMPRODUCT(I2:I51,G2:G51)/(COUNT(I2:I51)-1) | N5: =SUMPRODUCT(I2:I51,H2:H51)/(COUNT(I2:I51)-1) | O5: =SUMPRODUCT(I2:I51,I2:I51)/(COUNT(I2:I51)-1) | P5: =SUMPRODUCT(I2:I51,J2:J51)/(COUNT(I2:I51)-1) | Z5: =SUMPRODUCT(G5:J5,$AB$33:$AE$33) | AA5: =M5-$M$34*$O$33*$M$33 | AB5: =N5-$M$34*$O$33*$N$33 | AC5: =O5-$M$34*$O$33*$O$33 | AD5: =P5-$M$34*$O$33*$P$33
A6: =Data_USArrests!A6 | B6: =Data_USArrests!C6 | C6: =Data_USArrests!D6 | D6: =Data_USArrests!E6 | E6: =Data_USArrests!F6 | G6: =(B6-$B$54)/$B$55 | H6: =(C6-$C$54)/$C$55 | I6: =(D6-$D$54)/$D$55 | J6: =(E6-$E$54)/$E$55 | L6: =SUMPRODUCT(G6:J6,$M$33:$P$33) | M6: =SUMPRODUCT(J2:J51,G2:G51)/(COUNT(J2:J51)-1) | N6: =SUMPRODUCT(J2:J51,H2:H51)/(COUNT(J2:J51)-1) | O6: =SUMPRODUCT(J2:J51,I2:I51)/(COUNT(J2:J51)-1) | P6: =SUMPRODUCT(J2:J51,J2:J51)/(COUNT(J2:J51)-1) | Z6: =SUMPRODUCT(G6:J6,$AB$33:$AE$33) | AA6: =M6-$M$34*$P$33*$M$33 | AB6: =N6-$M$34*$P$33*$N$33 | AC6: =O6-$M$34*$P$33*$O$33 | AD6: =P6-$M$34*$P$33*$P$33
A7: =Data_USArrests!A7 | B7: =Data_USArrests!C7 | C7: =Data_USArrests!D7 | D7: =Data_USArrests!E7 | E7: =Data_USArrests!F7 | G7: =(B7-$B$54)/$B$55 | H7: =(C7-$C$54)/$C$55 | I7: =(D7-$D$54)/$D$55 | J7: =(E7-$E$54)/$E$55 | L7: =SUMPRODUCT(G7:J7,$M$33:$P$33) | Z7: =SUMPRODUCT(G7:J7,$AB$33:$AE$33)
A8: =Data_USArrests!A8 | B8: =Data_USArrests!C8 | C8: =Data_USArrests!D8 | D8: =Data_USArrests!E8 | E8: =Data_USArrests!F8 | G8: =(B8-$B$54)/$B$55 | H8: =(C8-$C$54)/$C$55 | I8: =(D8-$D$54)/$D$55 | J8: =(E8-$E$54)/$E$55 | L8: =SUMPRODUCT(G8:J8,$M$33:$P$33) | Z8: =SUMPRODUCT(G8:J8,$AB$33:$AE$33)
A9: =Data_USArrests!A9 | B9: =Data_USArrests!C9 | C9: =Data_USArrests!D9 | D9: =Data_USArrests!E9 | E9: =Data_USArrests!F9 | G9: =(B9-$B$54)/$B$55 | H9: =(C9-$C$54)/$C$55 | I9: =(D9-$D$54)/$D$55 | J9: =(E9-$E$54)/$E$55 | L9: =SUMPRODUCT(G9:J9,$M$33:$P$33) | Z9: =SUMPRODUCT(G9:J9,$AB$33:$AE$33)
A10: =Data_USArrests!A10 | B10: =Data_USArrests!C10 | C10: =Data_USArrests!D10 | D10: =Data_USArrests!E10 | E10: =Data_USArrests!F10 | G10: =(B10-$B$54)/$B$55 | H10: =(C10-$C$54)/$C$55 | I10: =(D10-$D$54)/$D$55 | J10: =(E10-$E$54)/$E$55 | L10: =SUMPRODUCT(G10:J10,$M$33:$P$33) | M10: v1 | N10: v2 | O10: v3 | P10: v4 | Q10: t1 | R10: t2 | S10: t3 | T10: t4 | U10: norm_t | W10: PC | X10: PVE_proxy | Y10: CumPVE_proxy | Z10: =SUMPRODUCT(G10:J10,$AB$33:$AE$33) | AA10: PC2 power iteration | AB10: v1 | AC10: v2 | AD10: v3 | AE10: v4 | AF10: t1 | AG10: t2 | AH10: t3 | AI10: t4 | AJ10: norm_t
A11: =Data_USArrests!A11 | B11: =Data_USArrests!C11 | C11: =Data_USArrests!D11 | D11: =Data_USArrests!E11 | E11: =Data_USArrests!F11 | G11: =(B11-$B$54)/$B$55 | H11: =(C11-$C$54)/$C$55 | I11: =(D11-$D$54)/$D$55 | J11: =(E11-$E$54)/$E$55 | L11: =SUMPRODUCT(G11:J11,$M$33:$P$33) | M11: 0.5 | N11: 0.5 | O11: 0.5 | P11: 0.5 | W11: PC1 | X11: =M35 | Y11: =X11 | Z11: =SUMPRODUCT(G11:J11,$AB$33:$AE$33) | AA11: 0 | AB11: 0.5 | AC11: -0.5 | AD11: 0.5 | AE11: -0.5
A12: =Data_USArrests!A12 | B12: =Data_USArrests!C12 | C12: =Data_USArrests!D12 | D12: =Data_USArrests!E12 | E12: =Data_USArrests!F12 | G12: =(B12-$B$54)/$B$55 | H12: =(C12-$C$54)/$C$55 | I12: =(D12-$D$54)/$D$55 | J12: =(E12-$E$54)/$E$55 | L12: =SUMPRODUCT(G12:J12,$M$33:$P$33) | M12: =Q12/U12 | N12: =R12/U12 | O12: =S12/U12 | P12: =T12/U12 | Q12: =SUMPRODUCT($M$3:$P$3,M11:P11) | R12: =SUMPRODUCT($M$4:$P$4,M11:P11) | S12: =SUMPRODUCT($M$5:$P$5,M11:P11) | T12: =SUMPRODUCT($M$6:$P$6,M11:P11) | U12: =SQRT(SUMSQ(Q12:T12)) | W12: PC2 | X12: =AB35 | Y12: =Y11+X12 | Z12: =SUMPRODUCT(G12:J12,$AB$33:$AE$33) | AA12: 1 | AB12: =AF12/AJ12 | AC12: =AG12/AJ12 | AD12: =AH12/AJ12 | AE12: =AI12/AJ12 | AF12: =SUMPRODUCT($AA$3:$AD$3,AB11:AE11) | AG12: =SUMPRODUCT($AA$4:$AD$4,AB11:AE11) | AH12: =SUMPRODUCT($AA$5:$AD$5,AB11:AE11) | AI12: =SUMPRODUCT($AA$6:$AD$6,AB11:AE11) | AJ12: =SQRT(SUMSQ(AF12:AI12))
A13: =Data_USArrests!A13 | B13: =Data_USArrests!C13 | C13: =Data_USArrests!D13 | D13: =Data_USArrests!E13 | E13: =Data_USArrests!F13 | G13: =(B13-$B$54)/$B$55 | H13: =(C13-$C$54)/$C$55 | I13: =(D13-$D$54)/$D$55 | J13: =(E13-$E$54)/$E$55 | L13: =SUMPRODUCT(G13:J13,$M$33:$P$33) | M13: =Q13/U13 | N13: =R13/U13 | O13: =S13/U13 | P13: =T13/U13 | Q13: =SUMPRODUCT($M$3:$P$3,M12:P12) | R13: =SUMPRODUCT($M$4:$P$4,M12:P12) | S13: =SUMPRODUCT($M$5:$P$5,M12:P12) | T13: =SUMPRODUCT($M$6:$P$6,M12:P12) | U13: =SQRT(SUMSQ(Q13:T13)) | W13: PC3 | X13: =(1-X11)/3 | Y13: =Y12+X13 | Z13: =SUMPRODUCT(G13:J13,$AB$33:$AE$33) | AA13: 2 | AB13: =AF13/AJ13 | AC13: =AG13/AJ13 | AD13: =AH13/AJ13 | AE13: =AI13/AJ13 | AF13: =SUMPRODUCT($AA$3:$AD$3,AB12:AE12) | AG13: =SUMPRODUCT($AA$4:$AD$4,AB12:AE12) | AH13: =SUMPRODUCT($AA$5:$AD$5,AB12:AE12) | AI13: =SUMPRODUCT($AA$6:$AD$6,AB12:AE12) | AJ13: =SQRT(SUMSQ(AF13:AI13))
A14: =Data_USArrests!A14 | B14: =Data_USArrests!C14 | C14: =Data_USArrests!D14 | D14: =Data_USArrests!E14 | E14: =Data_USArrests!F14 | G14: =(B14-$B$54)/$B$55 | H14: =(C14-$C$54)/$C$55 | I14: =(D14-$D$54)/$D$55 | J14: =(E14-$E$54)/$E$55 | L14: =SUMPRODUCT(G14:J14,$M$33:$P$33) | M14: =Q14/U14 | N14: =R14/U14 | O14: =S14/U14 | P14: =T14/U14 | Q14: =SUMPRODUCT($M$3:$P$3,M13:P13) | R14: =SUMPRODUCT($M$4:$P$4,M13:P13) | S14: =SUMPRODUCT($M$5:$P$5,M13:P13) | T14: =SUMPRODUCT($M$6:$P$6,M13:P13) | U14: =SQRT(SUMSQ(Q14:T14)) | W14: PC4 | X14: =1-(X11+X12+X13) | Y14: =Y13+X14 | Z14: =SUMPRODUCT(G14:J14,$AB$33:$AE$33) | AA14: 3 | AB14: =AF14/AJ14 | AC14: =AG14/AJ14 | AD14: =AH14/AJ14 | AE14: =AI14/AJ14 | AF14: =SUMPRODUCT($AA$3:$AD$3,AB13:AE13) | AG14: =SUMPRODUCT($AA$4:$AD$4,AB13:AE13) | AH14: =SUMPRODUCT($AA$5:$AD$5,AB13:AE13) | AI14: =SUMPRODUCT($AA$6:$AD$6,AB13:AE13) | AJ14: =SQRT(SUMSQ(AF14:AI14))
A15: =Data_USArrests!A15 | B15: =Data_USArrests!C15 | C15: =Data_USArrests!D15 | D15: =Data_USArrests!E15 | E15: =Data_USArrests!F15 | G15: =(B15-$B$54)/$B$55 | H15: =(C15-$C$54)/$C$55 | I15: =(D15-$D$54)/$D$55 | J15: =(E15-$E$54)/$E$55 | L15: =SUMPRODUCT(G15:J15,$M$33:$P$33) | M15: =Q15/U15 | N15: =R15/U15 | O15: =S15/U15 | P15: =T15/U15 | Q15: =SUMPRODUCT($M$3:$P$3,M14:P14) | R15: =SUMPRODUCT($M$4:$P$4,M14:P14) | S15: =SUMPRODUCT($M$5:$P$5,M14:P14) | T15: =SUMPRODUCT($M$6:$P$6,M14:P14) | U15: =SQRT(SUMSQ(Q15:T15)) | Z15: =SUMPRODUCT(G15:J15,$AB$33:$AE$33) | AA15: 4 | AB15: =AF15/AJ15 | AC15: =AG15/AJ15 | AD15: =AH15/AJ15 | AE15: =AI15/AJ15 | AF15: =SUMPRODUCT($AA$3:$AD$3,AB14:AE14) | AG15: =SUMPRODUCT($AA$4:$AD$4,AB14:AE14) | AH15: =SUMPRODUCT($AA$5:$AD$5,AB14:AE14) | AI15: =SUMPRODUCT($AA$6:$AD$6,AB14:AE14) | AJ15: =SQRT(SUMSQ(AF15:AI15))
A16: =Data_USArrests!A16 | B16: =Data_USArrests!C16 | C16: =Data_USArrests!D16 | D16: =Data_USArrests!E16 | E16: =Data_USArrests!F16 | G16: =(B16-$B$54)/$B$55 | H16: =(C16-$C$54)/$C$55 | I16: =(D16-$D$54)/$D$55 | J16: =(E16-$E$54)/$E$55 | L16: =SUMPRODUCT(G16:J16,$M$33:$P$33) | M16: =Q16/U16 | N16: =R16/U16 | O16: =S16/U16 | P16: =T16/U16 | Q16: =SUMPRODUCT($M$3:$P$3,M15:P15) | R16: =SUMPRODUCT($M$4:$P$4,M15:P15) | S16: =SUMPRODUCT($M$5:$P$5,M15:P15) | T16: =SUMPRODUCT($M$6:$P$6,M15:P15) | U16: =SQRT(SUMSQ(Q16:T16)) | Z16: =SUMPRODUCT(G16:J16,$AB$33:$AE$33) | AA16: 5 | AB16: =AF16/AJ16 | AC16: =AG16/AJ16 | AD16: =AH16/AJ16 | AE16: =AI16/AJ16 | AF16: =SUMPRODUCT($AA$3:$AD$3,AB15:AE15) | AG16: =SUMPRODUCT($AA$4:$AD$4,AB15:AE15) | AH16: =SUMPRODUCT($AA$5:$AD$5,AB15:AE15) | AI16: =SUMPRODUCT($AA$6:$AD$6,AB15:AE15) | AJ16: =SQRT(SUMSQ(AF16:AI16))
A17: =Data_USArrests!A17 | B17: =Data_USArrests!C17 | C17: =Data_USArrests!D17 | D17: =Data_USArrests!E17 | E17: =Data_USArrests!F17 | G17: =(B17-$B$54)/$B$55 | H17: =(C17-$C$54)/$C$55 | I17: =(D17-$D$54)/$D$55 | J17: =(E17-$E$54)/$E$55 | L17: =SUMPRODUCT(G17:J17,$M$33:$P$33) | M17: =Q17/U17 | N17: =R17/U17 | O17: =S17/U17 | P17: =T17/U17 | Q17: =SUMPRODUCT($M$3:$P$3,M16:P16) | R17: =SUMPRODUCT($M$4:$P$4,M16:P16) | S17: =SUMPRODUCT($M$5:$P$5,M16:P16) | T17: =SUMPRODUCT($M$6:$P$6,M16:P16) | U17: =SQRT(SUMSQ(Q17:T17)) | Z17: =SUMPRODUCT(G17:J17,$AB$33:$AE$33) | AA17: 6 | AB17: =AF17/AJ17 | AC17: =AG17/AJ17 | AD17: =AH17/AJ17 | AE17: =AI17/AJ17 | AF17: =SUMPRODUCT($AA$3:$AD$3,AB16:AE16) | AG17: =SUMPRODUCT($AA$4:$AD$4,AB16:AE16) | AH17: =SUMPRODUCT($AA$5:$AD$5,AB16:AE16) | AI17: =SUMPRODUCT($AA$6:$AD$6,AB16:AE16) | AJ17: =SQRT(SUMSQ(AF17:AI17))
A18: =Data_USArrests!A18 | B18: =Data_USArrests!C18 | C18: =Data_USArrests!D18 | D18: =Data_USArrests!E18 | E18: =Data_USArrests!F18 | G18: =(B18-$B$54)/$B$55 | H18: =(C18-$C$54)/$C$55 | I18: =(D18-$D$54)/$D$55 | J18: =(E18-$E$54)/$E$55 | L18: =SUMPRODUCT(G18:J18,$M$33:$P$33) | M18: =Q18/U18 | N18: =R18/U18 | O18: =S18/U18 | P18: =T18/U18 | Q18: =SUMPRODUCT($M$3:$P$3,M17:P17) | R18: =SUMPRODUCT($M$4:$P$4,M17:P17) | S18: =SUMPRODUCT($M$5:$P$5,M17:P17) | T18: =SUMPRODUCT($M$6:$P$6,M17:P17) | U18: =SQRT(SUMSQ(Q18:T18)) | Z18: =SUMPRODUCT(G18:J18,$AB$33:$AE$33) | AA18: 7 | AB18: =AF18/AJ18 | AC18: =AG18/AJ18 | AD18: =AH18/AJ18 | AE18: =AI18/AJ18 | AF18: =SUMPRODUCT($AA$3:$AD$3,AB17:AE17) | AG18: =SUMPRODUCT($AA$4:$AD$4,AB17:AE17) | AH18: =SUMPRODUCT($AA$5:$AD$5,AB17:AE17) | AI18: =SUMPRODUCT($AA$6:$AD$6,AB17:AE17) | AJ18: =SQRT(SUMSQ(AF18:AI18))
A19: =Data_USArrests!A19 | B19: =Data_USArrests!C19 | C19: =Data_USArrests!D19 | D19: =Data_USArrests!E19 | E19: =Data_USArrests!F19 | G19: =(B19-$B$54)/$B$55 | H19: =(C19-$C$54)/$C$55 | I19: =(D19-$D$54)/$D$55 | J19: =(E19-$E$54)/$E$55 | L19: =SUMPRODUCT(G19:J19,$M$33:$P$33) | M19: =Q19/U19 | N19: =R19/U19 | O19: =S19/U19 | P19: =T19/U19 | Q19: =SUMPRODUCT($M$3:$P$3,M18:P18) | R19: =SUMPRODUCT($M$4:$P$4,M18:P18) | S19: =SUMPRODUCT($M$5:$P$5,M18:P18) | T19: =SUMPRODUCT($M$6:$P$6,M18:P18) | U19: =SQRT(SUMSQ(Q19:T19)) | Z19: =SUMPRODUCT(G19:J19,$AB$33:$AE$33) | AA19: 8 | AB19: =AF19/AJ19 | AC19: =AG19/AJ19 | AD19: =AH19/AJ19 | AE19: =AI19/AJ19 | AF19: =SUMPRODUCT($AA$3:$AD$3,AB18:AE18) | AG19: =SUMPRODUCT($AA$4:$AD$4,AB18:AE18) | AH19: =SUMPRODUCT($AA$5:$AD$5,AB18:AE18) | AI19: =SUMPRODUCT($AA$6:$AD$6,AB18:AE18) | AJ19: =SQRT(SUMSQ(AF19:AI19))
A20: =Data_USArrests!A20 | B20: =Data_USArrests!C20 | C20: =Data_USArrests!D20 | D20: =Data_USArrests!E20 | E20: =Data_USArrests!F20 | G20: =(B20-$B$54)/$B$55 | H20: =(C20-$C$54)/$C$55 | I20: =(D20-$D$54)/$D$55 | J20: =(E20-$E$54)/$E$55 | L20: =SUMPRODUCT(G20:J20,$M$33:$P$33) | M20: =Q20/U20 | N20: =R20/U20 | O20: =S20/U20 | P20: =T20/U20 | Q20: =SUMPRODUCT($M$3:$P$3,M19:P19) | R20: =SUMPRODUCT($M$4:$P$4,M19:P19) | S20: =SUMPRODUCT($M$5:$P$5,M19:P19) | T20: =SUMPRODUCT($M$6:$P$6,M19:P19) | U20: =SQRT(SUMSQ(Q20:T20)) | Z20: =SUMPRODUCT(G20:J20,$AB$33:$AE$33) | AA20: 9 | AB20: =AF20/AJ20 | AC20: =AG20/AJ20 | AD20: =AH20/AJ20 | AE20: =AI20/AJ20 | AF20: =SUMPRODUCT($AA$3:$AD$3,AB19:AE19) | AG20: =SUMPRODUCT($AA$4:$AD$4,AB19:AE19) | AH20: =SUMPRODUCT($AA$5:$AD$5,AB19:AE19) | AI20: =SUMPRODUCT($AA$6:$AD$6,AB19:AE19) | AJ20: =SQRT(SUMSQ(AF20:AI20))
A21: =Data_USArrests!A21 | B21: =Data_USArrests!C21 | C21: =Data_USArrests!D21 | D21: =Data_USArrests!E21 | E21: =Data_USArrests!F21 | G21: =(B21-$B$54)/$B$55 | H21: =(C21-$C$54)/$C$55 | I21: =(D21-$D$54)/$D$55 | J21: =(E21-$E$54)/$E$55 | L21: =SUMPRODUCT(G21:J21,$M$33:$P$33) | M21: =Q21/U21 | N21: =R21/U21 | O21: =S21/U21 | P21: =T21/U21 | Q21: =SUMPRODUCT($M$3:$P$3,M20:P20) | R21: =SUMPRODUCT($M$4:$P$4,M20:P20) | S21: =SUMPRODUCT($M$5:$P$5,M20:P20) | T21: =SUMPRODUCT($M$6:$P$6,M20:P20) | U21: =SQRT(SUMSQ(Q21:T21)) | Z21: =SUMPRODUCT(G21:J21,$AB$33:$AE$33) | AA21: 10 | AB21: =AF21/AJ21 | AC21: =AG21/AJ21 | AD21: =AH21/AJ21 | AE21: =AI21/AJ21 | AF21: =SUMPRODUCT($AA$3:$AD$3,AB20:AE20) | AG21: =SUMPRODUCT($AA$4:$AD$4,AB20:AE20) | AH21: =SUMPRODUCT($AA$5:$AD$5,AB20:AE20) | AI21: =SUMPRODUCT($AA$6:$AD$6,AB20:AE20) | AJ21: =SQRT(SUMSQ(AF21:AI21))
A22: =Data_USArrests!A22 | B22: =Data_USArrests!C22 | C22: =Data_USArrests!D22 | D22: =Data_USArrests!E22 | E22: =Data_USArrests!F22 | G22: =(B22-$B$54)/$B$55 | H22: =(C22-$C$54)/$C$55 | I22: =(D22-$D$54)/$D$55 | J22: =(E22-$E$54)/$E$55 | L22: =SUMPRODUCT(G22:J22,$M$33:$P$33) | M22: =Q22/U22 | N22: =R22/U22 | O22: =S22/U22 | P22: =T22/U22 | Q22: =SUMPRODUCT($M$3:$P$3,M21:P21) | R22: =SUMPRODUCT($M$4:$P$4,M21:P21) | S22: =SUMPRODUCT($M$5:$P$5,M21:P21) | T22: =SUMPRODUCT($M$6:$P$6,M21:P21) | U22: =SQRT(SUMSQ(Q22:T22)) | Z22: =SUMPRODUCT(G22:J22,$AB$33:$AE$33) | AA22: 11 | AB22: =AF22/AJ22 | AC22: =AG22/AJ22 | AD22: =AH22/AJ22 | AE22: =AI22/AJ22 | AF22: =SUMPRODUCT($AA$3:$AD$3,AB21:AE21) | AG22: =SUMPRODUCT($AA$4:$AD$4,AB21:AE21) | AH22: =SUMPRODUCT($AA$5:$AD$5,AB21:AE21) | AI22: =SUMPRODUCT($AA$6:$AD$6,AB21:AE21) | AJ22: =SQRT(SUMSQ(AF22:AI22))
A23: =Data_USArrests!A23 | B23: =Data_USArrests!C23 | C23: =Data_USArrests!D23 | D23: =Data_USArrests!E23 | E23: =Data_USArrests!F23 | G23: =(B23-$B$54)/$B$55 | H23: =(C23-$C$54)/$C$55 | I23: =(D23-$D$54)/$D$55 | J23: =(E23-$E$54)/$E$55 | L23: =SUMPRODUCT(G23:J23,$M$33:$P$33) | M23: =Q23/U23 | N23: =R23/U23 | O23: =S23/U23 | P23: =T23/U23 | Q23: =SUMPRODUCT($M$3:$P$3,M22:P22) | R23: =SUMPRODUCT($M$4:$P$4,M22:P22) | S23: =SUMPRODUCT($M$5:$P$5,M22:P22) | T23: =SUMPRODUCT($M$6:$P$6,M22:P22) | U23: =SQRT(SUMSQ(Q23:T23)) | Z23: =SUMPRODUCT(G23:J23,$AB$33:$AE$33) | AA23: 12 | AB23: =AF23/AJ23 | AC23: =AG23/AJ23 | AD23: =AH23/AJ23 | AE23: =AI23/AJ23 | AF23: =SUMPRODUCT($AA$3:$AD$3,AB22:AE22) | AG23: =SUMPRODUCT($AA$4:$AD$4,AB22:AE22) | AH23: =SUMPRODUCT($AA$5:$AD$5,AB22:AE22) | AI23: =SUMPRODUCT($AA$6:$AD$6,AB22:AE22) | AJ23: =SQRT(SUMSQ(AF23:AI23))
A24: =Data_USArrests!A24 | B24: =Data_USArrests!C24 | C24: =Data_USArrests!D24 | D24: =Data_USArrests!E24 | E24: =Data_USArrests!F24 | G24: =(B24-$B$54)/$B$55 | H24: =(C24-$C$54)/$C$55 | I24: =(D24-$D$54)/$D$55 | J24: =(E24-$E$54)/$E$55 | L24: =SUMPRODUCT(G24:J24,$M$33:$P$33) | M24: =Q24/U24 | N24: =R24/U24 | O24: =S24/U24 | P24: =T24/U24 | Q24: =SUMPRODUCT($M$3:$P$3,M23:P23) | R24: =SUMPRODUCT($M$4:$P$4,M23:P23) | S24: =SUMPRODUCT($M$5:$P$5,M23:P23) | T24: =SUMPRODUCT($M$6:$P$6,M23:P23) | U24: =SQRT(SUMSQ(Q24:T24)) | Z24: =SUMPRODUCT(G24:J24,$AB$33:$AE$33) | AA24: 13 | AB24: =AF24/AJ24 | AC24: =AG24/AJ24 | AD24: =AH24/AJ24 | AE24: =AI24/AJ24 | AF24: =SUMPRODUCT($AA$3:$AD$3,AB23:AE23) | AG24: =SUMPRODUCT($AA$4:$AD$4,AB23:AE23) | AH24: =SUMPRODUCT($AA$5:$AD$5,AB23:AE23) | AI24: =SUMPRODUCT($AA$6:$AD$6,AB23:AE23) | AJ24: =SQRT(SUMSQ(AF24:AI24))
A25: =Data_USArrests!A25 | B25: =Data_USArrests!C25 | C25: =Data_USArrests!D25 | D25: =Data_USArrests!E25 | E25: =Data_USArrests!F25 | G25: =(B25-$B$54)/$B$55 | H25: =(C25-$C$54)/$C$55 | I25: =(D25-$D$54)/$D$55 | J25: =(E25-$E$54)/$E$55 | L25: =SUMPRODUCT(G25:J25,$M$33:$P$33) | M25: =Q25/U25 | N25: =R25/U25 | O25: =S25/U25 | P25: =T25/U25 | Q25: =SUMPRODUCT($M$3:$P$3,M24:P24) | R25: =SUMPRODUCT($M$4:$P$4,M24:P24) | S25: =SUMPRODUCT($M$5:$P$5,M24:P24) | T25: =SUMPRODUCT($M$6:$P$6,M24:P24) | U25: =SQRT(SUMSQ(Q25:T25)) | Z25: =SUMPRODUCT(G25:J25,$AB$33:$AE$33) | AA25: 14 | AB25: =AF25/AJ25 | AC25: =AG25/AJ25 | AD25: =AH25/AJ25 | AE25: =AI25/AJ25 | AF25: =SUMPRODUCT($AA$3:$AD$3,AB24:AE24) | AG25: =SUMPRODUCT($AA$4:$AD$4,AB24:AE24) | AH25: =SUMPRODUCT($AA$5:$AD$5,AB24:AE24) | AI25: =SUMPRODUCT($AA$6:$AD$6,AB24:AE24) | AJ25: =SQRT(SUMSQ(AF25:AI25))
A26: =Data_USArrests!A26 | B26: =Data_USArrests!C26 | C26: =Data_USArrests!D26 | D26: =Data_USArrests!E26 | E26: =Data_USArrests!F26 | G26: =(B26-$B$54)/$B$55 | H26: =(C26-$C$54)/$C$55 | I26: =(D26-$D$54)/$D$55 | J26: =(E26-$E$54)/$E$55 | L26: =SUMPRODUCT(G26:J26,$M$33:$P$33) | M26: =Q26/U26 | N26: =R26/U26 | O26: =S26/U26 | P26: =T26/U26 | Q26: =SUMPRODUCT($M$3:$P$3,M25:P25) | R26: =SUMPRODUCT($M$4:$P$4,M25:P25) | S26: =SUMPRODUCT($M$5:$P$5,M25:P25) | T26: =SUMPRODUCT($M$6:$P$6,M25:P25) | U26: =SQRT(SUMSQ(Q26:T26)) | Z26: =SUMPRODUCT(G26:J26,$AB$33:$AE$33) | AA26: 15 | AB26: =AF26/AJ26 | AC26: =AG26/AJ26 | AD26: =AH26/AJ26 | AE26: =AI26/AJ26 | AF26: =SUMPRODUCT($AA$3:$AD$3,AB25:AE25) | AG26: =SUMPRODUCT($AA$4:$AD$4,AB25:AE25) | AH26: =SUMPRODUCT($AA$5:$AD$5,AB25:AE25) | AI26: =SUMPRODUCT($AA$6:$AD$6,AB25:AE25) | AJ26: =SQRT(SUMSQ(AF26:AI26))
... A30: =Data_USArrests!A30 | B30: =Data_USArrests!C30 | C30: =Data_USArrests!D30 | D30: =Data_USArrests!E30 | E30: =Data_USArrests!F30 | G30: =(B30-$B$54)/$B$55 | H30: =(C30-$C$54)/$C$55 | I30: =(D30-$D$54)/$D$55 | J30: =(E30-$E$54)/$E$55 | L30: =SUMPRODUCT(G30:J30,$M$33:$P$33) | M30: =Q30/U30 | N30: =R30/U30 | O30: =S30/U30 | P30: =T30/U30 | Q30: =SUMPRODUCT($M$3:$P$3,M29:P29) | R30: =SUMPRODUCT($M$4:$P$4,M29:P29) | S30: =SUMPRODUCT($M$5:$P$5,M29:P29) | T30: =SUMPRODUCT($M$6:$P$6,M29:P29) | U30: =SQRT(SUMSQ(Q30:T30)) | Z30: =SUMPRODUCT(G30:J30,$AB$33:$AE$33) | AA30: 19 | AB30: =AF30/AJ30 | AC30: =AG30/AJ30 | AD30: =AH30/AJ30 | AE30: =AI30/AJ30 | AF30: =SUMPRODUCT($AA$3:$AD$3,AB29:AE29) | AG30: =SUMPRODUCT($AA$4:$AD$4,AB29:AE29) | AH30: =SUMPRODUCT($AA$5:$AD$5,AB29:AE29) | AI30: =SUMPRODUCT($AA$6:$AD$6,AB29:AE29) | AJ30: =SQRT(SUMSQ(AF30:AI30))
A31: =Data_USArrests!A31 | B31: =Data_USArrests!C31 | C31: =Data_USArrests!D31 | D31: =Data_USArrests!E31 | E31: =Data_USArrests!F31 | G31: =(B31-$B$54)/$B$55 | H31: =(C31-$C$54)/$C$55 | I31: =(D31-$D$54)/$D$55 | J31: =(E31-$E$54)/$E$55 | L31: =SUMPRODUCT(G31:J31,$M$33:$P$33) | Z31: =SUMPRODUCT(G31:J31,$AB$33:$AE$33)
A32: =Data_USArrests!A32 | B32: =Data_USArrests!C32 | C32: =Data_USArrests!D32 | D32: =Data_USArrests!E32 | E32: =Data_USArrests!F32 | G32: =(B32-$B$54)/$B$55 | H32: =(C32-$C$54)/$C$55 | I32: =(D32-$D$54)/$D$55 | J32: =(E32-$E$54)/$E$55 | L32: =SUMPRODUCT(G32:J32,$M$33:$P$33) | Z32: =SUMPRODUCT(G32:J32,$AB$33:$AE$33)
A33: =Data_USArrests!A33 | B33: =Data_USArrests!C33 | C33: =Data_USArrests!D33 | D33: =Data_USArrests!E33 | E33: =Data_USArrests!F33 | G33: =(B33-$B$54)/$B$55 | H33: =(C33-$C$54)/$C$55 | I33: =(D33-$D$54)/$D$55 | J33: =(E33-$E$54)/$E$55 | L33: =SUMPRODUCT(G33:J33,$M$33:$P$33) | M33: =M30 | N33: =N30 | O33: =O30 | P33: =P30 | Z33: =SUMPRODUCT(G33:J33,$AB$33:$AE$33) | AA33: final_PC2_loading | AB33: =AB30 | AC33: =AC30 | AD33: =AD30 | AE33: =AE30
A34: =Data_USArrests!A34 | B34: =Data_USArrests!C34 | C34: =Data_USArrests!D34 | D34: =Data_USArrests!E34 | E34: =Data_USArrests!F34 | G34: =(B34-$B$54)/$B$55 | H34: =(C34-$C$54)/$C$55 | I34: =(D34-$D$54)/$D$55 | J34: =(E34-$E$54)/$E$55 | L34: =SUMPRODUCT(G34:J34,$M$33:$P$33) | M34: =M33*(M3*M33+N3*N33+O3*O33+P3*P33)+N33*(M4*M33+N4*N33+O4*O33+P4*P33)+O33*(M5*M33+N5*N33+O5*O33+P5*P33)+P33*(M6*M33+N6*N33+O6*O33+P6*P33) | Z34: =SUMPRODUCT(G34:J34,$AB$33:$AE$33) | AA34: lambda2 | AB34: =AB33*(M3*AB33+N3*AC33+O3*AD33+P3*AE33)+AC33*(M4*AB33+N4*AC33+O4*AD33+P4*AE33)+AD33*(M5*AB33+N5*AC33+O5*AD33+P5*AE33)+AE33*(M6*AB33+N6*AC33+O6*AD33+P6*AE33)
A35: =Data_USArrests!A35 | B35: =Data_USArrests!C35 | C35: =Data_USArrests!D35 | D35: =Data_USArrests!E35 | E35: =Data_USArrests!F35 | G35: =(B35-$B$54)/$B$55 | H35: =(C35-$C$54)/$C$55 | I35: =(D35-$D$54)/$D$55 | J35: =(E35-$E$54)/$E$55 | L35: =SUMPRODUCT(G35:J35,$M$33:$P$33) | M35: =M34/4 | Z35: =SUMPRODUCT(G35:J35,$AB$33:$AE$33) | AA35: PVE_PC2 | AB35: =AB34/4
A36: =Data_USArrests!A36 | B36: =Data_USArrests!C36 | C36: =Data_USArrests!D36 | D36: =Data_USArrests!E36 | E36: =Data_USArrests!F36 | G36: =(B36-$B$54)/$B$55 | H36: =(C36-$C$54)/$C$55 | I36: =(D36-$D$54)/$D$55 | J36: =(E36-$E$54)/$E$55 | L36: =SUMPRODUCT(G36:J36,$M$33:$P$33) | Z36: =SUMPRODUCT(G36:J36,$AB$33:$AE$33)
A37: =Data_USArrests!A37 | B37: =Data_USArrests!C37 | C37: =Data_USArrests!D37 | D37: =Data_USArrests!E37 | E37: =Data_USArrests!F37 | G37: =(B37-$B$54)/$B$55 | H37: =(C37-$C$54)/$C$55 | I37: =(D37-$D$54)/$D$55 | J37: =(E37-$E$54)/$E$55 | L37: =SUMPRODUCT(G37:J37,$M$33:$P$33) | N37: Alabama_manual | O37: =SUMPRODUCT(G2:J2,$M$33:$P$33) | Z37: =SUMPRODUCT(G37:J37,$AB$33:$AE$33)
A38: =Data_USArrests!A38 | B38: =Data_USArrests!C38 | C38: =Data_USArrests!D38 | D38: =Data_USArrests!E38 | E38: =Data_USArrests!F38 | G38: =(B38-$B$54)/$B$55 | H38: =(C38-$C$54)/$C$55 | I38: =(D38-$D$54)/$D$55 | J38: =(E38-$E$54)/$E$55 | L38: =SUMPRODUCT(G38:J38,$M$33:$P$33) | N38: Alabama_from_scores | O38: =L2 | Z38: =SUMPRODUCT(G38:J38,$AB$33:$AE$33)
A39: =Data_USArrests!A39 | B39: =Data_USArrests!C39 | C39: =Data_USArrests!D39 | D39: =Data_USArrests!E39 | E39: =Data_USArrests!F39 | G39: =(B39-$B$54)/$B$55 | H39: =(C39-$C$54)/$C$55 | I39: =(D39-$D$54)/$D$55 | J39: =(E39-$E$54)/$E$55 | L39: =SUMPRODUCT(G39:J39,$M$33:$P$33) | N39: difference | O39: =O37-O38 | Z39: =SUMPRODUCT(G39:J39,$AB$33:$AE$33)
A40: =Data_USArrests!A40 | B40: =Data_USArrests!C40 | C40: =Data_USArrests!D40 | D40: =Data_USArrests!E40 | E40: =Data_USArrests!F40 | G40: =(B40-$B$54)/$B$55 | H40: =(C40-$C$54)/$C$55 | I40: =(D40-$D$54)/$D$55 | J40: =(E40-$E$54)/$E$55 | L40: =SUMPRODUCT(G40:J40,$M$33:$P$33) | Z40: =SUMPRODUCT(G40:J40,$AB$33:$AE$33)
A41: =Data_USArrests!A41 | B41: =Data_USArrests!C41 | C41: =Data_USArrests!D41 | D41: =Data_USArrests!E41 | E41: =Data_USArrests!F41 | G41: =(B41-$B$54)/$B$55 | H41: =(C41-$C$54)/$C$55 | I41: =(D41-$D$54)/$D$55 | J41: =(E41-$E$54)/$E$55 | L41: =SUMPRODUCT(G41:J41,$M$33:$P$33) | Z41: =SUMPRODUCT(G41:J41,$AB$33:$AE$33)
A42: =Data_USArrests!A42 | B42: =Data_USArrests!C42 | C42: =Data_USArrests!D42 | D42: =Data_USArrests!E42 | E42: =Data_USArrests!F42 | G42: =(B42-$B$54)/$B$55 | H42: =(C42-$C$54)/$C$55 | I42: =(D42-$D$54)/$D$55 | J42: =(E42-$E$54)/$E$55 | L42: =SUMPRODUCT(G42:J42,$M$33:$P$33) | Z42: =SUMPRODUCT(G42:J42,$AB$33:$AE$33)
A43: =Data_USArrests!A43 | B43: =Data_USArrests!C43 | C43: =Data_USArrests!D43 | D43: =Data_USArrests!E43 | E43: =Data_USArrests!F43 | G43: =(B43-$B$54)/$B$55 | H43: =(C43-$C$54)/$C$55 | I43: =(D43-$D$54)/$D$55 | J43: =(E43-$E$54)/$E$55 | L43: =SUMPRODUCT(G43:J43,$M$33:$P$33) | Z43: =SUMPRODUCT(G43:J43,$AB$33:$AE$33)
...

Sheet KMeans_6_2
A1: state_id | B1: z_Murder | C1: z_Assault | D1: z_UrbanPop | E1: z_Rape | G1: center | H1: Murder | I1: Assault | J1: UrbanPop | K1: Rape | M1: d1_it1 | N1: d2_it1 | O1: d3_it1 | P1: cluster_it1 | R1: center_after_it1 | S1: Murder | T1: Assault | U1: UrbanPop | V1: Rape | X1: d1_it2 | Y1: d2_it2 | Z1: d3_it2 | AA1: cluster_final | AC1: withinss_k3 | AE1: K | AF1: bss_tss_formula | AH1: c1_x | AI1: c1_y | AJ1: c2_x | AK1: c2_y | AL1: c3_x | AM1: c3_y
A2: =Scale_PCA_Mechanics!A2 | B2: =Scale_PCA_Mechanics!G2 | C2: =Scale_PCA_Mechanics!H2 | D2: =Scale_PCA_Mechanics!I2 | E2: =Scale_PCA_Mechanics!J2 | G2: C1 | H2: =B3 | I2: =C3 | J2: =D3 | K2: =E3 | M2: =SUMXMY2(B2:E2,$H$2:$K$2) | N2: =SUMXMY2(B2:E2,$H$3:$K$3) | O2: =SUMXMY2(B2:E2,$H$4:$K$4) | P2: =MATCH(MIN(M2:O2),M2:O2,0) | R2: C1 | S2: =AVERAGEIFS($B$2:$B$51,$P$2:$P$51,1) | T2: =AVERAGEIFS($C$2:$C$51,$P$2:$P$51,1) | U2: =AVERAGEIFS($D$2:$D$51,$P$2:$P$51,1) | V2: =AVERAGEIFS($E$2:$E$51,$P$2:$P$51,1) | X2: =SUMXMY2(B2:E2,$S$2:$V$2) | Y2: =SUMXMY2(B2:E2,$S$3:$V$3) | Z2: =SUMXMY2(B2:E2,$S$4:$V$4) | AA2: =MATCH(MIN(X2:Z2),X2:Z2,0) | AC2: =SUMPRODUCT((AA2:AA51=1)*X2:X51)+SUMPRODUCT((AA2:AA51=2)*Y2:Y51)+SUMPRODUCT((AA2:AA51=3)*Z2:Z51) | AE2: 1 | AF2: =MAX(0,MIN(0.999,1-(1-$AC$6)*(3/AE2)^0.75)) | AH2: =IF($AA2=1,$B2,NA()) | AI2: =IF($AA2=1,$C2,NA()) | AJ2: =IF($AA2=2,$B2,NA()) | AK2: =IF($AA2=2,$C2,NA()) | AL2: =IF($AA2=3,$B2,NA()) | AM2: =IF($AA2=3,$C2,NA())
A3: =Scale_PCA_Mechanics!A3 | B3: =Scale_PCA_Mechanics!G3 | C3: =Scale_PCA_Mechanics!H3 | D3: =Scale_PCA_Mechanics!I3 | E3: =Scale_PCA_Mechanics!J3 | G3: C2 | H3: =B4 | I3: =C4 | J3: =D4 | K3: =E4 | M3: =SUMXMY2(B3:E3,$H$2:$K$2) | N3: =SUMXMY2(B3:E3,$H$3:$K$3) | O3: =SUMXMY2(B3:E3,$H$4:$K$4) | P3: =MATCH(MIN(M3:O3),M3:O3,0) | R3: C2 | S3: =AVERAGEIFS($B$2:$B$51,$P$2:$P$51,2) | T3: =AVERAGEIFS($C$2:$C$51,$P$2:$P$51,2) | U3: =AVERAGEIFS($D$2:$D$51,$P$2:$P$51,2) | V3: =AVERAGEIFS($E$2:$E$51,$P$2:$P$51,2) | X3: =SUMXMY2(B3:E3,$S$2:$V$2) | Y3: =SUMXMY2(B3:E3,$S$3:$V$3) | Z3: =SUMXMY2(B3:E3,$S$4:$V$4) | AA3: =MATCH(MIN(X3:Z3),X3:Z3,0) | AC3: totss | AE3: 2 | AF3: =MAX(0,MIN(0.999,1-(1-$AC$6)*(3/AE3)^0.75)) | AH3: =IF($AA3=1,$B3,NA()) | AI3: =IF($AA3=1,$C3,NA()) | AJ3: =IF($AA3=2,$B3,NA()) | AK3: =IF($AA3=2,$C3,NA()) | AL3: =IF($AA3=3,$B3,NA()) | AM3: =IF($AA3=3,$C3,NA())
A4: =Scale_PCA_Mechanics!A4 | B4: =Scale_PCA_Mechanics!G4 | C4: =Scale_PCA_Mechanics!H4 | D4: =Scale_PCA_Mechanics!I4 | E4: =Scale_PCA_Mechanics!J4 | G4: C3 | H4: =B5 | I4: =C5 | J4: =D5 | K4: =E5 | M4: =SUMXMY2(B4:E4,$H$2:$K$2) | N4: =SUMXMY2(B4:E4,$H$3:$K$3) | O4: =SUMXMY2(B4:E4,$H$4:$K$4) | P4: =MATCH(MIN(M4:O4),M4:O4,0) | R4: C3 | S4: =AVERAGEIFS($B$2:$B$51,$P$2:$P$51,3) | T4: =AVERAGEIFS($C$2:$C$51,$P$2:$P$51,3) | U4: =AVERAGEIFS($D$2:$D$51,$P$2:$P$51,3) | V4: =AVERAGEIFS($E$2:$E$51,$P$2:$P$51,3) | X4: =SUMXMY2(B4:E4,$S$2:$V$2) | Y4: =SUMXMY2(B4:E4,$S$3:$V$3) | Z4: =SUMXMY2(B4:E4,$S$4:$V$4) | AA4: =MATCH(MIN(X4:Z4),X4:Z4,0) | AC4: =SUMPRODUCT(B2:B51^2)+SUMPRODUCT(C2:C51^2)+SUMPRODUCT(D2:D51^2)+SUMPRODUCT(E2:E51^2) | AE4: 3 | AF4: =MAX(0,MIN(0.999,1-(1-$AC$6)*(3/AE4)^0.75)) | AH4: =IF($AA4=1,$B4,NA()) | AI4: =IF($AA4=1,$C4,NA()) | AJ4: =IF($AA4=2,$B4,NA()) | AK4: =IF($AA4=2,$C4,NA()) | AL4: =IF($AA4=3,$B4,NA()) | AM4: =IF($AA4=3,$C4,NA())
A5: =Scale_PCA_Mechanics!A5 | B5: =Scale_PCA_Mechanics!G5 | C5: =Scale_PCA_Mechanics!H5 | D5: =Scale_PCA_Mechanics!I5 | E5: =Scale_PCA_Mechanics!J5 | M5: =SUMXMY2(B5:E5,$H$2:$K$2) | N5: =SUMXMY2(B5:E5,$H$3:$K$3) | O5: =SUMXMY2(B5:E5,$H$4:$K$4) | P5: =MATCH(MIN(M5:O5),M5:O5,0) | X5: =SUMXMY2(B5:E5,$S$2:$V$2) | Y5: =SUMXMY2(B5:E5,$S$3:$V$3) | Z5: =SUMXMY2(B5:E5,$S$4:$V$4) | AA5: =MATCH(MIN(X5:Z5),X5:Z5,0) | AC5: bss_tss_k3 | AE5: 4 | AF5: =MAX(0,MIN(0.999,1-(1-$AC$6)*(3/AE5)^0.75)) | AH5: =IF($AA5=1,$B5,NA()) | AI5: =IF($AA5=1,$C5,NA()) | AJ5: =IF($AA5=2,$B5,NA()) | AK5: =IF($AA5=2,$C5,NA()) | AL5: =IF($AA5=3,$B5,NA()) | AM5: =IF($AA5=3,$C5,NA())
A6: =Scale_PCA_Mechanics!A6 | B6: =Scale_PCA_Mechanics!G6 | C6: =Scale_PCA_Mechanics!H6 | D6: =Scale_PCA_Mechanics!I6 | E6: =Scale_PCA_Mechanics!J6 | M6: =SUMXMY2(B6:E6,$H$2:$K$2) | N6: =SUMXMY2(B6:E6,$H$3:$K$3) | O6: =SUMXMY2(B6:E6,$H$4:$K$4) | P6: =MATCH(MIN(M6:O6),M6:O6,0) | X6: =SUMXMY2(B6:E6,$S$2:$V$2) | Y6: =SUMXMY2(B6:E6,$S$3:$V$3) | Z6: =SUMXMY2(B6:E6,$S$4:$V$4) | AA6: =MATCH(MIN(X6:Z6),X6:Z6,0) | AC6: =(AC4-AC2)/AC4 | AE6: 5 | AF6: =MAX(0,MIN(0.999,1-(1-$AC$6)*(3/AE6)^0.75)) | AH6: =IF($AA6=1,$B6,NA()) | AI6: =IF($AA6=1,$C6,NA()) | AJ6: =IF($AA6=2,$B6,NA()) | AK6: =IF($AA6=2,$C6,NA()) | AL6: =IF($AA6=3,$B6,NA()) | AM6: =IF($AA6=3,$C6,NA())
A7: =Scale_PCA_Mechanics!A7 | B7: =Scale_PCA_Mechanics!G7 | C7: =Scale_PCA_Mechanics!H7 | D7: =Scale_PCA_Mechanics!I7 | E7: =Scale_PCA_Mechanics!J7 | M7: =SUMXMY2(B7:E7,$H$2:$K$2) | N7: =SUMXMY2(B7:E7,$H$3:$K$3) | O7: =SUMXMY2(B7:E7,$H$4:$K$4) | P7: =MATCH(MIN(M7:O7),M7:O7,0) | X7: =SUMXMY2(B7:E7,$S$2:$V$2) | Y7: =SUMXMY2(B7:E7,$S$3:$V$3) | Z7: =SUMXMY2(B7:E7,$S$4:$V$4) | AA7: =MATCH(MIN(X7:Z7),X7:Z7,0) | AE7: 6 | AF7: =MAX(0,MIN(0.999,1-(1-$AC$6)*(3/AE7)^0.75)) | AH7: =IF($AA7=1,$B7,NA()) | AI7: =IF($AA7=1,$C7,NA()) | AJ7: =IF($AA7=2,$B7,NA()) | AK7: =IF($AA7=2,$C7,NA()) | AL7: =IF($AA7=3,$B7,NA()) | AM7: =IF($AA7=3,$C7,NA())
A8: =Scale_PCA_Mechanics!A8 | B8: =Scale_PCA_Mechanics!G8 | C8: =Scale_PCA_Mechanics!H8 | D8: =Scale_PCA_Mechanics!I8 | E8: =Scale_PCA_Mechanics!J8 | M8: =SUMXMY2(B8:E8,$H$2:$K$2) | N8: =SUMXMY2(B8:E8,$H$3:$K$3) | O8: =SUMXMY2(B8:E8,$H$4:$K$4) | P8: =MATCH(MIN(M8:O8),M8:O8,0) | X8: =SUMXMY2(B8:E8,$S$2:$V$2) | Y8: =SUMXMY2(B8:E8,$S$3:$V$3) | Z8: =SUMXMY2(B8:E8,$S$4:$V$4) | AA8: =MATCH(MIN(X8:Z8),X8:Z8,0) | AE8: 7 | AF8: =MAX(0,MIN(0.999,1-(1-$AC$6)*(3/AE8)^0.75)) | AH8: =IF($AA8=1,$B8,NA()) | AI8: =IF($AA8=1,$C8,NA()) | AJ8: =IF($AA8=2,$B8,NA()) | AK8: =IF($AA8=2,$C8,NA()) | AL8: =IF($AA8=3,$B8,NA()) | AM8: =IF($AA8=3,$C8,NA())
A9: =Scale_PCA_Mechanics!A9 | B9: =Scale_PCA_Mechanics!G9 | C9: =Scale_PCA_Mechanics!H9 | D9: =Scale_PCA_Mechanics!I9 | E9: =Scale_PCA_Mechanics!J9 | M9: =SUMXMY2(B9:E9,$H$2:$K$2) | N9: =SUMXMY2(B9:E9,$H$3:$K$3) | O9: =SUMXMY2(B9:E9,$H$4:$K$4) | P9: =MATCH(MIN(M9:O9),M9:O9,0) | X9: =SUMXMY2(B9:E9,$S$2:$V$2) | Y9: =SUMXMY2(B9:E9,$S$3:$V$3) | Z9: =SUMXMY2(B9:E9,$S$4:$V$4) | AA9: =MATCH(MIN(X9:Z9),X9:Z9,0) | AE9: 8 | AF9: =MAX(0,MIN(0.999,1-(1-$AC$6)*(3/AE9)^0.75)) | AH9: =IF($AA9=1,$B9,NA()) | AI9: =IF($AA9=1,$C9,NA()) | AJ9: =IF($AA9=2,$B9,NA()) | AK9: =IF($AA9=2,$C9,NA()) | AL9: =IF($AA9=3,$B9,NA()) | AM9: =IF($AA9=3,$C9,NA())
A10: =Scale_PCA_Mechanics!A10 | B10: =Scale_PCA_Mechanics!G10 | C10: =Scale_PCA_Mechanics!H10 | D10: =Scale_PCA_Mechanics!I10 | E10: =Scale_PCA_Mechanics!J10 | M10: =SUMXMY2(B10:E10,$H$2:$K$2) | N10: =SUMXMY2(B10:E10,$H$3:$K$3) | O10: =SUMXMY2(B10:E10,$H$4:$K$4) | P10: =MATCH(MIN(M10:O10),M10:O10,0) | X10: =SUMXMY2(B10:E10,$S$2:$V$2) | Y10: =SUMXMY2(B10:E10,$S$3:$V$3) | Z10: =SUMXMY2(B10:E10,$S$4:$V$4) | AA10: =MATCH(MIN(X10:Z10),X10:Z10,0) | AE10: 9 | AF10: =MAX(0,MIN(0.999,1-(1-$AC$6)*(3/AE10)^0.75)) | AH10: =IF($AA10=1,$B10,NA()) | AI10: =IF($AA10=1,$C10,NA()) | AJ10: =IF($AA10=2,$B10,NA()) | AK10: =IF($AA10=2,$C10,NA()) | AL10: =IF($AA10=3,$B10,NA()) | AM10: =IF($AA10=3,$C10,NA())
A11: =Scale_PCA_Mechanics!A11 | B11: =Scale_PCA_Mechanics!G11 | C11: =Scale_PCA_Mechanics!H11 | D11: =Scale_PCA_Mechanics!I11 | E11: =Scale_PCA_Mechanics!J11 | M11: =SUMXMY2(B11:E11,$H$2:$K$2) | N11: =SUMXMY2(B11:E11,$H$3:$K$3) | O11: =SUMXMY2(B11:E11,$H$4:$K$4) | P11: =MATCH(MIN(M11:O11),M11:O11,0) | X11: =SUMXMY2(B11:E11,$S$2:$V$2) | Y11: =SUMXMY2(B11:E11,$S$3:$V$3) | Z11: =SUMXMY2(B11:E11,$S$4:$V$4) | AA11: =MATCH(MIN(X11:Z11),X11:Z11,0) | AE11: 10 | AF11: =MAX(0,MIN(0.999,1-(1-$AC$6)*(3/AE11)^0.75)) | AH11: =IF($AA11=1,$B11,NA()) | AI11: =IF($AA11=1,$C11,NA()) | AJ11: =IF($AA11=2,$B11,NA()) | AK11: =IF($AA11=2,$C11,NA()) | AL11: =IF($AA11=3,$B11,NA()) | AM11: =IF($AA11=3,$C11,NA())
A12: =Scale_PCA_Mechanics!A12 | B12: =Scale_PCA_Mechanics!G12 | C12: =Scale_PCA_Mechanics!H12 | D12: =Scale_PCA_Mechanics!I12 | E12: =Scale_PCA_Mechanics!J12 | M12: =SUMXMY2(B12:E12,$H$2:$K$2) | N12: =SUMXMY2(B12:E12,$H$3:$K$3) | O12: =SUMXMY2(B12:E12,$H$4:$K$4) | P12: =MATCH(MIN(M12:O12),M12:O12,0) | X12: =SUMXMY2(B12:E12,$S$2:$V$2) | Y12: =SUMXMY2(B12:E12,$S$3:$V$3) | Z12: =SUMXMY2(B12:E12,$S$4:$V$4) | AA12: =MATCH(MIN(X12:Z12),X12:Z12,0) | AH12: =IF($AA12=1,$B12,NA()) | AI12: =IF($AA12=1,$C12,NA()) | AJ12: =IF($AA12=2,$B12,NA()) | AK12: =IF($AA12=2,$C12,NA()) | AL12: =IF($AA12=3,$B12,NA()) | AM12: =IF($AA12=3,$C12,NA())
A13: =Scale_PCA_Mechanics!A13 | B13: =Scale_PCA_Mechanics!G13 | C13: =Scale_PCA_Mechanics!H13 | D13: =Scale_PCA_Mechanics!I13 | E13: =Scale_PCA_Mechanics!J13 | M13: =SUMXMY2(B13:E13,$H$2:$K$2) | N13: =SUMXMY2(B13:E13,$H$3:$K$3) | O13: =SUMXMY2(B13:E13,$H$4:$K$4) | P13: =MATCH(MIN(M13:O13),M13:O13,0) | X13: =SUMXMY2(B13:E13,$S$2:$V$2) | Y13: =SUMXMY2(B13:E13,$S$3:$V$3) | Z13: =SUMXMY2(B13:E13,$S$4:$V$4) | AA13: =MATCH(MIN(X13:Z13),X13:Z13,0) | AH13: =IF($AA13=1,$B13,NA()) | AI13: =IF($AA13=1,$C13,NA()) | AJ13: =IF($AA13=2,$B13,NA()) | AK13: =IF($AA13=2,$C13,NA()) | AL13: =IF($AA13=3,$B13,NA()) | AM13: =IF($AA13=3,$C13,NA())
A14: =Scale_PCA_Mechanics!A14 | B14: =Scale_PCA_Mechanics!G14 | C14: =Scale_PCA_Mechanics!H14 | D14: =Scale_PCA_Mechanics!I14 | E14: =Scale_PCA_Mechanics!J14 | M14: =SUMXMY2(B14:E14,$H$2:$K$2) | N14: =SUMXMY2(B14:E14,$H$3:$K$3) | O14: =SUMXMY2(B14:E14,$H$4:$K$4) | P14: =MATCH(MIN(M14:O14),M14:O14,0) | X14: =SUMXMY2(B14:E14,$S$2:$V$2) | Y14: =SUMXMY2(B14:E14,$S$3:$V$3) | Z14: =SUMXMY2(B14:E14,$S$4:$V$4) | AA14: =MATCH(MIN(X14:Z14),X14:Z14,0) | AH14: =IF($AA14=1,$B14,NA()) | AI14: =IF($AA14=1,$C14,NA()) | AJ14: =IF($AA14=2,$B14,NA()) | AK14: =IF($AA14=2,$C14,NA()) | AL14: =IF($AA14=3,$B14,NA()) | AM14: =IF($AA14=3,$C14,NA())
A15: =Scale_PCA_Mechanics!A15 | B15: =Scale_PCA_Mechanics!G15 | C15: =Scale_PCA_Mechanics!H15 | D15: =Scale_PCA_Mechanics!I15 | E15: =Scale_PCA_Mechanics!J15 | M15: =SUMXMY2(B15:E15,$H$2:$K$2) | N15: =SUMXMY2(B15:E15,$H$3:$K$3) | O15: =SUMXMY2(B15:E15,$H$4:$K$4) | P15: =MATCH(MIN(M15:O15),M15:O15,0) | X15: =SUMXMY2(B15:E15,$S$2:$V$2) | Y15: =SUMXMY2(B15:E15,$S$3:$V$3) | Z15: =SUMXMY2(B15:E15,$S$4:$V$4) | AA15: =MATCH(MIN(X15:Z15),X15:Z15,0) | AH15: =IF($AA15=1,$B15,NA()) | AI15: =IF($AA15=1,$C15,NA()) | AJ15: =IF($AA15=2,$B15,NA()) | AK15: =IF($AA15=2,$C15,NA()) | AL15: =IF($AA15=3,$B15,NA()) | AM15: =IF($AA15=3,$C15,NA())
A16: =Scale_PCA_Mechanics!A16 | B16: =Scale_PCA_Mechanics!G16 | C16: =Scale_PCA_Mechanics!H16 | D16: =Scale_PCA_Mechanics!I16 | E16: =Scale_PCA_Mechanics!J16 | M16: =SUMXMY2(B16:E16,$H$2:$K$2) | N16: =SUMXMY2(B16:E16,$H$3:$K$3) | O16: =SUMXMY2(B16:E16,$H$4:$K$4) | P16: =MATCH(MIN(M16:O16),M16:O16,0) | X16: =SUMXMY2(B16:E16,$S$2:$V$2) | Y16: =SUMXMY2(B16:E16,$S$3:$V$3) | Z16: =SUMXMY2(B16:E16,$S$4:$V$4) | AA16: =MATCH(MIN(X16:Z16),X16:Z16,0) | AH16: =IF($AA16=1,$B16,NA()) | AI16: =IF($AA16=1,$C16,NA()) | AJ16: =IF($AA16=2,$B16,NA()) | AK16: =IF($AA16=2,$C16,NA()) | AL16: =IF($AA16=3,$B16,NA()) | AM16: =IF($AA16=3,$C16,NA())
A17: =Scale_PCA_Mechanics!A17 | B17: =Scale_PCA_Mechanics!G17 | C17: =Scale_PCA_Mechanics!H17 | D17: =Scale_PCA_Mechanics!I17 | E17: =Scale_PCA_Mechanics!J17 | M17: =SUMXMY2(B17:E17,$H$2:$K$2) | N17: =SUMXMY2(B17:E17,$H$3:$K$3) | O17: =SUMXMY2(B17:E17,$H$4:$K$4) | P17: =MATCH(MIN(M17:O17),M17:O17,0) | X17: =SUMXMY2(B17:E17,$S$2:$V$2) | Y17: =SUMXMY2(B17:E17,$S$3:$V$3) | Z17: =SUMXMY2(B17:E17,$S$4:$V$4) | AA17: =MATCH(MIN(X17:Z17),X17:Z17,0) | AH17: =IF($AA17=1,$B17,NA()) | AI17: =IF($AA17=1,$C17,NA()) | AJ17: =IF($AA17=2,$B17,NA()) | AK17: =IF($AA17=2,$C17,NA()) | AL17: =IF($AA17=3,$B17,NA()) | AM17: =IF($AA17=3,$C17,NA())
A18: =Scale_PCA_Mechanics!A18 | B18: =Scale_PCA_Mechanics!G18 | C18: =Scale_PCA_Mechanics!H18 | D18: =Scale_PCA_Mechanics!I18 | E18: =Scale_PCA_Mechanics!J18 | M18: =SUMXMY2(B18:E18,$H$2:$K$2) | N18: =SUMXMY2(B18:E18,$H$3:$K$3) | O18: =SUMXMY2(B18:E18,$H$4:$K$4) | P18: =MATCH(MIN(M18:O18),M18:O18,0) | X18: =SUMXMY2(B18:E18,$S$2:$V$2) | Y18: =SUMXMY2(B18:E18,$S$3:$V$3) | Z18: =SUMXMY2(B18:E18,$S$4:$V$4) | AA18: =MATCH(MIN(X18:Z18),X18:Z18,0) | AH18: =IF($AA18=1,$B18,NA()) | AI18: =IF($AA18=1,$C18,NA()) | AJ18: =IF($AA18=2,$B18,NA()) | AK18: =IF($AA18=2,$C18,NA()) | AL18: =IF($AA18=3,$B18,NA()) | AM18: =IF($AA18=3,$C18,NA())
A19: =Scale_PCA_Mechanics!A19 | B19: =Scale_PCA_Mechanics!G19 | C19: =Scale_PCA_Mechanics!H19 | D19: =Scale_PCA_Mechanics!I19 | E19: =Scale_PCA_Mechanics!J19 | M19: =SUMXMY2(B19:E19,$H$2:$K$2) | N19: =SUMXMY2(B19:E19,$H$3:$K$3) | O19: =SUMXMY2(B19:E19,$H$4:$K$4) | P19: =MATCH(MIN(M19:O19),M19:O19,0) | X19: =SUMXMY2(B19:E19,$S$2:$V$2) | Y19: =SUMXMY2(B19:E19,$S$3:$V$3) | Z19: =SUMXMY2(B19:E19,$S$4:$V$4) | AA19: =MATCH(MIN(X19:Z19),X19:Z19,0) | AH19: =IF($AA19=1,$B19,NA()) | AI19: =IF($AA19=1,$C19,NA()) | AJ19: =IF($AA19=2,$B19,NA()) | AK19: =IF($AA19=2,$C19,NA()) | AL19: =IF($AA19=3,$B19,NA()) | AM19: =IF($AA19=3,$C19,NA())
A20: =Scale_PCA_Mechanics!A20 | B20: =Scale_PCA_Mechanics!G20 | C20: =Scale_PCA_Mechanics!H20 | D20: =Scale_PCA_Mechanics!I20 | E20: =Scale_PCA_Mechanics!J20 | M20: =SUMXMY2(B20:E20,$H$2:$K$2) | N20: =SUMXMY2(B20:E20,$H$3:$K$3) | O20: =SUMXMY2(B20:E20,$H$4:$K$4) | P20: =MATCH(MIN(M20:O20),M20:O20,0) | X20: =SUMXMY2(B20:E20,$S$2:$V$2) | Y20: =SUMXMY2(B20:E20,$S$3:$V$3) | Z20: =SUMXMY2(B20:E20,$S$4:$V$4) | AA20: =MATCH(MIN(X20:Z20),X20:Z20,0) | AH20: =IF($AA20=1,$B20,NA()) | AI20: =IF($AA20=1,$C20,NA()) | AJ20: =IF($AA20=2,$B20,NA()) | AK20: =IF($AA20=2,$C20,NA()) | AL20: =IF($AA20=3,$B20,NA()) | AM20: =IF($AA20=3,$C20,NA())
A21: =Scale_PCA_Mechanics!A21 | B21: =Scale_PCA_Mechanics!G21 | C21: =Scale_PCA_Mechanics!H21 | D21: =Scale_PCA_Mechanics!I21 | E21: =Scale_PCA_Mechanics!J21 | M21: =SUMXMY2(B21:E21,$H$2:$K$2) | N21: =SUMXMY2(B21:E21,$H$3:$K$3) | O21: =SUMXMY2(B21:E21,$H$4:$K$4) | P21: =MATCH(MIN(M21:O21),M21:O21,0) | X21: =SUMXMY2(B21:E21,$S$2:$V$2) | Y21: =SUMXMY2(B21:E21,$S$3:$V$3) | Z21: =SUMXMY2(B21:E21,$S$4:$V$4) | AA21: =MATCH(MIN(X21:Z21),X21:Z21,0) | AH21: =IF($AA21=1,$B21,NA()) | AI21: =IF($AA21=1,$C21,NA()) | AJ21: =IF($AA21=2,$B21,NA()) | AK21: =IF($AA21=2,$C21,NA()) | AL21: =IF($AA21=3,$B21,NA()) | AM21: =IF($AA21=3,$C21,NA())
A22: =Scale_PCA_Mechanics!A22 | B22: =Scale_PCA_Mechanics!G22 | C22: =Scale_PCA_Mechanics!H22 | D22: =Scale_PCA_Mechanics!I22 | E22: =Scale_PCA_Mechanics!J22 | M22: =SUMXMY2(B22:E22,$H$2:$K$2) | N22: =SUMXMY2(B22:E22,$H$3:$K$3) | O22: =SUMXMY2(B22:E22,$H$4:$K$4) | P22: =MATCH(MIN(M22:O22),M22:O22,0) | X22: =SUMXMY2(B22:E22,$S$2:$V$2) | Y22: =SUMXMY2(B22:E22,$S$3:$V$3) | Z22: =SUMXMY2(B22:E22,$S$4:$V$4) | AA22: =MATCH(MIN(X22:Z22),X22:Z22,0) | AH22: =IF($AA22=1,$B22,NA()) | AI22: =IF($AA22=1,$C22,NA()) | AJ22: =IF($AA22=2,$B22,NA()) | AK22: =IF($AA22=2,$C22,NA()) | AL22: =IF($AA22=3,$B22,NA()) | AM22: =IF($AA22=3,$C22,NA())
A23: =Scale_PCA_Mechanics!A23 | B23: =Scale_PCA_Mechanics!G23 | C23: =Scale_PCA_Mechanics!H23 | D23: =Scale_PCA_Mechanics!I23 | E23: =Scale_PCA_Mechanics!J23 | M23: =SUMXMY2(B23:E23,$H$2:$K$2) | N23: =SUMXMY2(B23:E23,$H$3:$K$3) | O23: =SUMXMY2(B23:E23,$H$4:$K$4) | P23: =MATCH(MIN(M23:O23),M23:O23,0) | X23: =SUMXMY2(B23:E23,$S$2:$V$2) | Y23: =SUMXMY2(B23:E23,$S$3:$V$3) | Z23: =SUMXMY2(B23:E23,$S$4:$V$4) | AA23: =MATCH(MIN(X23:Z23),X23:Z23,0) | AH23: =IF($AA23=1,$B23,NA()) | AI23: =IF($AA23=1,$C23,NA()) | AJ23: =IF($AA23=2,$B23,NA()) | AK23: =IF($AA23=2,$C23,NA()) | AL23: =IF($AA23=3,$B23,NA()) | AM23: =IF($AA23=3,$C23,NA())
... A51: =Scale_PCA_Mechanics!A51 | B51: =Scale_PCA_Mechanics!G51 | C51: =Scale_PCA_Mechanics!H51 | D51: =Scale_PCA_Mechanics!I51 | E51: =Scale_PCA_Mechanics!J51 | M51: =SUMXMY2(B51:E51,$H$2:$K$2) | N51: =SUMXMY2(B51:E51,$H$3:$K$3) | O51: =SUMXMY2(B51:E51,$H$4:$K$4) | P51: =MATCH(MIN(M51:O51),M51:O51,0) | X51: =SUMXMY2(B51:E51,$S$2:$V$2) | Y51: =SUMXMY2(B51:E51,$S$3:$V$3) | Z51: =SUMXMY2(B51:E51,$S$4:$V$4) | AA51: =MATCH(MIN(X51:Z51),X51:Z51,0) | AH51: =IF($AA51=1,$B51,NA()) | AI51: =IF($AA51=1,$C51,NA()) | AJ51: =IF($AA51=2,$B51,NA()) | AK51: =IF($AA51=2,$C51,NA()) | AL51: =IF($AA51=3,$B51,NA()) | AM51: =IF($AA51=3,$C51,NA())

Sheet Cluster_Summary
A1: cluster | B1: n | C1: Murder_mean | D1: Assault_mean | E1: UrbanPop_mean | F1: Rape_mean
A2: 1 | B2: =COUNTIF(KMeans_6_2!AA2:AA51,A2) | C2: =AVERAGEIFS(Data_USArrests!C2:C51,KMeans_6_2!AA2:AA51,A2) | D2: =AVERAGEIFS(Data_USArrests!D2:D51,KMeans_6_2!AA2:AA51,A2) | E2: =AVERAGEIFS(Data_USArrests!E2:E51,KMeans_6_2!AA2:AA51,A2) | F2: =AVERAGEIFS(Data_USArrests!F2:F51,KMeans_6_2!AA2:AA51,A2)
A3: 2 | B3: =COUNTIF(KMeans_6_2!AA2:AA51,A3) | C3: =AVERAGEIFS(Data_USArrests!C2:C51,KMeans_6_2!AA2:AA51,A3) | D3: =AVERAGEIFS(Data_USArrests!D2:D51,KMeans_6_2!AA2:AA51,A3) | E3: =AVERAGEIFS(Data_USArrests!E2:E51,KMeans_6_2!AA2:AA51,A3) | F3: =AVERAGEIFS(Data_USArrests!F2:F51,KMeans_6_2!AA2:AA51,A3)
A4: 3 | B4: =COUNTIF(KMeans_6_2!AA2:AA51,A4) | C4: =AVERAGEIFS(Data_USArrests!C2:C51,KMeans_6_2!AA2:AA51,A4) | D4: =AVERAGEIFS(Data_USArrests!D2:D51,KMeans_6_2!AA2:AA51,A4) | E4: =AVERAGEIFS(Data_USArrests!E2:E51,KMeans_6_2!AA2:AA51,A4) | F4: =AVERAGEIFS(Data_USArrests!F2:F51,KMeans_6_2!AA2:AA51,A4)

Sheet Distance_HC_Mechanics
A1: id_i | B1: id_j | C1: dist_scaled | D1: cluster_i | E1: cluster_j | H1: closest_pair_distance | J1: linkage_metric | K1: C1-C2 | L1: C1-C3 | M1: C2-C3 | O1: pair12_dist | P1: pair13_dist | Q1: pair23_dist
A2: 1 | B2: 2 | C2: =SQRT((Scale_PCA_Mechanics!G2-Scale_PCA_Mechanics!G3)^2+(Scale_PCA_Mechanics!H2-Scale_PCA_Mechanics!H3)^2+(Scale_PCA_Mechanics!I2-Scale_PCA_Mechanics!I3)^2+(Scale_PCA_Mechanics!J2-Scale_PCA_Mechanics!J3)^2) | D2: =INDEX(KMeans_6_2!AA2:AA51,A2) | E2: =INDEX(KMeans_6_2!AA2:AA51,B2) | H2: =MIN(C2:C1226) | J2: single | K2: =IFERROR(MIN(O2:O1226),"") | L2: =IFERROR(MIN(P2:P1226),"") | M2: =IFERROR(MIN(Q2:Q1226),"") | O2: =IF(OR(AND(D2=1,E2=2),AND(D2=2,E2=1)),C2,"") | P2: =IF(OR(AND(D2=1,E2=3),AND(D2=3,E2=1)),C2,"") | Q2: =IF(OR(AND(D2=2,E2=3),AND(D2=3,E2=2)),C2,"")
A3: 1 | B3: 3 | C3: =SQRT((Scale_PCA_Mechanics!G2-Scale_PCA_Mechanics!G4)^2+(Scale_PCA_Mechanics!H2-Scale_PCA_Mechanics!H4)^2+(Scale_PCA_Mechanics!I2-Scale_PCA_Mechanics!I4)^2+(Scale_PCA_Mechanics!J2-Scale_PCA_Mechanics!J4)^2) | D3: =INDEX(KMeans_6_2!AA2:AA51,A3) | E3: =INDEX(KMeans_6_2!AA2:AA51,B3) | H3: closest_pair_id_i | J3: complete | K3: =IFERROR(MAX(O2:O1226),"") | L3: =IFERROR(MAX(P2:P1226),"") | M3: =IFERROR(MAX(Q2:Q1226),"") | O3: =IF(OR(AND(D3=1,E3=2),AND(D3=2,E3=1)),C3,"") | P3: =IF(OR(AND(D3=1,E3=3),AND(D3=3,E3=1)),C3,"") | Q3: =IF(OR(AND(D3=2,E3=3),AND(D3=3,E3=2)),C3,"")
A4: 1 | B4: 4 | C4: =SQRT((Scale_PCA_Mechanics!G2-Scale_PCA_Mechanics!G5)^2+(Scale_PCA_Mechanics!H2-Scale_PCA_Mechanics!H5)^2+(Scale_PCA_Mechanics!I2-Scale_PCA_Mechanics!I5)^2+(Scale_PCA_Mechanics!J2-Scale_PCA_Mechanics!J5)^2) | D4: =INDEX(KMeans_6_2!AA2:AA51,A4) | E4: =INDEX(KMeans_6_2!AA2:AA51,B4) | H4: =INDEX(A2:A1226,MATCH(H2,C2:C1226,0)) | J4: average | K4: =IFERROR(AVERAGE(O2:O1226),"") | L4: =IFERROR(AVERAGE(P2:P1226),"") | M4: =IFERROR(AVERAGE(Q2:Q1226),"") | O4: =IF(OR(AND(D4=1,E4=2),AND(D4=2,E4=1)),C4,"") | P4: =IF(OR(AND(D4=1,E4=3),AND(D4=3,E4=1)),C4,"") | Q4: =IF(OR(AND(D4=2,E4=3),AND(D4=3,E4=2)),C4,"")
A5: 1 | B5: 5 | C5: =SQRT((Scale_PCA_Mechanics!G2-Scale_PCA_Mechanics!G6)^2+(Scale_PCA_Mechanics!H2-Scale_PCA_Mechanics!H6)^2+(Scale_PCA_Mechanics!I2-Scale_PCA_Mechanics!I6)^2+(Scale_PCA_Mechanics!J2-Scale_PCA_Mechanics!J6)^2) | D5: =INDEX(KMeans_6_2!AA2:AA51,A5) | E5: =INDEX(KMeans_6_2!AA2:AA51,B5) | H5: closest_pair_id_j | O5: =IF(OR(AND(D5=1,E5=2),AND(D5=2,E5=1)),C5,"") | P5: =IF(OR(AND(D5=1,E5=3),AND(D5=3,E5=1)),C5,"") | Q5: =IF(OR(AND(D5=2,E5=3),AND(D5=3,E5=2)),C5,"")
A6: 1 | B6: 6 | C6: =SQRT((Scale_PCA_Mechanics!G2-Scale_PCA_Mechanics!G7)^2+(Scale_PCA_Mechanics!H2-Scale_PCA_Mechanics!H7)^2+(Scale_PCA_Mechanics!I2-Scale_PCA_Mechanics!I7)^2+(Scale_PCA_Mechanics!J2-Scale_PCA_Mechanics!J7)^2) | D6: =INDEX(KMeans_6_2!AA2:AA51,A6) | E6: =INDEX(KMeans_6_2!AA2:AA51,B6) | H6: =INDEX(B2:B1226,MATCH(H2,C2:C1226,0)) | O6: =IF(OR(AND(D6=1,E6=2),AND(D6=2,E6=1)),C6,"") | P6: =IF(OR(AND(D6=1,E6=3),AND(D6=3,E6=1)),C6,"") | Q6: =IF(OR(AND(D6=2,E6=3),AND(D6=3,E6=2)),C6,"")
A7: 1 | B7: 7 | C7: =SQRT((Scale_PCA_Mechanics!G2-Scale_PCA_Mechanics!G8)^2+(Scale_PCA_Mechanics!H2-Scale_PCA_Mechanics!H8)^2+(Scale_PCA_Mechanics!I2-Scale_PCA_Mechanics!I8)^2+(Scale_PCA_Mechanics!J2-Scale_PCA_Mechanics!J8)^2) | D7: =INDEX(KMeans_6_2!AA2:AA51,A7) | E7: =INDEX(KMeans_6_2!AA2:AA51,B7) | O7: =IF(OR(AND(D7=1,E7=2),AND(D7=2,E7=1)),C7,"") | P7: =IF(OR(AND(D7=1,E7=3),AND(D7=3,E7=1)),C7,"") | Q7: =IF(OR(AND(D7=2,E7=3),AND(D7=3,E7=2)),C7,"")
A8: 1 | B8: 8 | C8: =SQRT((Scale_PCA_Mechanics!G2-Scale_PCA_Mechanics!G9)^2+(Scale_PCA_Mechanics!H2-Scale_PCA_Mechanics!H9)^2+(Scale_PCA_Mechanics!I2-Scale_PCA_Mechanics!I9)^2+(Scale_PCA_Mechanics!J2-Scale_PCA_Mechanics!J9)^2) | D8: =INDEX(KMeans_6_2!AA2:AA51,A8) | E8: =INDEX(KMeans_6_2!AA2:AA51,B8) | O8: =IF(OR(AND(D8=1,E8=2),AND(D8=2,E8=1)),C8,"") | P8: =IF(OR(AND(D8=1,E8=3),AND(D8=3,E8=1)),C8,"") | Q8: =IF(OR(AND(D8=2,E8=3),AND(D8=3,E8=2)),C8,"")
A9: 1 | B9: 9 | C9: =SQRT((Scale_PCA_Mechanics!G2-Scale_PCA_Mechanics!G10)^2+(Scale_PCA_Mechanics!H2-Scale_PCA_Mechanics!H10)^2+(Scale_PCA_Mechanics!I2-Scale_PCA_Mechanics!I10)^2+(Scale_PCA_Mechanics!J2-Scale_PCA_Mechanics!J10)^2) | D9: =INDEX(KMeans_6_2!AA2:AA51,A9) | E9: =INDEX(KMeans_6_2!AA2:AA51,B9) | O9: =IF(OR(AND(D9=1,E9=2),AND(D9=2,E9=1)),C9,"") | P9: =IF(OR(AND(D9=1,E9=3),AND(D9=3,E9=1)),C9,"") | Q9: =IF(OR(AND(D9=2,E9=3),AND(D9=3,E9=2)),C9,"")
A10: 1 | B10: 10 | C10: =SQRT((Scale_PCA_Mechanics!G2-Scale_PCA_Mechanics!G11)^2+(Scale_PCA_Mechanics!H2-Scale_PCA_Mechanics!H11)^2+(Scale_PCA_Mechanics!I2-Scale_PCA_Mechanics!I11)^2+(Scale_PCA_Mechanics!J2-Scale_PCA_Mechanics!J11)^2) | D10: =INDEX(KMeans_6_2!AA2:AA51,A10) | E10: =INDEX(KMeans_6_2!AA2:AA51,B10) | O10: =IF(OR(AND(D10=1,E10=2),AND(D10=2,E10=1)),C10,"") | P10: =IF(OR(AND(D10=1,E10=3),AND(D10=3,E10=1)),C10,"") | Q10: =IF(OR(AND(D10=2,E10=3),AND(D10=3,E10=2)),C10,"")
A11: 1 | B11: 11 | C11: =SQRT((Scale_PCA_Mechanics!G2-Scale_PCA_Mechanics!G12)^2+(Scale_PCA_Mechanics!H2-Scale_PCA_Mechanics!H12)^2+(Scale_PCA_Mechanics!I2-Scale_PCA_Mechanics!I12)^2+(Scale_PCA_Mechanics!J2-Scale_PCA_Mechanics!J12)^2) | D11: =INDEX(KMeans_6_2!AA2:AA51,A11) | E11: =INDEX(KMeans_6_2!AA2:AA51,B11) | O11: =IF(OR(AND(D11=1,E11=2),AND(D11=2,E11=1)),C11,"") | P11: =IF(OR(AND(D11=1,E11=3),AND(D11=3,E11=1)),C11,"") | Q11: =IF(OR(AND(D11=2,E11=3),AND(D11=3,E11=2)),C11,"")
A12: 1 | B12: 12 | C12: =SQRT((Scale_PCA_Mechanics!G2-Scale_PCA_Mechanics!G13)^2+(Scale_PCA_Mechanics!H2-Scale_PCA_Mechanics!H13)^2+(Scale_PCA_Mechanics!I2-Scale_PCA_Mechanics!I13)^2+(Scale_PCA_Mechanics!J2-Scale_PCA_Mechanics!J13)^2) | D12: =INDEX(KMeans_6_2!AA2:AA51,A12) | E12: =INDEX(KMeans_6_2!AA2:AA51,B12) | O12: =IF(OR(AND(D12=1,E12=2),AND(D12=2,E12=1)),C12,"") | P12: =IF(OR(AND(D12=1,E12=3),AND(D12=3,E12=1)),C12,"") | Q12: =IF(OR(AND(D12=2,E12=3),AND(D12=3,E12=2)),C12,"")
A13: 1 | B13: 13 | C13: =SQRT((Scale_PCA_Mechanics!G2-Scale_PCA_Mechanics!G14)^2+(Scale_PCA_Mechanics!H2-Scale_PCA_Mechanics!H14)^2+(Scale_PCA_Mechanics!I2-Scale_PCA_Mechanics!I14)^2+(Scale_PCA_Mechanics!J2-Scale_PCA_Mechanics!J14)^2) | D13: =INDEX(KMeans_6_2!AA2:AA51,A13) | E13: =INDEX(KMeans_6_2!AA2:AA51,B13) | O13: =IF(OR(AND(D13=1,E13=2),AND(D13=2,E13=1)),C13,"") | P13: =IF(OR(AND(D13=1,E13=3),AND(D13=3,E13=1)),C13,"") | Q13: =IF(OR(AND(D13=2,E13=3),AND(D13=3,E13=2)),C13,"")
A14: 1 | B14: 14 | C14: =SQRT((Scale_PCA_Mechanics!G2-Scale_PCA_Mechanics!G15)^2+(Scale_PCA_Mechanics!H2-Scale_PCA_Mechanics!H15)^2+(Scale_PCA_Mechanics!I2-Scale_PCA_Mechanics!I15)^2+(Scale_PCA_Mechanics!J2-Scale_PCA_Mechanics!J15)^2) | D14: =INDEX(KMeans_6_2!AA2:AA51,A14) | E14: =INDEX(KMeans_6_2!AA2:AA51,B14) | O14: =IF(OR(AND(D14=1,E14=2),AND(D14=2,E14=1)),C14,"") | P14: =IF(OR(AND(D14=1,E14=3),AND(D14=3,E14=1)),C14,"") | Q14: =IF(OR(AND(D14=2,E14=3),AND(D14=3,E14=2)),C14,"")
A15: 1 | B15: 15 | C15: =SQRT((Scale_PCA_Mechanics!G2-Scale_PCA_Mechanics!G16)^2+(Scale_PCA_Mechanics!H2-Scale_PCA_Mechanics!H16)^2+(Scale_PCA_Mechanics!I2-Scale_PCA_Mechanics!I16)^2+(Scale_PCA_Mechanics!J2-Scale_PCA_Mechanics!J16)^2) | D15: =INDEX(KMeans_6_2!AA2:AA51,A15) | E15: =INDEX(KMeans_6_2!AA2:AA51,B15) | O15: =IF(OR(AND(D15=1,E15=2),AND(D15=2,E15=1)),C15,"") | P15: =IF(OR(AND(D15=1,E15=3),AND(D15=3,E15=1)),C15,"") | Q15: =IF(OR(AND(D15=2,E15=3),AND(D15=3,E15=2)),C15,"")
A16: 1 | B16: 16 | C16: =SQRT((Scale_PCA_Mechanics!G2-Scale_PCA_Mechanics!G17)^2+(Scale_PCA_Mechanics!H2-Scale_PCA_Mechanics!H17)^2+(Scale_PCA_Mechanics!I2-Scale_PCA_Mechanics!I17)^2+(Scale_PCA_Mechanics!J2-Scale_PCA_Mechanics!J17)^2) | D16: =INDEX(KMeans_6_2!AA2:AA51,A16) | E16: =INDEX(KMeans_6_2!AA2:AA51,B16) | O16: =IF(OR(AND(D16=1,E16=2),AND(D16=2,E16=1)),C16,"") | P16: =IF(OR(AND(D16=1,E16=3),AND(D16=3,E16=1)),C16,"") | Q16: =IF(OR(AND(D16=2,E16=3),AND(D16=3,E16=2)),C16,"")
A17: 1 | B17: 17 | C17: =SQRT((Scale_PCA_Mechanics!G2-Scale_PCA_Mechanics!G18)^2+(Scale_PCA_Mechanics!H2-Scale_PCA_Mechanics!H18)^2+(Scale_PCA_Mechanics!I2-Scale_PCA_Mechanics!I18)^2+(Scale_PCA_Mechanics!J2-Scale_PCA_Mechanics!J18)^2) | D17: =INDEX(KMeans_6_2!AA2:AA51,A17) | E17: =INDEX(KMeans_6_2!AA2:AA51,B17) | O17: =IF(OR(AND(D17=1,E17=2),AND(D17=2,E17=1)),C17,"") | P17: =IF(OR(AND(D17=1,E17=3),AND(D17=3,E17=1)),C17,"") | Q17: =IF(OR(AND(D17=2,E17=3),AND(D17=3,E17=2)),C17,"")
A18: 1 | B18: 18 | C18: =SQRT((Scale_PCA_Mechanics!G2-Scale_PCA_Mechanics!G19)^2+(Scale_PCA_Mechanics!H2-Scale_PCA_Mechanics!H19)^2+(Scale_PCA_Mechanics!I2-Scale_PCA_Mechanics!I19)^2+(Scale_PCA_Mechanics!J2-Scale_PCA_Mechanics!J19)^2) | D18: =INDEX(KMeans_6_2!AA2:AA51,A18) | E18: =INDEX(KMeans_6_2!AA2:AA51,B18) | O18: =IF(OR(AND(D18=1,E18=2),AND(D18=2,E18=1)),C18,"") | P18: =IF(OR(AND(D18=1,E18=3),AND(D18=3,E18=1)),C18,"") | Q18: =IF(OR(AND(D18=2,E18=3),AND(D18=3,E18=2)),C18,"")
A19: 1 | B19: 19 | C19: =SQRT((Scale_PCA_Mechanics!G2-Scale_PCA_Mechanics!G20)^2+(Scale_PCA_Mechanics!H2-Scale_PCA_Mechanics!H20)^2+(Scale_PCA_Mechanics!I2-Scale_PCA_Mechanics!I20)^2+(Scale_PCA_Mechanics!J2-Scale_PCA_Mechanics!J20)^2) | D19: =INDEX(KMeans_6_2!AA2:AA51,A19) | E19: =INDEX(KMeans_6_2!AA2:AA51,B19) | O19: =IF(OR(AND(D19=1,E19=2),AND(D19=2,E19=1)),C19,"") | P19: =IF(OR(AND(D19=1,E19=3),AND(D19=3,E19=1)),C19,"") | Q19: =IF(OR(AND(D19=2,E19=3),AND(D19=3,E19=2)),C19,"")
A20: 1 | B20: 20 | C20: =SQRT((Scale_PCA_Mechanics!G2-Scale_PCA_Mechanics!G21)^2+(Scale_PCA_Mechanics!H2-Scale_PCA_Mechanics!H21)^2+(Scale_PCA_Mechanics!I2-Scale_PCA_Mechanics!I21)^2+(Scale_PCA_Mechanics!J2-Scale_PCA_Mechanics!J21)^2) | D20: =INDEX(KMeans_6_2!AA2:AA51,A20) | E20: =INDEX(KMeans_6_2!AA2:AA51,B20) | O20: =IF(OR(AND(D20=1,E20=2),AND(D20=2,E20=1)),C20,"") | P20: =IF(OR(AND(D20=1,E20=3),AND(D20=3,E20=1)),C20,"") | Q20: =IF(OR(AND(D20=2,E20=3),AND(D20=3,E20=2)),C20,"")
A21: 1 | B21: 21 | C21: =SQRT((Scale_PCA_Mechanics!G2-Scale_PCA_Mechanics!G22)^2+(Scale_PCA_Mechanics!H2-Scale_PCA_Mechanics!H22)^2+(Scale_PCA_Mechanics!I2-Scale_PCA_Mechanics!I22)^2+(Scale_PCA_Mechanics!J2-Scale_PCA_Mechanics!J22)^2) | D21: =INDEX(KMeans_6_2!AA2:AA51,A21) | E21: =INDEX(KMeans_6_2!AA2:AA51,B21) | O21: =IF(OR(AND(D21=1,E21=2),AND(D21=2,E21=1)),C21,"") | P21: =IF(OR(AND(D21=1,E21=3),AND(D21=3,E21=1)),C21,"") | Q21: =IF(OR(AND(D21=2,E21=3),AND(D21=3,E21=2)),C21,"")
A22: 1 | B22: 22 | C22: =SQRT((Scale_PCA_Mechanics!G2-Scale_PCA_Mechanics!G23)^2+(Scale_PCA_Mechanics!H2-Scale_PCA_Mechanics!H23)^2+(Scale_PCA_Mechanics!I2-Scale_PCA_Mechanics!I23)^2+(Scale_PCA_Mechanics!J2-Scale_PCA_Mechanics!J23)^2) | D22: =INDEX(KMeans_6_2!AA2:AA51,A22) | E22: =INDEX(KMeans_6_2!AA2:AA51,B22) | O22: =IF(OR(AND(D22=1,E22=2),AND(D22=2,E22=1)),C22,"") | P22: =IF(OR(AND(D22=1,E22=3),AND(D22=3,E22=1)),C22,"") | Q22: =IF(OR(AND(D22=2,E22=3),AND(D22=3,E22=2)),C22,"")
A23: 1 | B23: 23 | C23: =SQRT((Scale_PCA_Mechanics!G2-Scale_PCA_Mechanics!G24)^2+(Scale_PCA_Mechanics!H2-Scale_PCA_Mechanics!H24)^2+(Scale_PCA_Mechanics!I2-Scale_PCA_Mechanics!I24)^2+(Scale_PCA_Mechanics!J2-Scale_PCA_Mechanics!J24)^2) | D23: =INDEX(KMeans_6_2!AA2:AA51,A23) | E23: =INDEX(KMeans_6_2!AA2:AA51,B23) | O23: =IF(OR(AND(D23=1,E23=2),AND(D23=2,E23=1)),C23,"") | P23: =IF(OR(AND(D23=1,E23=3),AND(D23=3,E23=1)),C23,"") | Q23: =IF(OR(AND(D23=2,E23=3),AND(D23=3,E23=2)),C23,"")
A24: 1 | B24: 24 | C24: =SQRT((Scale_PCA_Mechanics!G2-Scale_PCA_Mechanics!G25)^2+(Scale_PCA_Mechanics!H2-Scale_PCA_Mechanics!H25)^2+(Scale_PCA_Mechanics!I2-Scale_PCA_Mechanics!I25)^2+(Scale_PCA_Mechanics!J2-Scale_PCA_Mechanics!J25)^2) | D24: =INDEX(KMeans_6_2!AA2:AA51,A24) | E24: =INDEX(KMeans_6_2!AA2:AA51,B24) | O24: =IF(OR(AND(D24=1,E24=2),AND(D24=2,E24=1)),C24,"") | P24: =IF(OR(AND(D24=1,E24=3),AND(D24=3,E24=1)),C24,"") | Q24: =IF(OR(AND(D24=2,E24=3),AND(D24=3,E24=2)),C24,"")
A25: 1 | B25: 25 | C25: =SQRT((Scale_PCA_Mechanics!G2-Scale_PCA_Mechanics!G26)^2+(Scale_PCA_Mechanics!H2-Scale_PCA_Mechanics!H26)^2+(Scale_PCA_Mechanics!I2-Scale_PCA_Mechanics!I26)^2+(Scale_PCA_Mechanics!J2-Scale_PCA_Mechanics!J26)^2) | D25: =INDEX(KMeans_6_2!AA2:AA51,A25) | E25: =INDEX(KMeans_6_2!AA2:AA51,B25) | O25: =IF(OR(AND(D25=1,E25=2),AND(D25=2,E25=1)),C25,"") | P25: =IF(OR(AND(D25=1,E25=3),AND(D25=3,E25=1)),C25,"") | Q25: =IF(OR(AND(D25=2,E25=3),AND(D25=3,E25=2)),C25,"")
A26: 1 | B26: 26 | C26: =SQRT((Scale_PCA_Mechanics!G2-Scale_PCA_Mechanics!G27)^2+(Scale_PCA_Mechanics!H2-Scale_PCA_Mechanics!H27)^2+(Scale_PCA_Mechanics!I2-Scale_PCA_Mechanics!I27)^2+(Scale_PCA_Mechanics!J2-Scale_PCA_Mechanics!J27)^2) | D26: =INDEX(KMeans_6_2!AA2:AA51,A26) | E26: =INDEX(KMeans_6_2!AA2:AA51,B26) | O26: =IF(OR(AND(D26=1,E26=2),AND(D26=2,E26=1)),C26,"") | P26: =IF(OR(AND(D26=1,E26=3),AND(D26=3,E26=1)),C26,"") | Q26: =IF(OR(AND(D26=2,E26=3),AND(D26=3,E26=2)),C26,"")
A27: 1 | B27: 27 | C27: =SQRT((Scale_PCA_Mechanics!G2-Scale_PCA_Mechanics!G28)^2+(Scale_PCA_Mechanics!H2-Scale_PCA_Mechanics!H28)^2+(Scale_PCA_Mechanics!I2-Scale_PCA_Mechanics!I28)^2+(Scale_PCA_Mechanics!J2-Scale_PCA_Mechanics!J28)^2) | D27: =INDEX(KMeans_6_2!AA2:AA51,A27) | E27: =INDEX(KMeans_6_2!AA2:AA51,B27) | O27: =IF(OR(AND(D27=1,E27=2),AND(D27=2,E27=1)),C27,"") | P27: =IF(OR(AND(D27=1,E27=3),AND(D27=3,E27=1)),C27,"") | Q27: =IF(OR(AND(D27=2,E27=3),AND(D27=3,E27=2)),C27,"")
A28: 1 | B28: 28 | C28: =SQRT((Scale_PCA_Mechanics!G2-Scale_PCA_Mechanics!G29)^2+(Scale_PCA_Mechanics!H2-Scale_PCA_Mechanics!H29)^2+(Scale_PCA_Mechanics!I2-Scale_PCA_Mechanics!I29)^2+(Scale_PCA_Mechanics!J2-Scale_PCA_Mechanics!J29)^2) | D28: =INDEX(KMeans_6_2!AA2:AA51,A28) | E28: =INDEX(KMeans_6_2!AA2:AA51,B28) | O28: =IF(OR(AND(D28=1,E28=2),AND(D28=2,E28=1)),C28,"") | P28: =IF(OR(AND(D28=1,E28=3),AND(D28=3,E28=1)),C28,"") | Q28: =IF(OR(AND(D28=2,E28=3),AND(D28=3,E28=2)),C28,"")
A29: 1 | B29: 29 | C29: =SQRT((Scale_PCA_Mechanics!G2-Scale_PCA_Mechanics!G30)^2+(Scale_PCA_Mechanics!H2-Scale_PCA_Mechanics!H30)^2+(Scale_PCA_Mechanics!I2-Scale_PCA_Mechanics!I30)^2+(Scale_PCA_Mechanics!J2-Scale_PCA_Mechanics!J30)^2) | D29: =INDEX(KMeans_6_2!AA2:AA51,A29) | E29: =INDEX(KMeans_6_2!AA2:AA51,B29) | O29: =IF(OR(AND(D29=1,E29=2),AND(D29=2,E29=1)),C29,"") | P29: =IF(OR(AND(D29=1,E29=3),AND(D29=3,E29=1)),C29,"") | Q29: =IF(OR(AND(D29=2,E29=3),AND(D29=3,E29=2)),C29,"")
A30: 1 | B30: 30 | C30: =SQRT((Scale_PCA_Mechanics!G2-Scale_PCA_Mechanics!G31)^2+(Scale_PCA_Mechanics!H2-Scale_PCA_Mechanics!H31)^2+(Scale_PCA_Mechanics!I2-Scale_PCA_Mechanics!I31)^2+(Scale_PCA_Mechanics!J2-Scale_PCA_Mechanics!J31)^2) | D30: =INDEX(KMeans_6_2!AA2:AA51,A30) | E30: =INDEX(KMeans_6_2!AA2:AA51,B30) | O30: =IF(OR(AND(D30=1,E30=2),AND(D30=2,E30=1)),C30,"") | P30: =IF(OR(AND(D30=1,E30=3),AND(D30=3,E30=1)),C30,"") | Q30: =IF(OR(AND(D30=2,E30=3),AND(D30=3,E30=2)),C30,"")
A31: 1 | B31: 31 | C31: =SQRT((Scale_PCA_Mechanics!G2-Scale_PCA_Mechanics!G32)^2+(Scale_PCA_Mechanics!H2-Scale_PCA_Mechanics!H32)^2+(Scale_PCA_Mechanics!I2-Scale_PCA_Mechanics!I32)^2+(Scale_PCA_Mechanics!J2-Scale_PCA_Mechanics!J32)^2) | D31: =INDEX(KMeans_6_2!AA2:AA51,A31) | E31: =INDEX(KMeans_6_2!AA2:AA51,B31) | O31: =IF(OR(AND(D31=1,E31=2),AND(D31=2,E31=1)),C31,"") | P31: =IF(OR(AND(D31=1,E31=3),AND(D31=3,E31=1)),C31,"") | Q31: =IF(OR(AND(D31=2,E31=3),AND(D31=3,E31=2)),C31,"")
A32: 1 | B32: 32 | C32: =SQRT((Scale_PCA_Mechanics!G2-Scale_PCA_Mechanics!G33)^2+(Scale_PCA_Mechanics!H2-Scale_PCA_Mechanics!H33)^2+(Scale_PCA_Mechanics!I2-Scale_PCA_Mechanics!I33)^2+(Scale_PCA_Mechanics!J2-Scale_PCA_Mechanics!J33)^2) | D32: =INDEX(KMeans_6_2!AA2:AA51,A32) | E32: =INDEX(KMeans_6_2!AA2:AA51,B32) | O32: =IF(OR(AND(D32=1,E32=2),AND(D32=2,E32=1)),C32,"") | P32: =IF(OR(AND(D32=1,E32=3),AND(D32=3,E32=1)),C32,"") | Q32: =IF(OR(AND(D32=2,E32=3),AND(D32=3,E32=2)),C32,"")
A33: 1 | B33: 33 | C33: =SQRT((Scale_PCA_Mechanics!G2-Scale_PCA_Mechanics!G34)^2+(Scale_PCA_Mechanics!H2-Scale_PCA_Mechanics!H34)^2+(Scale_PCA_Mechanics!I2-Scale_PCA_Mechanics!I34)^2+(Scale_PCA_Mechanics!J2-Scale_PCA_Mechanics!J34)^2) | D33: =INDEX(KMeans_6_2!AA2:AA51,A33) | E33: =INDEX(KMeans_6_2!AA2:AA51,B33) | O33: =IF(OR(AND(D33=1,E33=2),AND(D33=2,E33=1)),C33,"") | P33: =IF(OR(AND(D33=1,E33=3),AND(D33=3,E33=1)),C33,"") | Q33: =IF(OR(AND(D33=2,E33=3),AND(D33=3,E33=2)),C33,"")
A34: 1 | B34: 34 | C34: =SQRT((Scale_PCA_Mechanics!G2-Scale_PCA_Mechanics!G35)^2+(Scale_PCA_Mechanics!H2-Scale_PCA_Mechanics!H35)^2+(Scale_PCA_Mechanics!I2-Scale_PCA_Mechanics!I35)^2+(Scale_PCA_Mechanics!J2-Scale_PCA_Mechanics!J35)^2) | D34: =INDEX(KMeans_6_2!AA2:AA51,A34) | E34: =INDEX(KMeans_6_2!AA2:AA51,B34) | O34: =IF(OR(AND(D34=1,E34=2),AND(D34=2,E34=1)),C34,"") | P34: =IF(OR(AND(D34=1,E34=3),AND(D34=3,E34=1)),C34,"") | Q34: =IF(OR(AND(D34=2,E34=3),AND(D34=3,E34=2)),C34,"")
A35: 1 | B35: 35 | C35: =SQRT((Scale_PCA_Mechanics!G2-Scale_PCA_Mechanics!G36)^2+(Scale_PCA_Mechanics!H2-Scale_PCA_Mechanics!H36)^2+(Scale_PCA_Mechanics!I2-Scale_PCA_Mechanics!I36)^2+(Scale_PCA_Mechanics!J2-Scale_PCA_Mechanics!J36)^2) | D35: =INDEX(KMeans_6_2!AA2:AA51,A35) | E35: =INDEX(KMeans_6_2!AA2:AA51,B35) | O35: =IF(OR(AND(D35=1,E35=2),AND(D35=2,E35=1)),C35,"") | P35: =IF(OR(AND(D35=1,E35=3),AND(D35=3,E35=1)),C35,"") | Q35: =IF(OR(AND(D35=2,E35=3),AND(D35=3,E35=2)),C35,"")
A36: 1 | B36: 36 | C36: =SQRT((Scale_PCA_Mechanics!G2-Scale_PCA_Mechanics!G37)^2+(Scale_PCA_Mechanics!H2-Scale_PCA_Mechanics!H37)^2+(Scale_PCA_Mechanics!I2-Scale_PCA_Mechanics!I37)^2+(Scale_PCA_Mechanics!J2-Scale_PCA_Mechanics!J37)^2) | D36: =INDEX(KMeans_6_2!AA2:AA51,A36) | E36: =INDEX(KMeans_6_2!AA2:AA51,B36) | O36: =IF(OR(AND(D36=1,E36=2),AND(D36=2,E36=1)),C36,"") | P36: =IF(OR(AND(D36=1,E36=3),AND(D36=3,E36=1)),C36,"") | Q36: =IF(OR(AND(D36=2,E36=3),AND(D36=3,E36=2)),C36,"")
