Workbook

Sheet README
A1: sheet | B1: purpose
A2: Controls | B2: Global parameters used by all mechanics formulas.
A3: Data | B3: Wage subset with wage_flag and train/test split.
A4: Transform_Tree | B4: Chunk 4 mechanics: wage vs sqrt(wage) stump split on age.
A5: ClassTree | B5: Chunks 5, 8, 9, 14 mechanics: class tree, confusion matrix.
A6: ROC_Mechanics | B6: Chunk 15 mechanics: threshold sweep and ROC points from class probabilities.
A7: RF_Mechanics | B7: Chunks 19-23 mechanics: per-tree class votes and majority prediction.
A8: Boosting_Lite | B8: Chunk 26-27 style additive stage logic (formula-only approximation).
A9: CP_Pruning_Mechanics | B9: cp, xerror, and pruning pick mechanics tied to tree variants.
A10: RF_CV_Tuning | B10: Repeated CV + downsampling + mtry/ntree tuning grid mechanics.
A11: RF_Importance_PDP | B11: Variable-importance proxies and PDP-style views.
A12: XGB_Mechanics | B12: xgbTree-style tuning grid and prediction mechanics.
A13: Summary | B13: Key metrics pulled from all mechanics tabs.

Sheet Controls
A1: wage_high_cutoff | B1: 100
A2: classification_threshold | B2: 0.5
A3: rf_visible_trees | B3: 25
A4: boosting_stages | B4: 12
A5: boosting_learning_rate | B5: 0.2
A6: note | B6: Workbook is formula-first mechanics, not a full package replication.
A7: cp_alpha_override (optional)

Sheet Data
A1: id | B1: year | C1: age | D1: maritl | E1: maritl_collapsed | F1: race | G1: education | H1: jobclass | I1: health | J1: health_ins | K1: wage | L1: wage_flag | M1: set
A2: 1 | B2: 2006 | C2: 18 | D2: 1. Never Married | E2: 1. Never Married | F2: 1. White | G2: 1. < HS Grad | H2: 1. Industrial | I2: 1. <=Good | J2: 2. No | K2: 75.043154 | L2: 0 | M2: Train
A3: 2 | B3: 2004 | C3: 24 | D3: 1. Never Married | E3: 1. Never Married | F3: 1. White | G3: 4. College Grad | H3: 2. Information | I3: 2. >=Very Good | J3: 2. No | K3: 70.47602 | L3: 0 | M3: Train
A4: 3 | B4: 2003 | C4: 45 | D4: 2. Married | E4: 2. Married | F4: 1. White | G4: 3. Some College | H4: 1. Industrial | I4: 1. <=Good | J4: 1. Yes | K4: 130.98218 | L4: 1 | M4: Train
A5: 4 | B5: 2003 | C5: 43 | D5: 2. Married | E5: 2. Married | F5: 3. Asian | G5: 4. College Grad | H5: 2. Information | I5: 2. >=Very Good | J5: 1. Yes | K5: 154.68529 | L5: 1 | M5: Train
A6: 5 | B6: 2005 | C6: 50 | D6: 4. Divorced | E6: 3. Other | F6: 1. White | G6: 2. HS Grad | H6: 2. Information | I6: 1. <=Good | J6: 1. Yes | K6: 75.043154 | L6: 0 | M6: Train
A7: 6 | B7: 2008 | C7: 54 | D7: 2. Married | E7: 2. Married | F7: 1. White | G7: 4. College Grad | H7: 2. Information | I7: 2. >=Very Good | J7: 1. Yes | K7: 127.11574 | L7: 1 | M7: Train
A8: 7 | B8: 2009 | C8: 44 | D8: 2. Married | E8: 2. Married | F8: 4. Other | G8: 3. Some College | H8: 1. Industrial | I8: 2. >=Very Good | J8: 1. Yes | K8: 169.52854 | L8: 1 | M8: Train
A9: 8 | B9: 2008 | C9: 30 | D9: 1. Never Married | E9: 1. Never Married | F9: 3. Asian | G9: 3. Some College | H9: 2. Information | I9: 1. <=Good | J9: 1. Yes | K9: 111.72085 | L9: 1 | M9: Train
A10: 9 | B10: 2006 | C10: 41 | D10: 1. Never Married | E10: 1. Never Married | F10: 2. Black | G10: 3. Some College | H10: 2. Information | I10: 2. >=Very Good | J10: 1. Yes | K10: 118.88436 | L10: 1 | M10: Train
A11: 10 | B11: 2004 | C11: 52 | D11: 2. Married | E11: 2. Married | F11: 1. White | G11: 2. HS Grad | H11: 2. Information | I11: 2. >=Very Good | J11: 1. Yes | K11: 128.68049 | L11: 1 | M11: Train
A12: 11 | B12: 2007 | C12: 45 | D12: 4. Divorced | E12: 3. Other | F12: 1. White | G12: 3. Some College | H12: 2. Information | I12: 1. <=Good | J12: 1. Yes | K12: 117.14682 | L12: 1 | M12: Train
A13: 12 | B13: 2007 | C13: 34 | D13: 2. Married | E13: 2. Married | F13: 1. White | G13: 2. HS Grad | H13: 1. Industrial | I13: 2. >=Very Good | J13: 2. No | K13: 81.283253 | L13: 0 | M13: Train
... A301: 300 | B301: 2009 | C301: 52 | D301: 5. Separated | E301: 3. Other | F301: 2. Black | G301: 2. HS Grad | H301: 1. Industrial | I301: 2. >=Very Good | J301: 1. Yes | K301: 87.981033 | L301: 0 | M301: Test

Sheet Transform_Tree
A1: age_threshold | B1: left_n | C1: left_mean_wage | D1: right_n | E1: right_mean_wage | F1: sse_wage | G1: left_mean_sqrtwage | H1: right_mean_sqrtwage | I1: sse_sqrtwage | J1: valid_split | K1: valid_sse_wage | L1: valid_sse_sqrt | N1: best_threshold_wage
A2: =Data!C2 -> 18 | B2: =COUNTIF(Data!$C$2:$C$301,"<="&A2) -> 2 | C2: =IF(B2=0,0,AVERAGEIF(Data!$C$2:$C$301,"<="&A2,Data!$K$2:$K$301)) -> 72.759587 | D2: =COUNTIF(Data!$C$2:$C$301,">"&A2) -> 298 | E2: =IF(D2=0,0,AVERAGEIF(Data!$C$2:$C$301,">"&A2,Data!$K$2:$K$301)) -> 110.49152 | F2: =SUMPRODUCT(--(Data!$C$2:$C$301<=A2),(Data!$K$2:$K$301-C2)^2)+SUMPRODUCT(--(Data!$C$2:$C$301>A2),(Data!$K$2:$K$301-E2)^2) -> 534445.49 | G2: =IF(B2=0,0,SUMPRODUCT(--(Data!$C$2:$C$301<=A2),SQRT(Data!$K$2:$K$301))/B2) -> 8.5288724 | H2: =IF(D2=0,0,SUMPRODUCT(--(Data!$C$2:$C$301>A2),SQRT(Data!$K$2:$K$301))/D2) -> 10.339827 | I2: =SUMPRODUCT(--(Data!$C$2:$C$301<=A2),(SQRT(Data!$K$2:$K$301)-G2)^2)+SUMPRODUCT(--(Data!$C$2:$C$301>A2),(SQRT(Data!$K$2:$K$301)-H2)^2) -> 1066.728 | J2: =IF(AND(B2>0,D2>0),1,0) -> 1 | K2: =IF(J2=1,F2,1E+99) -> 534445.49 | L2: =IF(J2=1,I2,1E+99) -> 1066.728 | N2: =INDEX(A2:A251,MATCH(MIN(K2:K251),K2:K251,0)) -> 34
A3: =Data!C3 -> 24 | B3: =COUNTIF(Data!$C$2:$C$301,"<="&A3) -> 16 | C3: =IF(B3=0,0,AVERAGEIF(Data!$C$2:$C$301,"<="&A3,Data!$K$2:$K$301)) -> 64.145616 | D3: =COUNTIF(Data!$C$2:$C$301,">"&A3) -> 284 | E3: =IF(D3=0,0,AVERAGEIF(Data!$C$2:$C$301,">"&A3,Data!$K$2:$K$301)) -> 112.83684 | F3: =SUMPRODUCT(--(Data!$C$2:$C$301<=A3),(Data!$K$2:$K$301-C3)^2)+SUMPRODUCT(--(Data!$C$2:$C$301>A3),(Data!$K$2:$K$301-E3)^2) -> 501363.65 | G3: =IF(B3=0,0,SUMPRODUCT(--(Data!$C$2:$C$301<=A3),SQRT(Data!$K$2:$K$301))/B3) -> 7.9418889 | H3: =IF(D3=0,0,SUMPRODUCT(--(Data!$C$2:$C$301>A3),SQRT(Data!$K$2:$K$301))/D3) -> 10.462169 | I3: =SUMPRODUCT(--(Data!$C$2:$C$301<=A3),(SQRT(Data!$K$2:$K$301)-G3)^2)+SUMPRODUCT(--(Data!$C$2:$C$301>A3),(SQRT(Data!$K$2:$K$301)-H3)^2) -> 977.03465 | J3: =IF(AND(B3>0,D3>0),1,0) -> 1 | K3: =IF(J3=1,F3,1E+99) -> 501363.65 | L3: =IF(J3=1,I3,1E+99) -> 977.03465 | N3: best_threshold_sqrt_wage
A4: =Data!C4 -> 45 | B4: =COUNTIF(Data!$C$2:$C$301,"<="&A4) -> 176 | C4: =IF(B4=0,0,AVERAGEIF(Data!$C$2:$C$301,"<="&A4,Data!$K$2:$K$301)) -> 107.19123 | D4: =COUNTIF(Data!$C$2:$C$301,">"&A4) -> 124 | E4: =IF(D4=0,0,AVERAGEIF(Data!$C$2:$C$301,">"&A4,Data!$K$2:$K$301)) -> 114.56723 | F4: =SUMPRODUCT(--(Data!$C$2:$C$301<=A4),(Data!$K$2:$K$301-C4)^2)+SUMPRODUCT(--(Data!$C$2:$C$301>A4),(Data!$K$2:$K$301-E4)^2) -> 533316.09 | G4: =IF(B4=0,0,SUMPRODUCT(--(Data!$C$2:$C$301<=A4),SQRT(Data!$K$2:$K$301))/B4) -> 10.17883 | H4: =IF(D4=0,0,SUMPRODUCT(--(Data!$C$2:$C$301>A4),SQRT(Data!$K$2:$K$301))/D4) -> 10.53913 | I4: =SUMPRODUCT(--(Data!$C$2:$C$301<=A4),(SQRT(Data!$K$2:$K$301)-G4)^2)+SUMPRODUCT(--(Data!$C$2:$C$301>A4),(SQRT(Data!$K$2:$K$301)-H4)^2) -> 1063.7997 | J4: =IF(AND(B4>0,D4>0),1,0) -> 1 | K4: =IF(J4=1,F4,1E+99) -> 533316.09 | L4: =IF(J4=1,I4,1E+99) -> 1063.7997 | N4: =INDEX(A2:A251,MATCH(MIN(L2:L251),L2:L251,0)) -> 27
A5: =Data!C5 -> 43 | B5: =COUNTIF(Data!$C$2:$C$301,"<="&A5) -> 161 | C5: =IF(B5=0,0,AVERAGEIF(Data!$C$2:$C$301,"<="&A5,Data!$K$2:$K$301)) -> 105.87301 | D5: =COUNTIF(Data!$C$2:$C$301,">"&A5) -> 139 | E5: =IF(D5=0,0,AVERAGEIF(Data!$C$2:$C$301,">"&A5,Data!$K$2:$K$301)) -> 115.29812 | F5: =SUMPRODUCT(--(Data!$C$2:$C$301<=A5),(Data!$K$2:$K$301-C5)^2)+SUMPRODUCT(--(Data!$C$2:$C$301>A5),(Data!$K$2:$K$301-E5)^2) -> 530647.27 | G5: =IF(B5=0,0,SUMPRODUCT(--(Data!$C$2:$C$301<=A5),SQRT(Data!$K$2:$K$301))/B5) -> 10.10807 | H5: =IF(D5=0,0,SUMPRODUCT(--(Data!$C$2:$C$301>A5),SQRT(Data!$K$2:$K$301))/D5) -> 10.582208 | I5: =SUMPRODUCT(--(Data!$C$2:$C$301<=A5),(SQRT(Data!$K$2:$K$301)-G5)^2)+SUMPRODUCT(--(Data!$C$2:$C$301>A5),(SQRT(Data!$K$2:$K$301)-H5)^2) -> 1056.4735 | J5: =IF(AND(B5>0,D5>0),1,0) -> 1 | K5: =IF(J5=1,F5,1E+99) -> 530647.27 | L5: =IF(J5=1,I5,1E+99) -> 1056.4735 | N5: abs_difference
A6: =Data!C6 -> 50 | B6: =COUNTIF(Data!$C$2:$C$301,"<="&A6) -> 219 | C6: =IF(B6=0,0,AVERAGEIF(Data!$C$2:$C$301,"<="&A6,Data!$K$2:$K$301)) -> 108.70258 | D6: =COUNTIF(Data!$C$2:$C$301,">"&A6) -> 81 | E6: =IF(D6=0,0,AVERAGEIF(Data!$C$2:$C$301,">"&A6,Data!$K$2:$K$301)) -> 114.39664 | F6: =SUMPRODUCT(--(Data!$C$2:$C$301<=A6),(Data!$K$2:$K$301-C6)^2)+SUMPRODUCT(--(Data!$C$2:$C$301>A6),(Data!$K$2:$K$301-E6)^2) -> 535356.77 | G6: =IF(B6=0,0,SUMPRODUCT(--(Data!$C$2:$C$301<=A6),SQRT(Data!$K$2:$K$301))/B6) -> 10.25444 | H6: =IF(D6=0,0,SUMPRODUCT(--(Data!$C$2:$C$301>A6),SQRT(Data!$K$2:$K$301))/D6) -> 10.525972 | I6: =SUMPRODUCT(--(Data!$C$2:$C$301<=A6),(SQRT(Data!$K$2:$K$301)-G6)^2)+SUMPRODUCT(--(Data!$C$2:$C$301>A6),(SQRT(Data!$K$2:$K$301)-H6)^2) -> 1068.8838 | J6: =IF(AND(B6>0,D6>0),1,0) -> 1 | K6: =IF(J6=1,F6,1E+99) -> 535356.77 | L6: =IF(J6=1,I6,1E+99) -> 1068.8838 | N6: =ABS(N2-N4) -> 7
A7: =Data!C7 -> 54 | B7: =COUNTIF(Data!$C$2:$C$301,"<="&A7) -> 245 | C7: =IF(B7=0,0,AVERAGEIF(Data!$C$2:$C$301,"<="&A7,Data!$K$2:$K$301)) -> 108.70437 | D7: =COUNTIF(Data!$C$2:$C$301,">"&A7) -> 55 | E7: =IF(D7=0,0,AVERAGEIF(Data!$C$2:$C$301,">"&A7,Data!$K$2:$K$301)) -> 117.0804 | F7: =SUMPRODUCT(--(Data!$C$2:$C$301<=A7),(Data!$K$2:$K$301-C7)^2)+SUMPRODUCT(--(Data!$C$2:$C$301>A7),(Data!$K$2:$K$301-E7)^2) -> 534122.65 | G7: =IF(B7=0,0,SUMPRODUCT(--(Data!$C$2:$C$301<=A7),SQRT(Data!$K$2:$K$301))/B7) -> 10.262431 | H7: =IF(D7=0,0,SUMPRODUCT(--(Data!$C$2:$C$301>A7),SQRT(Data!$K$2:$K$301))/D7) -> 10.618737 | I7: =SUMPRODUCT(--(Data!$C$2:$C$301<=A7),(SQRT(Data!$K$2:$K$301)-G7)^2)+SUMPRODUCT(--(Data!$C$2:$C$301>A7),(SQRT(Data!$K$2:$K$301)-H7)^2) -> 1067.5411 | J7: =IF(AND(B7>0,D7>0),1,0) -> 1 | K7: =IF(J7=1,F7,1E+99) -> 534122.65 | L7: =IF(J7=1,I7,1E+99) -> 1067.5411
A8: =Data!C8 -> 44 | B8: =COUNTIF(Data!$C$2:$C$301,"<="&A8) -> 168 | C8: =IF(B8=0,0,AVERAGEIF(Data!$C$2:$C$301,"<="&A8,Data!$K$2:$K$301)) -> 106.42367 | D8: =COUNTIF(Data!$C$2:$C$301,">"&A8) -> 132 | E8: =IF(D8=0,0,AVERAGEIF(Data!$C$2:$C$301,">"&A8,Data!$K$2:$K$301)) -> 115.0971 | F8: =SUMPRODUCT(--(Data!$C$2:$C$301<=A8),(Data!$K$2:$K$301-C8)^2)+SUMPRODUCT(--(Data!$C$2:$C$301>A8),(Data!$K$2:$K$301-E8)^2) -> 531713.03 | G8: =IF(B8=0,0,SUMPRODUCT(--(Data!$C$2:$C$301<=A8),SQRT(Data!$K$2:$K$301))/B8) -> 10.139424 | H8: =IF(D8=0,0,SUMPRODUCT(--(Data!$C$2:$C$301>A8),SQRT(Data!$K$2:$K$301))/D8) -> 10.567446 | I8: =SUMPRODUCT(--(Data!$C$2:$C$301<=A8),(SQRT(Data!$K$2:$K$301)-G8)^2)+SUMPRODUCT(--(Data!$C$2:$C$301>A8),(SQRT(Data!$K$2:$K$301)-H8)^2) -> 1059.7011 | J8: =IF(AND(B8>0,D8>0),1,0) -> 1 | K8: =IF(J8=1,F8,1E+99) -> 531713.03 | L8: =IF(J8=1,I8,1E+99) -> 1059.7011
A9: =Data!C9 -> 30 | B9: =COUNTIF(Data!$C$2:$C$301,"<="&A9) -> 52 | C9: =IF(B9=0,0,AVERAGEIF(Data!$C$2:$C$301,"<="&A9,Data!$K$2:$K$301)) -> 86.222807 | D9: =COUNTIF(Data!$C$2:$C$301,">"&A9) -> 248 | E9: =IF(D9=0,0,AVERAGEIF(Data!$C$2:$C$301,">"&A9,Data!$K$2:$K$301)) -> 115.27584 | F9: =SUMPRODUCT(--(Data!$C$2:$C$301<=A9),(Data!$K$2:$K$301-C9)^2)+SUMPRODUCT(--(Data!$C$2:$C$301>A9),(Data!$K$2:$K$301-E9)^2) -> 500989.79 | G9: =IF(B9=0,0,SUMPRODUCT(--(Data!$C$2:$C$301<=A9),SQRT(Data!$K$2:$K$301))/B9) -> 9.1609179 | H9: =IF(D9=0,0,SUMPRODUCT(--(Data!$C$2:$C$301>A9),SQRT(Data!$K$2:$K$301))/D9) -> 10.572413 | I9: =SUMPRODUCT(--(Data!$C$2:$C$301<=A9),(SQRT(Data!$K$2:$K$301)-G9)^2)+SUMPRODUCT(--(Data!$C$2:$C$301>A9),(SQRT(Data!$K$2:$K$301)-H9)^2) -> 987.60028 | J9: =IF(AND(B9>0,D9>0),1,0) -> 1 | K9: =IF(J9=1,F9,1E+99) -> 500989.79 | L9: =IF(J9=1,I9,1E+99) -> 987.60028
A10: =Data!C10 -> 41 | B10: =COUNTIF(Data!$C$2:$C$301,"<="&A10) -> 143 | C10: =IF(B10=0,0,AVERAGEIF(Data!$C$2:$C$301,"<="&A10,Data!$K$2:$K$301)) -> 103.77383 | D10: =COUNTIF(Data!$C$2:$C$301,">"&A10) -> 157 | E10: =IF(D10=0,0,AVERAGEIF(Data!$C$2:$C$301,">"&A10,Data!$K$2:$K$301)) -> 116.12953 | F10: =SUMPRODUCT(--(Data!$C$2:$C$301<=A10),(Data!$K$2:$K$301-C10)^2)+SUMPRODUCT(--(Data!$C$2:$C$301>A10),(Data!$K$2:$K$301-E10)^2) -> 525849.1 | G10: =IF(B10=0,0,SUMPRODUCT(--(Data!$C$2:$C$301<=A10),SQRT(Data!$K$2:$K$301))/B10) -> 10.028926 | H10: =IF(D10=0,0,SUMPRODUCT(--(Data!$C$2:$C$301>A10),SQRT(Data!$K$2:$K$301))/D10) -> 10.599935 | I10: =SUMPRODUCT(--(Data!$C$2:$C$301<=A10),(SQRT(Data!$K$2:$K$301)-G10)^2)+SUMPRODUCT(--(Data!$C$2:$C$301>A10),(SQRT(Data!$K$2:$K$301)-H10)^2) -> 1048.8429 | J10: =IF(AND(B10>0,D10>0),1,0) -> 1 | K10: =IF(J10=1,F10,1E+99) -> 525849.1 | L10: =IF(J10=1,I10,1E+99) -> 1048.8429
A11: =Data!C11 -> 52 | B11: =COUNTIF(Data!$C$2:$C$301,"<="&A11) -> 233 | C11: =IF(B11=0,0,AVERAGEIF(Data!$C$2:$C$301,"<="&A11,Data!$K$2:$K$301)) -> 108.60726 | D11: =COUNTIF(Data!$C$2:$C$301,">"&A11) -> 67 | E11: =IF(D11=0,0,AVERAGEIF(Data!$C$2:$C$301,">"&A11,Data!$K$2:$K$301)) -> 115.91794 | F11: =SUMPRODUCT(--(Data!$C$2:$C$301<=A11),(Data!$K$2:$K$301-C11)^2)+SUMPRODUCT(--(Data!$C$2:$C$301>A11),(Data!$K$2:$K$301-E11)^2) -> 534492.75 | G11: =IF(B11=0,0,SUMPRODUCT(--(Data!$C$2:$C$301<=A11),SQRT(Data!$K$2:$K$301))/B11) -> 10.252914 | H11: =IF(D11=0,0,SUMPRODUCT(--(Data!$C$2:$C$301>A11),SQRT(Data!$K$2:$K$301))/D11) -> 10.588019 | I11: =SUMPRODUCT(--(Data!$C$2:$C$301<=A11),(SQRT(Data!$K$2:$K$301)-G11)^2)+SUMPRODUCT(--(Data!$C$2:$C$301>A11),(SQRT(Data!$K$2:$K$301)-H11)^2) -> 1067.3999 | J11: =IF(AND(B11>0,D11>0),1,0) -> 1 | K11: =IF(J11=1,F11,1E+99) -> 534492.75 | L11: =IF(J11=1,I11,1E+99) -> 1067.3999
A12: =Data!C12 -> 45 | B12: =COUNTIF(Data!$C$2:$C$301,"<="&A12) -> 176 | C12: =IF(B12=0,0,AVERAGEIF(Data!$C$2:$C$301,"<="&A12,Data!$K$2:$K$301)) -> 107.19123 | D12: =COUNTIF(Data!$C$2:$C$301,">"&A12) -> 124 | E12: =IF(D12=0,0,AVERAGEIF(Data!$C$2:$C$301,">"&A12,Data!$K$2:$K$301)) -> 114.56723 | F12: =SUMPRODUCT(--(Data!$C$2:$C$301<=A12),(Data!$K$2:$K$301-C12)^2)+SUMPRODUCT(--(Data!$C$2:$C$301>A12),(Data!$K$2:$K$301-E12)^2) -> 533316.09 | G12: =IF(B12=0,0,SUMPRODUCT(--(Data!$C$2:$C$301<=A12),SQRT(Data!$K$2:$K$301))/B12) -> 10.17883 | H12: =IF(D12=0,0,SUMPRODUCT(--(Data!$C$2:$C$301>A12),SQRT(Data!$K$2:$K$301))/D12) -> 10.53913 | I12: =SUMPRODUCT(--(Data!$C$2:$C$301<=A12),(SQRT(Data!$K$2:$K$301)-G12)^2)+SUMPRODUCT(--(Data!$C$2:$C$301>A12),(SQRT(Data!$K$2:$K$301)-H12)^2) -> 1063.7997 | J12: =IF(AND(B12>0,D12>0),1,0) -> 1 | K12: =IF(J12=1,F12,1E+99) -> 533316.09 | L12: =IF(J12=1,I12,1E+99) -> 1063.7997
A13: =Data!C13 -> 34 | B13: =COUNTIF(Data!$C$2:$C$301,"<="&A13) -> 79 | C13: =IF(B13=0,0,AVERAGEIF(Data!$C$2:$C$301,"<="&A13,Data!$K$2:$K$301)) -> 89.239688 | D13: =COUNTIF(Data!$C$2:$C$301,">"&A13) -> 221 | E13: =IF(D13=0,0,AVERAGEIF(Data!$C$2:$C$301,">"&A13,Data!$K$2:$K$301)) -> 117.74687 | F13: =SUMPRODUCT(--(Data!$C$2:$C$301<=A13),(Data!$K$2:$K$301-C13)^2)+SUMPRODUCT(--(Data!$C$2:$C$301>A13),(Data!$K$2:$K$301-E13)^2) -> 489979.84 | G13: =IF(B13=0,0,SUMPRODUCT(--(Data!$C$2:$C$301<=A13),SQRT(Data!$K$2:$K$301))/B13) -> 9.3403512 | H13: =IF(D13=0,0,SUMPRODUCT(--(Data!$C$2:$C$301>A13),SQRT(Data!$K$2:$K$301))/D13) -> 10.680717 | I13: =SUMPRODUCT(--(Data!$C$2:$C$301<=A13),(SQRT(Data!$K$2:$K$301)-G13)^2)+SUMPRODUCT(--(Data!$C$2:$C$301>A13),(SQRT(Data!$K$2:$K$301)-H13)^2) -> 968.68845 | J13: =IF(AND(B13>0,D13>0),1,0) -> 1 | K13: =IF(J13=1,F13,1E+99) -> 489979.84 | L13: =IF(J13=1,I13,1E+99) -> 968.68845
A14: =Data!C14 -> 35 | B14: =COUNTIF(Data!$C$2:$C$301,"<="&A14) -> 90 | C14: =IF(B14=0,0,AVERAGEIF(Data!$C$2:$C$301,"<="&A14,Data!$K$2:$K$301)) -> 94.577555 | D14: =COUNTIF(Data!$C$2:$C$301,">"&A14) -> 210 | E14: =IF(D14=0,0,AVERAGEIF(Data!$C$2:$C$301,">"&A14,Data!$K$2:$K$301)) -> 116.95244 | F14: =SUMPRODUCT(--(Data!$C$2:$C$301<=A14),(Data!$K$2:$K$301-C14)^2)+SUMPRODUCT(--(Data!$C$2:$C$301>A14),(Data!$K$2:$K$301-E14)^2) -> 505733.86 | G14: =IF(B14=0,0,SUMPRODUCT(--(Data!$C$2:$C$301<=A14),SQRT(Data!$K$2:$K$301))/B14) -> 9.5793805 | H14: =IF(D14=0,0,SUMPRODUCT(--(Data!$C$2:$C$301>A14),SQRT(Data!$K$2:$K$301))/D14) -> 10.648485 | I14: =SUMPRODUCT(--(Data!$C$2:$C$301<=A14),(SQRT(Data!$K$2:$K$301)-G14)^2)+SUMPRODUCT(--(Data!$C$2:$C$301>A14),(SQRT(Data!$K$2:$K$301)-H14)^2) -> 1001.2354 | J14: =IF(AND(B14>0,D14>0),1,0) -> 1 | K14: =IF(J14=1,F14,1E+99) -> 505733.86 | L14: =IF(J14=1,I14,1E+99) -> 1001.2354
A15: =Data!C15 -> 39 | B15: =COUNTIF(Data!$C$2:$C$301,"<="&A15) -> 124 | C15: =IF(B15=0,0,AVERAGEIF(Data!$C$2:$C$301,"<="&A15,Data!$K$2:$K$301)) -> 102.61245 | D15: =COUNTIF(Data!$C$2:$C$301,">"&A15) -> 176 | E15: =IF(D15=0,0,AVERAGEIF(Data!$C$2:$C$301,">"&A15,Data!$K$2:$K$301)) -> 115.61392 | F15: =SUMPRODUCT(--(Data!$C$2:$C$301<=A15),(Data!$K$2:$K$301-C15)^2)+SUMPRODUCT(--(Data!$C$2:$C$301>A15),(Data!$K$2:$K$301-E15)^2) -> 524976.93 | G15: =IF(B15=0,0,SUMPRODUCT(--(Data!$C$2:$C$301<=A15),SQRT(Data!$K$2:$K$301))/B15) -> 9.9647092 | H15: =IF(D15=0,0,SUMPRODUCT(--(Data!$C$2:$C$301>A15),SQRT(Data!$K$2:$K$301))/D15) -> 10.583535 | I15: =SUMPRODUCT(--(Data!$C$2:$C$301<=A15),(SQRT(Data!$K$2:$K$301)-G15)^2)+SUMPRODUCT(--(Data!$C$2:$C$301>A15),(SQRT(Data!$K$2:$K$301)-H15)^2) -> 1045.3854 | J15: =IF(AND(B15>0,D15>0),1,0) -> 1 | K15: =IF(J15=1,F15,1E+99) -> 524976.93 | L15: =IF(J15=1,I15,1E+99) -> 1045.3854
A16: =Data!C16 -> 54 | B16: =COUNTIF(Data!$C$2:$C$301,"<="&A16) -> 245 | C16: =IF(B16=0,0,AVERAGEIF(Data!$C$2:$C$301,"<="&A16,Data!$K$2:$K$301)) -> 108.70437 | D16: =COUNTIF(Data!$C$2:$C$301,">"&A16) -> 55 | E16: =IF(D16=0,0,AVERAGEIF(Data!$C$2:$C$301,">"&A16,Data!$K$2:$K$301)) -> 117.0804 | F16: =SUMPRODUCT(--(Data!$C$2:$C$301<=A16),(Data!$K$2:$K$301-C16)^2)+SUMPRODUCT(--(Data!$C$2:$C$301>A16),(Data!$K$2:$K$301-E16)^2) -> 534122.65 | G16: =IF(B16=0,0,SUMPRODUCT(--(Data!$C$2:$C$301<=A16),SQRT(Data!$K$2:$K$301))/B16) -> 10.262431 | H16: =IF(D16=0,0,SUMPRODUCT(--(Data!$C$2:$C$301>A16),SQRT(Data!$K$2:$K$301))/D16) -> 10.618737 | I16: =SUMPRODUCT(--(Data!$C$2:$C$301<=A16),(SQRT(Data!$K$2:$K$301)-G16)^2)+SUMPRODUCT(--(Data!$C$2:$C$301>A16),(SQRT(Data!$K$2:$K$301)-H16)^2) -> 1067.5411 | J16: =IF(AND(B16>0,D16>0),1,0) -> 1 | K16: =IF(J16=1,F16,1E+99) -> 534122.65 | L16: =IF(J16=1,I16,1E+99) -> 1067.5411
A17: =Data!C17 -> 51 | B17: =COUNTIF(Data!$C$2:$C$301,"<="&A17) -> 225 | C17: =IF(B17=0,0,AVERAGEIF(Data!$C$2:$C$301,"<="&A17,Data!$K$2:$K$301)) -> 108.72268 | D17: =COUNTIF(Data!$C$2:$C$301,">"&A17) -> 75 | E17: =IF(D17=0,0,AVERAGEIF(Data!$C$2:$C$301,">"&A17,Data!$K$2:$K$301)) -> 114.79187 | F17: =SUMPRODUCT(--(Data!$C$2:$C$301<=A17),(Data!$K$2:$K$301-C17)^2)+SUMPRODUCT(--(Data!$C$2:$C$301>A17),(Data!$K$2:$K$301-E17)^2) -> 535201.93 | G17: =IF(B17=0,0,SUMPRODUCT(--(Data!$C$2:$C$301<=A17),SQRT(Data!$K$2:$K$301))/B17) -> 10.256534 | H17: =IF(D17=0,0,SUMPRODUCT(--(Data!$C$2:$C$301>A17),SQRT(Data!$K$2:$K$301))/D17) -> 10.541413 | I17: =SUMPRODUCT(--(Data!$C$2:$C$301<=A17),(SQRT(Data!$K$2:$K$301)-G17)^2)+SUMPRODUCT(--(Data!$C$2:$C$301>A17),(SQRT(Data!$K$2:$K$301)-H17)^2) -> 1068.6784 | J17: =IF(AND(B17>0,D17>0),1,0) -> 1 | K17: =IF(J17=1,F17,1E+99) -> 535201.93 | L17: =IF(J17=1,I17,1E+99) -> 1068.6784
A18: =Data!C18 -> 37 | B18: =COUNTIF(Data!$C$2:$C$301,"<="&A18) -> 106 | C18: =IF(B18=0,0,AVERAGEIF(Data!$C$2:$C$301,"<="&A18,Data!$K$2:$K$301)) -> 97.276623 | D18: =COUNTIF(Data!$C$2:$C$301,">"&A18) -> 194 | E18: =IF(D18=0,0,AVERAGEIF(Data!$C$2:$C$301,">"&A18,Data!$K$2:$K$301)) -> 117.32305 | F18: =SUMPRODUCT(--(Data!$C$2:$C$301<=A18),(Data!$K$2:$K$301-C18)^2)+SUMPRODUCT(--(Data!$C$2:$C$301>A18),(Data!$K$2:$K$301-E18)^2) -> 509727.8 | G18: =IF(B18=0,0,SUMPRODUCT(--(Data!$C$2:$C$301<=A18),SQRT(Data!$K$2:$K$301))/B18) -> 9.7174656 | H18: =IF(D18=0,0,SUMPRODUCT(--(Data!$C$2:$C$301>A18),SQRT(Data!$K$2:$K$301))/D18) -> 10.66121 | I18: =SUMPRODUCT(--(Data!$C$2:$C$301<=A18),(SQRT(Data!$K$2:$K$301)-G18)^2)+SUMPRODUCT(--(Data!$C$2:$C$301>A18),(SQRT(Data!$K$2:$K$301)-H18)^2) -> 1012.192 | J18: =IF(AND(B18>0,D18>0),1,0) -> 1 | K18: =IF(J18=1,F18,1E+99) -> 509727.8 | L18: =IF(J18=1,I18,1E+99) -> 1012.192
... A251: =Data!C251 -> 38 | B251: =COUNTIF(Data!$C$2:$C$301,"<="&A251) -> 115 | C251: =IF(B251=0,0,AVERAGEIF(Data!$C$2:$C$301,"<="&A251,Data!$K$2:$K$301)) -> 101.18702 | D251: =COUNTIF(Data!$C$2:$C$301,">"&A251) -> 185 | E251: =IF(D251=0,0,AVERAGEIF(Data!$C$2:$C$301,">"&A251,Data!$K$2:$K$301)) -> 115.86749 | F251: =SUMPRODUCT(--(Data!$C$2:$C$301<=A251),(Data!$K$2:$K$301-C251)^2)+SUMPRODUCT(--(Data!$C$2:$C$301>A251),(Data!$K$2:$K$301-E251)^2) -> 521990.2 | G251: =IF(B251=0,0,SUMPRODUCT(--(Data!$C$2:$C$301<=A251),SQRT(Data!$K$2:$K$301))/B251) -> 9.8881544 | H251: =IF(D251=0,0,SUMPRODUCT(--(Data!$C$2:$C$301>A251),SQRT(Data!$K$2:$K$301))/D251) -> 10.601018 | I251: =SUMPRODUCT(--(Data!$C$2:$C$301<=A251),(SQRT(Data!$K$2:$K$301)-G251)^2)+SUMPRODUCT(--(Data!$C$2:$C$301>A251),(SQRT(Data!$K$2:$K$301)-H251)^2) -> 1037.2053 | J251: =IF(AND(B251>0,D251>0),1,0) -> 1 | K251: =IF(J251=1,F251,1E+99) -> 521990.2 | L251: =IF(J251=1,I251,1E+99) -> 1037.2053

Sheet ClassTree
A1: age_threshold | B1: left_train_n | C1: left_train_pos | D1: right_train_n | E1: right_train_pos | F1: left_gini | G1: right_gini | H1: weighted_gini | I1: valid_split | J1: valid_gini | L1: best_threshold_age | N1: test_id | O1: actual | P1: pred_prob | Q1: pred_class | R1: correct
A2: =Data!C2 -> 18 | B2: =COUNTIFS(Data!$M$2:$M$301,"Train",Data!$C$2:$C$301,"<="&A2) -> 2 | C2: =SUMIFS(Data!$L$2:$L$301,Data!$M$2:$M$301,"Train",Data!$C$2:$C$301,"<="&A2) -> 0 | D2: =COUNTIFS(Data!$M$2:$M$301,"Train",Data!$C$2:$C$301,">"&A2) -> 208 | E2: =SUMIFS(Data!$L$2:$L$301,Data!$M$2:$M$301,"Train",Data!$C$2:$C$301,">"&A2) -> 110 | F2: =IF(B2=0,0,1-(C2/B2)^2-(1-C2/B2)^2) -> 0 | G2: =IF(D2=0,0,1-(E2/D2)^2-(1-E2/D2)^2) -> 0.4983358 | H2: =IF(B2+D2=0,1,(B2*F2+D2*G2)/(B2+D2)) -> 0.49358974 | I2: =IF(AND(B2>0,D2>0),1,0) -> 1 | J2: =IF(I2=1,H2,1E+99) -> 0.49358974 | L2: =INDEX(A2:A251,MATCH(MIN(J2:J251),J2:J251,0)) -> 26 | N2: =Data!A206 -> 205 | O2: =Data!L206 -> 1 | P2: =IF(Data!C206<=$L$2,$L$4,$L$6) -> 0.57978723 | Q2: =IF(P2>=Controls!$B$2,1,0) -> 1 | R2: =--(Q2=O2) -> 1
A3: =Data!C3 -> 24 | B3: =COUNTIFS(Data!$M$2:$M$301,"Train",Data!$C$2:$C$301,"<="&A3) -> 12 | C3: =SUMIFS(Data!$L$2:$L$301,Data!$M$2:$M$301,"Train",Data!$C$2:$C$301,"<="&A3) -> 0 | D3: =COUNTIFS(Data!$M$2:$M$301,"Train",Data!$C$2:$C$301,">"&A3) -> 198 | E3: =SUMIFS(Data!$L$2:$L$301,Data!$M$2:$M$301,"Train",Data!$C$2:$C$301,">"&A3) -> 110 | F3: =IF(B3=0,0,1-(C3/B3)^2-(1-C3/B3)^2) -> 0 | G3: =IF(D3=0,0,1-(E3/D3)^2-(1-E3/D3)^2) -> 0.49382716 | H3: =IF(B3+D3=0,1,(B3*F3+D3*G3)/(B3+D3)) -> 0.46560847 | I3: =IF(AND(B3>0,D3>0),1,0) -> 1 | J3: =IF(I3=1,H3,1E+99) -> 0.46560847 | L3: left_prob_high | N3: =Data!A208 -> 207 | O3: =Data!L208 -> 1 | P3: =IF(Data!C208<=$L$2,$L$4,$L$6) -> 0.57978723 | Q3: =IF(P3>=Controls!$B$2,1,0) -> 1 | R3: =--(Q3=O3) -> 1
A4: =Data!C4 -> 45 | B4: =COUNTIFS(Data!$M$2:$M$301,"Train",Data!$C$2:$C$301,"<="&A4) -> 123 | C4: =SUMIFS(Data!$L$2:$L$301,Data!$M$2:$M$301,"Train",Data!$C$2:$C$301,"<="&A4) -> 55 | D4: =COUNTIFS(Data!$M$2:$M$301,"Train",Data!$C$2:$C$301,">"&A4) -> 87 | E4: =SUMIFS(Data!$L$2:$L$301,Data!$M$2:$M$301,"Train",Data!$C$2:$C$301,">"&A4) -> 55 | F4: =IF(B4=0,0,1-(C4/B4)^2-(1-C4/B4)^2) -> 0.4944147 | G4: =IF(D4=0,0,1-(E4/D4)^2-(1-E4/D4)^2) -> 0.46505483 | H4: =IF(B4+D4=0,1,(B4*F4+D4*G4)/(B4+D4)) -> 0.48225132 | I4: =IF(AND(B4>0,D4>0),1,0) -> 1 | J4: =IF(I4=1,H4,1E+99) -> 0.48225132 | L4: =IFERROR(AVERAGEIFS(Data!$L$2:$L$301,Data!$M$2:$M$301,"Train",Data!$C$2:$C$301,"<="&$L$2),0) -> 0.045454545 | N4: =Data!A209 -> 208 | O4: =Data!L209 -> 1 | P4: =IF(Data!C209<=$L$2,$L$4,$L$6) -> 0.57978723 | Q4: =IF(P4>=Controls!$B$2,1,0) -> 1 | R4: =--(Q4=O4) -> 1
A5: =Data!C5 -> 43 | B5: =COUNTIFS(Data!$M$2:$M$301,"Train",Data!$C$2:$C$301,"<="&A5) -> 113 | C5: =SUMIFS(Data!$L$2:$L$301,Data!$M$2:$M$301,"Train",Data!$C$2:$C$301,"<="&A5) -> 48 | D5: =COUNTIFS(Data!$M$2:$M$301,"Train",Data!$C$2:$C$301,">"&A5) -> 97 | E5: =SUMIFS(Data!$L$2:$L$301,Data!$M$2:$M$301,"Train",Data!$C$2:$C$301,">"&A5) -> 62 | F5: =IF(B5=0,0,1-(C5/B5)^2-(1-C5/B5)^2) -> 0.48868353 | G5: =IF(D5=0,0,1-(E5/D5)^2-(1-E5/D5)^2) -> 0.4612605 | H5: =IF(B5+D5=0,1,(B5*F5+D5*G5)/(B5+D5)) -> 0.4760167 | I5: =IF(AND(B5>0,D5>0),1,0) -> 1 | J5: =IF(I5=1,H5,1E+99) -> 0.4760167 | L5: right_prob_high | N5: =Data!A210 -> 209 | O5: =Data!L210 -> 1 | P5: =IF(Data!C210<=$L$2,$L$4,$L$6) -> 0.57978723 | Q5: =IF(P5>=Controls!$B$2,1,0) -> 1 | R5: =--(Q5=O5) -> 1
A6: =Data!C6 -> 50 | B6: =COUNTIFS(Data!$M$2:$M$301,"Train",Data!$C$2:$C$301,"<="&A6) -> 149 | C6: =SUMIFS(Data!$L$2:$L$301,Data!$M$2:$M$301,"Train",Data!$C$2:$C$301,"<="&A6) -> 74 | D6: =COUNTIFS(Data!$M$2:$M$301,"Train",Data!$C$2:$C$301,">"&A6) -> 61 | E6: =SUMIFS(Data!$L$2:$L$301,Data!$M$2:$M$301,"Train",Data!$C$2:$C$301,">"&A6) -> 36 | F6: =IF(B6=0,0,1-(C6/B6)^2-(1-C6/B6)^2) -> 0.49997748 | G6: =IF(D6=0,0,1-(E6/D6)^2-(1-E6/D6)^2) -> 0.48374093 | H6: =IF(B6+D6=0,1,(B6*F6+D6*G6)/(B6+D6)) -> 0.49526115 | I6: =IF(AND(B6>0,D6>0),1,0) -> 1 | J6: =IF(I6=1,H6,1E+99) -> 0.49526115 | L6: =IFERROR(AVERAGEIFS(Data!$L$2:$L$301,Data!$M$2:$M$301,"Train",Data!$C$2:$C$301,">"&$L$2),0) -> 0.57978723 | N6: =Data!A212 -> 211 | O6: =Data!L212 -> 1 | P6: =IF(Data!C212<=$L$2,$L$4,$L$6) -> 0.57978723 | Q6: =IF(P6>=Controls!$B$2,1,0) -> 1 | R6: =--(Q6=O6) -> 1
A7: =Data!C7 -> 54 | B7: =COUNTIFS(Data!$M$2:$M$301,"Train",Data!$C$2:$C$301,"<="&A7) -> 169 | C7: =SUMIFS(Data!$L$2:$L$301,Data!$M$2:$M$301,"Train",Data!$C$2:$C$301,"<="&A7) -> 87 | D7: =COUNTIFS(Data!$M$2:$M$301,"Train",Data!$C$2:$C$301,">"&A7) -> 41 | E7: =SUMIFS(Data!$L$2:$L$301,Data!$M$2:$M$301,"Train",Data!$C$2:$C$301,">"&A7) -> 23 | F7: =IF(B7=0,0,1-(C7/B7)^2-(1-C7/B7)^2) -> 0.49956234 | G7: =IF(D7=0,0,1-(E7/D7)^2-(1-E7/D7)^2) -> 0.49256395 | H7: =IF(B7+D7=0,1,(B7*F7+D7*G7)/(B7+D7)) -> 0.49819599 | I7: =IF(AND(B7>0,D7>0),1,0) -> 1 | J7: =IF(I7=1,H7,1E+99) -> 0.49819599 | L7: left_class_pred | N7: =Data!A214 -> 213 | O7: =Data!L214 -> 1 | P7: =IF(Data!C214<=$L$2,$L$4,$L$6) -> 0.57978723 | Q7: =IF(P7>=Controls!$B$2,1,0) -> 1 | R7: =--(Q7=O7) -> 1
A8: =Data!C8 -> 44 | B8: =COUNTIFS(Data!$M$2:$M$301,"Train",Data!$C$2:$C$301,"<="&A8) -> 119 | C8: =SUMIFS(Data!$L$2:$L$301,Data!$M$2:$M$301,"Train",Data!$C$2:$C$301,"<="&A8) -> 52 | D8: =COUNTIFS(Data!$M$2:$M$301,"Train",Data!$C$2:$C$301,">"&A8) -> 91 | E8: =SUMIFS(Data!$L$2:$L$301,Data!$M$2:$M$301,"Train",Data!$C$2:$C$301,">"&A8) -> 58 | F8: =IF(B8=0,0,1-(C8/B8)^2-(1-C8/B8)^2) -> 0.49205565 | G8: =IF(D8=0,0,1-(E8/D8)^2-(1-E8/D8)^2) -> 0.46226301 | H8: =IF(B8+D8=0,1,(B8*F8+D8*G8)/(B8+D8)) -> 0.4791455 | I8: =IF(AND(B8>0,D8>0),1,0) -> 1 | J8: =IF(I8=1,H8,1E+99) -> 0.4791455 | L8: =IF(L4>=Controls!$B$2,1,0) -> 0 | N8: =Data!A215 -> 214 | O8: =Data!L215 -> 1 | P8: =IF(Data!C215<=$L$2,$L$4,$L$6) -> 0.57978723 | Q8: =IF(P8>=Controls!$B$2,1,0) -> 1 | R8: =--(Q8=O8) -> 1
A9: =Data!C9 -> 30 | B9: =COUNTIFS(Data!$M$2:$M$301,"Train",Data!$C$2:$C$301,"<="&A9) -> 35 | C9: =SUMIFS(Data!$L$2:$L$301,Data!$M$2:$M$301,"Train",Data!$C$2:$C$301,"<="&A9) -> 9 | D9: =COUNTIFS(Data!$M$2:$M$301,"Train",Data!$C$2:$C$301,">"&A9) -> 175 | E9: =SUMIFS(Data!$L$2:$L$301,Data!$M$2:$M$301,"Train",Data!$C$2:$C$301,">"&A9) -> 101 | F9: =IF(B9=0,0,1-(C9/B9)^2-(1-C9/B9)^2) -> 0.38204082 | G9: =IF(D9=0,0,1-(E9/D9)^2-(1-E9/D9)^2) -> 0.48809796 | H9: =IF(B9+D9=0,1,(B9*F9+D9*G9)/(B9+D9)) -> 0.47042177 | I9: =IF(AND(B9>0,D9>0),1,0) -> 1 | J9: =IF(I9=1,H9,1E+99) -> 0.47042177 | L9: right_class_pred | N9: =Data!A217 -> 216 | O9: =Data!L217 -> 1 | P9: =IF(Data!C217<=$L$2,$L$4,$L$6) -> 0.57978723 | Q9: =IF(P9>=Controls!$B$2,1,0) -> 1 | R9: =--(Q9=O9) -> 1
A10: =Data!C10 -> 41 | B10: =COUNTIFS(Data!$M$2:$M$301,"Train",Data!$C$2:$C$301,"<="&A10) -> 99 | C10: =SUMIFS(Data!$L$2:$L$301,Data!$M$2:$M$301,"Train",Data!$C$2:$C$301,"<="&A10) -> 41 | D10: =COUNTIFS(Data!$M$2:$M$301,"Train",Data!$C$2:$C$301,">"&A10) -> 111 | E10: =SUMIFS(Data!$L$2:$L$301,Data!$M$2:$M$301,"Train",Data!$C$2:$C$301,">"&A10) -> 69 | F10: =IF(B10=0,0,1-(C10/B10)^2-(1-C10/B10)^2) -> 0.48525661 | G10: =IF(D10=0,0,1-(E10/D10)^2-(1-E10/D10)^2) -> 0.47041636 | H10: =IF(B10+D10=0,1,(B10*F10+D10*G10)/(B10+D10)) -> 0.47741248 | I10: =IF(AND(B10>0,D10>0),1,0) -> 1 | J10: =IF(I10=1,H10,1E+99) -> 0.47741248 | L10: =IF(L6>=Controls!$B$2,1,0) -> 1 | N10: =Data!A218 -> 217 | O10: =Data!L218 -> 1 | P10: =IF(Data!C218<=$L$2,$L$4,$L$6) -> 0.57978723 | Q10: =IF(P10>=Controls!$B$2,1,0) -> 1 | R10: =--(Q10=O10) -> 1
A11: =Data!C11 -> 52 | B11: =COUNTIFS(Data!$M$2:$M$301,"Train",Data!$C$2:$C$301,"<="&A11) -> 160 | C11: =SUMIFS(Data!$L$2:$L$301,Data!$M$2:$M$301,"Train",Data!$C$2:$C$301,"<="&A11) -> 81 | D11: =COUNTIFS(Data!$M$2:$M$301,"Train",Data!$C$2:$C$301,">"&A11) -> 50 | E11: =SUMIFS(Data!$L$2:$L$301,Data!$M$2:$M$301,"Train",Data!$C$2:$C$301,">"&A11) -> 29 | F11: =IF(B11=0,0,1-(C11/B11)^2-(1-C11/B11)^2) -> 0.49992187 | G11: =IF(D11=0,0,1-(E11/D11)^2-(1-E11/D11)^2) -> 0.4872 | H11: =IF(B11+D11=0,1,(B11*F11+D11*G11)/(B11+D11)) -> 0.49689286 | I11: =IF(AND(B11>0,D11>0),1,0) -> 1 | J11: =IF(I11=1,H11,1E+99) -> 0.49689286 | N11: =Data!A220 -> 219 | O11: =Data!L220 -> 1 | P11: =IF(Data!C220<=$L$2,$L$4,$L$6) -> 0.57978723 | Q11: =IF(P11>=Controls!$B$2,1,0) -> 1 | R11: =--(Q11=O11) -> 1
A12: =Data!C12 -> 45 | B12: =COUNTIFS(Data!$M$2:$M$301,"Train",Data!$C$2:$C$301,"<="&A12) -> 123 | C12: =SUMIFS(Data!$L$2:$L$301,Data!$M$2:$M$301,"Train",Data!$C$2:$C$301,"<="&A12) -> 55 | D12: =COUNTIFS(Data!$M$2:$M$301,"Train",Data!$C$2:$C$301,">"&A12) -> 87 | E12: =SUMIFS(Data!$L$2:$L$301,Data!$M$2:$M$301,"Train",Data!$C$2:$C$301,">"&A12) -> 55 | F12: =IF(B12=0,0,1-(C12/B12)^2-(1-C12/B12)^2) -> 0.4944147 | G12: =IF(D12=0,0,1-(E12/D12)^2-(1-E12/D12)^2) -> 0.46505483 | H12: =IF(B12+D12=0,1,(B12*F12+D12*G12)/(B12+D12)) -> 0.48225132 | I12: =IF(AND(B12>0,D12>0),1,0) -> 1 | J12: =IF(I12=1,H12,1E+99) -> 0.48225132 | N12: =Data!A222 -> 221 | O12: =Data!L222 -> 0 | P12: =IF(Data!C222<=$L$2,$L$4,$L$6) -> 0.57978723 | Q12: =IF(P12>=Controls!$B$2,1,0) -> 1 | R12: =--(Q12=O12) -> 0
A13: =Data!C13 -> 34 | B13: =COUNTIFS(Data!$M$2:$M$301,"Train",Data!$C$2:$C$301,"<="&A13) -> 55 | C13: =SUMIFS(Data!$L$2:$L$301,Data!$M$2:$M$301,"Train",Data!$C$2:$C$301,"<="&A13) -> 17 | D13: =COUNTIFS(Data!$M$2:$M$301,"Train",Data!$C$2:$C$301,">"&A13) -> 155 | E13: =SUMIFS(Data!$L$2:$L$301,Data!$M$2:$M$301,"Train",Data!$C$2:$C$301,">"&A13) -> 93 | F13: =IF(B13=0,0,1-(C13/B13)^2-(1-C13/B13)^2) -> 0.42710744 | G13: =IF(D13=0,0,1-(E13/D13)^2-(1-E13/D13)^2) -> 0.48 | H13: =IF(B13+D13=0,1,(B13*F13+D13*G13)/(B13+D13)) -> 0.46614719 | I13: =IF(AND(B13>0,D13>0),1,0) -> 1 | J13: =IF(I13=1,H13,1E+99) -> 0.46614719 | N13: =Data!A223 -> 222 | O13: =Data!L223 -> 0 | P13: =IF(Data!C223<=$L$2,$L$4,$L$6) -> 0.57978723 | Q13: =IF(P13>=Controls!$B$2,1,0) -> 1 | R13: =--(Q13=O13) -> 0
A14: =Data!C14 -> 35 | B14: =COUNTIFS(Data!$M$2:$M$301,"Train",Data!$C$2:$C$301,"<="&A14) -> 64 | C14: =SUMIFS(Data!$L$2:$L$301,Data!$M$2:$M$301,"Train",Data!$C$2:$C$301,"<="&A14) -> 22 | D14: =COUNTIFS(Data!$M$2:$M$301,"Train",Data!$C$2:$C$301,">"&A14) -> 146 | E14: =SUMIFS(Data!$L$2:$L$301,Data!$M$2:$M$301,"Train",Data!$C$2:$C$301,">"&A14) -> 88 | F14: =IF(B14=0,0,1-(C14/B14)^2-(1-C14/B14)^2) -> 0.45117188 | G14: =IF(D14=0,0,1-(E14/D14)^2-(1-E14/D14)^2) -> 0.4788891 | H14: =IF(B14+D14=0,1,(B14*F14+D14*G14)/(B14+D14)) -> 0.47044194 | I14: =IF(AND(B14>0,D14>0),1,0) -> 1 | J14: =IF(I14=1,H14,1E+99) -> 0.47044194 | N14: =Data!A224 -> 223 | O14: =Data!L224 -> 0 | P14: =IF(Data!C224<=$L$2,$L$4,$L$6) -> 0.57978723 | Q14: =IF(P14>=Controls!$B$2,1,0) -> 1 | R14: =--(Q14=O14) -> 0
A15: =Data!C15 -> 39 | B15: =COUNTIFS(Data!$M$2:$M$301,"Train",Data!$C$2:$C$301,"<="&A15) -> 87 | C15: =SUMIFS(Data!$L$2:$L$301,Data!$M$2:$M$301,"Train",Data!$C$2:$C$301,"<="&A15) -> 36 | D15: =COUNTIFS(Data!$M$2:$M$301,"Train",Data!$C$2:$C$301,">"&A15) -> 123 | E15: =SUMIFS(Data!$L$2:$L$301,Data!$M$2:$M$301,"Train",Data!$C$2:$C$301,">"&A15) -> 74 | F15: =IF(B15=0,0,1-(C15/B15)^2-(1-C15/B15)^2) -> 0.48513674 | G15: =IF(D15=0,0,1-(E15/D15)^2-(1-E15/D15)^2) -> 0.47934431 | H15: =IF(B15+D15=0,1,(B15*F15+D15*G15)/(B15+D15)) -> 0.48174403 | I15: =IF(AND(B15>0,D15>0),1,0) -> 1 | J15: =IF(I15=1,H15,1E+99) -> 0.48174403 | N15: =Data!A225 -> 224 | O15: =Data!L225 -> 1 | P15: =IF(Data!C225<=$L$2,$L$4,$L$6) -> 0.57978723 | Q15: =IF(P15>=Controls!$B$2,1,0) -> 1 | R15: =--(Q15=O15) -> 1
A16: =Data!C16 -> 54 | B16: =COUNTIFS(Data!$M$2:$M$301,"Train",Data!$C$2:$C$301,"<="&A16) -> 169 | C16: =SUMIFS(Data!$L$2:$L$301,Data!$M$2:$M$301,"Train",Data!$C$2:$C$301,"<="&A16) -> 87 | D16: =COUNTIFS(Data!$M$2:$M$301,"Train",Data!$C$2:$C$301,">"&A16) -> 41 | E16: =SUMIFS(Data!$L$2:$L$301,Data!$M$2:$M$301,"Train",Data!$C$2:$C$301,">"&A16) -> 23 | F16: =IF(B16=0,0,1-(C16/B16)^2-(1-C16/B16)^2) -> 0.49956234 | G16: =IF(D16=0,0,1-(E16/D16)^2-(1-E16/D16)^2) -> 0.49256395 | H16: =IF(B16+D16=0,1,(B16*F16+D16*G16)/(B16+D16)) -> 0.49819599 | I16: =IF(AND(B16>0,D16>0),1,0) -> 1 | J16: =IF(I16=1,H16,1E+99) -> 0.49819599 | N16: =Data!A226 -> 225 | O16: =Data!L226 -> 0 | P16: =IF(Data!C226<=$L$2,$L$4,$L$6) -> 0.045454545 | Q16: =IF(P16>=Controls!$B$2,1,0) -> 0 | R16: =--(Q16=O16) -> 1
A17: =Data!C17 -> 51 | B17: =COUNTIFS(Data!$M$2:$M$301,"Train",Data!$C$2:$C$301,"<="&A17) -> 155 | C17: =SUMIFS(Data!$L$2:$L$301,Data!$M$2:$M$301,"Train",Data!$C$2:$C$301,"<="&A17) -> 77 | D17: =COUNTIFS(Data!$M$2:$M$301,"Train",Data!$C$2:$C$301,">"&A17) -> 55 | E17: =SUMIFS(Data!$L$2:$L$301,Data!$M$2:$M$301,"Train",Data!$C$2:$C$301,">"&A17) -> 33 | F17: =IF(B17=0,0,1-(C17/B17)^2-(1-C17/B17)^2) -> 0.49997919 | G17: =IF(D17=0,0,1-(E17/D17)^2-(1-E17/D17)^2) -> 0.48 | H17: =IF(B17+D17=0,1,(B17*F17+D17*G17)/(B17+D17)) -> 0.49474654 | I17: =IF(AND(B17>0,D17>0),1,0) -> 1 | J17: =IF(I17=1,H17,1E+99) -> 0.49474654 | N17: =Data!A227 -> 226 | O17: =Data!L227 -> 0 | P17: =IF(Data!C227<=$L$2,$L$4,$L$6) -> 0.57978723 | Q17: =IF(P17>=Controls!$B$2,1,0) -> 1 | R17: =--(Q17=O17) -> 0
A18: =Data!C18 -> 37 | B18: =COUNTIFS(Data!$M$2:$M$301,"Train",Data!$C$2:$C$301,"<="&A18) -> 74 | C18: =SUMIFS(Data!$L$2:$L$301,Data!$M$2:$M$301,"Train",Data!$C$2:$C$301,"<="&A18) -> 26 | D18: =COUNTIFS(Data!$M$2:$M$301,"Train",Data!$C$2:$C$301,">"&A18) -> 136 | E18: =SUMIFS(Data!$L$2:$L$301,Data!$M$2:$M$301,"Train",Data!$C$2:$C$301,">"&A18) -> 84 | F18: =IF(B18=0,0,1-(C18/B18)^2-(1-C18/B18)^2) -> 0.45580716 | G18: =IF(D18=0,0,1-(E18/D18)^2-(1-E18/D18)^2) -> 0.47231834 | H18: =IF(B18+D18=0,1,(B18*F18+D18*G18)/(B18+D18)) -> 0.46650011 | I18: =IF(AND(B18>0,D18>0),1,0) -> 1 | J18: =IF(I18=1,H18,1E+99) -> 0.46650011 | N18: =Data!A228 -> 227 | O18: =Data!L228 -> 0 | P18: =IF(Data!C228<=$L$2,$L$4,$L$6) -> 0.045454545 | Q18: =IF(P18>=Controls!$B$2,1,0) -> 0 | R18: =--(Q18=O18) -> 1
A19: =Data!C19 -> 50 | B19: =COUNTIFS(Data!$M$2:$M$301,"Train",Data!$C$2:$C$301,"<="&A19) -> 149 | C19: =SUMIFS(Data!$L$2:$L$301,Data!$M$2:$M$301,"Train",Data!$C$2:$C$301,"<="&A19) -> 74 | D19: =COUNTIFS(Data!$M$2:$M$301,"Train",Data!$C$2:$C$301,">"&A19) -> 61 | E19: =SUMIFS(Data!$L$2:$L$301,Data!$M$2:$M$301,"Train",Data!$C$2:$C$301,">"&A19) -> 36 | F19: =IF(B19=0,0,1-(C19/B19)^2-(1-C19/B19)^2) -> 0.49997748 | G19: =IF(D19=0,0,1-(E19/D19)^2-(1-E19/D19)^2) -> 0.48374093 | H19: =IF(B19+D19=0,1,(B19*F19+D19*G19)/(B19+D19)) -> 0.49526115 | I19: =IF(AND(B19>0,D19>0),1,0) -> 1 | J19: =IF(I19=1,H19,1E+99) -> 0.49526115 | N19: =Data!A229 -> 228 | O19: =Data!L229 -> 0 | P19: =IF(Data!C229<=$L$2,$L$4,$L$6) -> 0.57978723 | Q19: =IF(P19>=Controls!$B$2,1,0) -> 1 | R19: =--(Q19=O19) -> 0
A20: =Data!C20 -> 56 | B20: =COUNTIFS(Data!$M$2:$M$301,"Train",Data!$C$2:$C$301,"<="&A20) -> 178 | C20: =SUMIFS(Data!$L$2:$L$301,Data!$M$2:$M$301,"Train",Data!$C$2:$C$301,"<="&A20) -> 92 | D20: =COUNTIFS(Data!$M$2:$M$301,"Train",Data!$C$2:$C$301,">"&A20) -> 32 | E20: =SUMIFS(Data!$L$2:$L$301,Data!$M$2:$M$301,"Train",Data!$C$2:$C$301,">"&A20) -> 18 | F20: =IF(B20=0,0,1-(C20/B20)^2-(1-C20/B20)^2) -> 0.49943189 | G20: =IF(D20=0,0,1-(E20/D20)^2-(1-E20/D20)^2) -> 0.4921875 | H20: =IF(B20+D20=0,1,(B20*F20+D20*G20)/(B20+D20)) -> 0.49832798 | I20: =IF(AND(B20>0,D20>0),1,0) -> 1 | J20: =IF(I20=1,H20,1E+99) -> 0.49832798 | N20: =Data!A230 -> 229 | O20: =Data!L230 -> 1 | P20: =IF(Data!C230<=$L$2,$L$4,$L$6) -> 0.57978723 | Q20: =IF(P20>=Controls!$B$2,1,0) -> 1 | R20: =--(Q20=O20) -> 1
A21: =Data!C21 -> 37 | B21: =COUNTIFS(Data!$M$2:$M$301,"Train",Data!$C$2:$C$301,"<="&A21) -> 74 | C21: =SUMIFS(Data!$L$2:$L$301,Data!$M$2:$M$301,"Train",Data!$C$2:$C$301,"<="&A21) -> 26 | D21: =COUNTIFS(Data!$M$2:$M$301,"Train",Data!$C$2:$C$301,">"&A21) -> 136 | E21: =SUMIFS(Data!$L$2:$L$301,Data!$M$2:$M$301,"Train",Data!$C$2:$C$301,">"&A21) -> 84 | F21: =IF(B21=0,0,1-(C21/B21)^2-(1-C21/B21)^2) -> 0.45580716 | G21: =IF(D21=0,0,1-(E21/D21)^2-(1-E21/D21)^2) -> 0.47231834 | H21: =IF(B21+D21=0,1,(B21*F21+D21*G21)/(B21+D21)) -> 0.46650011 | I21: =IF(AND(B21>0,D21>0),1,0) -> 1 | J21: =IF(I21=1,H21,1E+99) -> 0.46650011 | N21: =Data!A231 -> 230 | O21: =Data!L231 -> 0 | P21: =IF(Data!C231<=$L$2,$L$4,$L$6) -> 0.57978723 | Q21: =IF(P21>=Controls!$B$2,1,0) -> 1 | R21: =--(Q21=O21) -> 0
A22: =Data!C22 -> 38 | B22: =COUNTIFS(Data!$M$2:$M$301,"Train",Data!$C$2:$C$301,"<="&A22) -> 81 | C22: =SUMIFS(Data!$L$2:$L$301,Data!$M$2:$M$301,"Train",Data!$C$2:$C$301,"<="&A22) -> 32 | D22: =COUNTIFS(Data!$M$2:$M$301,"Train",Data!$C$2:$C$301,">"&A22) -> 129 | E22: =SUMIFS(Data!$L$2:$L$301,Data!$M$2:$M$301,"Train",Data!$C$2:$C$301,">"&A22) -> 78 | F22: =IF(B22=0,0,1-(C22/B22)^2-(1-C22/B22)^2) -> 0.47797592 | G22: =IF(D22=0,0,1-(E22/D22)^2-(1-E22/D22)^2) -> 0.47809627 | H22: =IF(B22+D22=0,1,(B22*F22+D22*G22)/(B22+D22)) -> 0.47804985 | I22: =IF(AND(B22>0,D22>0),1,0) -> 1 | J22: =IF(I22=1,H22,1E+99) -> 0.47804985 | N22: =Data!A232 -> 231 | O22: =Data!L232 -> 0 | P22: =IF(Data!C232<=$L$2,$L$4,$L$6) -> 0.57978723 | Q22: =IF(P22>=Controls!$B$2,1,0) -> 1 | R22: =--(Q22=O22) -> 0
A23: =Data!C23 -> 40 | B23: =COUNTIFS(Data!$M$2:$M$301,"Train",Data!$C$2:$C$301,"<="&A23) -> 95 | C23: =SUMIFS(Data!$L$2:$L$301,Data!$M$2:$M$301,"Train",Data!$C$2:$C$301,"<="&A23) -> 40 | D23: =COUNTIFS(Data!$M$2:$M$301,"Train",Data!$C$2:$C$301,">"&A23) -> 115 | E23: =SUMIFS(Data!$L$2:$L$301,Data!$M$2:$M$301,"Train",Data!$C$2:$C$301,">"&A23) -> 70 | F23: =IF(B23=0,0,1-(C23/B23)^2-(1-C23/B23)^2) -> 0.48753463 | G23: =IF(D23=0,0,1-(E23/D23)^2-(1-E23/D23)^2) -> 0.47637051 | H23: =IF(B23+D23=0,1,(B23*F23+D23*G23)/(B23+D23)) -> 0.48142094 | I23: =IF(AND(B23>0,D23>0),1,0) -> 1 | J23: =IF(I23=1,H23,1E+99) -> 0.48142094 | N23: =Data!A233 -> 232 | O23: =Data!L233 -> 1 | P23: =IF(Data!C233<=$L$2,$L$4,$L$6) -> 0.57978723 | Q23: =IF(P23>=Controls!$B$2,1,0) -> 1 | R23: =--(Q23=O23) -> 1
... A91: =Data!C91 -> 70 | B91: =COUNTIFS(Data!$M$2:$M$301,"Train",Data!$C$2:$C$301,"<="&A91) -> 207 | C91: =SUMIFS(Data!$L$2:$L$301,Data!$M$2:$M$301,"Train",Data!$C$2:$C$301,"<="&A91) -> 109 | D91: =COUNTIFS(Data!$M$2:$M$301,"Train",Data!$C$2:$C$301,">"&A91) -> 3 | E91: =SUMIFS(Data!$L$2:$L$301,Data!$M$2:$M$301,"Train",Data!$C$2:$C$301,">"&A91) -> 1 | F91: =IF(B91=0,0,1-(C91/B91)^2-(1-C91/B91)^2) -> 0.49858807 | G91: =IF(D91=0,0,1-(E91/D91)^2-(1-E91/D91)^2) -> 0.44444444 | H91: =IF(B91+D91=0,1,(B91*F91+D91*G91)/(B91+D91)) -> 0.49781458 | I91: =IF(AND(B91>0,D91>0),1,0) -> 1 | J91: =IF(I91=1,H91,1E+99) -> 0.49781458 | N91: =Data!A301 -> 300 | O91: =Data!L301 -> 0 | P91: =IF(Data!C301<=$L$2,$L$4,$L$6) -> 0.57978723 | Q91: =IF(P91>=Controls!$B$2,1,0) -> 1 | R91: =--(Q91=O91) -> 0
A92: =Data!C92 -> 47 | B92: =COUNTIFS(Data!$M$2:$M$301,"Train",Data!$C$2:$C$301,"<="&A92) -> 132 | C92: =SUMIFS(Data!$L$2:$L$301,Data!$M$2:$M$301,"Train",Data!$C$2:$C$301,"<="&A92) -> 60 | D92: =COUNTIFS(Data!$M$2:$M$301,"Train",Data!$C$2:$C$301,">"&A92) -> 78 | E92: =SUMIFS(Data!$L$2:$L$301,Data!$M$2:$M$301,"Train",Data!$C$2:$C$301,">"&A92) -> 50 | F92: =IF(B92=0,0,1-(C92/B92)^2-(1-C92/B92)^2) -> 0.49586777 | G92: =IF(D92=0,0,1-(E92/D92)^2-(1-E92/D92)^2) -> 0.46022354 | H92: =IF(B92+D92=0,1,(B92*F92+D92*G92)/(B92+D92)) -> 0.48262848 | I92: =IF(AND(B92>0,D92>0),1,0) -> 1 | J92: =IF(I92=1,H92,1E+99) -> 0.48262848
A93: =Data!C93 -> 46 | B93: =COUNTIFS(Data!$M$2:$M$301,"Train",Data!$C$2:$C$301,"<="&A93) -> 128 | C93: =SUMIFS(Data!$L$2:$L$301,Data!$M$2:$M$301,"Train",Data!$C$2:$C$301,"<="&A93) -> 56 | D93: =COUNTIFS(Data!$M$2:$M$301,"Train",Data!$C$2:$C$301,">"&A93) -> 82 | E93: =SUMIFS(Data!$L$2:$L$301,Data!$M$2:$M$301,"Train",Data!$C$2:$C$301,">"&A93) -> 54 | F93: =IF(B93=0,0,1-(C93/B93)^2-(1-C93/B93)^2) -> 0.4921875 | G93: =IF(D93=0,0,1-(E93/D93)^2-(1-E93/D93)^2) -> 0.4497323 | H93: =IF(B93+D93=0,1,(B93*F93+D93*G93)/(B93+D93)) -> 0.47560976 | I93: =IF(AND(B93>0,D93>0),1,0) -> 1 | J93: =IF(I93=1,H93,1E+99) -> 0.47560976
A94: =Data!C94 -> 33 | B94: =COUNTIFS(Data!$M$2:$M$301,"Train",Data!$C$2:$C$301,"<="&A94) -> 47 | C94: =SUMIFS(Data!$L$2:$L$301,Data!$M$2:$M$301,"Train",Data!$C$2:$C$301,"<="&A94) -> 14 | D94: =COUNTIFS(Data!$M$2:$M$301,"Train",Data!$C$2:$C$301,">"&A94) -> 163 | E94: =SUMIFS(Data!$L$2:$L$301,Data!$M$2:$M$301,"Train",Data!$C$2:$C$301,">"&A94) -> 96 | F94: =IF(B94=0,0,1-(C94/B94)^2-(1-C94/B94)^2) -> 0.41828882 | G94: =IF(D94=0,0,1-(E94/D94)^2-(1-E94/D94)^2) -> 0.48417328 | H94: =IF(B94+D94=0,1,(B94*F94+D94*G94)/(B94+D94)) -> 0.46942771 | I94: =IF(AND(B94>0,D94>0),1,0) -> 1 | J94: =IF(I94=1,H94,1E+99) -> 0.46942771 | N94: accuracy | O94: =AVERAGE(R2:R91) -> 0.57777778
A95: =Data!C95 -> 34 | B95: =COUNTIFS(Data!$M$2:$M$301,"Train",Data!$C$2:$C$301,"<="&A95) -> 55 | C95: =SUMIFS(Data!$L$2:$L$301,Data!$M$2:$M$301,"Train",Data!$C$2:$C$301,"<="&A95) -> 17 | D95: =COUNTIFS(Data!$M$2:$M$301,"Train",Data!$C$2:$C$301,">"&A95) -> 155 | E95: =SUMIFS(Data!$L$2:$L$301,Data!$M$2:$M$301,"Train",Data!$C$2:$C$301,">"&A95) -> 93 | F95: =IF(B95=0,0,1-(C95/B95)^2-(1-C95/B95)^2) -> 0.42710744 | G95: =IF(D95=0,0,1-(E95/D95)^2-(1-E95/D95)^2) -> 0.48 | H95: =IF(B95+D95=0,1,(B95*F95+D95*G95)/(B95+D95)) -> 0.46614719 | I95: =IF(AND(B95>0,D95>0),1,0) -> 1 | J95: =IF(I95=1,H95,1E+99) -> 0.46614719 | N95: TP | O95: =COUNTIFS(O2:O91,1,Q2:Q91,1) -> 46
A96: =Data!C96 -> 22 | B96: =COUNTIFS(Data!$M$2:$M$301,"Train",Data!$C$2:$C$301,"<="&A96) -> 8 | C96: =SUMIFS(Data!$L$2:$L$301,Data!$M$2:$M$301,"Train",Data!$C$2:$C$301,"<="&A96) -> 0 | D96: =COUNTIFS(Data!$M$2:$M$301,"Train",Data!$C$2:$C$301,">"&A96) -> 202 | E96: =SUMIFS(Data!$L$2:$L$301,Data!$M$2:$M$301,"Train",Data!$C$2:$C$301,">"&A96) -> 110 | F96: =IF(B96=0,0,1-(C96/B96)^2-(1-C96/B96)^2) -> 0 | G96: =IF(D96=0,0,1-(E96/D96)^2-(1-E96/D96)^2) -> 0.4960298 | H96: =IF(B96+D96=0,1,(B96*F96+D96*G96)/(B96+D96)) -> 0.47713343 | I96: =IF(AND(B96>0,D96>0),1,0) -> 1 | J96: =IF(I96=1,H96,1E+99) -> 0.47713343 | N96: TN | O96: =COUNTIFS(O2:O91,0,Q2:Q91,0) -> 6
A97: =Data!C97 -> 74 | B97: =COUNTIFS(Data!$M$2:$M$301,"Train",Data!$C$2:$C$301,"<="&A97) -> 209 | C97: =SUMIFS(Data!$L$2:$L$301,Data!$M$2:$M$301,"Train",Data!$C$2:$C$301,"<="&A97) -> 110 | D97: =COUNTIFS(Data!$M$2:$M$301,"Train",Data!$C$2:$C$301,">"&A97) -> 1 | E97: =SUMIFS(Data!$L$2:$L$301,Data!$M$2:$M$301,"Train",Data!$C$2:$C$301,">"&A97) -> 0 | F97: =IF(B97=0,0,1-(C97/B97)^2-(1-C97/B97)^2) -> 0.49861496 | G97: =IF(D97=0,0,1-(E97/D97)^2-(1-E97/D97)^2) -> 0 | H97: =IF(B97+D97=0,1,(B97*F97+D97*G97)/(B97+D97)) -> 0.4962406 | I97: =IF(AND(B97>0,D97>0),1,0) -> 1 | J97: =IF(I97=1,H97,1E+99) -> 0.4962406 | N97: FP | O97: =COUNTIFS(O2:O91,0,Q2:Q91,1) -> 37
A98: =Data!C98 -> 40 | B98: =COUNTIFS(Data!$M$2:$M$301,"Train",Data!$C$2:$C$301,"<="&A98) -> 95 | C98: =SUMIFS(Data!$L$2:$L$301,Data!$M$2:$M$301,"Train",Data!$C$2:$C$301,"<="&A98) -> 40 | D98: =COUNTIFS(Data!$M$2:$M$301,"Train",Data!$C$2:$C$301,">"&A98) -> 115 | E98: =SUMIFS(Data!$L$2:$L$301,Data!$M$2:$M$301,"Train",Data!$C$2:$C$301,">"&A98) -> 70 | F98: =IF(B98=0,0,1-(C98/B98)^2-(1-C98/B98)^2) -> 0.48753463 | G98: =IF(D98=0,0,1-(E98/D98)^2-(1-E98/D98)^2) -> 0.47637051 | H98: =IF(B98+D98=0,1,(B98*F98+D98*G98)/(B98+D98)) -> 0.48142094 | I98: =IF(AND(B98>0,D98>0),1,0) -> 1 | J98: =IF(I98=1,H98,1E+99) -> 0.48142094 | N98: FN | O98: =COUNTIFS(O2:O91,1,Q2:Q91,0) -> 1
A99: =Data!C99 -> 45 | B99: =COUNTIFS(Data!$M$2:$M$301,"Train",Data!$C$2:$C$301,"<="&A99) -> 123 | C99: =SUMIFS(Data!$L$2:$L$301,Data!$M$2:$M$301,"Train",Data!$C$2:$C$301,"<="&A99) -> 55 | D99: =COUNTIFS(Data!$M$2:$M$301,"Train",Data!$C$2:$C$301,">"&A99) -> 87 | E99: =SUMIFS(Data!$L$2:$L$301,Data!$M$2:$M$301,"Train",Data!$C$2:$C$301,">"&A99) -> 55 | F99: =IF(B99=0,0,1-(C99/B99)^2-(1-C99/B99)^2) -> 0.4944147 | G99: =IF(D99=0,0,1-(E99/D99)^2-(1-E99/D99)^2) -> 0.46505483 | H99: =IF(B99+D99=0,1,(B99*F99+D99*G99)/(B99+D99)) -> 0.48225132 | I99: =IF(AND(B99>0,D99>0),1,0) -> 1 | J99: =IF(I99=1,H99,1E+99) -> 0.48225132
A100: =Data!C100 -> 43 | B100: =COUNTIFS(Data!$M$2:$M$301,"Train",Data!$C$2:$C$301,"<="&A100) -> 113 | C100: =SUMIFS(Data!$L$2:$L$301,Data!$M$2:$M$301,"Train",Data!$C$2:$C$301,"<="&A100) -> 48 | D100: =COUNTIFS(Data!$M$2:$M$301,"Train",Data!$C$2:$C$301,">"&A100) -> 97 | E100: =SUMIFS(Data!$L$2:$L$301,Data!$M$2:$M$301,"Train",Data!$C$2:$C$301,">"&A100) -> 62 | F100: =IF(B100=0,0,1-(C100/B100)^2-(1-C100/B100)^2) -> 0.48868353 | G100: =IF(D100=0,0,1-(E100/D100)^2-(1-E100/D100)^2) -> 0.4612605 | H100: =IF(B100+D100=0,1,(B100*F100+D100*G100)/(B100+D100)) -> 0.4760167 | I100: =IF(AND(B100>0,D100>0),1,0) -> 1 | J100: =IF(I100=1,H100,1E+99) -> 0.4760167
A101: =Data!C101 -> 33 | B101: =COUNTIFS(Data!$M$2:$M$301,"Train",Data!$C$2:$C$301,"<="&A101) -> 47 | C101: =SUMIFS(Data!$L$2:$L$301,Data!$M$2:$M$301,"Train",Data!$C$2:$C$301,"<="&A101) -> 14 | D101: =COUNTIFS(Data!$M$2:$M$301,"Train",Data!$C$2:$C$301,">"&A101) -> 163 | E101: =SUMIFS(Data!$L$2:$L$301,Data!$M$2:$M$301,"Train",Data!$C$2:$C$301,">"&A101) -> 96 | F101: =IF(B101=0,0,1-(C101/B101)^2-(1-C101/B101)^2) -> 0.41828882 | G101: =IF(D101=0,0,1-(E101/D101)^2-(1-E101/D101)^2) -> 0.48417328 | H101: =IF(B101+D101=0,1,(B101*F101+D101*G101)/(B101+D101)) -> 0.46942771 | I101: =IF(AND(B101>0,D101>0),1,0) -> 1 | J101: =IF(I101=1,H101,1E+99) -> 0.46942771
A102: =Data!C102 -> 62 | B102: =COUNTIFS(Data!$M$2:$M$301,"Train",Data!$C$2:$C$301,"<="&A102) -> 200 | C102: =SUMIFS(Data!$L$2:$L$301,Data!$M$2:$M$301,"Train",Data!$C$2:$C$301,"<="&A102) -> 107 | D102: =COUNTIFS(Data!$M$2:$M$301,"Train",Data!$C$2:$C$301,">"&A102) -> 10 | E102: =SUMIFS(Data!$L$2:$L$301,Data!$M$2:$M$301,"Train",Data!$C$2:$C$301,">"&A102) -> 3 | F102: =IF(B102=0,0,1-(C102/B102)^2-(1-C102/B102)^2) -> 0.49755 | G102: =IF(D102=0,0,1-(E102/D102)^2-(1-E102/D102)^2) -> 0.42 | H102: =IF(B102+D102=0,1,(B102*F102+D102*G102)/(B102+D102)) -> 0.49385714 | I102: =IF(AND(B102>0,D102>0),1,0) -> 1 | J102: =IF(I102=1,H102,1E+99) -> 0.49385714
A103: =Data!C103 -> 37 | B103: =COUNTIFS(Data!$M$2:$M$301,"Train",Data!$C$2:$C$301,"<="&A103) -> 74 | C103: =SUMIFS(Data!$L$2:$L$301,Data!$M$2:$M$301,"Train",Data!$C$2:$C$301,"<="&A103) -> 26 | D103: =COUNTIFS(Data!$M$2:$M$301,"Train",Data!$C$2:$C$301,">"&A103) -> 136 | E103: =SUMIFS(Data!$L$2:$L$301,Data!$M$2:$M$301,"Train",Data!$C$2:$C$301,">"&A103) -> 84 | F103: =IF(B103=0,0,1-(C103/B103)^2-(1-C103/B103)^2) -> 0.45580716 | G103: =IF(D103=0,0,1-(E103/D103)^2-(1-E103/D103)^2) -> 0.47231834 | H103: =IF(B103+D103=0,1,(B103*F103+D103*G103)/(B103+D103)) -> 0.46650011 | I103: =IF(AND(B103>0,D103>0),1,0) -> 1 | J103: =IF(I103=1,H103,1E+99) -> 0.46650011
A104: =Data!C104 -> 54 | B104: =COUNTIFS(Data!$M$2:$M$301,"Train",Data!$C$2:$C$301,"<="&A104) -> 169 | C104: =SUMIFS(Data!$L$2:$L$301,Data!$M$2:$M$301,"Train",Data!$C$2:$C$301,"<="&A104) -> 87 | D104: =COUNTIFS(Data!$M$2:$M$301,"Train",Data!$C$2:$C$301,">"&A104) -> 41 | E104: =SUMIFS(Data!$L$2:$L$301,Data!$M$2:$M$301,"Train",Data!$C$2:$C$301,">"&A104) -> 23 | F104: =IF(B104=0,0,1-(C104/B104)^2-(1-C104/B104)^2) -> 0.49956234 | G104: =IF(D104=0,0,1-(E104/D104)^2-(1-E104/D104)^2) -> 0.49256395 | H104: =IF(B104+D104=0,1,(B104*F104+D104*G104)/(B104+D104)) -> 0.49819599 | I104: =IF(AND(B104>0,D104>0),1,0) -> 1 | J104: =IF(I104=1,H104,1E+99) -> 0.49819599
A105: =Data!C105 -> 34 | B105: =COUNTIFS(Data!$M$2:$M$301,"Train",Data!$C$2:$C$301,"<="&A105) -> 55 | C105: =SUMIFS(Data!$L$2:$L$301,Data!$M$2:$M$301,"Train",Data!$C$2:$C$301,"<="&A105) -> 17 | D105: =COUNTIFS(Data!$M$2:$M$301,"Train",Data!$C$2:$C$301,">"&A105) -> 155 | E105: =SUMIFS(Data!$L$2:$L$301,Data!$M$2:$M$301,"Train",Data!$C$2:$C$301,">"&A105) -> 93 | F105: =IF(B105=0,0,1-(C105/B105)^2-(1-C105/B105)^2) -> 0.42710744 | G105: =IF(D105=0,0,1-(E105/D105)^2-(1-E105/D105)^2) -> 0.48 | H105: =IF(B105+D105=0,1,(B105*F105+D105*G105)/(B105+D105)) -> 0.46614719 | I105: =IF(AND(B105>0,D105>0),1,0) -> 1 | J105: =IF(I105=1,H105,1E+99) -> 0.46614719
A106: =Data!C106 -> 50 | B106: =COUNTIFS(Data!$M$2:$M$301,"Train",Data!$C$2:$C$301,"<="&A106) -> 149 | C106: =SUMIFS(Data!$L$2:$L$301,Data!$M$2:$M$301,"Train",Data!$C$2:$C$301,"<="&A106) -> 74 | D106: =COUNTIFS(Data!$M$2:$M$301,"Train",Data!$C$2:$C$301,">"&A106) -> 61 | E106: =SUMIFS(Data!$L$2:$L$301,Data!$M$2:$M$301,"Train",Data!$C$2:$C$301,">"&A106) -> 36 | F106: =IF(B106=0,0,1-(C106/B106)^2-(1-C106/B106)^2) -> 0.49997748 | G106: =IF(D106=0,0,1-(E106/D106)^2-(1-E106/D106)^2) -> 0.48374093 | H106: =IF(B106+D106=0,1,(B106*F106+D106*G106)/(B106+D106)) -> 0.49526115 | I106: =IF(AND(B106>0,D106>0),1,0) -> 1 | J106: =IF(I106=1,H106,1E+99) -> 0.49526115
A107: =Data!C107 -> 46 | B107: =COUNTIFS(Data!$M$2:$M$301,"Train",Data!$C$2:$C$301,"<="&A107) -> 128 | C107: =SUMIFS(Data!$L$2:$L$301,Data!$M$2:$M$301,"Train",Data!$C$2:$C$301,"<="&A107) -> 56 | D107: =COUNTIFS(Data!$M$2:$M$301,"Train",Data!$C$2:$C$301,">"&A107) -> 82 | E107: =SUMIFS(Data!$L$2:$L$301,Data!$M$2:$M$301,"Train",Data!$C$2:$C$301,">"&A107) -> 54 | F107: =IF(B107=0,0,1-(C107/B107)^2-(1-C107/B107)^2) -> 0.4921875 | G107: =IF(D107=0,0,1-(E107/D107)^2-(1-E107/D107)^2) -> 0.4497323 | H107: =IF(B107+D107=0,1,(B107*F107+D107*G107)/(B107+D107)) -> 0.47560976 | I107: =IF(AND(B107>0,D107>0),1,0) -> 1 | J107: =IF(I107=1,H107,1E+99) -> 0.47560976
...

Sheet ROC_Mechanics
A1: threshold | B1: TP | C1: FP | D1: TN | E1: FN | F1: TPR | G1: FPR | I1: approx_auc
A2: 0 | B2: =COUNTIFS(ClassTree!$O$2:$O$91,1,ClassTree!$P$2:$P$91,">="&A2) -> 47 | C2: =COUNTIFS(ClassTree!$O$2:$O$91,0,ClassTree!$P$2:$P$91,">="&A2) -> 43 | D2: =COUNTIFS(ClassTree!$O$2:$O$91,0,ClassTree!$P$2:$P$91,"<"&A2) -> 0 | E2: =COUNTIFS(ClassTree!$O$2:$O$91,1,ClassTree!$P$2:$P$91,"<"&A2) -> 0 | F2: =IF(B2+E2=0,0,B2/(B2+E2)) -> 1 | G2: =IF(C2+D2=0,0,C2/(C2+D2)) -> 1 | I2: =SUMPRODUCT((G2:G21-G3:G22),(F2:F21+F3:F22)/2) -> 0.55912914
A3: 0.05 | B3: =COUNTIFS(ClassTree!$O$2:$O$91,1,ClassTree!$P$2:$P$91,">="&A3) -> 46 | C3: =COUNTIFS(ClassTree!$O$2:$O$91,0,ClassTree!$P$2:$P$91,">="&A3) -> 37 | D3: =COUNTIFS(ClassTree!$O$2:$O$91,0,ClassTree!$P$2:$P$91,"<"&A3) -> 6 | E3: =COUNTIFS(ClassTree!$O$2:$O$91,1,ClassTree!$P$2:$P$91,"<"&A3) -> 1 | F3: =IF(B3+E3=0,0,B3/(B3+E3)) -> 0.9787234 | G3: =IF(C3+D3=0,0,C3/(C3+D3)) -> 0.86046512
A4: 0.1 | B4: =COUNTIFS(ClassTree!$O$2:$O$91,1,ClassTree!$P$2:$P$91,">="&A4) -> 46 | C4: =COUNTIFS(ClassTree!$O$2:$O$91,0,ClassTree!$P$2:$P$91,">="&A4) -> 37 | D4: =COUNTIFS(ClassTree!$O$2:$O$91,0,ClassTree!$P$2:$P$91,"<"&A4) -> 6 | E4: =COUNTIFS(ClassTree!$O$2:$O$91,1,ClassTree!$P$2:$P$91,"<"&A4) -> 1 | F4: =IF(B4+E4=0,0,B4/(B4+E4)) -> 0.9787234 | G4: =IF(C4+D4=0,0,C4/(C4+D4)) -> 0.86046512
A5: 0.15 | B5: =COUNTIFS(ClassTree!$O$2:$O$91,1,ClassTree!$P$2:$P$91,">="&A5) -> 46 | C5: =COUNTIFS(ClassTree!$O$2:$O$91,0,ClassTree!$P$2:$P$91,">="&A5) -> 37 | D5: =COUNTIFS(ClassTree!$O$2:$O$91,0,ClassTree!$P$2:$P$91,"<"&A5) -> 6 | E5: =COUNTIFS(ClassTree!$O$2:$O$91,1,ClassTree!$P$2:$P$91,"<"&A5) -> 1 | F5: =IF(B5+E5=0,0,B5/(B5+E5)) -> 0.9787234 | G5: =IF(C5+D5=0,0,C5/(C5+D5)) -> 0.86046512
A6: 0.2 | B6: =COUNTIFS(ClassTree!$O$2:$O$91,1,ClassTree!$P$2:$P$91,">="&A6) -> 46 | C6: =COUNTIFS(ClassTree!$O$2:$O$91,0,ClassTree!$P$2:$P$91,">="&A6) -> 37 | D6: =COUNTIFS(ClassTree!$O$2:$O$91,0,ClassTree!$P$2:$P$91,"<"&A6) -> 6 | E6: =COUNTIFS(ClassTree!$O$2:$O$91,1,ClassTree!$P$2:$P$91,"<"&A6) -> 1 | F6: =IF(B6+E6=0,0,B6/(B6+E6)) -> 0.9787234 | G6: =IF(C6+D6=0,0,C6/(C6+D6)) -> 0.86046512
A7: 0.25 | B7: =COUNTIFS(ClassTree!$O$2:$O$91,1,ClassTree!$P$2:$P$91,">="&A7) -> 46 | C7: =COUNTIFS(ClassTree!$O$2:$O$91,0,ClassTree!$P$2:$P$91,">="&A7) -> 37 | D7: =COUNTIFS(ClassTree!$O$2:$O$91,0,ClassTree!$P$2:$P$91,"<"&A7) -> 6 | E7: =COUNTIFS(ClassTree!$O$2:$O$91,1,ClassTree!$P$2:$P$91,"<"&A7) -> 1 | F7: =IF(B7+E7=0,0,B7/(B7+E7)) -> 0.9787234 | G7: =IF(C7+D7=0,0,C7/(C7+D7)) -> 0.86046512
A8: 0.3 | B8: =COUNTIFS(ClassTree!$O$2:$O$91,1,ClassTree!$P$2:$P$91,">="&A8) -> 46 | C8: =COUNTIFS(ClassTree!$O$2:$O$91,0,ClassTree!$P$2:$P$91,">="&A8) -> 37 | D8: =COUNTIFS(ClassTree!$O$2:$O$91,0,ClassTree!$P$2:$P$91,"<"&A8) -> 6 | E8: =COUNTIFS(ClassTree!$O$2:$O$91,1,ClassTree!$P$2:$P$91,"<"&A8) -> 1 | F8: =IF(B8+E8=0,0,B8/(B8+E8)) -> 0.9787234 | G8: =IF(C8+D8=0,0,C8/(C8+D8)) -> 0.86046512
A9: 0.35 | B9: =COUNTIFS(ClassTree!$O$2:$O$91,1,ClassTree!$P$2:$P$91,">="&A9) -> 46 | C9: =COUNTIFS(ClassTree!$O$2:$O$91,0,ClassTree!$P$2:$P$91,">="&A9) -> 37 | D9: =COUNTIFS(ClassTree!$O$2:$O$91,0,ClassTree!$P$2:$P$91,"<"&A9) -> 6 | E9: =COUNTIFS(ClassTree!$O$2:$O$91,1,ClassTree!$P$2:$P$91,"<"&A9) -> 1 | F9: =IF(B9+E9=0,0,B9/(B9+E9)) -> 0.9787234 | G9: =IF(C9+D9=0,0,C9/(C9+D9)) -> 0.86046512
A10: 0.4 | B10: =COUNTIFS(ClassTree!$O$2:$O$91,1,ClassTree!$P$2:$P$91,">="&A10) -> 46 | C10: =COUNTIFS(ClassTree!$O$2:$O$91,0,ClassTree!$P$2:$P$91,">="&A10) -> 37 | D10: =COUNTIFS(ClassTree!$O$2:$O$91,0,ClassTree!$P$2:$P$91,"<"&A10) -> 6 | E10: =COUNTIFS(ClassTree!$O$2:$O$91,1,ClassTree!$P$2:$P$91,"<"&A10) -> 1 | F10: =IF(B10+E10=0,0,B10/(B10+E10)) -> 0.9787234 | G10: =IF(C10+D10=0,0,C10/(C10+D10)) -> 0.86046512
A11: 0.45 | B11: =COUNTIFS(ClassTree!$O$2:$O$91,1,ClassTree!$P$2:$P$91,">="&A11) -> 46 | C11: =COUNTIFS(ClassTree!$O$2:$O$91,0,ClassTree!$P$2:$P$91,">="&A11) -> 37 | D11: =COUNTIFS(ClassTree!$O$2:$O$91,0,ClassTree!$P$2:$P$91,"<"&A11) -> 6 | E11: =COUNTIFS(ClassTree!$O$2:$O$91,1,ClassTree!$P$2:$P$91,"<"&A11) -> 1 | F11: =IF(B11+E11=0,0,B11/(B11+E11)) -> 0.9787234 | G11: =IF(C11+D11=0,0,C11/(C11+D11)) -> 0.86046512
A12: 0.5 | B12: =COUNTIFS(ClassTree!$O$2:$O$91,1,ClassTree!$P$2:$P$91,">="&A12) -> 46 | C12: =COUNTIFS(ClassTree!$O$2:$O$91,0,ClassTree!$P$2:$P$91,">="&A12) -> 37 | D12: =COUNTIFS(ClassTree!$O$2:$O$91,0,ClassTree!$P$2:$P$91,"<"&A12) -> 6 | E12: =COUNTIFS(ClassTree!$O$2:$O$91,1,ClassTree!$P$2:$P$91,"<"&A12) -> 1 | F12: =IF(B12+E12=0,0,B12/(B12+E12)) -> 0.9787234 | G12: =IF(C12+D12=0,0,C12/(C12+D12)) -> 0.86046512
A13: 0.55 | B13: =COUNTIFS(ClassTree!$O$2:$O$91,1,ClassTree!$P$2:$P$91,">="&A13) -> 46 | C13: =COUNTIFS(ClassTree!$O$2:$O$91,0,ClassTree!$P$2:$P$91,">="&A13) -> 37 | D13: =COUNTIFS(ClassTree!$O$2:$O$91,0,ClassTree!$P$2:$P$91,"<"&A13) -> 6 | E13: =COUNTIFS(ClassTree!$O$2:$O$91,1,ClassTree!$P$2:$P$91,"<"&A13) -> 1 | F13: =IF(B13+E13=0,0,B13/(B13+E13)) -> 0.9787234 | G13: =IF(C13+D13=0,0,C13/(C13+D13)) -> 0.86046512
A14: 0.6 | B14: =COUNTIFS(ClassTree!$O$2:$O$91,1,ClassTree!$P$2:$P$91,">="&A14) -> 0 | C14: =COUNTIFS(ClassTree!$O$2:$O$91,0,ClassTree!$P$2:$P$91,">="&A14) -> 0 | D14: =COUNTIFS(ClassTree!$O$2:$O$91,0,ClassTree!$P$2:$P$91,"<"&A14) -> 43 | E14: =COUNTIFS(ClassTree!$O$2:$O$91,1,ClassTree!$P$2:$P$91,"<"&A14) -> 47 | F14: =IF(B14+E14=0,0,B14/(B14+E14)) -> 0 | G14: =IF(C14+D14=0,0,C14/(C14+D14)) -> 0
... A22: 1 | B22: =COUNTIFS(ClassTree!$O$2:$O$91,1,ClassTree!$P$2:$P$91,">="&A22) -> 0 | C22: =COUNTIFS(ClassTree!$O$2:$O$91,0,ClassTree!$P$2:$P$91,">="&A22) -> 0 | D22: =COUNTIFS(ClassTree!$O$2:$O$91,0,ClassTree!$P$2:$P$91,"<"&A22) -> 43 | E22: =COUNTIFS(ClassTree!$O$2:$O$91,1,ClassTree!$P$2:$P$91,"<"&A22) -> 47 | F22: =IF(B22+E22=0,0,B22/(B22+E22)) -> 0 | G22: =IF(C22+D22=0,0,C22/(C22+D22)) -> 0

Sheet RF_Mechanics
A1: tree | B1: feature_used | C1: threshold | D1: left_prob_high | E1: right_prob_high | F1: left_class | G1: right_class | I1: test_id | J1: actual | K1: tree_01_pred | L1: tree_02_pred | M1: tree_03_pred | N1: tree_04_pred | O1: tree_05_pred | P1: tree_06_pred | Q1: tree_07_pred | R1: tree_08_pred | S1: tree_09_pred | T1: tree_10_pred | U1: tree_11_pred | V1: tree_12_pred | W1: tree_13_pred | X1: tree_14_pred | Y1: tree_15_pred | Z1: tree_16_pred | AA1: tree_17_pred | AB1: tree_18_pred | AC1: tree_19_pred | AD1: tree_20_pred | AE1: tree_21_pred | AF1: tree_22_pred | AG1: tree_23_pred | AH1: tree_24_pred | AI1: tree_25_pred | AJ1: vote_prob_high | AK1: pred_class | AL1: correct
A2: 1 | B2: =IF(MOD(1,2)=1,"age","year") -> age | C2: =IF(B2="age",INDEX(Data!$C$2:$C$301,1+MOD(INT(ABS(SIN((1*41+ROW()))*1000000)),300)),INDEX(Data!$B$2:$B$301,1+MOD(INT(ABS(SIN((1*53+ROW()))*1000000)),300))) -> 50 | D2: =IF(B2="age",IFERROR(AVERAGEIFS(Data!$L$2:$L$301,Data!$M$2:$M$301,"Train",Data!$C$2:$C$301,"<="&C2),0),IFERROR(AVERAGEIFS(Data!$L$2:$L$301,Data!$M$2:$M$301,"Train",Data!$B$2:$B$301,"<="&C2),0)) -> 0.4966443 | E2: =IF(B2="age",IFERROR(AVERAGEIFS(Data!$L$2:$L$301,Data!$M$2:$M$301,"Train",Data!$C$2:$C$301,">"&C2),0),IFERROR(AVERAGEIFS(Data!$L$2:$L$301,Data!$M$2:$M$301,"Train",Data!$B$2:$B$301,">"&C2),0)) -> 0.59016393 | F2: =IF(D2>=Controls!$B$2,1,0) -> 0 | G2: =IF(E2>=Controls!$B$2,1,0) -> 1 | I2: =Data!A206 -> 205 | J2: =Data!L206 -> 1 | K2: =IF($B$2="age",IF(Data!C206<=$C$2,$F$2,$G$2),IF(Data!B206<=$C$2,$F$2,$G$2)) -> 0 | L2: =IF($B$3="age",IF(Data!C206<=$C$3,$F$3,$G$3),IF(Data!B206<=$C$3,$F$3,$G$3)) -> 1 | M2: =IF($B$4="age",IF(Data!C206<=$C$4,$F$4,$G$4),IF(Data!B206<=$C$4,$F$4,$G$4)) -> 1 | N2: =IF($B$5="age",IF(Data!C206<=$C$5,$F$5,$G$5),IF(Data!B206<=$C$5,$F$5,$G$5)) -> 1 | O2: =IF($B$6="age",IF(Data!C206<=$C$6,$F$6,$G$6),IF(Data!B206<=$C$6,$F$6,$G$6)) -> 1 | P2: =IF($B$7="age",IF(Data!C206<=$C$7,$F$7,$G$7),IF(Data!B206<=$C$7,$F$7,$G$7)) -> 1 | Q2: =IF($B$8="age",IF(Data!C206<=$C$8,$F$8,$G$8),IF(Data!B206<=$C$8,$F$8,$G$8)) -> 1 | R2: =IF($B$9="age",IF(Data!C206<=$C$9,$F$9,$G$9),IF(Data!B206<=$C$9,$F$9,$G$9)) -> 1 | S2: =IF($B$10="age",IF(Data!C206<=$C$10,$F$10,$G$10),IF(Data!B206<=$C$10,$F$10,$G$10)) -> 0 | T2: =IF($B$11="age",IF(Data!C206<=$C$11,$F$11,$G$11),IF(Data!B206<=$C$11,$F$11,$G$11)) -> 1 | U2: =IF($B$12="age",IF(Data!C206<=$C$12,$F$12,$G$12),IF(Data!B206<=$C$12,$F$12,$G$12)) -> 1 | V2: =IF($B$13="age",IF(Data!C206<=$C$13,$F$13,$G$13),IF(Data!B206<=$C$13,$F$13,$G$13)) -> 1 | W2: =IF($B$14="age",IF(Data!C206<=$C$14,$F$14,$G$14),IF(Data!B206<=$C$14,$F$14,$G$14)) -> 1 | X2: =IF($B$15="age",IF(Data!C206<=$C$15,$F$15,$G$15),IF(Data!B206<=$C$15,$F$15,$G$15)) -> 1 | Y2: =IF($B$16="age",IF(Data!C206<=$C$16,$F$16,$G$16),IF(Data!B206<=$C$16,$F$16,$G$16)) -> 1 | Z2: =IF($B$17="age",IF(Data!C206<=$C$17,$F$17,$G$17),IF(Data!B206<=$C$17,$F$17,$G$17)) -> 0 | AA2: =IF($B$18="age",IF(Data!C206<=$C$18,$F$18,$G$18),IF(Data!B206<=$C$18,$F$18,$G$18)) -> 1 | AB2: =IF($B$19="age",IF(Data!C206<=$C$19,$F$19,$G$19),IF(Data!B206<=$C$19,$F$19,$G$19)) -> 1 | AC2: =IF($B$20="age",IF(Data!C206<=$C$20,$F$20,$G$20),IF(Data!B206<=$C$20,$F$20,$G$20)) -> 1 | AD2: =IF($B$21="age",IF(Data!C206<=$C$21,$F$21,$G$21),IF(Data!B206<=$C$21,$F$21,$G$21)) -> 0 | AE2: =IF($B$22="age",IF(Data!C206<=$C$22,$F$22,$G$22),IF(Data!B206<=$C$22,$F$22,$G$22)) -> 1 | AF2: =IF($B$23="age",IF(Data!C206<=$C$23,$F$23,$G$23),IF(Data!B206<=$C$23,$F$23,$G$23)) -> 1 | AG2: =IF($B$24="age",IF(Data!C206<=$C$24,$F$24,$G$24),IF(Data!B206<=$C$24,$F$24,$G$24)) -> 1 | AH2: =IF($B$25="age",IF(Data!C206<=$C$25,$F$25,$G$25),IF(Data!B206<=$C$25,$F$25,$G$25)) -> 1 | AI2: =IF($B$26="age",IF(Data!C206<=$C$26,$F$26,$G$26),IF(Data!B206<=$C$26,$F$26,$G$26)) -> 1 | AJ2: =AVERAGE(K2:AI2) -> 0.84 | AK2: =IF(AJ2>=Controls!$B$2,1,0) -> 1 | AL2: =--(AK2=J2) -> 1
